Workbook
Name cv_rev: 'Setup'!$B$4
Name cv_gp: 'Setup'!$B$5
Name cv_opex: 'Setup'!$B$6
Name cv_da: 'Setup'!$B$7
Name cv_capex: 'Setup'!$B$8
Name dv_rate: 'Setup'!$B$9
Name dv_tax: 'Setup'!$B$10
Name dv_debt: 'Setup'!$B$11
Name dv_cash: 'Setup'!$B$12
Name dv_n: 'Setup'!$B$13

Sheet README
A1: K08 · Divestiture / Carve-out & Leverage Sensitivity (no-code kernel)
A3: Replaces openfpa: pyfpa.analysis.divestiture (Carveout, divest, net_debt_to_ebitda) and the Fox Factory Marucci sensitivity grid.
A4: 1. Paste K01 'Export_Rows' VALUES (not formulas) into 'Forecast' (one row per month).
A5: 2. Enter the unit's MONTHLY contribution on 'Setup' (revenue, gross profit, opex, D&A, capex - positive numbers), interest rate on retired debt, tax rate, debt balance and cash for leverage.
A6: 3. Define up to 10 scenarios (label, sale_month = months RETAINED before the sale closes, proceeds). Slot 0 is always 'Hold'.
A7: Rules: from month sale_month+1 onward the carve-out is removed; interest falls by proceeds x rate / 12; tax = max(0, pre-tax) x tax rate (no loss carryforward); WC impact and principal held constant; one-time proceeds are EXCLUDED from FCF; ending cash is rebuilt from cumulative change in cash. The input forecast is never altered.
A8: Leverage = (debt - proceeds - cash) / EBITDA of the FINAL 12 months (run-rate). Negative = 'net cash'. Zero EBITDA = 'inf'.

Sheet Checks
A1: Checks - OVERALL must be PASS
B3: OVERALL | C3: =IF(COUNTIF(C5:C8,"PASS")=COUNT(A5:A8),"PASS","FAIL") | D3: =COUNTIF(C5:C8,"PASS")&" pass / "&COUNTIF(C5:C8,"FAIL")&" fail / "&(COUNT(A5:A8)-COUNTIF(C5:C8,"PASS")-COUNTIF(C5:C8,"FAIL"))&" error"
A4: # | B4: check | C4: result | D4: detail
A5: 1 | B5: forecast rows supplied | C5: =IF(Setup!$B$13>0,"PASS","FAIL") | D5: =Setup!$B$13
A6: 2 | B6: carve-out inputs >= 0 | C6: =IF(AND(Setup!$B$4>=0,Setup!$B$5>=0,Setup!$B$6>=0,Setup!$B$7>=0,Setup!$B$8>=0),"PASS","FAIL")
A7: 3 | B7: Hold scenario reproduces input FCF | C7: =IF(ABS(Grid!E5-SUM(Forecast!O5:O124))<0.005,"PASS","FAIL")
A8: 4 | B8: every scenario's sale_month is a whole number >= 0 | C8: =IF(SUMPRODUCT((Setup!B18:B27<>"")*((Setup!C18:C27<0)+(INT(N(Setup!C18:C27))<>N(Setup!C18:C27))))=0,"PASS","FAIL")

Sheet Setup
A1: Setup
A4: carve-out monthly revenue | B4: 25000000
A5: carve-out monthly gross_profit | B5: 12500000
A6: carve-out monthly opex | B6: 6250000
A7: carve-out monthly D&A | B7: 1833333.3
A8: carve-out monthly capex | B8: 416666.67
A9: annual rate on debt retired by proceeds | B9: 0.08
A10: tax rate for post-sale months | B10: 0.22
A11: debt balance for leverage | B11: 523538000
A12: cash for leverage (0 = gross of cash) | B12: 0
A13: months in forecast | B13: =SUMPRODUCT((Forecast!A5:A124<>"")*1)
A16: slot | B16: scenario label | C16: sale_month (months retained) | D16: proceeds
A17: 0 | B17: Hold | C17: =9999 | D17: 0
A18: 1 | B18: Sell at 6mo | C18: 6 | D18: 300000000
A19: 2 | B19: Sell at 12mo | C19: 12 | D19: 300000000
A20: 3 | B20: Sell at 18mo | C20: 18 | D20: 300000000
A21: 4 | B21: Sell at 24mo | C21: 24 | D21: 300000000
A22: 5 | B22: At cost (~$567M paid) @12mo | C22: 12 | D22: 567194000
A23: 6 | B23: Default markdown @12mo | C23: 12 | D23: 300000000
A24: 7 | B24: 8x EBITDA @12mo | C24: 12 | D24: 600000000
A25: 8 | B25: 12x EBITDA @12mo | C25: 12 | D25: 900000000
A26: 9
A27: 10

Sheet Forecast
A1: Forecast input - paste K01 Export_Rows values (month rows)
A4: month_no | B4: revenue | C4: gross_profit | D4: opex | E4: ebitda | F4: da | G4: interest | H4: pretax_income | I4: tax | J4: net_income | K4: wc_cash_impact | L4: operating_cash_flow | M4: capex | N4: principal | O4: free_cash_flow | P4: change_in_cash | Q4: ending_cash
A5: 1 | B5: 1.2671089e+08 | C5: 38279360 | D5: 18550253 | E5: 19729107 | F5: 7333333.3 | G5: 3490253.3 | H5: 8905520.2 | I5: 1959214.5 | J5: 6946305.8 | K5: -15872934 | L5: -1593295.3 | M5: 3500000 | N5: 2083333.3 | O5: -5093295.3 | P5: -7176628.6 | Q5: 50831371
A6: 2 | B6: 1.2671089e+08 | C6: 38279360 | D6: 18550253 | E6: 19729107 | F6: 7333333.3 | G6: 3476364.4 | H6: 8919409.1 | I6: 1962270 | J6: 6957139.1 | K6: 0 | L6: 14290472 | M6: 3500000 | N6: 2083333.3 | O6: 10790472 | P6: 8707139.1 | Q6: 59538511
A7: 3 | B7: 1.2671089e+08 | C7: 38279360 | D7: 18550253 | E7: 19729107 | F7: 7333333.3 | G7: 3462475.6 | H7: 8933298 | I7: 1965325.6 | J7: 6967972.5 | K7: 0 | L7: 14301306 | M7: 3500000 | N7: 2083333.3 | O7: 10801306 | P7: 8717972.5 | Q7: 68256483
A8: 4 | B8: 1.2671089e+08 | C8: 38279360 | D8: 18550253 | E8: 19729107 | F8: 7333333.3 | G8: 3448586.7 | H8: 8947186.9 | I8: 1968381.1 | J8: 6978805.8 | K8: 0 | L8: 14312139 | M8: 3500000 | N8: 2083333.3 | O8: 10812139 | P8: 8728805.8 | Q8: 76985289
A9: 5 | B9: 1.2671089e+08 | C9: 38279360 | D9: 18550253 | E9: 19729107 | F9: 7333333.3 | G9: 3434697.8 | H9: 8961075.8 | I9: 1971436.7 | J9: 6989639.1 | K9: 0 | L9: 14322972 | M9: 3500000 | N9: 2083333.3 | O9: 10822972 | P9: 8739639.1 | Q9: 85724928
A10: 6 | B10: 1.2671089e+08 | C10: 38279360 | D10: 18550253 | E10: 19729107 | F10: 7333333.3 | G10: 3420808.9 | H10: 8974964.7 | I10: 1974492.2 | J10: 7000472.5 | K10: 0 | L10: 14333806 | M10: 3500000 | N10: 2083333.3 | O10: 10833806 | P10: 8750472.5 | Q10: 94475400
A11: 7 | B11: 1.2671089e+08 | C11: 38279360 | D11: 18550253 | E11: 19729107 | F11: 7333333.3 | G11: 3406920 | H11: 8988853.6 | I11: 1977547.8 | J11: 7011305.8 | K11: 0 | L11: 14344639 | M11: 3500000 | N11: 2083333.3 | O11: 10844639 | P11: 8761305.8 | Q11: 1.0323671e+08
A12: 8 | B12: 1.2671089e+08 | C12: 38279360 | D12: 18550253 | E12: 19729107 | F12: 7333333.3 | G12: 3393031.1 | H12: 9002742.5 | I12: 1980603.3 | J12: 7022139.1 | K12: 0 | L12: 14355472 | M12: 3500000 | N12: 2083333.3 | O12: 10855472 | P12: 8772139.1 | Q12: 1.1200885e+08
A13: 9 | B13: 1.2671089e+08 | C13: 38279360 | D13: 18550253 | E13: 19729107 | F13: 7333333.3 | G13: 3379142.2 | H13: 9016631.3 | I13: 1983658.9 | J13: 7032972.5 | K13: 0 | L13: 14366306 | M13: 3500000 | N13: 2083333.3 | O13: 10866306 | P13: 8782972.5 | Q13: 1.2079182e+08
A14: 10 | B14: 1.2671089e+08 | C14: 38279360 | D14: 18550253 | E14: 19729107 | F14: 7333333.3 | G14: 3365253.3 | H14: 9030520.2 | I14: 1986714.5 | J14: 7043805.8 | K14: 0 | L14: 14377139 | M14: 3500000 | N14: 2083333.3 | O14: 10877139 | P14: 8793805.8 | Q14: 1.2958562e+08
A15: 11 | B15: 1.2671089e+08 | C15: 38279360 | D15: 18550253 | E15: 19729107 | F15: 7333333.3 | G15: 3351364.4 | H15: 9044409.1 | I15: 1989770 | J15: 7054639.1 | K15: 0 | L15: 14387972 | M15: 3500000 | N15: 2083333.3 | O15: 10887972 | P15: 8804639.1 | Q15: 1.3839026e+08
A16: 12 | B16: 1.2671089e+08 | C16: 38279360 | D16: 18550253 | E16: 19729107 | F16: 7333333.3 | G16: 3337475.6 | H16: 9058298 | I16: 1992825.6 | J16: 7065472.5 | K16: 0 | L16: 14398806 | M16: 3500000 | N16: 2083333.3 | O16: 10898806 | P16: 8815472.5 | Q16: 1.4720574e+08
... A28: 24 | B28: 1.3134653e+08 | C28: 40060693 | D28: 19199462 | E28: 20861231 | F28: 6833333.3 | G28: 3170808.9 | H28: 10857089 | I28: 2388559.5 | J28: 8468529.2 | K28: 0 | L28: 15301863 | M28: 3500000 | N28: 2083333.3 | O28: 11801863 | P28: 9718529.2 | Q28: 2.4761468e+08

Sheet S0
A1: Scenario slot 0
B2: =Setup!B17
A4: month_no | B4: post-sale? | C4: revenue | D4: gross_profit | E4: opex | F4: ebitda | G4: da | H4: interest | I4: pretax_income | J4: tax | K4: net_income | L4: operating_cash_flow | M4: capex | N4: free_cash_flow | O4: change_in_cash | P4: ending_cash
A5: =IF(Forecast!A5="","",Forecast!A5) | B5: =IF(A5="","",IF(0>=N(Setup!$C$17),1,0)) | C5: =IF(A5="","",IF($B5=1,Forecast!B5-Setup!$B$4,Forecast!B5)) | D5: =IF(A5="","",IF($B5=1,Forecast!C5-Setup!$B$5,Forecast!C5)) | E5: =IF(A5="","",IF($B5=1,Forecast!D5-Setup!$B$6,Forecast!D5)) | F5: =IF(A5="","",IF($B5=1,D5-E5,Forecast!E5)) | G5: =IF(A5="","",IF($B5=1,Forecast!F5-Setup!$B$7,Forecast!F5)) | H5: =IF(A5="","",IF($B5=1,Forecast!G5-N(Setup!$D$17)*Setup!$B$9/12,Forecast!G5)) | I5: =IF(A5="","",IF($B5=1,F5-G5-H5,Forecast!H5)) | J5: =IF(A5="","",IF($B5=1,MAX(0,I5)*Setup!$B$10,Forecast!I5)) | K5: =IF(A5="","",IF($B5=1,I5-J5,Forecast!J5)) | L5: =IF(A5="","",IF($B5=1,K5+G5+Forecast!K5,Forecast!L5)) | M5: =IF(A5="","",IF($B5=1,Forecast!M5-Setup!$B$8,Forecast!M5)) | N5: =IF(A5="","",IF($B5=1,L5-M5,Forecast!O5)) | O5: =IF(A5="","",IF($B5=1,N5-Forecast!N5,Forecast!P5)) | P5: =IF(A5="","",(Forecast!$Q$5-Forecast!$P$5)+SUM($O$5:O5))
A6: =IF(Forecast!A6="","",Forecast!A6) | B6: =IF(A6="","",IF(1>=N(Setup!$C$17),1,0)) | C6: =IF(A6="","",IF($B6=1,Forecast!B6-Setup!$B$4,Forecast!B6)) | D6: =IF(A6="","",IF($B6=1,Forecast!C6-Setup!$B$5,Forecast!C6)) | E6: =IF(A6="","",IF($B6=1,Forecast!D6-Setup!$B$6,Forecast!D6)) | F6: =IF(A6="","",IF($B6=1,D6-E6,Forecast!E6)) | G6: =IF(A6="","",IF($B6=1,Forecast!F6-Setup!$B$7,Forecast!F6)) | H6: =IF(A6="","",IF($B6=1,Forecast!G6-N(Setup!$D$17)*Setup!$B$9/12,Forecast!G6)) | I6: =IF(A6="","",IF($B6=1,F6-G6-H6,Forecast!H6)) | J6: =IF(A6="","",IF($B6=1,MAX(0,I6)*Setup!$B$10,Forecast!I6)) | K6: =IF(A6="","",IF($B6=1,I6-J6,Forecast!J6)) | L6: =IF(A6="","",IF($B6=1,K6+G6+Forecast!K6,Forecast!L6)) | M6: =IF(A6="","",IF($B6=1,Forecast!M6-Setup!$B$8,Forecast!M6)) | N6: =IF(A6="","",IF($B6=1,L6-M6,Forecast!O6)) | O6: =IF(A6="","",IF($B6=1,N6-Forecast!N6,Forecast!P6)) | P6: =IF(A6="","",(Forecast!$Q$5-Forecast!$P$5)+SUM($O$5:O6))
A7: =IF(Forecast!A7="","",Forecast!A7) | B7: =IF(A7="","",IF(2>=N(Setup!$C$17),1,0)) | C7: =IF(A7="","",IF($B7=1,Forecast!B7-Setup!$B$4,Forecast!B7)) | D7: =IF(A7="","",IF($B7=1,Forecast!C7-Setup!$B$5,Forecast!C7)) | E7: =IF(A7="","",IF($B7=1,Forecast!D7-Setup!$B$6,Forecast!D7)) | F7: =IF(A7="","",IF($B7=1,D7-E7,Forecast!E7)) | G7: =IF(A7="","",IF($B7=1,Forecast!F7-Setup!$B$7,Forecast!F7)) | H7: =IF(A7="","",IF($B7=1,Forecast!G7-N(Setup!$D$17)*Setup!$B$9/12,Forecast!G7)) | I7: =IF(A7="","",IF($B7=1,F7-G7-H7,Forecast!H7)) | J7: =IF(A7="","",IF($B7=1,MAX(0,I7)*Setup!$B$10,Forecast!I7)) | K7: =IF(A7="","",IF($B7=1,I7-J7,Forecast!J7)) | L7: =IF(A7="","",IF($B7=1,K7+G7+Forecast!K7,Forecast!L7)) | M7: =IF(A7="","",IF($B7=1,Forecast!M7-Setup!$B$8,Forecast!M7)) | N7: =IF(A7="","",IF($B7=1,L7-M7,Forecast!O7)) | O7: =IF(A7="","",IF($B7=1,N7-Forecast!N7,Forecast!P7)) | P7: =IF(A7="","",(Forecast!$Q$5-Forecast!$P$5)+SUM($O$5:O7))
A8: =IF(Forecast!A8="","",Forecast!A8) | B8: =IF(A8="","",IF(3>=N(Setup!$C$17),1,0)) | C8: =IF(A8="","",IF($B8=1,Forecast!B8-Setup!$B$4,Forecast!B8)) | D8: =IF(A8="","",IF($B8=1,Forecast!C8-Setup!$B$5,Forecast!C8)) | E8: =IF(A8="","",IF($B8=1,Forecast!D8-Setup!$B$6,Forecast!D8)) | F8: =IF(A8="","",IF($B8=1,D8-E8,Forecast!E8)) | G8: =IF(A8="","",IF($B8=1,Forecast!F8-Setup!$B$7,Forecast!F8)) | H8: =IF(A8="","",IF($B8=1,Forecast!G8-N(Setup!$D$17)*Setup!$B$9/12,Forecast!G8)) | I8: =IF(A8="","",IF($B8=1,F8-G8-H8,Forecast!H8)) | J8: =IF(A8="","",IF($B8=1,MAX(0,I8)*Setup!$B$10,Forecast!I8)) | K8: =IF(A8="","",IF($B8=1,I8-J8,Forecast!J8)) | L8: =IF(A8="","",IF($B8=1,K8+G8+Forecast!K8,Forecast!L8)) | M8: =IF(A8="","",IF($B8=1,Forecast!M8-Setup!$B$8,Forecast!M8)) | N8: =IF(A8="","",IF($B8=1,L8-M8,Forecast!O8)) | O8: =IF(A8="","",IF($B8=1,N8-Forecast!N8,Forecast!P8)) | P8: =IF(A8="","",(Forecast!$Q$5-Forecast!$P$5)+SUM($O$5:O8))
A9: =IF(Forecast!A9="","",Forecast!A9) | B9: =IF(A9="","",IF(4>=N(Setup!$C$17),1,0)) | C9: =IF(A9="","",IF($B9=1,Forecast!B9-Setup!$B$4,Forecast!B9)) | D9: =IF(A9="","",IF($B9=1,Forecast!C9-Setup!$B$5,Forecast!C9)) | E9: =IF(A9="","",IF($B9=1,Forecast!D9-Setup!$B$6,Forecast!D9)) | F9: =IF(A9="","",IF($B9=1,D9-E9,Forecast!E9)) | G9: =IF(A9="","",IF($B9=1,Forecast!F9-Setup!$B$7,Forecast!F9)) | H9: =IF(A9="","",IF($B9=1,Forecast!G9-N(Setup!$D$17)*Setup!$B$9/12,Forecast!G9)) | I9: =IF(A9="","",IF($B9=1,F9-G9-H9,Forecast!H9)) | J9: =IF(A9="","",IF($B9=1,MAX(0,I9)*Setup!$B$10,Forecast!I9)) | K9: =IF(A9="","",IF($B9=1,I9-J9,Forecast!J9)) | L9: =IF(A9="","",IF($B9=1,K9+G9+Forecast!K9,Forecast!L9)) | M9: =IF(A9="","",IF($B9=1,Forecast!M9-Setup!$B$8,Forecast!M9)) | N9: =IF(A9="","",IF($B9=1,L9-M9,Forecast!O9)) | O9: =IF(A9="","",IF($B9=1,N9-Forecast!N9,Forecast!P9)) | P9: =IF(A9="","",(Forecast!$Q$5-Forecast!$P$5)+SUM($O$5:O9))
A10: =IF(Forecast!A10="","",Forecast!A10) | B10: =IF(A10="","",IF(5>=N(Setup!$C$17),1,0)) | C10: =IF(A10="","",IF($B10=1,Forecast!B10-Setup!$B$4,Forecast!B10)) | D10: =IF(A10="","",IF($B10=1,Forecast!C10-Setup!$B$5,Forecast!C10)) | E10: =IF(A10="","",IF($B10=1,Forecast!D10-Setup!$B$6,Forecast!D10)) | F10: =IF(A10="","",IF($B10=1,D10-E10,Forecast!E10)) | G10: =IF(A10="","",IF($B10=1,Forecast!F10-Setup!$B$7,Forecast!F10)) | H10: =IF(A10="","",IF($B10=1,Forecast!G10-N(Setup!$D$17)*Setup!$B$9/12,Forecast!G10)) | I10: =IF(A10="","",IF($B10=1,F10-G10-H10,Forecast!H10)) | J10: =IF(A10="","",IF($B10=1,MAX(0,I10)*Setup!$B$10,Forecast!I10)) | K10: =IF(A10="","",IF($B10=1,I10-J10,Forecast!J10)) | L10: =IF(A10="","",IF($B10=1,K10+G10+Forecast!K10,Forecast!L10)) | M10: =IF(A10="","",IF($B10=1,Forecast!M10-Setup!$B$8,Forecast!M10)) | N10: =IF(A10="","",IF($B10=1,L10-M10,Forecast!O10)) | O10: =IF(A10="","",IF($B10=1,N10-Forecast!N10,Forecast!P10)) | P10: =IF(A10="","",(Forecast!$Q$5-Forecast!$P$5)+SUM($O$5:O10))
A11: =IF(Forecast!A11="","",Forecast!A11) | B11: =IF(A11="","",IF(6>=N(Setup!$C$17),1,0)) | C11: =IF(A11="","",IF($B11=1,Forecast!B11-Setup!$B$4,Forecast!B11)) | D11: =IF(A11="","",IF($B11=1,Forecast!C11-Setup!$B$5,Forecast!C11)) | E11: =IF(A11="","",IF($B11=1,Forecast!D11-Setup!$B$6,Forecast!D11)) | F11: =IF(A11="","",IF($B11=1,D11-E11,Forecast!E11)) | G11: =IF(A11="","",IF($B11=1,Forecast!F11-Setup!$B$7,Forecast!F11)) | H11: =IF(A11="","",IF($B11=1,Forecast!G11-N(Setup!$D$17)*Setup!$B$9/12,Forecast!G11)) | I11: =IF(A11="","",IF($B11=1,F11-G11-H11,Forecast!H11)) | J11: =IF(A11="","",IF($B11=1,MAX(0,I11)*Setup!$B$10,Forecast!I11)) | K11: =IF(A11="","",IF($B11=1,I11-J11,Forecast!J11)) | L11: =IF(A11="","",IF($B11=1,K11+G11+Forecast!K11,Forecast!L11)) | M11: =IF(A11="","",IF($B11=1,Forecast!M11-Setup!$B$8,Forecast!M11)) | N11: =IF(A11="","",IF($B11=1,L11-M11,Forecast!O11)) | O11: =IF(A11="","",IF($B11=1,N11-Forecast!N11,Forecast!P11)) | P11: =IF(A11="","",(Forecast!$Q$5-Forecast!$P$5)+SUM($O$5:O11))
A12: =IF(Forecast!A12="","",Forecast!A12) | B12: =IF(A12="","",IF(7>=N(Setup!$C$17),1,0)) | C12: =IF(A12="","",IF($B12=1,Forecast!B12-Setup!$B$4,Forecast!B12)) | D12: =IF(A12="","",IF($B12=1,Forecast!C12-Setup!$B$5,Forecast!C12)) | E12: =IF(A12="","",IF($B12=1,Forecast!D12-Setup!$B$6,Forecast!D12)) | F12: =IF(A12="","",IF($B12=1,D12-E12,Forecast!E12)) | G12: =IF(A12="","",IF($B12=1,Forecast!F12-Setup!$B$7,Forecast!F12)) | H12: =IF(A12="","",IF($B12=1,Forecast!G12-N(Setup!$D$17)*Setup!$B$9/12,Forecast!G12)) | I12: =IF(A12="","",IF($B12=1,F12-G12-H12,Forecast!H12)) | J12: =IF(A12="","",IF($B12=1,MAX(0,I12)*Setup!$B$10,Forecast!I12)) | K12: =IF(A12="","",IF($B12=1,I12-J12,Forecast!J12)) | L12: =IF(A12="","",IF($B12=1,K12+G12+Forecast!K12,Forecast!L12)) | M12: =IF(A12="","",IF($B12=1,Forecast!M12-Setup!$B$8,Forecast!M12)) | N12: =IF(A12="","",IF($B12=1,L12-M12,Forecast!O12)) | O12: =IF(A12="","",IF($B12=1,N12-Forecast!N12,Forecast!P12)) | P12: =IF(A12="","",(Forecast!$Q$5-Forecast!$P$5)+SUM($O$5:O12))
A13: =IF(Forecast!A13="","",Forecast!A13) | B13: =IF(A13="","",IF(8>=N(Setup!$C$17),1,0)) | C13: =IF(A13="","",IF($B13=1,Forecast!B13-Setup!$B$4,Forecast!B13)) | D13: =IF(A13="","",IF($B13=1,Forecast!C13-Setup!$B$5,Forecast!C13)) | E13: =IF(A13="","",IF($B13=1,Forecast!D13-Setup!$B$6,Forecast!D13)) | F13: =IF(A13="","",IF($B13=1,D13-E13,Forecast!E13)) | G13: =IF(A13="","",IF($B13=1,Forecast!F13-Setup!$B$7,Forecast!F13)) | H13: =IF(A13="","",IF($B13=1,Forecast!G13-N(Setup!$D$17)*Setup!$B$9/12,Forecast!G13)) | I13: =IF(A13="","",IF($B13=1,F13-G13-H13,Forecast!H13)) | J13: =IF(A13="","",IF($B13=1,MAX(0,I13)*Setup!$B$10,Forecast!I13)) | K13: =IF(A13="","",IF($B13=1,I13-J13,Forecast!J13)) | L13: =IF(A13="","",IF($B13=1,K13+G13+Forecast!K13,Forecast!L13)) | M13: =IF(A13="","",IF($B13=1,Forecast!M13-Setup!$B$8,Forecast!M13)) | N13: =IF(A13="","",IF($B13=1,L13-M13,Forecast!O13)) | O13: =IF(A13="","",IF($B13=1,N13-Forecast!N13,Forecast!P13)) | P13: =IF(A13="","",(Forecast!$Q$5-Forecast!$P$5)+SUM($O$5:O13))
A14: =IF(Forecast!A14="","",Forecast!A14) | B14: =IF(A14="","",IF(9>=N(Setup!$C$17),1,0)) | C14: =IF(A14="","",IF($B14=1,Forecast!B14-Setup!$B$4,Forecast!B14)) | D14: =IF(A14="","",IF($B14=1,Forecast!C14-Setup!$B$5,Forecast!C14)) | E14: =IF(A14="","",IF($B14=1,Forecast!D14-Setup!$B$6,Forecast!D14)) | F14: =IF(A14="","",IF($B14=1,D14-E14,Forecast!E14)) | G14: =IF(A14="","",IF($B14=1,Forecast!F14-Setup!$B$7,Forecast!F14)) | H14: =IF(A14="","",IF($B14=1,Forecast!G14-N(Setup!$D$17)*Setup!$B$9/12,Forecast!G14)) | I14: =IF(A14="","",IF($B14=1,F14-G14-H14,Forecast!H14)) | J14: =IF(A14="","",IF($B14=1,MAX(0,I14)*Setup!$B$10,Forecast!I14)) | K14: =IF(A14="","",IF($B14=1,I14-J14,Forecast!J14)) | L14: =IF(A14="","",IF($B14=1,K14+G14+Forecast!K14,Forecast!L14)) | M14: =IF(A14="","",IF($B14=1,Forecast!M14-Setup!$B$8,Forecast!M14)) | N14: =IF(A14="","",IF($B14=1,L14-M14,Forecast!O14)) | O14: =IF(A14="","",IF($B14=1,N14-Forecast!N14,Forecast!P14)) | P14: =IF(A14="","",(Forecast!$Q$5-Forecast!$P$5)+SUM($O$5:O14))
A15: =IF(Forecast!A15="","",Forecast!A15) | B15: =IF(A15="","",IF(10>=N(Setup!$C$17),1,0)) | C15: =IF(A15="","",IF($B15=1,Forecast!B15-Setup!$B$4,Forecast!B15)) | D15: =IF(A15="","",IF($B15=1,Forecast!C15-Setup!$B$5,Forecast!C15)) | E15: =IF(A15="","",IF($B15=1,Forecast!D15-Setup!$B$6,Forecast!D15)) | F15: =IF(A15="","",IF($B15=1,D15-E15,Forecast!E15)) | G15: =IF(A15="","",IF($B15=1,Forecast!F15-Setup!$B$7,Forecast!F15)) | H15: =IF(A15="","",IF($B15=1,Forecast!G15-N(Setup!$D$17)*Setup!$B$9/12,Forecast!G15)) | I15: =IF(A15="","",IF($B15=1,F15-G15-H15,Forecast!H15)) | J15: =IF(A15="","",IF($B15=1,MAX(0,I15)*Setup!$B$10,Forecast!I15)) | K15: =IF(A15="","",IF($B15=1,I15-J15,Forecast!J15)) | L15: =IF(A15="","",IF($B15=1,K15+G15+Forecast!K15,Forecast!L15)) | M15: =IF(A15="","",IF($B15=1,Forecast!M15-Setup!$B$8,Forecast!M15)) | N15: =IF(A15="","",IF($B15=1,L15-M15,Forecast!O15)) | O15: =IF(A15="","",IF($B15=1,N15-Forecast!N15,Forecast!P15)) | P15: =IF(A15="","",(Forecast!$Q$5-Forecast!$P$5)+SUM($O$5:O15))
A16: =IF(Forecast!A16="","",Forecast!A16) | B16: =IF(A16="","",IF(11>=N(Setup!$C$17),1,0)) | C16: =IF(A16="","",IF($B16=1,Forecast!B16-Setup!$B$4,Forecast!B16)) | D16: =IF(A16="","",IF($B16=1,Forecast!C16-Setup!$B$5,Forecast!C16)) | E16: =IF(A16="","",IF($B16=1,Forecast!D16-Setup!$B$6,Forecast!D16)) | F16: =IF(A16="","",IF($B16=1,D16-E16,Forecast!E16)) | G16: =IF(A16="","",IF($B16=1,Forecast!F16-Setup!$B$7,Forecast!F16)) | H16: =IF(A16="","",IF($B16=1,Forecast!G16-N(Setup!$D$17)*Setup!$B$9/12,Forecast!G16)) | I16: =IF(A16="","",IF($B16=1,F16-G16-H16,Forecast!H16)) | J16: =IF(A16="","",IF($B16=1,MAX(0,I16)*Setup!$B$10,Forecast!I16)) | K16: =IF(A16="","",IF($B16=1,I16-J16,Forecast!J16)) | L16: =IF(A16="","",IF($B16=1,K16+G16+Forecast!K16,Forecast!L16)) | M16: =IF(A16="","",IF($B16=1,Forecast!M16-Setup!$B$8,Forecast!M16)) | N16: =IF(A16="","",IF($B16=1,L16-M16,Forecast!O16)) | O16: =IF(A16="","",IF($B16=1,N16-Forecast!N16,Forecast!P16)) | P16: =IF(A16="","",(Forecast!$Q$5-Forecast!$P$5)+SUM($O$5:O16))
A17: =IF(Forecast!A17="","",Forecast!A17) | B17: =IF(A17="","",IF(12>=N(Setup!$C$17),1,0)) | C17: =IF(A17="","",IF($B17=1,Forecast!B17-Setup!$B$4,Forecast!B17)) | D17: =IF(A17="","",IF($B17=1,Forecast!C17-Setup!$B$5,Forecast!C17)) | E17: =IF(A17="","",IF($B17=1,Forecast!D17-Setup!$B$6,Forecast!D17)) | F17: =IF(A17="","",IF($B17=1,D17-E17,Forecast!E17)) | G17: =IF(A17="","",IF($B17=1,Forecast!F17-Setup!$B$7,Forecast!F17)) | H17: =IF(A17="","",IF($B17=1,Forecast!G17-N(Setup!$D$17)*Setup!$B$9/12,Forecast!G17)) | I17: =IF(A17="","",IF($B17=1,F17-G17-H17,Forecast!H17)) | J17: =IF(A17="","",IF($B17=1,MAX(0,I17)*Setup!$B$10,Forecast!I17)) | K17: =IF(A17="","",IF($B17=1,I17-J17,Forecast!J17)) | L17: =IF(A17="","",IF($B17=1,K17+G17+Forecast!K17,Forecast!L17)) | M17: =IF(A17="","",IF($B17=1,Forecast!M17-Setup!$B$8,Forecast!M17)) | N17: =IF(A17="","",IF($B17=1,L17-M17,Forecast!O17)) | O17: =IF(A17="","",IF($B17=1,N17-Forecast!N17,Forecast!P17)) | P17: =IF(A17="","",(Forecast!$Q$5-Forecast!$P$5)+SUM($O$5:O17))
A18: =IF(Forecast!A18="","",Forecast!A18) | B18: =IF(A18="","",IF(13>=N(Setup!$C$17),1,0)) | C18: =IF(A18="","",IF($B18=1,Forecast!B18-Setup!$B$4,Forecast!B18)) | D18: =IF(A18="","",IF($B18=1,Forecast!C18-Setup!$B$5,Forecast!C18)) | E18: =IF(A18="","",IF($B18=1,Forecast!D18-Setup!$B$6,Forecast!D18)) | F18: =IF(A18="","",IF($B18=1,D18-E18,Forecast!E18)) | G18: =IF(A18="","",IF($B18=1,Forecast!F18-Setup!$B$7,Forecast!F18)) | H18: =IF(A18="","",IF($B18=1,Forecast!G18-N(Setup!$D$17)*Setup!$B$9/12,Forecast!G18)) | I18: =IF(A18="","",IF($B18=1,F18-G18-H18,Forecast!H18)) | J18: =IF(A18="","",IF($B18=1,MAX(0,I18)*Setup!$B$10,Forecast!I18)) | K18: =IF(A18="","",IF($B18=1,I18-J18,Forecast!J18)) | L18: =IF(A18="","",IF($B18=1,K18+G18+Forecast!K18,Forecast!L18)) | M18: =IF(A18="","",IF($B18=1,Forecast!M18-Setup!$B$8,Forecast!M18)) | N18: =IF(A18="","",IF($B18=1,L18-M18,Forecast!O18)) | O18: =IF(A18="","",IF($B18=1,N18-Forecast!N18,Forecast!P18)) | P18: =IF(A18="","",(Forecast!$Q$5-Forecast!$P$5)+SUM($O$5:O18))
A19: =IF(Forecast!A19="","",Forecast!A19) | B19: =IF(A19="","",IF(14>=N(Setup!$C$17),1,0)) | C19: =IF(A19="","",IF($B19=1,Forecast!B19-Setup!$B$4,Forecast!B19)) | D19: =IF(A19="","",IF($B19=1,Forecast!C19-Setup!$B$5,Forecast!C19)) | E19: =IF(A19="","",IF($B19=1,Forecast!D19-Setup!$B$6,Forecast!D19)) | F19: =IF(A19="","",IF($B19=1,D19-E19,Forecast!E19)) | G19: =IF(A19="","",IF($B19=1,Forecast!F19-Setup!$B$7,Forecast!F19)) | H19: =IF(A19="","",IF($B19=1,Forecast!G19-N(Setup!$D$17)*Setup!$B$9/12,Forecast!G19)) | I19: =IF(A19="","",IF($B19=1,F19-G19-H19,Forecast!H19)) | J19: =IF(A19="","",IF($B19=1,MAX(0,I19)*Setup!$B$10,Forecast!I19)) | K19: =IF(A19="","",IF($B19=1,I19-J19,Forecast!J19)) | L19: =IF(A19="","",IF($B19=1,K19+G19+Forecast!K19,Forecast!L19)) | M19: =IF(A19="","",IF($B19=1,Forecast!M19-Setup!$B$8,Forecast!M19)) | N19: =IF(A19="","",IF($B19=1,L19-M19,Forecast!O19)) | O19: =IF(A19="","",IF($B19=1,N19-Forecast!N19,Forecast!P19)) | P19: =IF(A19="","",(Forecast!$Q$5-Forecast!$P$5)+SUM($O$5:O19))
A20: =IF(Forecast!A20="","",Forecast!A20) | B20: =IF(A20="","",IF(15>=N(Setup!$C$17),1,0)) | C20: =IF(A20="","",IF($B20=1,Forecast!B20-Setup!$B$4,Forecast!B20)) | D20: =IF(A20="","",IF($B20=1,Forecast!C20-Setup!$B$5,Forecast!C20)) | E20: =IF(A20="","",IF($B20=1,Forecast!D20-Setup!$B$6,Forecast!D20)) | F20: =IF(A20="","",IF($B20=1,D20-E20,Forecast!E20)) | G20: =IF(A20="","",IF($B20=1,Forecast!F20-Setup!$B$7,Forecast!F20)) | H20: =IF(A20="","",IF($B20=1,Forecast!G20-N(Setup!$D$17)*Setup!$B$9/12,Forecast!G20)) | I20: =IF(A20="","",IF($B20=1,F20-G20-H20,Forecast!H20)) | J20: =IF(A20="","",IF($B20=1,MAX(0,I20)*Setup!$B$10,Forecast!I20)) | K20: =IF(A20="","",IF($B20=1,I20-J20,Forecast!J20)) | L20: =IF(A20="","",IF($B20=1,K20+G20+Forecast!K20,Forecast!L20)) | M20: =IF(A20="","",IF($B20=1,Forecast!M20-Setup!$B$8,Forecast!M20)) | N20: =IF(A20="","",IF($B20=1,L20-M20,Forecast!O20)) | O20: =IF(A20="","",IF($B20=1,N20-Forecast!N20,Forecast!P20)) | P20: =IF(A20="","",(Forecast!$Q$5-Forecast!$P$5)+SUM($O$5:O20))
A21: =IF(Forecast!A21="","",Forecast!A21) | B21: =IF(A21="","",IF(16>=N(Setup!$C$17),1,0)) | C21: =IF(A21="","",IF($B21=1,Forecast!B21-Setup!$B$4,Forecast!B21)) | D21: =IF(A21="","",IF($B21=1,Forecast!C21-Setup!$B$5,Forecast!C21)) | E21: =IF(A21="","",IF($B21=1,Forecast!D21-Setup!$B$6,Forecast!D21)) | F21: =IF(A21="","",IF($B21=1,D21-E21,Forecast!E21)) | G21: =IF(A21="","",IF($B21=1,Forecast!F21-Setup!$B$7,Forecast!F21)) | H21: =IF(A21="","",IF($B21=1,Forecast!G21-N(Setup!$D$17)*Setup!$B$9/12,Forecast!G21)) | I21: =IF(A21="","",IF($B21=1,F21-G21-H21,Forecast!H21)) | J21: =IF(A21="","",IF($B21=1,MAX(0,I21)*Setup!$B$10,Forecast!I21)) | K21: =IF(A21="","",IF($B21=1,I21-J21,Forecast!J21)) | L21: =IF(A21="","",IF($B21=1,K21+G21+Forecast!K21,Forecast!L21)) | M21: =IF(A21="","",IF($B21=1,Forecast!M21-Setup!$B$8,Forecast!M21)) | N21: =IF(A21="","",IF($B21=1,L21-M21,Forecast!O21)) | O21: =IF(A21="","",IF($B21=1,N21-Forecast!N21,Forecast!P21)) | P21: =IF(A21="","",(Forecast!$Q$5-Forecast!$P$5)+SUM($O$5:O21))
A22: =IF(Forecast!A22="","",Forecast!A22) | B22: =IF(A22="","",IF(17>=N(Setup!$C$17),1,0)) | C22: =IF(A22="","",IF($B22=1,Forecast!B22-Setup!$B$4,Forecast!B22)) | D22: =IF(A22="","",IF($B22=1,Forecast!C22-Setup!$B$5,Forecast!C22)) | E22: =IF(A22="","",IF($B22=1,Forecast!D22-Setup!$B$6,Forecast!D22)) | F22: =IF(A22="","",IF($B22=1,D22-E22,Forecast!E22)) | G22: =IF(A22="","",IF($B22=1,Forecast!F22-Setup!$B$7,Forecast!F22)) | H22: =IF(A22="","",IF($B22=1,Forecast!G22-N(Setup!$D$17)*Setup!$B$9/12,Forecast!G22)) | I22: =IF(A22="","",IF($B22=1,F22-G22-H22,Forecast!H22)) | J22: =IF(A22="","",IF($B22=1,MAX(0,I22)*Setup!$B$10,Forecast!I22)) | K22: =IF(A22="","",IF($B22=1,I22-J22,Forecast!J22)) | L22: =IF(A22="","",IF($B22=1,K22+G22+Forecast!K22,Forecast!L22)) | M22: =IF(A22="","",IF($B22=1,Forecast!M22-Setup!$B$8,Forecast!M22)) | N22: =IF(A22="","",IF($B22=1,L22-M22,Forecast!O22)) | O22: =IF(A22="","",IF($B22=1,N22-Forecast!N22,Forecast!P22)) | P22: =IF(A22="","",(Forecast!$Q$5-Forecast!$P$5)+SUM($O$5:O22))
A23: =IF(Forecast!A23="","",Forecast!A23) | B23: =IF(A23="","",IF(18>=N(Setup!$C$17),1,0)) | C23: =IF(A23="","",IF($B23=1,Forecast!B23-Setup!$B$4,Forecast!B23)) | D23: =IF(A23="","",IF($B23=1,Forecast!C23-Setup!$B$5,Forecast!C23)) | E23: =IF(A23="","",IF($B23=1,Forecast!D23-Setup!$B$6,Forecast!D23)) | F23: =IF(A23="","",IF($B23=1,D23-E23,Forecast!E23)) | G23: =IF(A23="","",IF($B23=1,Forecast!F23-Setup!$B$7,Forecast!F23)) | H23: =IF(A23="","",IF($B23=1,Forecast!G23-N(Setup!$D$17)*Setup!$B$9/12,Forecast!G23)) | I23: =IF(A23="","",IF($B23=1,F23-G23-H23,Forecast!H23)) | J23: =IF(A23="","",IF($B23=1,MAX(0,I23)*Setup!$B$10,Forecast!I23)) | K23: =IF(A23="","",IF($B23=1,I23-J23,Forecast!J23)) | L23: =IF(A23="","",IF($B23=1,K23+G23+Forecast!K23,Forecast!L23)) | M23: =IF(A23="","",IF($B23=1,Forecast!M23-Setup!$B$8,Forecast!M23)) | N23: =IF(A23="","",IF($B23=1,L23-M23,Forecast!O23)) | O23: =IF(A23="","",IF($B23=1,N23-Forecast!N23,Forecast!P23)) | P23: =IF(A23="","",(Forecast!$Q$5-Forecast!$P$5)+SUM($O$5:O23))
A24: =IF(Forecast!A24="","",Forecast!A24) | B24: =IF(A24="","",IF(19>=N(Setup!$C$17),1,0)) | C24: =IF(A24="","",IF($B24=1,Forecast!B24-Setup!$B$4,Forecast!B24)) | D24: =IF(A24="","",IF($B24=1,Forecast!C24-Setup!$B$5,Forecast!C24)) | E24: =IF(A24="","",IF($B24=1,Forecast!D24-Setup!$B$6,Forecast!D24)) | F24: =IF(A24="","",IF($B24=1,D24-E24,Forecast!E24)) | G24: =IF(A24="","",IF($B24=1,Forecast!F24-Setup!$B$7,Forecast!F24)) | H24: =IF(A24="","",IF($B24=1,Forecast!G24-N(Setup!$D$17)*Setup!$B$9/12,Forecast!G24)) | I24: =IF(A24="","",IF($B24=1,F24-G24-H24,Forecast!H24)) | J24: =IF(A24="","",IF($B24=1,MAX(0,I24)*Setup!$B$10,Forecast!I24)) | K24: =IF(A24="","",IF($B24=1,I24-J24,Forecast!J24)) | L24: =IF(A24="","",IF($B24=1,K24+G24+Forecast!K24,Forecast!L24)) | M24: =IF(A24="","",IF($B24=1,Forecast!M24-Setup!$B$8,Forecast!M24)) | N24: =IF(A24="","",IF($B24=1,L24-M24,Forecast!O24)) | O24: =IF(A24="","",IF($B24=1,N24-Forecast!N24,Forecast!P24)) | P24: =IF(A24="","",(Forecast!$Q$5-Forecast!$P$5)+SUM($O$5:O24))
A25: =IF(Forecast!A25="","",Forecast!A25) | B25: =IF(A25="","",IF(20>=N(Setup!$C$17),1,0)) | C25: =IF(A25="","",IF($B25=1,Forecast!B25-Setup!$B$4,Forecast!B25)) | D25: =IF(A25="","",IF($B25=1,Forecast!C25-Setup!$B$5,Forecast!C25)) | E25: =IF(A25="","",IF($B25=1,Forecast!D25-Setup!$B$6,Forecast!D25)) | F25: =IF(A25="","",IF($B25=1,D25-E25,Forecast!E25)) | G25: =IF(A25="","",IF($B25=1,Forecast!F25-Setup!$B$7,Forecast!F25)) | H25: =IF(A25="","",IF($B25=1,Forecast!G25-N(Setup!$D$17)*Setup!$B$9/12,Forecast!G25)) | I25: =IF(A25="","",IF($B25=1,F25-G25-H25,Forecast!H25)) | J25: =IF(A25="","",IF($B25=1,MAX(0,I25)*Setup!$B$10,Forecast!I25)) | K25: =IF(A25="","",IF($B25=1,I25-J25,Forecast!J25)) | L25: =IF(A25="","",IF($B25=1,K25+G25+Forecast!K25,Forecast!L25)) | M25: =IF(A25="","",IF($B25=1,Forecast!M25-Setup!$B$8,Forecast!M25)) | N25: =IF(A25="","",IF($B25=1,L25-M25,Forecast!O25)) | O25: =IF(A25="","",IF($B25=1,N25-Forecast!N25,Forecast!P25)) | P25: =IF(A25="","",(Forecast!$Q$5-Forecast!$P$5)+SUM($O$5:O25))
A26: =IF(Forecast!A26="","",Forecast!A26) | B26: =IF(A26="","",IF(21>=N(Setup!$C$17),1,0)) | C26: =IF(A26="","",IF($B26=1,Forecast!B26-Setup!$B$4,Forecast!B26)) | D26: =IF(A26="","",IF($B26=1,Forecast!C26-Setup!$B$5,Forecast!C26)) | E26: =IF(A26="","",IF($B26=1,Forecast!D26-Setup!$B$6,Forecast!D26)) | F26: =IF(A26="","",IF($B26=1,D26-E26,Forecast!E26)) | G26: =IF(A26="","",IF($B26=1,Forecast!F26-Setup!$B$7,Forecast!F26)) | H26: =IF(A26="","",IF($B26=1,Forecast!G26-N(Setup!$D$17)*Setup!$B$9/12,Forecast!G26)) | I26: =IF(A26="","",IF($B26=1,F26-G26-H26,Forecast!H26)) | J26: =IF(A26="","",IF($B26=1,MAX(0,I26)*Setup!$B$10,Forecast!I26)) | K26: =IF(A26="","",IF($B26=1,I26-J26,Forecast!J26)) | L26: =IF(A26="","",IF($B26=1,K26+G26+Forecast!K26,Forecast!L26)) | M26: =IF(A26="","",IF($B26=1,Forecast!M26-Setup!$B$8,Forecast!M26)) | N26: =IF(A26="","",IF($B26=1,L26-M26,Forecast!O26)) | O26: =IF(A26="","",IF($B26=1,N26-Forecast!N26,Forecast!P26)) | P26: =IF(A26="","",(Forecast!$Q$5-Forecast!$P$5)+SUM($O$5:O26))
A27: =IF(Forecast!A27="","",Forecast!A27) | B27: =IF(A27="","",IF(22>=N(Setup!$C$17),1,0)) | C27: =IF(A27="","",IF($B27=1,Forecast!B27-Setup!$B$4,Forecast!B27)) | D27: =IF(A27="","",IF($B27=1,Forecast!C27-Setup!$B$5,Forecast!C27)) | E27: =IF(A27="","",IF($B27=1,Forecast!D27-Setup!$B$6,Forecast!D27)) | F27: =IF(A27="","",IF($B27=1,D27-E27,Forecast!E27)) | G27: =IF(A27="","",IF($B27=1,Forecast!F27-Setup!$B$7,Forecast!F27)) | H27: =IF(A27="","",IF($B27=1,Forecast!G27-N(Setup!$D$17)*Setup!$B$9/12,Forecast!G27)) | I27: =IF(A27="","",IF($B27=1,F27-G27-H27,Forecast!H27)) | J27: =IF(A27="","",IF($B27=1,MAX(0,I27)*Setup!$B$10,Forecast!I27)) | K27: =IF(A27="","",IF($B27=1,I27-J27,Forecast!J27)) | L27: =IF(A27="","",IF($B27=1,K27+G27+Forecast!K27,Forecast!L27)) | M27: =IF(A27="","",IF($B27=1,Forecast!M27-Setup!$B$8,Forecast!M27)) | N27: =IF(A27="","",IF($B27=1,L27-M27,Forecast!O27)) | O27: =IF(A27="","",IF($B27=1,N27-Forecast!N27,Forecast!P27)) | P27: =IF(A27="","",(Forecast!$Q$5-Forecast!$P$5)+SUM($O$5:O27))
A28: =IF(Forecast!A28="","",Forecast!A28) | B28: =IF(A28="","",IF(23>=N(Setup!$C$17),1,0)) | C28: =IF(A28="","",IF($B28=1,Forecast!B28-Setup!$B$4,Forecast!B28)) | D28: =IF(A28="","",IF($B28=1,Forecast!C28-Setup!$B$5,Forecast!C28)) | E28: =IF(A28="","",IF($B28=1,Forecast!D28-Setup!$B$6,Forecast!D28)) | F28: =IF(A28="","",IF($B28=1,D28-E28,Forecast!E28)) | G28: =IF(A28="","",IF($B28=1,Forecast!F28-Setup!$B$7,Forecast!F28)) | H28: =IF(A28="","",IF($B28=1,Forecast!G28-N(Setup!$D$17)*Setup!$B$9/12,Forecast!G28)) | I28: =IF(A28="","",IF($B28=1,F28-G28-H28,Forecast!H28)) | J28: =IF(A28="","",IF($B28=1,MAX(0,I28)*Setup!$B$10,Forecast!I28)) | K28: =IF(A28="","",IF($B28=1,I28-J28,Forecast!J28)) | L28: =IF(A28="","",IF($B28=1,K28+G28+Forecast!K28,Forecast!L28)) | M28: =IF(A28="","",IF($B28=1,Forecast!M28-Setup!$B$8,Forecast!M28)) | N28: =IF(A28="","",IF($B28=1,L28-M28,Forecast!O28)) | O28: =IF(A28="","",IF($B28=1,N28-Forecast!N28,Forecast!P28)) | P28: =IF(A28="","",(Forecast!$Q$5-Forecast!$P$5)+SUM($O$5:O28))
A29: =IF(Forecast!A29="","",Forecast!A29) | B29: =IF(A29="","",IF(24>=N(Setup!$C$17),1,0)) | C29: =IF(A29="","",IF($B29=1,Forecast!B29-Setup!$B$4,Forecast!B29)) | D29: =IF(A29="","",IF($B29=1,Forecast!C29-Setup!$B$5,Forecast!C29)) | E29: =IF(A29="","",IF($B29=1,Forecast!D29-Setup!$B$6,Forecast!D29)) | F29: =IF(A29="","",IF($B29=1,D29-E29,Forecast!E29)) | G29: =IF(A29="","",IF($B29=1,Forecast!F29-Setup!$B$7,Forecast!F29)) | H29: =IF(A29="","",IF($B29=1,Forecast!G29-N(Setup!$D$17)*Setup!$B$9/12,Forecast!G29)) | I29: =IF(A29="","",IF($B29=1,F29-G29-H29,Forecast!H29)) | J29: =IF(A29="","",IF($B29=1,MAX(0,I29)*Setup!$B$10,Forecast!I29)) | K29: =IF(A29="","",IF($B29=1,I29-J29,Forecast!J29)) | L29: =IF(A29="","",IF($B29=1,K29+G29+Forecast!K29,Forecast!L29)) | M29: =IF(A29="","",IF($B29=1,Forecast!M29-Setup!$B$8,Forecast!M29)) | N29: =IF(A29="","",IF($B29=1,L29-M29,Forecast!O29)) | O29: =IF(A29="","",IF($B29=1,N29-Forecast!N29,Forecast!P29)) | P29: =IF(A29="","",(Forecast!$Q$5-Forecast!$P$5)+SUM($O$5:O29))
A30: =IF(Forecast!A30="","",Forecast!A30) | B30: =IF(A30="","",IF(25>=N(Setup!$C$17),1,0)) | C30: =IF(A30="","",IF($B30=1,Forecast!B30-Setup!$B$4,Forecast!B30)) | D30: =IF(A30="","",IF($B30=1,Forecast!C30-Setup!$B$5,Forecast!C30)) | E30: =IF(A30="","",IF($B30=1,Forecast!D30-Setup!$B$6,Forecast!D30)) | F30: =IF(A30="","",IF($B30=1,D30-E30,Forecast!E30)) | G30: =IF(A30="","",IF($B30=1,Forecast!F30-Setup!$B$7,Forecast!F30)) | H30: =IF(A30="","",IF($B30=1,Forecast!G30-N(Setup!$D$17)*Setup!$B$9/12,Forecast!G30)) | I30: =IF(A30="","",IF($B30=1,F30-G30-H30,Forecast!H30)) | J30: =IF(A30="","",IF($B30=1,MAX(0,I30)*Setup!$B$10,Forecast!I30)) | K30: =IF(A30="","",IF($B30=1,I30-J30,Forecast!J30)) | L30: =IF(A30="","",IF($B30=1,K30+G30+Forecast!K30,Forecast!L30)) | M30: =IF(A30="","",IF($B30=1,Forecast!M30-Setup!$B$8,Forecast!M30)) | N30: =IF(A30="","",IF($B30=1,L30-M30,Forecast!O30)) | O30: =IF(A30="","",IF($B30=1,N30-Forecast!N30,Forecast!P30)) | P30: =IF(A30="","",(Forecast!$Q$5-Forecast!$P$5)+SUM($O$5:O30))
A31: =IF(Forecast!A31="","",Forecast!A31) | B31: =IF(A31="","",IF(26>=N(Setup!$C$17),1,0)) | C31: =IF(A31="","",IF($B31=1,Forecast!B31-Setup!$B$4,Forecast!B31)) | D31: =IF(A31="","",IF($B31=1,Forecast!C31-Setup!$B$5,Forecast!C31)) | E31: =IF(A31="","",IF($B31=1,Forecast!D31-Setup!$B$6,Forecast!D31)) | F31: =IF(A31="","",IF($B31=1,D31-E31,Forecast!E31)) | G31: =IF(A31="","",IF($B31=1,Forecast!F31-Setup!$B$7,Forecast!F31)) | H31: =IF(A31="","",IF($B31=1,Forecast!G31-N(Setup!$D$17)*Setup!$B$9/12,Forecast!G31)) | I31: =IF(A31="","",IF($B31=1,F31-G31-H31,Forecast!H31)) | J31: =IF(A31="","",IF($B31=1,MAX(0,I31)*Setup!$B$10,Forecast!I31)) | K31: =IF(A31="","",IF($B31=1,I31-J31,Forecast!J31)) | L31: =IF(A31="","",IF($B31=1,K31+G31+Forecast!K31,Forecast!L31)) | M31: =IF(A31="","",IF($B31=1,Forecast!M31-Setup!$B$8,Forecast!M31)) | N31: =IF(A31="","",IF($B31=1,L31-M31,Forecast!O31)) | O31: =IF(A31="","",IF($B31=1,N31-Forecast!N31,Forecast!P31)) | P31: =IF(A31="","",(Forecast!$Q$5-Forecast!$P$5)+SUM($O$5:O31))
A32: =IF(Forecast!A32="","",Forecast!A32) | B32: =IF(A32="","",IF(27>=N(Setup!$C$17),1,0)) | C32: =IF(A32="","",IF($B32=1,Forecast!B32-Setup!$B$4,Forecast!B32)) | D32: =IF(A32="","",IF($B32=1,Forecast!C32-Setup!$B$5,Forecast!C32)) | E32: =IF(A32="","",IF($B32=1,Forecast!D32-Setup!$B$6,Forecast!D32)) | F32: =IF(A32="","",IF($B32=1,D32-E32,Forecast!E32)) | G32: =IF(A32="","",IF($B32=1,Forecast!F32-Setup!$B$7,Forecast!F32)) | H32: =IF(A32="","",IF($B32=1,Forecast!G32-N(Setup!$D$17)*Setup!$B$9/12,Forecast!G32)) | I32: =IF(A32="","",IF($B32=1,F32-G32-H32,Forecast!H32)) | J32: =IF(A32="","",IF($B32=1,MAX(0,I32)*Setup!$B$10,Forecast!I32)) | K32: =IF(A32="","",IF($B32=1,I32-J32,Forecast!J32)) | L32: =IF(A32="","",IF($B32=1,K32+G32+Forecast!K32,Forecast!L32)) | M32: =IF(A32="","",IF($B32=1,Forecast!M32-Setup!$B$8,Forecast!M32)) | N32: =IF(A32="","",IF($B32=1,L32-M32,Forecast!O32)) | O32: =IF(A32="","",IF($B32=1,N32-Forecast!N32,Forecast!P32)) | P32: =IF(A32="","",(Forecast!$Q$5-Forecast!$P$5)+SUM($O$5:O32))
A33: =IF(Forecast!A33="","",Forecast!A33) | B33: =IF(A33="","",IF(28>=N(Setup!$C$17),1,0)) | C33: =IF(A33="","",IF($B33=1,Forecast!B33-Setup!$B$4,Forecast!B33)) | D33: =IF(A33="","",IF($B33=1,Forecast!C33-Setup!$B$5,Forecast!C33)) | E33: =IF(A33="","",IF($B33=1,Forecast!D33-Setup!$B$6,Forecast!D33)) | F33: =IF(A33="","",IF($B33=1,D33-E33,Forecast!E33)) | G33: =IF(A33="","",IF($B33=1,Forecast!F33-Setup!$B$7,Forecast!F33)) | H33: =IF(A33="","",IF($B33=1,Forecast!G33-N(Setup!$D$17)*Setup!$B$9/12,Forecast!G33)) | I33: =IF(A33="","",IF($B33=1,F33-G33-H33,Forecast!H33)) | J33: =IF(A33="","",IF($B33=1,MAX(0,I33)*Setup!$B$10,Forecast!I33)) | K33: =IF(A33="","",IF($B33=1,I33-J33,Forecast!J33)) | L33: =IF(A33="","",IF($B33=1,K33+G33+Forecast!K33,Forecast!L33)) | M33: =IF(A33="","",IF($B33=1,Forecast!M33-Setup!$B$8,Forecast!M33)) | N33: =IF(A33="","",IF($B33=1,L33-M33,Forecast!O33)) | O33: =IF(A33="","",IF($B33=1,N33-Forecast!N33,Forecast!P33)) | P33: =IF(A33="","",(Forecast!$Q$5-Forecast!$P$5)+SUM($O$5:O33))
A34: =IF(Forecast!A34="","",Forecast!A34) | B34: =IF(A34="","",IF(29>=N(Setup!$C$17),1,0)) | C34: =IF(A34="","",IF($B34=1,Forecast!B34-Setup!$B$4,Forecast!B34)) | D34: =IF(A34="","",IF($B34=1,Forecast!C34-Setup!$B$5,Forecast!C34)) | E34: =IF(A34="","",IF($B34=1,Forecast!D34-Setup!$B$6,Forecast!D34)) | F34: =IF(A34="","",IF($B34=1,D34-E34,Forecast!E34)) | G34: =IF(A34="","",IF($B34=1,Forecast!F34-Setup!$B$7,Forecast!F34)) | H34: =IF(A34="","",IF($B34=1,Forecast!G34-N(Setup!$D$17)*Setup!$B$9/12,Forecast!G34)) | I34: =IF(A34="","",IF($B34=1,F34-G34-H34,Forecast!H34)) | J34: =IF(A34="","",IF($B34=1,MAX(0,I34)*Setup!$B$10,Forecast!I34)) | K34: =IF(A34="","",IF($B34=1,I34-J34,Forecast!J34)) | L34: =IF(A34="","",IF($B34=1,K34+G34+Forecast!K34,Forecast!L34)) | M34: =IF(A34="","",IF($B34=1,Forecast!M34-Setup!$B$8,Forecast!M34)) | N34: =IF(A34="","",IF($B34=1,L34-M34,Forecast!O34)) | O34: =IF(A34="","",IF($B34=1,N34-Forecast!N34,Forecast!P34)) | P34: =IF(A34="","",(Forecast!$Q$5-Forecast!$P$5)+SUM($O$5:O34))
A35: =IF(Forecast!A35="","",Forecast!A35) | B35: =IF(A35="","",IF(30>=N(Setup!$C$17),1,0)) | C35: =IF(A35="","",IF($B35=1,Forecast!B35-Setup!$B$4,Forecast!B35)) | D35: =IF(A35="","",IF($B35=1,Forecast!C35-Setup!$B$5,Forecast!C35)) | E35: =IF(A35="","",IF($B35=1,Forecast!D35-Setup!$B$6,Forecast!D35)) | F35: =IF(A35="","",IF($B35=1,D35-E35,Forecast!E35)) | G35: =IF(A35="","",IF($B35=1,Forecast!F35-Setup!$B$7,Forecast!F35)) | H35: =IF(A35="","",IF($B35=1,Forecast!G35-N(Setup!$D$17)*Setup!$B$9/12,Forecast!G35)) | I35: =IF(A35="","",IF($B35=1,F35-G35-H35,Forecast!H35)) | J35: =IF(A35="","",IF($B35=1,MAX(0,I35)*Setup!$B$10,Forecast!I35)) | K35: =IF(A35="","",IF($B35=1,I35-J35,Forecast!J35)) | L35: =IF(A35="","",IF($B35=1,K35+G35+Forecast!K35,Forecast!L35)) | M35: =IF(A35="","",IF($B35=1,Forecast!M35-Setup!$B$8,Forecast!M35)) | N35: =IF(A35="","",IF($B35=1,L35-M35,Forecast!O35)) | O35: =IF(A35="","",IF($B35=1,N35-Forecast!N35,Forecast!P35)) | P35: =IF(A35="","",(Forecast!$Q$5-Forecast!$P$5)+SUM($O$5:O35))
A36: =IF(Forecast!A36="","",Forecast!A36) | B36: =IF(A36="","",IF(31>=N(Setup!$C$17),1,0)) | C36: =IF(A36="","",IF($B36=1,Forecast!B36-Setup!$B$4,Forecast!B36)) | D36: =IF(A36="","",IF($B36=1,Forecast!C36-Setup!$B$5,Forecast!C36)) | E36: =IF(A36="","",IF($B36=1,Forecast!D36-Setup!$B$6,Forecast!D36)) | F36: =IF(A36="","",IF($B36=1,D36-E36,Forecast!E36)) | G36: =IF(A36="","",IF($B36=1,Forecast!F36-Setup!$B$7,Forecast!F36)) | H36: =IF(A36="","",IF($B36=1,Forecast!G36-N(Setup!$D$17)*Setup!$B$9/12,Forecast!G36)) | I36: =IF(A36="","",IF($B36=1,F36-G36-H36,Forecast!H36)) | J36: =IF(A36="","",IF($B36=1,MAX(0,I36)*Setup!$B$10,Forecast!I36)) | K36: =IF(A36="","",IF($B36=1,I36-J36,Forecast!J36)) | L36: =IF(A36="","",IF($B36=1,K36+G36+Forecast!K36,Forecast!L36)) | M36: =IF(A36="","",IF($B36=1,Forecast!M36-Setup!$B$8,Forecast!M36)) | N36: =IF(A36="","",IF($B36=1,L36-M36,Forecast!O36)) | O36: =IF(A36="","",IF($B36=1,N36-Forecast!N36,Forecast!P36)) | P36: =IF(A36="","",(Forecast!$Q$5-Forecast!$P$5)+SUM($O$5:O36))
A37: =IF(Forecast!A37="","",Forecast!A37) | B37: =IF(A37="","",IF(32>=N(Setup!$C$17),1,0)) | C37: =IF(A37="","",IF($B37=1,Forecast!B37-Setup!$B$4,Forecast!B37)) | D37: =IF(A37="","",IF($B37=1,Forecast!C37-Setup!$B$5,Forecast!C37)) | E37: =IF(A37="","",IF($B37=1,Forecast!D37-Setup!$B$6,Forecast!D37)) | F37: =IF(A37="","",IF($B37=1,D37-E37,Forecast!E37)) | G37: =IF(A37="","",IF($B37=1,Forecast!F37-Setup!$B$7,Forecast!F37)) | H37: =IF(A37="","",IF($B37=1,Forecast!G37-N(Setup!$D$17)*Setup!$B$9/12,Forecast!G37)) | I37: =IF(A37="","",IF($B37=1,F37-G37-H37,Forecast!H37)) | J37: =IF(A37="","",IF($B37=1,MAX(0,I37)*Setup!$B$10,Forecast!I37)) | K37: =IF(A37="","",IF($B37=1,I37-J37,Forecast!J37)) | L37: =IF(A37="","",IF($B37=1,K37+G37+Forecast!K37,Forecast!L37)) | M37: =IF(A37="","",IF($B37=1,Forecast!M37-Setup!$B$8,Forecast!M37)) | N37: =IF(A37="","",IF($B37=1,L37-M37,Forecast!O37)) | O37: =IF(A37="","",IF($B37=1,N37-Forecast!N37,Forecast!P37)) | P37: =IF(A37="","",(Forecast!$Q$5-Forecast!$P$5)+SUM($O$5:O37))
A38: =IF(Forecast!A38="","",Forecast!A38) | B38: =IF(A38="","",IF(33>=N(Setup!$C$17),1,0)) | C38: =IF(A38="","",IF($B38=1,Forecast!B38-Setup!$B$4,Forecast!B38)) | D38: =IF(A38="","",IF($B38=1,Forecast!C38-Setup!$B$5,Forecast!C38)) | E38: =IF(A38="","",IF($B38=1,Forecast!D38-Setup!$B$6,Forecast!D38)) | F38: =IF(A38="","",IF($B38=1,D38-E38,Forecast!E38)) | G38: =IF(A38="","",IF($B38=1,Forecast!F38-Setup!$B$7,Forecast!F38)) | H38: =IF(A38="","",IF($B38=1,Forecast!G38-N(Setup!$D$17)*Setup!$B$9/12,Forecast!G38)) | I38: =IF(A38="","",IF($B38=1,F38-G38-H38,Forecast!H38)) | J38: =IF(A38="","",IF($B38=1,MAX(0,I38)*Setup!$B$10,Forecast!I38)) | K38: =IF(A38="","",IF($B38=1,I38-J38,Forecast!J38)) | L38: =IF(A38="","",IF($B38=1,K38+G38+Forecast!K38,Forecast!L38)) | M38: =IF(A38="","",IF($B38=1,Forecast!M38-Setup!$B$8,Forecast!M38)) | N38: =IF(A38="","",IF($B38=1,L38-M38,Forecast!O38)) | O38: =IF(A38="","",IF($B38=1,N38-Forecast!N38,Forecast!P38)) | P38: =IF(A38="","",(Forecast!$Q$5-Forecast!$P$5)+SUM($O$5:O38))
A39: =IF(Forecast!A39="","",Forecast!A39) | B39: =IF(A39="","",IF(34>=N(Setup!$C$17),1,0)) | C39: =IF(A39="","",IF($B39=1,Forecast!B39-Setup!$B$4,Forecast!B39)) | D39: =IF(A39="","",IF($B39=1,Forecast!C39-Setup!$B$5,Forecast!C39)) | E39: =IF(A39="","",IF($B39=1,Forecast!D39-Setup!$B$6,Forecast!D39)) | F39: =IF(A39="","",IF($B39=1,D39-E39,Forecast!E39)) | G39: =IF(A39="","",IF($B39=1,Forecast!F39-Setup!$B$7,Forecast!F39)) | H39: =IF(A39="","",IF($B39=1,Forecast!G39-N(Setup!$D$17)*Setup!$B$9/12,Forecast!G39)) | I39: =IF(A39="","",IF($B39=1,F39-G39-H39,Forecast!H39)) | J39: =IF(A39="","",IF($B39=1,MAX(0,I39)*Setup!$B$10,Forecast!I39)) | K39: =IF(A39="","",IF($B39=1,I39-J39,Forecast!J39)) | L39: =IF(A39="","",IF($B39=1,K39+G39+Forecast!K39,Forecast!L39)) | M39: =IF(A39="","",IF($B39=1,Forecast!M39-Setup!$B$8,Forecast!M39)) | N39: =IF(A39="","",IF($B39=1,L39-M39,Forecast!O39)) | O39: =IF(A39="","",IF($B39=1,N39-Forecast!N39,Forecast!P39)) | P39: =IF(A39="","",(Forecast!$Q$5-Forecast!$P$5)+SUM($O$5:O39))
A40: =IF(Forecast!A40="","",Forecast!A40) | B40: =IF(A40="","",IF(35>=N(Setup!$C$17),1,0)) | C40: =IF(A40="","",IF($B40=1,Forecast!B40-Setup!$B$4,Forecast!B40)) | D40: =IF(A40="","",IF($B40=1,Forecast!C40-Setup!$B$5,Forecast!C40)) | E40: =IF(A40="","",IF($B40=1,Forecast!D40-Setup!$B$6,Forecast!D40)) | F40: =IF(A40="","",IF($B40=1,D40-E40,Forecast!E40)) | G40: =IF(A40="","",IF($B40=1,Forecast!F40-Setup!$B$7,Forecast!F40)) | H40: =IF(A40="","",IF($B40=1,Forecast!G40-N(Setup!$D$17)*Setup!$B$9/12,Forecast!G40)) | I40: =IF(A40="","",IF($B40=1,F40-G40-H40,Forecast!H40)) | J40: =IF(A40="","",IF($B40=1,MAX(0,I40)*Setup!$B$10,Forecast!I40)) | K40: =IF(A40="","",IF($B40=1,I40-J40,Forecast!J40)) | L40: =IF(A40="","",IF($B40=1,K40+G40+Forecast!K40,Forecast!L40)) | M40: =IF(A40="","",IF($B40=1,Forecast!M40-Setup!$B$8,Forecast!M40)) | N40: =IF(A40="","",IF($B40=1,L40-M40,Forecast!O40)) | O40: =IF(A40="","",IF($B40=1,N40-Forecast!N40,Forecast!P40)) | P40: =IF(A40="","",(Forecast!$Q$5-Forecast!$P$5)+SUM($O$5:O40))
A41: =IF(Forecast!A41="","",Forecast!A41) | B41: =IF(A41="","",IF(36>=N(Setup!$C$17),1,0)) | C41: =IF(A41="","",IF($B41=1,Forecast!B41-Setup!$B$4,Forecast!B41)) | D41: =IF(A41="","",IF($B41=1,Forecast!C41-Setup!$B$5,Forecast!C41)) | E41: =IF(A41="","",IF($B41=1,Forecast!D41-Setup!$B$6,Forecast!D41)) | F41: =IF(A41="","",IF($B41=1,D41-E41,Forecast!E41)) | G41: =IF(A41="","",IF($B41=1,Forecast!F41-Setup!$B$7,Forecast!F41)) | H41: =IF(A41="","",IF($B41=1,Forecast!G41-N(Setup!$D$17)*Setup!$B$9/12,Forecast!G41)) | I41: =IF(A41="","",IF($B41=1,F41-G41-H41,Forecast!H41)) | J41: =IF(A41="","",IF($B41=1,MAX(0,I41)*Setup!$B$10,Forecast!I41)) | K41: =IF(A41="","",IF($B41=1,I41-J41,Forecast!J41)) | L41: =IF(A41="","",IF($B41=1,K41+G41+Forecast!K41,Forecast!L41)) | M41: =IF(A41="","",IF($B41=1,Forecast!M41-Setup!$B$8,Forecast!M41)) | N41: =IF(A41="","",IF($B41=1,L41-M41,Forecast!O41)) | O41: =IF(A41="","",IF($B41=1,N41-Forecast!N41,Forecast!P41)) | P41: =IF(A41="","",(Forecast!$Q$5-Forecast!$P$5)+SUM($O$5:O41))
...

Sheet S1
A1: Scenario slot 1
B2: =Setup!B18
A4: month_no | B4: post-sale? | C4: revenue | D4: gross_profit | E4: opex | F4: ebitda | G4: da | H4: interest | I4: pretax_income | J4: tax | K4: net_income | L4: operating_cash_flow | M4: capex | N4: free_cash_flow | O4: change_in_cash | P4: ending_cash
A5: =IF(Forecast!A5="","",Forecast!A5) | B5: =IF(A5="","",IF(0>=N(Setup!$C$18),1,0)) | C5: =IF(A5="","",IF($B5=1,Forecast!B5-Setup!$B$4,Forecast!B5)) | D5: =IF(A5="","",IF($B5=1,Forecast!C5-Setup!$B$5,Forecast!C5)) | E5: =IF(A5="","",IF($B5=1,Forecast!D5-Setup!$B$6,Forecast!D5)) | F5: =IF(A5="","",IF($B5=1,D5-E5,Forecast!E5)) | G5: =IF(A5="","",IF($B5=1,Forecast!F5-Setup!$B$7,Forecast!F5)) | H5: =IF(A5="","",IF($B5=1,Forecast!G5-N(Setup!$D$18)*Setup!$B$9/12,Forecast!G5)) | I5: =IF(A5="","",IF($B5=1,F5-G5-H5,Forecast!H5)) | J5: =IF(A5="","",IF($B5=1,MAX(0,I5)*Setup!$B$10,Forecast!I5)) | K5: =IF(A5="","",IF($B5=1,I5-J5,Forecast!J5)) | L5: =IF(A5="","",IF($B5=1,K5+G5+Forecast!K5,Forecast!L5)) | M5: =IF(A5="","",IF($B5=1,Forecast!M5-Setup!$B$8,Forecast!M5)) | N5: =IF(A5="","",IF($B5=1,L5-M5,Forecast!O5)) | O5: =IF(A5="","",IF($B5=1,N5-Forecast!N5,Forecast!P5)) | P5: =IF(A5="","",(Forecast!$Q$5-Forecast!$P$5)+SUM($O$5:O5))
A6: =IF(Forecast!A6="","",Forecast!A6) | B6: =IF(A6="","",IF(1>=N(Setup!$C$18),1,0)) | C6: =IF(A6="","",IF($B6=1,Forecast!B6-Setup!$B$4,Forecast!B6)) | D6: =IF(A6="","",IF($B6=1,Forecast!C6-Setup!$B$5,Forecast!C6)) | E6: =IF(A6="","",IF($B6=1,Forecast!D6-Setup!$B$6,Forecast!D6)) | F6: =IF(A6="","",IF($B6=1,D6-E6,Forecast!E6)) | G6: =IF(A6="","",IF($B6=1,Forecast!F6-Setup!$B$7,Forecast!F6)) | H6: =IF(A6="","",IF($B6=1,Forecast!G6-N(Setup!$D$18)*Setup!$B$9/12,Forecast!G6)) | I6: =IF(A6="","",IF($B6=1,F6-G6-H6,Forecast!H6)) | J6: =IF(A6="","",IF($B6=1,MAX(0,I6)*Setup!$B$10,Forecast!I6)) | K6: =IF(A6="","",IF($B6=1,I6-J6,Forecast!J6)) | L6: =IF(A6="","",IF($B6=1,K6+G6+Forecast!K6,Forecast!L6)) | M6: =IF(A6="","",IF($B6=1,Forecast!M6-Setup!$B$8,Forecast!M6)) | N6: =IF(A6="","",IF($B6=1,L6-M6,Forecast!O6)) | O6: =IF(A6="","",IF($B6=1,N6-Forecast!N6,Forecast!P6)) | P6: =IF(A6="","",(Forecast!$Q$5-Forecast!$P$5)+SUM($O$5:O6))
A7: =IF(Forecast!A7="","",Forecast!A7) | B7: =IF(A7="","",IF(2>=N(Setup!$C$18),1,0)) | C7: =IF(A7="","",IF($B7=1,Forecast!B7-Setup!$B$4,Forecast!B7)) | D7: =IF(A7="","",IF($B7=1,Forecast!C7-Setup!$B$5,Forecast!C7)) | E7: =IF(A7="","",IF($B7=1,Forecast!D7-Setup!$B$6,Forecast!D7)) | F7: =IF(A7="","",IF($B7=1,D7-E7,Forecast!E7)) | G7: =IF(A7="","",IF($B7=1,Forecast!F7-Setup!$B$7,Forecast!F7)) | H7: =IF(A7="","",IF($B7=1,Forecast!G7-N(Setup!$D$18)*Setup!$B$9/12,Forecast!G7)) | I7: =IF(A7="","",IF($B7=1,F7-G7-H7,Forecast!H7)) | J7: =IF(A7="","",IF($B7=1,MAX(0,I7)*Setup!$B$10,Forecast!I7)) | K7: =IF(A7="","",IF($B7=1,I7-J7,Forecast!J7)) | L7: =IF(A7="","",IF($B7=1,K7+G7+Forecast!K7,Forecast!L7)) | M7: =IF(A7="","",IF($B7=1,Forecast!M7-Setup!$B$8,Forecast!M7)) | N7: =IF(A7="","",IF($B7=1,L7-M7,Forecast!O7)) | O7: =IF(A7="","",IF($B7=1,N7-Forecast!N7,Forecast!P7)) | P7: =IF(A7="","",(Forecast!$Q$5-Forecast!$P$5)+SUM($O$5:O7))
A8: =IF(Forecast!A8="","",Forecast!A8) | B8: =IF(A8="","",IF(3>=N(Setup!$C$18),1,0)) | C8: =IF(A8="","",IF($B8=1,Forecast!B8-Setup!$B$4,Forecast!B8)) | D8: =IF(A8="","",IF($B8=1,Forecast!C8-Setup!$B$5,Forecast!C8)) | E8: =IF(A8="","",IF($B8=1,Forecast!D8-Setup!$B$6,Forecast!D8)) | F8: =IF(A8="","",IF($B8=1,D8-E8,Forecast!E8)) | G8: =IF(A8="","",IF($B8=1,Forecast!F8-Setup!$B$7,Forecast!F8)) | H8: =IF(A8="","",IF($B8=1,Forecast!G8-N(Setup!$D$18)*Setup!$B$9/12,Forecast!G8)) | I8: =IF(A8="","",IF($B8=1,F8-G8-H8,Forecast!H8)) | J8: =IF(A8="","",IF($B8=1,MAX(0,I8)*Setup!$B$10,Forecast!I8)) | K8: =IF(A8="","",IF($B8=1,I8-J8,Forecast!J8)) | L8: =IF(A8="","",IF($B8=1,K8+G8+Forecast!K8,Forecast!L8)) | M8: =IF(A8="","",IF($B8=1,Forecast!M8-Setup!$B$8,Forecast!M8)) | N8: =IF(A8="","",IF($B8=1,L8-M8,Forecast!O8)) | O8: =IF(A8="","",IF($B8=1,N8-Forecast!N8,Forecast!P8)) | P8: =IF(A8="","",(Forecast!$Q$5-Forecast!$P$5)+SUM($O$5:O8))
A9: =IF(Forecast!A9="","",Forecast!A9) | B9: =IF(A9="","",IF(4>=N(Setup!$C$18),1,0)) | C9: =IF(A9="","",IF($B9=1,Forecast!B9-Setup!$B$4,Forecast!B9)) | D9: =IF(A9="","",IF($B9=1,Forecast!C9-Setup!$B$5,Forecast!C9)) | E9: =IF(A9="","",IF($B9=1,Forecast!D9-Setup!$B$6,Forecast!D9)) | F9: =IF(A9="","",IF($B9=1,D9-E9,Forecast!E9)) | G9: =IF(A9="","",IF($B9=1,Forecast!F9-Setup!$B$7,Forecast!F9)) | H9: =IF(A9="","",IF($B9=1,Forecast!G9-N(Setup!$D$18)*Setup!$B$9/12,Forecast!G9)) | I9: =IF(A9="","",IF($B9=1,F9-G9-H9,Forecast!H9)) | J9: =IF(A9="","",IF($B9=1,MAX(0,I9)*Setup!$B$10,Forecast!I9)) | K9: =IF(A9="","",IF($B9=1,I9-J9,Forecast!J9)) | L9: =IF(A9="","",IF($B9=1,K9+G9+Forecast!K9,Forecast!L9)) | M9: =IF(A9="","",IF($B9=1,Forecast!M9-Setup!$B$8,Forecast!M9)) | N9: =IF(A9="","",IF($B9=1,L9-M9,Forecast!O9)) | O9: =IF(A9="","",IF($B9=1,N9-Forecast!N9,Forecast!P9)) | P9: =IF(A9="","",(Forecast!$Q$5-Forecast!$P$5)+SUM($O$5:O9))
A10: =IF(Forecast!A10="","",Forecast!A10) | B10: =IF(A10="","",IF(5>=N(Setup!$C$18),1,0)) | C10: =IF(A10="","",IF($B10=1,Forecast!B10-Setup!$B$4,Forecast!B10)) | D10: =IF(A10="","",IF($B10=1,Forecast!C10-Setup!$B$5,Forecast!C10)) | E10: =IF(A10="","",IF($B10=1,Forecast!D10-Setup!$B$6,Forecast!D10)) | F10: =IF(A10="","",IF($B10=1,D10-E10,Forecast!E10)) | G10: =IF(A10="","",IF($B10=1,Forecast!F10-Setup!$B$7,Forecast!F10)) | H10: =IF(A10="","",IF($B10=1,Forecast!G10-N(Setup!$D$18)*Setup!$B$9/12,Forecast!G10)) | I10: =IF(A10="","",IF($B10=1,F10-G10-H10,Forecast!H10)) | J10: =IF(A10="","",IF($B10=1,MAX(0,I10)*Setup!$B$10,Forecast!I10)) | K10: =IF(A10="","",IF($B10=1,I10-J10,Forecast!J10)) | L10: =IF(A10="","",IF($B10=1,K10+G10+Forecast!K10,Forecast!L10)) | M10: =IF(A10="","",IF($B10=1,Forecast!M10-Setup!$B$8,Forecast!M10)) | N10: =IF(A10="","",IF($B10=1,L10-M10,Forecast!O10)) | O10: =IF(A10="","",IF($B10=1,N10-Forecast!N10,Forecast!P10)) | P10: =IF(A10="","",(Forecast!$Q$5-Forecast!$P$5)+SUM($O$5:O10))
A11: =IF(Forecast!A11="","",Forecast!A11) | B11: =IF(A11="","",IF(6>=N(Setup!$C$18),1,0)) | C11: =IF(A11="","",IF($B11=1,Forecast!B11-Setup!$B$4,Forecast!B11)) | D11: =IF(A11="","",IF($B11=1,Forecast!C11-Setup!$B$5,Forecast!C11)) | E11: =IF(A11="","",IF($B11=1,Forecast!D11-Setup!$B$6,Forecast!D11)) | F11: =IF(A11="","",IF($B11=1,D11-E11,Forecast!E11)) | G11: =IF(A11="","",IF($B11=1,Forecast!F11-Setup!$B$7,Forecast!F11)) | H11: =IF(A11="","",IF($B11=1,Forecast!G11-N(Setup!$D$18)*Setup!$B$9/12,Forecast!G11)) | I11: =IF(A11="","",IF($B11=1,F11-G11-H11,Forecast!H11)) | J11: =IF(A11="","",IF($B11=1,MAX(0,I11)*Setup!$B$10,Forecast!I11)) | K11: =IF(A11="","",IF($B11=1,I11-J11,Forecast!J11)) | L11: =IF(A11="","",IF($B11=1,K11+G11+Forecast!K11,Forecast!L11)) | M11: =IF(A11="","",IF($B11=1,Forecast!M11-Setup!$B$8,Forecast!M11)) | N11: =IF(A11="","",IF($B11=1,L11-M11,Forecast!O11)) | O11: =IF(A11="","",IF($B11=1,N11-Forecast!N11,Forecast!P11)) | P11: =IF(A11="","",(Forecast!$Q$5-Forecast!$P$5)+SUM($O$5:O11))
A12: =IF(Forecast!A12="","",Forecast!A12) | B12: =IF(A12="","",IF(7>=N(Setup!$C$18),1,0)) | C12: =IF(A12="","",IF($B12=1,Forecast!B12-Setup!$B$4,Forecast!B12)) | D12: =IF(A12="","",IF($B12=1,Forecast!C12-Setup!$B$5,Forecast!C12)) | E12: =IF(A12="","",IF($B12=1,Forecast!D12-Setup!$B$6,Forecast!D12)) | F12: =IF(A12="","",IF($B12=1,D12-E12,Forecast!E12)) | G12: =IF(A12="","",IF($B12=1,Forecast!F12-Setup!$B$7,Forecast!F12)) | H12: =IF(A12="","",IF($B12=1,Forecast!G12-N(Setup!$D$18)*Setup!$B$9/12,Forecast!G12)) | I12: =IF(A12="","",IF($B12=1,F12-G12-H12,Forecast!H12)) | J12: =IF(A12="","",IF($B12=1,MAX(0,I12)*Setup!$B$10,Forecast!I12)) | K12: =IF(A12="","",IF($B12=1,I12-J12,Forecast!J12)) | L12: =IF(A12="","",IF($B12=1,K12+G12+Forecast!K12,Forecast!L12)) | M12: =IF(A12="","",IF($B12=1,Forecast!M12-Setup!$B$8,Forecast!M12)) | N12: =IF(A12="","",IF($B12=1,L12-M12,Forecast!O12)) | O12: =IF(A12="","",IF($B12=1,N12-Forecast!N12,Forecast!P12)) | P12: =IF(A12="","",(Forecast!$Q$5-Forecast!$P$5)+SUM($O$5:O12))
A13: =IF(Forecast!A13="","",Forecast!A13) | B13: =IF(A13="","",IF(8>=N(Setup!$C$18),1,0)) | C13: =IF(A13="","",IF($B13=1,Forecast!B13-Setup!$B$4,Forecast!B13)) | D13: =IF(A13="","",IF($B13=1,Forecast!C13-Setup!$B$5,Forecast!C13)) | E13: =IF(A13="","",IF($B13=1,Forecast!D13-Setup!$B$6,Forecast!D13)) | F13: =IF(A13="","",IF($B13=1,D13-E13,Forecast!E13)) | G13: =IF(A13="","",IF($B13=1,Forecast!F13-Setup!$B$7,Forecast!F13)) | H13: =IF(A13="","",IF($B13=1,Forecast!G13-N(Setup!$D$18)*Setup!$B$9/12,Forecast!G13)) | I13: =IF(A13="","",IF($B13=1,F13-G13-H13,Forecast!H13)) | J13: =IF(A13="","",IF($B13=1,MAX(0,I13)*Setup!$B$10,Forecast!I13)) | K13: =IF(A13="","",IF($B13=1,I13-J13,Forecast!J13)) | L13: =IF(A13="","",IF($B13=1,K13+G13+Forecast!K13,Forecast!L13)) | M13: =IF(A13="","",IF($B13=1,Forecast!M13-Setup!$B$8,Forecast!M13)) | N13: =IF(A13="","",IF($B13=1,L13-M13,Forecast!O13)) | O13: =IF(A13="","",IF($B13=1,N13-Forecast!N13,Forecast!P13)) | P13: =IF(A13="","",(Forecast!$Q$5-Forecast!$P$5)+SUM($O$5:O13))
A14: =IF(Forecast!A14="","",Forecast!A14) | B14: =IF(A14="","",IF(9>=N(Setup!$C$18),1,0)) | C14: =IF(A14="","",IF($B14=1,Forecast!B14-Setup!$B$4,Forecast!B14)) | D14: =IF(A14="","",IF($B14=1,Forecast!C14-Setup!$B$5,Forecast!C14)) | E14: =IF(A14="","",IF($B14=1,Forecast!D14-Setup!$B$6,Forecast!D14)) | F14: =IF(A14="","",IF($B14=1,D14-E14,Forecast!E14)) | G14: =IF(A14="","",IF($B14=1,Forecast!F14-Setup!$B$7,Forecast!F14)) | H14: =IF(A14="","",IF($B14=1,Forecast!G14-N(Setup!$D$18)*Setup!$B$9/12,Forecast!G14)) | I14: =IF(A14="","",IF($B14=1,F14-G14-H14,Forecast!H14)) | J14: =IF(A14="","",IF($B14=1,MAX(0,I14)*Setup!$B$10,Forecast!I14)) | K14: =IF(A14="","",IF($B14=1,I14-J14,Forecast!J14)) | L14: =IF(A14="","",IF($B14=1,K14+G14+Forecast!K14,Forecast!L14)) | M14: =IF(A14="","",IF($B14=1,Forecast!M14-Setup!$B$8,Forecast!M14)) | N14: =IF(A14="","",IF($B14=1,L14-M14,Forecast!O14)) | O14: =IF(A14="","",IF($B14=1,N14-Forecast!N14,Forecast!P14)) | P14: =IF(A14="","",(Forecast!$Q$5-Forecast!$P$5)+SUM($O$5:O14))
A15: =IF(Forecast!A15="","",Forecast!A15) | B15: =IF(A15="","",IF(10>=N(Setup!$C$18),1,0)) | C15: =IF(A15="","",IF($B15=1,Forecast!B15-Setup!$B$4,Forecast!B15)) | D15: =IF(A15="","",IF($B15=1,Forecast!C15-Setup!$B$5,Forecast!C15)) | E15: =IF(A15="","",IF($B15=1,Forecast!D15-Setup!$B$6,Forecast!D15)) | F15: =IF(A15="","",IF($B15=1,D15-E15,Forecast!E15)) | G15: =IF(A15="","",IF($B15=1,Forecast!F15-Setup!$B$7,Forecast!F15)) | H15: =IF(A15="","",IF($B15=1,Forecast!G15-N(Setup!$D$18)*Setup!$B$9/12,Forecast!G15)) | I15: =IF(A15="","",IF($B15=1,F15-G15-H15,Forecast!H15)) | J15: =IF(A15="","",IF($B15=1,MAX(0,I15)*Setup!$B$10,Forecast!I15)) | K15: =IF(A15="","",IF($B15=1,I15-J15,Forecast!J15)) | L15: =IF(A15="","",IF($B15=1,K15+G15+Forecast!K15,Forecast!L15)) | M15: =IF(A15="","",IF($B15=1,Forecast!M15-Setup!$B$8,Forecast!M15)) | N15: =IF(A15="","",IF($B15=1,L15-M15,Forecast!O15)) | O15: =IF(A15="","",IF($B15=1,N15-Forecast!N15,Forecast!P15)) | P15: =IF(A15="","",(Forecast!$Q$5-Forecast!$P$5)+SUM($O$5:O15))
A16: =IF(Forecast!A16="","",Forecast!A16) | B16: =IF(A16="","",IF(11>=N(Setup!$C$18),1,0)) | C16: =IF(A16="","",IF($B16=1,Forecast!B16-Setup!$B$4,Forecast!B16)) | D16: =IF(A16="","",IF($B16=1,Forecast!C16-Setup!$B$5,Forecast!C16)) | E16: =IF(A16="","",IF($B16=1,Forecast!D16-Setup!$B$6,Forecast!D16)) | F16: =IF(A16="","",IF($B16=1,D16-E16,Forecast!E16)) | G16: =IF(A16="","",IF($B16=1,Forecast!F16-Setup!$B$7,Forecast!F16)) | H16: =IF(A16="","",IF($B16=1,Forecast!G16-N(Setup!$D$18)*Setup!$B$9/12,Forecast!G16)) | I16: =IF(A16="","",IF($B16=1,F16-G16-H16,Forecast!H16)) | J16: =IF(A16="","",IF($B16=1,MAX(0,I16)*Setup!$B$10,Forecast!I16)) | K16: =IF(A16="","",IF($B16=1,I16-J16,Forecast!J16)) | L16: =IF(A16="","",IF($B16=1,K16+G16+Forecast!K16,Forecast!L16)) | M16: =IF(A16="","",IF($B16=1,Forecast!M16-Setup!$B$8,Forecast!M16)) | N16: =IF(A16="","",IF($B16=1,L16-M16,Forecast!O16)) | O16: =IF(A16="","",IF($B16=1,N16-Forecast!N16,Forecast!P16)) | P16: =IF(A16="","",(Forecast!$Q$5-Forecast!$P$5)+SUM($O$5:O16))
A17: =IF(Forecast!A17="","",Forecast!A17) | B17: =IF(A17="","",IF(12>=N(Setup!$C$18),1,0)) | C17: =IF(A17="","",IF($B17=1,Forecast!B17-Setup!$B$4,Forecast!B17)) | D17: =IF(A17="","",IF($B17=1,Forecast!C17-Setup!$B$5,Forecast!C17)) | E17: =IF(A17="","",IF($B17=1,Forecast!D17-Setup!$B$6,Forecast!D17)) | F17: =IF(A17="","",IF($B17=1,D17-E17,Forecast!E17)) | G17: =IF(A17="","",IF($B17=1,Forecast!F17-Setup!$B$7,Forecast!F17)) | H17: =IF(A17="","",IF($B17=1,Forecast!G17-N(Setup!$D$18)*Setup!$B$9/12,Forecast!G17)) | I17: =IF(A17="","",IF($B17=1,F17-G17-H17,Forecast!H17)) | J17: =IF(A17="","",IF($B17=1,MAX(0,I17)*Setup!$B$10,Forecast!I17)) | K17: =IF(A17="","",IF($B17=1,I17-J17,Forecast!J17)) | L17: =IF(A17="","",IF($B17=1,K17+G17+Forecast!K17,Forecast!L17)) | M17: =IF(A17="","",IF($B17=1,Forecast!M17-Setup!$B$8,Forecast!M17)) | N17: =IF(A17="","",IF($B17=1,L17-M17,Forecast!O17)) | O17: =IF(A17="","",IF($B17=1,N17-Forecast!N17,Forecast!P17)) | P17: =IF(A17="","",(Forecast!$Q$5-Forecast!$P$5)+SUM($O$5:O17))
A18: =IF(Forecast!A18="","",Forecast!A18) | B18: =IF(A18="","",IF(13>=N(Setup!$C$18),1,0)) | C18: =IF(A18="","",IF($B18=1,Forecast!B18-Setup!$B$4,Forecast!B18)) | D18: =IF(A18="","",IF($B18=1,Forecast!C18-Setup!$B$5,Forecast!C18)) | E18: =IF(A18="","",IF($B18=1,Forecast!D18-Setup!$B$6,Forecast!D18)) | F18: =IF(A18="","",IF($B18=1,D18-E18,Forecast!E18)) | G18: =IF(A18="","",IF($B18=1,Forecast!F18-Setup!$B$7,Forecast!F18)) | H18: =IF(A18="","",IF($B18=1,Forecast!G18-N(Setup!$D$18)*Setup!$B$9/12,Forecast!G18)) | I18: =IF(A18="","",IF($B18=1,F18-G18-H18,Forecast!H18)) | J18: =IF(A18="","",IF($B18=1,MAX(0,I18)*Setup!$B$10,Forecast!I18)) | K18: =IF(A18="","",IF($B18=1,I18-J18,Forecast!J18)) | L18: =IF(A18="","",IF($B18=1,K18+G18+Forecast!K18,Forecast!L18)) | M18: =IF(A18="","",IF($B18=1,Forecast!M18-Setup!$B$8,Forecast!M18)) | N18: =IF(A18="","",IF($B18=1,L18-M18,Forecast!O18)) | O18: =IF(A18="","",IF($B18=1,N18-Forecast!N18,Forecast!P18)) | P18: =IF(A18="","",(Forecast!$Q$5-Forecast!$P$5)+SUM($O$5:O18))
A19: =IF(Forecast!A19="","",Forecast!A19) | B19: =IF(A19="","",IF(14>=N(Setup!$C$18),1,0)) | C19: =IF(A19="","",IF($B19=1,Forecast!B19-Setup!$B$4,Forecast!B19)) | D19: =IF(A19="","",IF($B19=1,Forecast!C19-Setup!$B$5,Forecast!C19)) | E19: =IF(A19="","",IF($B19=1,Forecast!D19-Setup!$B$6,Forecast!D19)) | F19: =IF(A19="","",IF($B19=1,D19-E19,Forecast!E19)) | G19: =IF(A19="","",IF($B19=1,Forecast!F19-Setup!$B$7,Forecast!F19)) | H19: =IF(A19="","",IF($B19=1,Forecast!G19-N(Setup!$D$18)*Setup!$B$9/12,Forecast!G19)) | I19: =IF(A19="","",IF($B19=1,F19-G19-H19,Forecast!H19)) | J19: =IF(A19="","",IF($B19=1,MAX(0,I19)*Setup!$B$10,Forecast!I19)) | K19: =IF(A19="","",IF($B19=1,I19-J19,Forecast!J19)) | L19: =IF(A19="","",IF($B19=1,K19+G19+Forecast!K19,Forecast!L19)) | M19: =IF(A19="","",IF($B19=1,Forecast!M19-Setup!$B$8,Forecast!M19)) | N19: =IF(A19="","",IF($B19=1,L19-M19,Forecast!O19)) | O19: =IF(A19="","",IF($B19=1,N19-Forecast!N19,Forecast!P19)) | P19: =IF(A19="","",(Forecast!$Q$5-Forecast!$P$5)+SUM($O$5:O19))
