Workbook
Name rc_source: 'Setup'!$B$4
Name rc_tol: 'Setup'!$B$5
Name rc_crsign: 'Setup'!$B$6
Name rc_allow: 'Setup'!$B$9
Name rc_passed: 'Reconcile'!$B$9

Sheet README
A1: K03 · Inspect, Profile, Map & Reconcile Sources (no-code kernel)
A3: Replaces openfpa CLI: inspect-data, source-profile, reconcile-source, connector-validate (fixture mode) and pyfpa read_pl_csv / _parse_amount.
A4: Sheets
A5: Inspect - paste a file listing (relative path, bytes) of a data folder; each file gets extension, candidate flag and a category from the classifier table. Missing priority categories are listed.
A6: Profile - paste any table (header row + up to 1,000 rows x 15 columns) exported from CSV/TSV/XLS/XLSX/ODS; returns rows, columns, empty cells per column and duplicate rows (pandas.duplicated semantics: repeats of an earlier row).
A7: Mapping - paste memory/mappings/registry.csv rows (source_id, source_value, target, status mapped/ignored, rationale).
A8: Reconcile - paste the source's Account and Amount columns (up to 1,500 rows). Amounts are parsed like openfpa (currency symbol, thousands separators, (parens)=negative, blank/'-'=0) plus India rules: ₹, Rs., INR, lakh-style commas, and a trailing Dr/Cr (Cr sign set on Setup).
A9: Output: row count, source total, mapped total, mapped totals per target, duplicates, unmapped, ignored, variances vs expected totals, PASSED.
A10: Connector validation = the same sheet with tolerance 0 and expected = the golden totals stored in the connector contract (connectors/<name>/connector.md). It never touches a live system.
A11: Rules (identical to openfpa)
A12: Blank account rows are skipped. Any duplicate account FAILS. Any account without a mapping rule for this source FAILS (never silently dropped). Ignored rules need a rationale and are excluded from totals.
A13: Variance = mapped - expected; variance_pct = variance/expected (0 if expected is 0); within tolerance when |variance_pct| <= tolerance, or exact equality when expected is 0.
A14: When expected totals are provided every mapped target is compared; a mapped target missing from the expected list is compared to 0.

Sheet Checks
A1: Checks - OVERALL must be PASS
B3: OVERALL | C3: =IF(COUNTIF(C5:C11,"PASS")=COUNT(A5:A11),"PASS","FAIL") | D3: =COUNTIF(C5:C11,"PASS")&" pass / "&COUNTIF(C5:C11,"FAIL")&" fail / "&(COUNT(A5:A11)-COUNTIF(C5:C11,"PASS")-COUNTIF(C5:C11,"FAIL"))&" error"
A4: # | B4: check | C4: result | D4: detail
A5: 1 | B5: source_id set | C5: =IF(TRIM(Setup!$B$4)<>"","PASS","FAIL") | D5: =Setup!$B$4
A6: 2 | B6: every mapping rule valid (mapped needs target; ignored needs rationale) | C6: =IF(COUNTIF(Mapping!$G$5:$G$504,0)=0,"PASS","FAIL") | D6: =COUNTIF(Mapping!$G$5:$G$504,0)&" invalid"
A7: 3 | B7: no duplicate (source_id, source_value) mapping keys in first 60 rules | C7: =IF((IF(Mapping!F5="",0,IF(SUMPRODUCT((Mapping!$F$5:$F$504=Mapping!F5)*1)>1,1,0))+IF(Mapping!F6="",0,IF(SUMPRODUCT((Mapping!$F$5:$F$504=Mapping!F6)*1)>1,1,0))+IF(Mapping!F7="",0,IF(SUMPRODUCT((Mapping!$F$5:$F$504=Mapping!F7)*1)>1,1,0))+IF(Mapping!F8="",0,IF(SUMPRODUCT((Mapping!$F$5:$F$504=Mapping!F8)*1)>1,1,0))+IF(Mapping!F9="",0,IF(SUMPRODUCT((Mapping!$F$5:$F$504=Mapping!F9)*1)>1,1,0))+IF(Mapping!F10="",0,IF(SUMPRODUCT((Mapping!$F$5:$F$504=Mapping!F10)*1)>1,1,0))+IF(Mapping!F11="",0,IF(SUMPRODUCT((Mapping!$F$5:$F$504=Mapping!F11)*1)>1,1,0))+IF(Mapping!F12="",0,IF(SUMPRODUCT((Mapping!$F$5:$F$504=Mapping!F12)*1)>1,1,0))+IF(Mapping!F13="",0,IF(SUMPRODUCT((Mapping!$F$5:$F$504=Mapping!F13)*1)>1,1,0))+IF(Mapping!F14="",0,IF(SUMPRODUCT((Mapping!$F$5:$F$504=Mapping!F14)*1)>1,1,0))+IF(Mapping!F15="",0,IF(SUMPRODUCT((Mapping!$F$5:$F$504=Mapping!F15)*1)>1,1,0))+IF(Mapping!F16="",0,IF(SUMPRODUCT((Mapping!$F$5:$F$504=Mapping!F16)*1)>1,1,0))+IF(Mapping!F17="",0,IF(SUMPRODUCT((Mapping!$F$5:$F$504=Mapping!F17)*1)>1,1,0))+IF(Mapping!F18="",0,IF(SUMPRODUCT((Mapping!$F$5:$F$504=Mapping!F18)*1)>1,1,0))+IF(Mapping!F19="",0,IF(SUMPRODUCT((Mapping!$F$5:$F$504=Mapping!F19)*1)>1,1,0))+IF(Mapping!F20="",0,IF(SUMPRODUCT((Mapping!$F$5:$F$504=Mapping!F20)*1)>1,1,0))+IF(Mapping!F21="",0,IF(SUMPRODUCT((Mapping!$F$5:$F$504=Mapping!F21)*1)>1,1,0))+IF(Mapping!F22="",0,IF(SUMPRODUCT((Mapping!$F$5:$F$504=Mapping!F22)*1)>1,1,0))+IF(Mapping!F23="",0,IF(SUMPRODUCT((Mapping!$F$5:$F$504=Mapping!F23)*1)>1,1,0))+IF(Mapping!F24="",0,IF(SUMPRODUCT((Mapping!$F$5:$F$504=Mapping!F24)*1)>1,1,0))+IF(Mapping!F25="",0,IF(SUMPRODUCT((Mapping!$F$5:$F$504=Mapping!F25)*1)>1,1,0))+IF(Mapping!F26="",0,IF(SUMPRODUCT((Mapping!$F$5:$F$504=Mapping!F26)*1)>1,1,0))+IF(Mapping!F27="",0,IF(SUMPRODUCT((Mapping!$F$5:$F$504=Mapping!F27)*1)>1,1,0))+IF(Mapping!F28="",0,IF(SUMPRODUCT((Mapping!$F$5:$F$504=Mapping!F28)*1)>1,1,0))+IF(Mapping!F29="",0,IF(SUMPRODUCT((Mapping!$F$5:$F$504=Mapping!F29)*1)>1,1,0))+IF(Mapping!F30="",0,IF(SUMPRODUCT((Mapping!$F$5:$F$504=Mapping!F30)*1)>1,1,0))+IF(Mapping!F31="",0,IF(SUMPRODUCT((Mapping!$F$5:$F$504=Mapping!F31)*1)>1,1,0))+IF(Mapping!F32="",0,IF(SUMPRODUCT((Mapping!$F$5:$F$504=Mapping!F32)*1)>1,1,0))+IF(Mapping!F33="",0,IF(SUMPRODUCT((Mapping!$F$5:$F$504=Mapping!F33)*1)>1,1,0))+IF(Mapping!F34="",0,IF(SUMPRODUCT((Mapping!$F$5:$F$504=Mapping!F34)*1)>1,1,0))+IF(Mapping!F35="",0,IF(SUMPRODUCT((Mapping!$F$5:$F$504=Mapping!F35)*1)>1,1,0))+IF(Mapping!F36="",0,IF(SUMPRODUCT((Mapping!$F$5:$F$504=Mapping!F36)*1)>1,1,0))+IF(Mapping!F37="",0,IF(SUMPRODUCT((Mapping!$F$5:$F$504=Mapping!F37)*1)>1,1,0))+IF(Mapping!F38="",0,IF(SUMPRODUCT((Mapping!$F$5:$F$504=Mapping!F38)*1)>1,1,0))+IF(Mapping!F39="",0,IF(SUMPRODUCT((Mapping!$F$5:$F$504=Mapping!F39)*1)>1,1,0))+IF(Mapping!F40="",0,IF(SUMPRODUCT((Mapping!$F$5:$F$504=Mapping!F40)*1)>1,1,0))+IF(Mapping!F41="",0,IF(SUMPRODUCT((Mapping!$F$5:$F$504=Mapping!F41)*1)>1,1,0))+IF(Mapping!F42="",0,IF(SUMPRODUCT((Mapping!$F$5:$F$504=Mapping!F42)*1)>1,1,0))+IF(Mapping!F43="",0,IF(SUMPRODUCT((Mapping!$F$5:$F$504=Mapping!F43)*1)>1,1,0))+IF(Mapping!F44="",0,IF(SUMPRODUCT((Mapping!$F$5:$F$504=Mapping!F44)*1)>1,1,0))+IF(Mapping!F45="",0,IF(SUMPRODUCT((Mapping!$F$5:$F$504=Mapping!F45)*1)>1,1,0))+IF(Mapping!F46="",0,IF(SUMPRODUCT((Mapping!$F$5:$F$504=Mapping!F46)*1)>1,1,0))+IF(Mapping!F47="",0,IF(SUMPRODUCT((Mapping!$F$5:$F$504=Mapping!F47)*1)>1,1,0))+IF(Mapping!F48="",0,IF(SUMPRODUCT((Mapping!$F$5:$F$504=Mapping!F48)*1)>1,1,0))+IF(Mapping!F49="",0,IF(SUMPRODUCT((Mapping!$F$5:$F$504=Mapping!F49)*1)>1,1,0))+IF(Mapping!F50="",0,IF(SUMPRODUCT((Mapping!$F$5:$F$504=Mapping!F50)*1)>1,1,0))+IF(Mapping!F51="",0,IF(SUMPRODUCT((Mapping!$F$5:$F$504=Mapping!F51)*1)>1,1,0))+IF(Mapping!F52="",0,IF(SUMPRODUCT((Mapping!$F$5:$F$504=Mapping!F52)*1)>1,1,0))+IF(Mapping!F53="",0,IF(SUMPRODUCT((Mapping!$F$5:$F$504=Mapping!F53)*1)>1,1,0))+IF(Mapping!F54="",0,IF(SUMPRODUCT((Mapping!$F$5:$F$504=Mapping!F54)*1)>1,1,0))+IF(Mapping!F55="",0,IF(SUMPRODUCT((Mapping!$F$5:$F$504=Mapping!F55)*1)>1,1,0))+IF(Mapping!F56="",0,IF(SUMPRODUCT((Mapping!$F$5:$F$504=Mapping!F56)*1)>1,1,0))+IF(Mapping!F57="",0,IF(SUMPRODUCT((Mapping!$F$5:$F$504=Mapping!F57)*1)>1,1,0))+IF(Mapping!F58="",0,IF(SUMPRODUCT((Mapping!$F$5:$F$504=Mapping!F58)*1)>1,1,0))+IF(Mapping!F59="",0,IF(SUMPRODUCT((Mapping!$F$5:$F$504=Mapping!F59)*1)>1,1,0))+IF(Mapping!F60="",0,IF(SUMPRODUCT((Mapping!$F$5:$F$504=Mapping!F60)*1)>1,1,0))+IF(Mapping!F61="",0,IF(SUMPRODUCT((Mapping!$F$5:$F$504=Mapping!F61)*1)>1,1,0))+IF(Mapping!F62="",0,IF(SUMPRODUCT((Mapping!$F$5:$F$504=Mapping!F62)*1)>1,1,0))+IF(Mapping!F63="",0,IF(SUMPRODUCT((Mapping!$F$5:$F$504=Mapping!F63)*1)>1,1,0))+IF(Mapping!F64="",0,IF(SUMPRODUCT((Mapping!$F$5:$F$504=Mapping!F64)*1)>1,1,0)))=0,"PASS","FAIL")
A8: 4 | B8: no duplicate accounts in source | C8: =IF(Reconcile!B6=0,"PASS","FAIL") | D8: =Reconcile!B6
A9: 5 | B9: no unmapped accounts (never silently dropped; allowed only when Setup says yes - still listed in Results) | C9: =IF(OR(Reconcile!B7=0,LOWER(Setup!$B$9)="yes"),"PASS","FAIL") | D9: =Reconcile!B7
A10: 6 | B10: all amounts parse | C10: =IF(Reconcile!B8=0,"PASS","FAIL") | D10: =Reconcile!B8
A11: 7 | B11: expected totals within tolerance (if provided) | C11: =IF(Results!B3,"PASS","FAIL")

Sheet Setup
A1: Setup
A4: source_id | B4: tally-pl-monthly
A5: tolerance (0.01 = 1%; 0 for connector validation) | B5: 0.01
A6: sign applied to amounts suffixed 'Cr' | B6: -1
A7: account column name in source | B7: Particulars
A8: amount column name in source | B8: Closing Balance
A9: allow unmapped? (yes = --allow-unmapped: unmapped listed but do not fail; duplicates still fail) | B9: no

Sheet Inspect
A1: Inspect (inspect-data): paste a file listing; classification is formula-driven
A4: relative path | B4: bytes | C4: file name | D4: extension | E4: stem (normalised) | F4: data ext? | G4: context signal? | H4: candidate? | I4: category | J4: profit_and_loss | K4: balance_sheet | L4: ar_aging | M4: ap_aging | N4: inventory | O4: cash_and_bank | P4: payroll_and_headcount | Q4: sales_and_revenue | R4: budget_and_forecast | S4: operations | T4: gst_and_indirect_tax | U4: tds_and_direct_tax | V4: statutory_payroll | W4: tally_or_erp_export
C5: =IF(A5="","",TRIM(RIGHT(SUBSTITUTE(A5,"/",REPT(" ",250)),250))) | D5: =IF(C5="","",IF(ISNUMBER(SEARCH(".",C5)),LOWER("."&TRIM(RIGHT(SUBSTITUTE(C5,".",REPT(" ",250)),250))),"")) | E5: =IF(C5="","",TRIM(SUBSTITUTE(SUBSTITUTE(SUBSTITUTE(SUBSTITUTE(SUBSTITUTE(SUBSTITUTE(SUBSTITUTE(SUBSTITUTE(SUBSTITUTE(SUBSTITUTE(SUBSTITUTE(SUBSTITUTE(SUBSTITUTE(SUBSTITUTE(SUBSTITUTE(SUBSTITUTE(SUBSTITUTE(SUBSTITUTE(SUBSTITUTE(SUBSTITUTE(LOWER(LEFT(C5,LEN(C5)-LEN(D5))),"_"," "),"-"," "),"."," "),","," "),"("," "),")"," "),"["," "),"]"," "),"&"," "),"+"," "),"@"," "),"#"," "),"!"," "),"'"," "),"/"," "),":"," "),";"," "),"="," "),"~"," "),"%"," "))) | F5: =IF(C5="","",IF(COUNTIF(Classifiers!$A$23:$A$40,D5)>0,1,0)) | G5: =IF(C5="","",IF(COUNTIF(Classifiers!$C$23:$C$30,D5)>0,IF((IF(ISNUMBER(SEARCH(Classifiers!$E$23,E5)),1,0)+IF(ISNUMBER(SEARCH(Classifiers!$E$24,E5)),1,0)+IF(ISNUMBER(SEARCH(Classifiers!$E$25,E5)),1,0)+IF(ISNUMBER(SEARCH(Classifiers!$E$26,E5)),1,0)+IF(ISNUMBER(SEARCH(Classifiers!$E$27,E5)),1,0)+IF(ISNUMBER(SEARCH(Classifiers!$E$28,E5)),1,0)+IF(ISNUMBER(SEARCH(Classifiers!$E$29,E5)),1,0)+IF(ISNUMBER(SEARCH(Classifiers!$E$30,E5)),1,0))>0,1,0),0)) | H5: =IF(C5="","",IF(OR(LEFT(C5,1)=".",AND(F5=0,G5=0)),0,1)) | I5: =IF(H5<>1,"",IF(SUM(J5:W5)=0,"unclassified",INDEX(Classifiers!$A$5:$A$18,MATCH(1,J5:W5,0),1))) | J5: =IF(H5<>1,0,IF((IF(Classifiers!$B$5="",0,IF(ISNUMBER(SEARCH(Classifiers!$B$5,E5)),1,0))+IF(Classifiers!$C$5="",0,IF(ISNUMBER(SEARCH(Classifiers!$C$5,E5)),1,0))+IF(Classifiers!$D$5="",0,IF(ISNUMBER(SEARCH(Classifiers!$D$5,E5)),1,0))+IF(Classifiers!$E$5="",0,IF(ISNUMBER(SEARCH(Classifiers!$E$5,E5)),1,0))+IF(Classifiers!$F$5="",0,IF(ISNUMBER(SEARCH(Classifiers!$F$5,E5)),1,0))+IF(Classifiers!$G$5="",0,IF(ISNUMBER(SEARCH(Classifiers!$G$5,E5)),1,0)))>0,1,0)) | K5: =IF(H5<>1,0,IF((IF(Classifiers!$B$6="",0,IF(ISNUMBER(SEARCH(Classifiers!$B$6,E5)),1,0))+IF(Classifiers!$C$6="",0,IF(ISNUMBER(SEARCH(Classifiers!$C$6,E5)),1,0))+IF(Classifiers!$D$6="",0,IF(ISNUMBER(SEARCH(Classifiers!$D$6,E5)),1,0))+IF(Classifiers!$E$6="",0,IF(ISNUMBER(SEARCH(Classifiers!$E$6,E5)),1,0))+IF(Classifiers!$F$6="",0,IF(ISNUMBER(SEARCH(Classifiers!$F$6,E5)),1,0))+IF(Classifiers!$G$6="",0,IF(ISNUMBER(SEARCH(Classifiers!$G$6,E5)),1,0)))>0,1,0)) | L5: =IF(H5<>1,0,IF((IF(Classifiers!$B$7="",0,IF(ISNUMBER(SEARCH(Classifiers!$B$7,E5)),1,0))+IF(Classifiers!$C$7="",0,IF(ISNUMBER(SEARCH(Classifiers!$C$7,E5)),1,0))+IF(Classifiers!$D$7="",0,IF(ISNUMBER(SEARCH(Classifiers!$D$7,E5)),1,0))+IF(Classifiers!$E$7="",0,IF(ISNUMBER(SEARCH(Classifiers!$E$7,E5)),1,0))+IF(Classifiers!$F$7="",0,IF(ISNUMBER(SEARCH(Classifiers!$F$7,E5)),1,0))+IF(Classifiers!$G$7="",0,IF(ISNUMBER(SEARCH(Classifiers!$G$7,E5)),1,0)))>0,1,0)) | M5: =IF(H5<>1,0,IF((IF(Classifiers!$B$8="",0,IF(ISNUMBER(SEARCH(Classifiers!$B$8,E5)),1,0))+IF(Classifiers!$C$8="",0,IF(ISNUMBER(SEARCH(Classifiers!$C$8,E5)),1,0))+IF(Classifiers!$D$8="",0,IF(ISNUMBER(SEARCH(Classifiers!$D$8,E5)),1,0))+IF(Classifiers!$E$8="",0,IF(ISNUMBER(SEARCH(Classifiers!$E$8,E5)),1,0))+IF(Classifiers!$F$8="",0,IF(ISNUMBER(SEARCH(Classifiers!$F$8,E5)),1,0))+IF(Classifiers!$G$8="",0,IF(ISNUMBER(SEARCH(Classifiers!$G$8,E5)),1,0)))>0,1,0)) | N5: =IF(H5<>1,0,IF((IF(Classifiers!$B$9="",0,IF(ISNUMBER(SEARCH(Classifiers!$B$9,E5)),1,0))+IF(Classifiers!$C$9="",0,IF(ISNUMBER(SEARCH(Classifiers!$C$9,E5)),1,0))+IF(Classifiers!$D$9="",0,IF(ISNUMBER(SEARCH(Classifiers!$D$9,E5)),1,0))+IF(Classifiers!$E$9="",0,IF(ISNUMBER(SEARCH(Classifiers!$E$9,E5)),1,0))+IF(Classifiers!$F$9="",0,IF(ISNUMBER(SEARCH(Classifiers!$F$9,E5)),1,0))+IF(Classifiers!$G$9="",0,IF(ISNUMBER(SEARCH(Classifiers!$G$9,E5)),1,0)))>0,1,0)) | O5: =IF(H5<>1,0,IF((IF(Classifiers!$B$10="",0,IF(ISNUMBER(SEARCH(Classifiers!$B$10,E5)),1,0))+IF(Classifiers!$C$10="",0,IF(ISNUMBER(SEARCH(Classifiers!$C$10,E5)),1,0))+IF(Classifiers!$D$10="",0,IF(ISNUMBER(SEARCH(Classifiers!$D$10,E5)),1,0))+IF(Classifiers!$E$10="",0,IF(ISNUMBER(SEARCH(Classifiers!$E$10,E5)),1,0))+IF(Classifiers!$F$10="",0,IF(ISNUMBER(SEARCH(Classifiers!$F$10,E5)),1,0))+IF(Classifiers!$G$10="",0,IF(ISNUMBER(SEARCH(Classifiers!$G$10,E5)),1,0)))>0,1,0)) | P5: =IF(H5<>1,0,IF((IF(Classifiers!$B$11="",0,IF(ISNUMBER(SEARCH(Classifiers!$B$11,E5)),1,0))+IF(Classifiers!$C$11="",0,IF(ISNUMBER(SEARCH(Classifiers!$C$11,E5)),1,0))+IF(Classifiers!$D$11="",0,IF(ISNUMBER(SEARCH(Classifiers!$D$11,E5)),1,0))+IF(Classifiers!$E$11="",0,IF(ISNUMBER(SEARCH(Classifiers!$E$11,E5)),1,0))+IF(Classifiers!$F$11="",0,IF(ISNUMBER(SEARCH(Classifiers!$F$11,E5)),1,0))+IF(Classifiers!$G$11="",0,IF(ISNUMBER(SEARCH(Classifiers!$G$11,E5)),1,0)))>0,1,0)) | Q5: =IF(H5<>1,0,IF((IF(Classifiers!$B$12="",0,IF(ISNUMBER(SEARCH(Classifiers!$B$12,E5)),1,0))+IF(Classifiers!$C$12="",0,IF(ISNUMBER(SEARCH(Classifiers!$C$12,E5)),1,0))+IF(Classifiers!$D$12="",0,IF(ISNUMBER(SEARCH(Classifiers!$D$12,E5)),1,0))+IF(Classifiers!$E$12="",0,IF(ISNUMBER(SEARCH(Classifiers!$E$12,E5)),1,0))+IF(Classifiers!$F$12="",0,IF(ISNUMBER(SEARCH(Classifiers!$F$12,E5)),1,0))+IF(Classifiers!$G$12="",0,IF(ISNUMBER(SEARCH(Classifiers!$G$12,E5)),1,0)))>0,1,0)) | R5: =IF(H5<>1,0,IF((IF(Classifiers!$B$13="",0,IF(ISNUMBER(SEARCH(Classifiers!$B$13,E5)),1,0))+IF(Classifiers!$C$13="",0,IF(ISNUMBER(SEARCH(Classifiers!$C$13,E5)),1,0))+IF(Classifiers!$D$13="",0,IF(ISNUMBER(SEARCH(Classifiers!$D$13,E5)),1,0))+IF(Classifiers!$E$13="",0,IF(ISNUMBER(SEARCH(Classifiers!$E$13,E5)),1,0))+IF(Classifiers!$F$13="",0,IF(ISNUMBER(SEARCH(Classifiers!$F$13,E5)),1,0))+IF(Classifiers!$G$13="",0,IF(ISNUMBER(SEARCH(Classifiers!$G$13,E5)),1,0)))>0,1,0)) | S5: =IF(H5<>1,0,IF((IF(Classifiers!$B$14="",0,IF(ISNUMBER(SEARCH(Classifiers!$B$14,E5)),1,0))+IF(Classifiers!$C$14="",0,IF(ISNUMBER(SEARCH(Classifiers!$C$14,E5)),1,0))+IF(Classifiers!$D$14="",0,IF(ISNUMBER(SEARCH(Classifiers!$D$14,E5)),1,0))+IF(Classifiers!$E$14="",0,IF(ISNUMBER(SEARCH(Classifiers!$E$14,E5)),1,0))+IF(Classifiers!$F$14="",0,IF(ISNUMBER(SEARCH(Classifiers!$F$14,E5)),1,0))+IF(Classifiers!$G$14="",0,IF(ISNUMBER(SEARCH(Classifiers!$G$14,E5)),1,0)))>0,1,0)) | T5: =IF(H5<>1,0,IF((IF(Classifiers!$B$15="",0,IF(ISNUMBER(SEARCH(Classifiers!$B$15,E5)),1,0))+IF(Classifiers!$C$15="",0,IF(ISNUMBER(SEARCH(Classifiers!$C$15,E5)),1,0))+IF(Classifiers!$D$15="",0,IF(ISNUMBER(SEARCH(Classifiers!$D$15,E5)),1,0))+IF(Classifiers!$E$15="",0,IF(ISNUMBER(SEARCH(Classifiers!$E$15,E5)),1,0))+IF(Classifiers!$F$15="",0,IF(ISNUMBER(SEARCH(Classifiers!$F$15,E5)),1,0))+IF(Classifiers!$G$15="",0,IF(ISNUMBER(SEARCH(Classifiers!$G$15,E5)),1,0)))>0,1,0)) | U5: =IF(H5<>1,0,IF((IF(Classifiers!$B$16="",0,IF(ISNUMBER(SEARCH(Classifiers!$B$16,E5)),1,0))+IF(Classifiers!$C$16="",0,IF(ISNUMBER(SEARCH(Classifiers!$C$16,E5)),1,0))+IF(Classifiers!$D$16="",0,IF(ISNUMBER(SEARCH(Classifiers!$D$16,E5)),1,0))+IF(Classifiers!$E$16="",0,IF(ISNUMBER(SEARCH(Classifiers!$E$16,E5)),1,0))+IF(Classifiers!$F$16="",0,IF(ISNUMBER(SEARCH(Classifiers!$F$16,E5)),1,0))+IF(Classifiers!$G$16="",0,IF(ISNUMBER(SEARCH(Classifiers!$G$16,E5)),1,0)))>0,1,0)) | V5: =IF(H5<>1,0,IF((IF(Classifiers!$B$17="",0,IF(ISNUMBER(SEARCH(Classifiers!$B$17,E5)),1,0))+IF(Classifiers!$C$17="",0,IF(ISNUMBER(SEARCH(Classifiers!$C$17,E5)),1,0))+IF(Classifiers!$D$17="",0,IF(ISNUMBER(SEARCH(Classifiers!$D$17,E5)),1,0))+IF(Classifiers!$E$17="",0,IF(ISNUMBER(SEARCH(Classifiers!$E$17,E5)),1,0))+IF(Classifiers!$F$17="",0,IF(ISNUMBER(SEARCH(Classifiers!$F$17,E5)),1,0))+IF(Classifiers!$G$17="",0,IF(ISNUMBER(SEARCH(Classifiers!$G$17,E5)),1,0)))>0,1,0)) | W5: =IF(H5<>1,0,IF((IF(Classifiers!$B$18="",0,IF(ISNUMBER(SEARCH(Classifiers!$B$18,E5)),1,0))+IF(Classifiers!$C$18="",0,IF(ISNUMBER(SEARCH(Classifiers!$C$18,E5)),1,0))+IF(Classifiers!$D$18="",0,IF(ISNUMBER(SEARCH(Classifiers!$D$18,E5)),1,0))+IF(Classifiers!$E$18="",0,IF(ISNUMBER(SEARCH(Classifiers!$E$18,E5)),1,0))+IF(Classifiers!$F$18="",0,IF(ISNUMBER(SEARCH(Classifiers!$F$18,E5)),1,0))+IF(Classifiers!$G$18="",0,IF(ISNUMBER(SEARCH(Classifiers!$G$18,E5)),1,0)))>0,1,0))
C6: =IF(A6="","",TRIM(RIGHT(SUBSTITUTE(A6,"/",REPT(" ",250)),250))) | D6: =IF(C6="","",IF(ISNUMBER(SEARCH(".",C6)),LOWER("."&TRIM(RIGHT(SUBSTITUTE(C6,".",REPT(" ",250)),250))),"")) | E6: =IF(C6="","",TRIM(SUBSTITUTE(SUBSTITUTE(SUBSTITUTE(SUBSTITUTE(SUBSTITUTE(SUBSTITUTE(SUBSTITUTE(SUBSTITUTE(SUBSTITUTE(SUBSTITUTE(SUBSTITUTE(SUBSTITUTE(SUBSTITUTE(SUBSTITUTE(SUBSTITUTE(SUBSTITUTE(SUBSTITUTE(SUBSTITUTE(SUBSTITUTE(SUBSTITUTE(LOWER(LEFT(C6,LEN(C6)-LEN(D6))),"_"," "),"-"," "),"."," "),","," "),"("," "),")"," "),"["," "),"]"," "),"&"," "),"+"," "),"@"," "),"#"," "),"!"," "),"'"," "),"/"," "),":"," "),";"," "),"="," "),"~"," "),"%"," "))) | F6: =IF(C6="","",IF(COUNTIF(Classifiers!$A$23:$A$40,D6)>0,1,0)) | G6: =IF(C6="","",IF(COUNTIF(Classifiers!$C$23:$C$30,D6)>0,IF((IF(ISNUMBER(SEARCH(Classifiers!$E$23,E6)),1,0)+IF(ISNUMBER(SEARCH(Classifiers!$E$24,E6)),1,0)+IF(ISNUMBER(SEARCH(Classifiers!$E$25,E6)),1,0)+IF(ISNUMBER(SEARCH(Classifiers!$E$26,E6)),1,0)+IF(ISNUMBER(SEARCH(Classifiers!$E$27,E6)),1,0)+IF(ISNUMBER(SEARCH(Classifiers!$E$28,E6)),1,0)+IF(ISNUMBER(SEARCH(Classifiers!$E$29,E6)),1,0)+IF(ISNUMBER(SEARCH(Classifiers!$E$30,E6)),1,0))>0,1,0),0)) | H6: =IF(C6="","",IF(OR(LEFT(C6,1)=".",AND(F6=0,G6=0)),0,1)) | I6: =IF(H6<>1,"",IF(SUM(J6:W6)=0,"unclassified",INDEX(Classifiers!$A$5:$A$18,MATCH(1,J6:W6,0),1))) | J6: =IF(H6<>1,0,IF((IF(Classifiers!$B$5="",0,IF(ISNUMBER(SEARCH(Classifiers!$B$5,E6)),1,0))+IF(Classifiers!$C$5="",0,IF(ISNUMBER(SEARCH(Classifiers!$C$5,E6)),1,0))+IF(Classifiers!$D$5="",0,IF(ISNUMBER(SEARCH(Classifiers!$D$5,E6)),1,0))+IF(Classifiers!$E$5="",0,IF(ISNUMBER(SEARCH(Classifiers!$E$5,E6)),1,0))+IF(Classifiers!$F$5="",0,IF(ISNUMBER(SEARCH(Classifiers!$F$5,E6)),1,0))+IF(Classifiers!$G$5="",0,IF(ISNUMBER(SEARCH(Classifiers!$G$5,E6)),1,0)))>0,1,0)) | K6: =IF(H6<>1,0,IF((IF(Classifiers!$B$6="",0,IF(ISNUMBER(SEARCH(Classifiers!$B$6,E6)),1,0))+IF(Classifiers!$C$6="",0,IF(ISNUMBER(SEARCH(Classifiers!$C$6,E6)),1,0))+IF(Classifiers!$D$6="",0,IF(ISNUMBER(SEARCH(Classifiers!$D$6,E6)),1,0))+IF(Classifiers!$E$6="",0,IF(ISNUMBER(SEARCH(Classifiers!$E$6,E6)),1,0))+IF(Classifiers!$F$6="",0,IF(ISNUMBER(SEARCH(Classifiers!$F$6,E6)),1,0))+IF(Classifiers!$G$6="",0,IF(ISNUMBER(SEARCH(Classifiers!$G$6,E6)),1,0)))>0,1,0)) | L6: =IF(H6<>1,0,IF((IF(Classifiers!$B$7="",0,IF(ISNUMBER(SEARCH(Classifiers!$B$7,E6)),1,0))+IF(Classifiers!$C$7="",0,IF(ISNUMBER(SEARCH(Classifiers!$C$7,E6)),1,0))+IF(Classifiers!$D$7="",0,IF(ISNUMBER(SEARCH(Classifiers!$D$7,E6)),1,0))+IF(Classifiers!$E$7="",0,IF(ISNUMBER(SEARCH(Classifiers!$E$7,E6)),1,0))+IF(Classifiers!$F$7="",0,IF(ISNUMBER(SEARCH(Classifiers!$F$7,E6)),1,0))+IF(Classifiers!$G$7="",0,IF(ISNUMBER(SEARCH(Classifiers!$G$7,E6)),1,0)))>0,1,0)) | M6: =IF(H6<>1,0,IF((IF(Classifiers!$B$8="",0,IF(ISNUMBER(SEARCH(Classifiers!$B$8,E6)),1,0))+IF(Classifiers!$C$8="",0,IF(ISNUMBER(SEARCH(Classifiers!$C$8,E6)),1,0))+IF(Classifiers!$D$8="",0,IF(ISNUMBER(SEARCH(Classifiers!$D$8,E6)),1,0))+IF(Classifiers!$E$8="",0,IF(ISNUMBER(SEARCH(Classifiers!$E$8,E6)),1,0))+IF(Classifiers!$F$8="",0,IF(ISNUMBER(SEARCH(Classifiers!$F$8,E6)),1,0))+IF(Classifiers!$G$8="",0,IF(ISNUMBER(SEARCH(Classifiers!$G$8,E6)),1,0)))>0,1,0)) | N6: =IF(H6<>1,0,IF((IF(Classifiers!$B$9="",0,IF(ISNUMBER(SEARCH(Classifiers!$B$9,E6)),1,0))+IF(Classifiers!$C$9="",0,IF(ISNUMBER(SEARCH(Classifiers!$C$9,E6)),1,0))+IF(Classifiers!$D$9="",0,IF(ISNUMBER(SEARCH(Classifiers!$D$9,E6)),1,0))+IF(Classifiers!$E$9="",0,IF(ISNUMBER(SEARCH(Classifiers!$E$9,E6)),1,0))+IF(Classifiers!$F$9="",0,IF(ISNUMBER(SEARCH(Classifiers!$F$9,E6)),1,0))+IF(Classifiers!$G$9="",0,IF(ISNUMBER(SEARCH(Classifiers!$G$9,E6)),1,0)))>0,1,0)) | O6: =IF(H6<>1,0,IF((IF(Classifiers!$B$10="",0,IF(ISNUMBER(SEARCH(Classifiers!$B$10,E6)),1,0))+IF(Classifiers!$C$10="",0,IF(ISNUMBER(SEARCH(Classifiers!$C$10,E6)),1,0))+IF(Classifiers!$D$10="",0,IF(ISNUMBER(SEARCH(Classifiers!$D$10,E6)),1,0))+IF(Classifiers!$E$10="",0,IF(ISNUMBER(SEARCH(Classifiers!$E$10,E6)),1,0))+IF(Classifiers!$F$10="",0,IF(ISNUMBER(SEARCH(Classifiers!$F$10,E6)),1,0))+IF(Classifiers!$G$10="",0,IF(ISNUMBER(SEARCH(Classifiers!$G$10,E6)),1,0)))>0,1,0)) | P6: =IF(H6<>1,0,IF((IF(Classifiers!$B$11="",0,IF(ISNUMBER(SEARCH(Classifiers!$B$11,E6)),1,0))+IF(Classifiers!$C$11="",0,IF(ISNUMBER(SEARCH(Classifiers!$C$11,E6)),1,0))+IF(Classifiers!$D$11="",0,IF(ISNUMBER(SEARCH(Classifiers!$D$11,E6)),1,0))+IF(Classifiers!$E$11="",0,IF(ISNUMBER(SEARCH(Classifiers!$E$11,E6)),1,0))+IF(Classifiers!$F$11="",0,IF(ISNUMBER(SEARCH(Classifiers!$F$11,E6)),1,0))+IF(Classifiers!$G$11="",0,IF(ISNUMBER(SEARCH(Classifiers!$G$11,E6)),1,0)))>0,1,0)) | Q6: =IF(H6<>1,0,IF((IF(Classifiers!$B$12="",0,IF(ISNUMBER(SEARCH(Classifiers!$B$12,E6)),1,0))+IF(Classifiers!$C$12="",0,IF(ISNUMBER(SEARCH(Classifiers!$C$12,E6)),1,0))+IF(Classifiers!$D$12="",0,IF(ISNUMBER(SEARCH(Classifiers!$D$12,E6)),1,0))+IF(Classifiers!$E$12="",0,IF(ISNUMBER(SEARCH(Classifiers!$E$12,E6)),1,0))+IF(Classifiers!$F$12="",0,IF(ISNUMBER(SEARCH(Classifiers!$F$12,E6)),1,0))+IF(Classifiers!$G$12="",0,IF(ISNUMBER(SEARCH(Classifiers!$G$12,E6)),1,0)))>0,1,0)) | R6: =IF(H6<>1,0,IF((IF(Classifiers!$B$13="",0,IF(ISNUMBER(SEARCH(Classifiers!$B$13,E6)),1,0))+IF(Classifiers!$C$13="",0,IF(ISNUMBER(SEARCH(Classifiers!$C$13,E6)),1,0))+IF(Classifiers!$D$13="",0,IF(ISNUMBER(SEARCH(Classifiers!$D$13,E6)),1,0))+IF(Classifiers!$E$13="",0,IF(ISNUMBER(SEARCH(Classifiers!$E$13,E6)),1,0))+IF(Classifiers!$F$13="",0,IF(ISNUMBER(SEARCH(Classifiers!$F$13,E6)),1,0))+IF(Classifiers!$G$13="",0,IF(ISNUMBER(SEARCH(Classifiers!$G$13,E6)),1,0)))>0,1,0)) | S6: =IF(H6<>1,0,IF((IF(Classifiers!$B$14="",0,IF(ISNUMBER(SEARCH(Classifiers!$B$14,E6)),1,0))+IF(Classifiers!$C$14="",0,IF(ISNUMBER(SEARCH(Classifiers!$C$14,E6)),1,0))+IF(Classifiers!$D$14="",0,IF(ISNUMBER(SEARCH(Classifiers!$D$14,E6)),1,0))+IF(Classifiers!$E$14="",0,IF(ISNUMBER(SEARCH(Classifiers!$E$14,E6)),1,0))+IF(Classifiers!$F$14="",0,IF(ISNUMBER(SEARCH(Classifiers!$F$14,E6)),1,0))+IF(Classifiers!$G$14="",0,IF(ISNUMBER(SEARCH(Classifiers!$G$14,E6)),1,0)))>0,1,0)) | T6: =IF(H6<>1,0,IF((IF(Classifiers!$B$15="",0,IF(ISNUMBER(SEARCH(Classifiers!$B$15,E6)),1,0))+IF(Classifiers!$C$15="",0,IF(ISNUMBER(SEARCH(Classifiers!$C$15,E6)),1,0))+IF(Classifiers!$D$15="",0,IF(ISNUMBER(SEARCH(Classifiers!$D$15,E6)),1,0))+IF(Classifiers!$E$15="",0,IF(ISNUMBER(SEARCH(Classifiers!$E$15,E6)),1,0))+IF(Classifiers!$F$15="",0,IF(ISNUMBER(SEARCH(Classifiers!$F$15,E6)),1,0))+IF(Classifiers!$G$15="",0,IF(ISNUMBER(SEARCH(Classifiers!$G$15,E6)),1,0)))>0,1,0)) | U6: =IF(H6<>1,0,IF((IF(Classifiers!$B$16="",0,IF(ISNUMBER(SEARCH(Classifiers!$B$16,E6)),1,0))+IF(Classifiers!$C$16="",0,IF(ISNUMBER(SEARCH(Classifiers!$C$16,E6)),1,0))+IF(Classifiers!$D$16="",0,IF(ISNUMBER(SEARCH(Classifiers!$D$16,E6)),1,0))+IF(Classifiers!$E$16="",0,IF(ISNUMBER(SEARCH(Classifiers!$E$16,E6)),1,0))+IF(Classifiers!$F$16="",0,IF(ISNUMBER(SEARCH(Classifiers!$F$16,E6)),1,0))+IF(Classifiers!$G$16="",0,IF(ISNUMBER(SEARCH(Classifiers!$G$16,E6)),1,0)))>0,1,0)) | V6: =IF(H6<>1,0,IF((IF(Classifiers!$B$17="",0,IF(ISNUMBER(SEARCH(Classifiers!$B$17,E6)),1,0))+IF(Classifiers!$C$17="",0,IF(ISNUMBER(SEARCH(Classifiers!$C$17,E6)),1,0))+IF(Classifiers!$D$17="",0,IF(ISNUMBER(SEARCH(Classifiers!$D$17,E6)),1,0))+IF(Classifiers!$E$17="",0,IF(ISNUMBER(SEARCH(Classifiers!$E$17,E6)),1,0))+IF(Classifiers!$F$17="",0,IF(ISNUMBER(SEARCH(Classifiers!$F$17,E6)),1,0))+IF(Classifiers!$G$17="",0,IF(ISNUMBER(SEARCH(Classifiers!$G$17,E6)),1,0)))>0,1,0)) | W6: =IF(H6<>1,0,IF((IF(Classifiers!$B$18="",0,IF(ISNUMBER(SEARCH(Classifiers!$B$18,E6)),1,0))+IF(Classifiers!$C$18="",0,IF(ISNUMBER(SEARCH(Classifiers!$C$18,E6)),1,0))+IF(Classifiers!$D$18="",0,IF(ISNUMBER(SEARCH(Classifiers!$D$18,E6)),1,0))+IF(Classifiers!$E$18="",0,IF(ISNUMBER(SEARCH(Classifiers!$E$18,E6)),1,0))+IF(Classifiers!$F$18="",0,IF(ISNUMBER(SEARCH(Classifiers!$F$18,E6)),1,0))+IF(Classifiers!$G$18="",0,IF(ISNUMBER(SEARCH(Classifiers!$G$18,E6)),1,0)))>0,1,0))
C7: =IF(A7="","",TRIM(RIGHT(SUBSTITUTE(A7,"/",REPT(" ",250)),250))) | D7: =IF(C7="","",IF(ISNUMBER(SEARCH(".",C7)),LOWER("."&TRIM(RIGHT(SUBSTITUTE(C7,".",REPT(" ",250)),250))),"")) | E7: =IF(C7="","",TRIM(SUBSTITUTE(SUBSTITUTE(SUBSTITUTE(SUBSTITUTE(SUBSTITUTE(SUBSTITUTE(SUBSTITUTE(SUBSTITUTE(SUBSTITUTE(SUBSTITUTE(SUBSTITUTE(SUBSTITUTE(SUBSTITUTE(SUBSTITUTE(SUBSTITUTE(SUBSTITUTE(SUBSTITUTE(SUBSTITUTE(SUBSTITUTE(SUBSTITUTE(LOWER(LEFT(C7,LEN(C7)-LEN(D7))),"_"," "),"-"," "),"."," "),","," "),"("," "),")"," "),"["," "),"]"," "),"&"," "),"+"," "),"@"," "),"#"," "),"!"," "),"'"," "),"/"," "),":"," "),";"," "),"="," "),"~"," "),"%"," "))) | F7: =IF(C7="","",IF(COUNTIF(Classifiers!$A$23:$A$40,D7)>0,1,0)) | G7: =IF(C7="","",IF(COUNTIF(Classifiers!$C$23:$C$30,D7)>0,IF((IF(ISNUMBER(SEARCH(Classifiers!$E$23,E7)),1,0)+IF(ISNUMBER(SEARCH(Classifiers!$E$24,E7)),1,0)+IF(ISNUMBER(SEARCH(Classifiers!$E$25,E7)),1,0)+IF(ISNUMBER(SEARCH(Classifiers!$E$26,E7)),1,0)+IF(ISNUMBER(SEARCH(Classifiers!$E$27,E7)),1,0)+IF(ISNUMBER(SEARCH(Classifiers!$E$28,E7)),1,0)+IF(ISNUMBER(SEARCH(Classifiers!$E$29,E7)),1,0)+IF(ISNUMBER(SEARCH(Classifiers!$E$30,E7)),1,0))>0,1,0),0)) | H7: =IF(C7="","",IF(OR(LEFT(C7,1)=".",AND(F7=0,G7=0)),0,1)) | I7: =IF(H7<>1,"",IF(SUM(J7:W7)=0,"unclassified",INDEX(Classifiers!$A$5:$A$18,MATCH(1,J7:W7,0),1))) | J7: =IF(H7<>1,0,IF((IF(Classifiers!$B$5="",0,IF(ISNUMBER(SEARCH(Classifiers!$B$5,E7)),1,0))+IF(Classifiers!$C$5="",0,IF(ISNUMBER(SEARCH(Classifiers!$C$5,E7)),1,0))+IF(Classifiers!$D$5="",0,IF(ISNUMBER(SEARCH(Classifiers!$D$5,E7)),1,0))+IF(Classifiers!$E$5="",0,IF(ISNUMBER(SEARCH(Classifiers!$E$5,E7)),1,0))+IF(Classifiers!$F$5="",0,IF(ISNUMBER(SEARCH(Classifiers!$F$5,E7)),1,0))+IF(Classifiers!$G$5="",0,IF(ISNUMBER(SEARCH(Classifiers!$G$5,E7)),1,0)))>0,1,0)) | K7: =IF(H7<>1,0,IF((IF(Classifiers!$B$6="",0,IF(ISNUMBER(SEARCH(Classifiers!$B$6,E7)),1,0))+IF(Classifiers!$C$6="",0,IF(ISNUMBER(SEARCH(Classifiers!$C$6,E7)),1,0))+IF(Classifiers!$D$6="",0,IF(ISNUMBER(SEARCH(Classifiers!$D$6,E7)),1,0))+IF(Classifiers!$E$6="",0,IF(ISNUMBER(SEARCH(Classifiers!$E$6,E7)),1,0))+IF(Classifiers!$F$6="",0,IF(ISNUMBER(SEARCH(Classifiers!$F$6,E7)),1,0))+IF(Classifiers!$G$6="",0,IF(ISNUMBER(SEARCH(Classifiers!$G$6,E7)),1,0)))>0,1,0)) | L7: =IF(H7<>1,0,IF((IF(Classifiers!$B$7="",0,IF(ISNUMBER(SEARCH(Classifiers!$B$7,E7)),1,0))+IF(Classifiers!$C$7="",0,IF(ISNUMBER(SEARCH(Classifiers!$C$7,E7)),1,0))+IF(Classifiers!$D$7="",0,IF(ISNUMBER(SEARCH(Classifiers!$D$7,E7)),1,0))+IF(Classifiers!$E$7="",0,IF(ISNUMBER(SEARCH(Classifiers!$E$7,E7)),1,0))+IF(Classifiers!$F$7="",0,IF(ISNUMBER(SEARCH(Classifiers!$F$7,E7)),1,0))+IF(Classifiers!$G$7="",0,IF(ISNUMBER(SEARCH(Classifiers!$G$7,E7)),1,0)))>0,1,0)) | M7: =IF(H7<>1,0,IF((IF(Classifiers!$B$8="",0,IF(ISNUMBER(SEARCH(Classifiers!$B$8,E7)),1,0))+IF(Classifiers!$C$8="",0,IF(ISNUMBER(SEARCH(Classifiers!$C$8,E7)),1,0))+IF(Classifiers!$D$8="",0,IF(ISNUMBER(SEARCH(Classifiers!$D$8,E7)),1,0))+IF(Classifiers!$E$8="",0,IF(ISNUMBER(SEARCH(Classifiers!$E$8,E7)),1,0))+IF(Classifiers!$F$8="",0,IF(ISNUMBER(SEARCH(Classifiers!$F$8,E7)),1,0))+IF(Classifiers!$G$8="",0,IF(ISNUMBER(SEARCH(Classifiers!$G$8,E7)),1,0)))>0,1,0)) | N7: =IF(H7<>1,0,IF((IF(Classifiers!$B$9="",0,IF(ISNUMBER(SEARCH(Classifiers!$B$9,E7)),1,0))+IF(Classifiers!$C$9="",0,IF(ISNUMBER(SEARCH(Classifiers!$C$9,E7)),1,0))+IF(Classifiers!$D$9="",0,IF(ISNUMBER(SEARCH(Classifiers!$D$9,E7)),1,0))+IF(Classifiers!$E$9="",0,IF(ISNUMBER(SEARCH(Classifiers!$E$9,E7)),1,0))+IF(Classifiers!$F$9="",0,IF(ISNUMBER(SEARCH(Classifiers!$F$9,E7)),1,0))+IF(Classifiers!$G$9="",0,IF(ISNUMBER(SEARCH(Classifiers!$G$9,E7)),1,0)))>0,1,0)) | O7: =IF(H7<>1,0,IF((IF(Classifiers!$B$10="",0,IF(ISNUMBER(SEARCH(Classifiers!$B$10,E7)),1,0))+IF(Classifiers!$C$10="",0,IF(ISNUMBER(SEARCH(Classifiers!$C$10,E7)),1,0))+IF(Classifiers!$D$10="",0,IF(ISNUMBER(SEARCH(Classifiers!$D$10,E7)),1,0))+IF(Classifiers!$E$10="",0,IF(ISNUMBER(SEARCH(Classifiers!$E$10,E7)),1,0))+IF(Classifiers!$F$10="",0,IF(ISNUMBER(SEARCH(Classifiers!$F$10,E7)),1,0))+IF(Classifiers!$G$10="",0,IF(ISNUMBER(SEARCH(Classifiers!$G$10,E7)),1,0)))>0,1,0)) | P7: =IF(H7<>1,0,IF((IF(Classifiers!$B$11="",0,IF(ISNUMBER(SEARCH(Classifiers!$B$11,E7)),1,0))+IF(Classifiers!$C$11="",0,IF(ISNUMBER(SEARCH(Classifiers!$C$11,E7)),1,0))+IF(Classifiers!$D$11="",0,IF(ISNUMBER(SEARCH(Classifiers!$D$11,E7)),1,0))+IF(Classifiers!$E$11="",0,IF(ISNUMBER(SEARCH(Classifiers!$E$11,E7)),1,0))+IF(Classifiers!$F$11="",0,IF(ISNUMBER(SEARCH(Classifiers!$F$11,E7)),1,0))+IF(Classifiers!$G$11="",0,IF(ISNUMBER(SEARCH(Classifiers!$G$11,E7)),1,0)))>0,1,0)) | Q7: =IF(H7<>1,0,IF((IF(Classifiers!$B$12="",0,IF(ISNUMBER(SEARCH(Classifiers!$B$12,E7)),1,0))+IF(Classifiers!$C$12="",0,IF(ISNUMBER(SEARCH(Classifiers!$C$12,E7)),1,0))+IF(Classifiers!$D$12="",0,IF(ISNUMBER(SEARCH(Classifiers!$D$12,E7)),1,0))+IF(Classifiers!$E$12="",0,IF(ISNUMBER(SEARCH(Classifiers!$E$12,E7)),1,0))+IF(Classifiers!$F$12="",0,IF(ISNUMBER(SEARCH(Classifiers!$F$12,E7)),1,0))+IF(Classifiers!$G$12="",0,IF(ISNUMBER(SEARCH(Classifiers!$G$12,E7)),1,0)))>0,1,0)) | R7: =IF(H7<>1,0,IF((IF(Classifiers!$B$13="",0,IF(ISNUMBER(SEARCH(Classifiers!$B$13,E7)),1,0))+IF(Classifiers!$C$13="",0,IF(ISNUMBER(SEARCH(Classifiers!$C$13,E7)),1,0))+IF(Classifiers!$D$13="",0,IF(ISNUMBER(SEARCH(Classifiers!$D$13,E7)),1,0))+IF(Classifiers!$E$13="",0,IF(ISNUMBER(SEARCH(Classifiers!$E$13,E7)),1,0))+IF(Classifiers!$F$13="",0,IF(ISNUMBER(SEARCH(Classifiers!$F$13,E7)),1,0))+IF(Classifiers!$G$13="",0,IF(ISNUMBER(SEARCH(Classifiers!$G$13,E7)),1,0)))>0,1,0)) | S7: =IF(H7<>1,0,IF((IF(Classifiers!$B$14="",0,IF(ISNUMBER(SEARCH(Classifiers!$B$14,E7)),1,0))+IF(Classifiers!$C$14="",0,IF(ISNUMBER(SEARCH(Classifiers!$C$14,E7)),1,0))+IF(Classifiers!$D$14="",0,IF(ISNUMBER(SEARCH(Classifiers!$D$14,E7)),1,0))+IF(Classifiers!$E$14="",0,IF(ISNUMBER(SEARCH(Classifiers!$E$14,E7)),1,0))+IF(Classifiers!$F$14="",0,IF(ISNUMBER(SEARCH(Classifiers!$F$14,E7)),1,0))+IF(Classifiers!$G$14="",0,IF(ISNUMBER(SEARCH(Classifiers!$G$14,E7)),1,0)))>0,1,0)) | T7: =IF(H7<>1,0,IF((IF(Classifiers!$B$15="",0,IF(ISNUMBER(SEARCH(Classifiers!$B$15,E7)),1,0))+IF(Classifiers!$C$15="",0,IF(ISNUMBER(SEARCH(Classifiers!$C$15,E7)),1,0))+IF(Classifiers!$D$15="",0,IF(ISNUMBER(SEARCH(Classifiers!$D$15,E7)),1,0))+IF(Classifiers!$E$15="",0,IF(ISNUMBER(SEARCH(Classifiers!$E$15,E7)),1,0))+IF(Classifiers!$F$15="",0,IF(ISNUMBER(SEARCH(Classifiers!$F$15,E7)),1,0))+IF(Classifiers!$G$15="",0,IF(ISNUMBER(SEARCH(Classifiers!$G$15,E7)),1,0)))>0,1,0)) | U7: =IF(H7<>1,0,IF((IF(Classifiers!$B$16="",0,IF(ISNUMBER(SEARCH(Classifiers!$B$16,E7)),1,0))+IF(Classifiers!$C$16="",0,IF(ISNUMBER(SEARCH(Classifiers!$C$16,E7)),1,0))+IF(Classifiers!$D$16="",0,IF(ISNUMBER(SEARCH(Classifiers!$D$16,E7)),1,0))+IF(Classifiers!$E$16="",0,IF(ISNUMBER(SEARCH(Classifiers!$E$16,E7)),1,0))+IF(Classifiers!$F$16="",0,IF(ISNUMBER(SEARCH(Classifiers!$F$16,E7)),1,0))+IF(Classifiers!$G$16="",0,IF(ISNUMBER(SEARCH(Classifiers!$G$16,E7)),1,0)))>0,1,0)) | V7: =IF(H7<>1,0,IF((IF(Classifiers!$B$17="",0,IF(ISNUMBER(SEARCH(Classifiers!$B$17,E7)),1,0))+IF(Classifiers!$C$17="",0,IF(ISNUMBER(SEARCH(Classifiers!$C$17,E7)),1,0))+IF(Classifiers!$D$17="",0,IF(ISNUMBER(SEARCH(Classifiers!$D$17,E7)),1,0))+IF(Classifiers!$E$17="",0,IF(ISNUMBER(SEARCH(Classifiers!$E$17,E7)),1,0))+IF(Classifiers!$F$17="",0,IF(ISNUMBER(SEARCH(Classifiers!$F$17,E7)),1,0))+IF(Classifiers!$G$17="",0,IF(ISNUMBER(SEARCH(Classifiers!$G$17,E7)),1,0)))>0,1,0)) | W7: =IF(H7<>1,0,IF((IF(Classifiers!$B$18="",0,IF(ISNUMBER(SEARCH(Classifiers!$B$18,E7)),1,0))+IF(Classifiers!$C$18="",0,IF(ISNUMBER(SEARCH(Classifiers!$C$18,E7)),1,0))+IF(Classifiers!$D$18="",0,IF(ISNUMBER(SEARCH(Classifiers!$D$18,E7)),1,0))+IF(Classifiers!$E$18="",0,IF(ISNUMBER(SEARCH(Classifiers!$E$18,E7)),1,0))+IF(Classifiers!$F$18="",0,IF(ISNUMBER(SEARCH(Classifiers!$F$18,E7)),1,0))+IF(Classifiers!$G$18="",0,IF(ISNUMBER(SEARCH(Classifiers!$G$18,E7)),1,0)))>0,1,0))
C8: =IF(A8="","",TRIM(RIGHT(SUBSTITUTE(A8,"/",REPT(" ",250)),250))) | D8: =IF(C8="","",IF(ISNUMBER(SEARCH(".",C8)),LOWER("."&TRIM(RIGHT(SUBSTITUTE(C8,".",REPT(" ",250)),250))),"")) | E8: =IF(C8="","",TRIM(SUBSTITUTE(SUBSTITUTE(SUBSTITUTE(SUBSTITUTE(SUBSTITUTE(SUBSTITUTE(SUBSTITUTE(SUBSTITUTE(SUBSTITUTE(SUBSTITUTE(SUBSTITUTE(SUBSTITUTE(SUBSTITUTE(SUBSTITUTE(SUBSTITUTE(SUBSTITUTE(SUBSTITUTE(SUBSTITUTE(SUBSTITUTE(SUBSTITUTE(LOWER(LEFT(C8,LEN(C8)-LEN(D8))),"_"," "),"-"," "),"."," "),","," "),"("," "),")"," "),"["," "),"]"," "),"&"," "),"+"," "),"@"," "),"#"," "),"!"," "),"'"," "),"/"," "),":"," "),";"," "),"="," "),"~"," "),"%"," "))) | F8: =IF(C8="","",IF(COUNTIF(Classifiers!$A$23:$A$40,D8)>0,1,0)) | G8: =IF(C8="","",IF(COUNTIF(Classifiers!$C$23:$C$30,D8)>0,IF((IF(ISNUMBER(SEARCH(Classifiers!$E$23,E8)),1,0)+IF(ISNUMBER(SEARCH(Classifiers!$E$24,E8)),1,0)+IF(ISNUMBER(SEARCH(Classifiers!$E$25,E8)),1,0)+IF(ISNUMBER(SEARCH(Classifiers!$E$26,E8)),1,0)+IF(ISNUMBER(SEARCH(Classifiers!$E$27,E8)),1,0)+IF(ISNUMBER(SEARCH(Classifiers!$E$28,E8)),1,0)+IF(ISNUMBER(SEARCH(Classifiers!$E$29,E8)),1,0)+IF(ISNUMBER(SEARCH(Classifiers!$E$30,E8)),1,0))>0,1,0),0)) | H8: =IF(C8="","",IF(OR(LEFT(C8,1)=".",AND(F8=0,G8=0)),0,1)) | I8: =IF(H8<>1,"",IF(SUM(J8:W8)=0,"unclassified",INDEX(Classifiers!$A$5:$A$18,MATCH(1,J8:W8,0),1))) | J8: =IF(H8<>1,0,IF((IF(Classifiers!$B$5="",0,IF(ISNUMBER(SEARCH(Classifiers!$B$5,E8)),1,0))+IF(Classifiers!$C$5="",0,IF(ISNUMBER(SEARCH(Classifiers!$C$5,E8)),1,0))+IF(Classifiers!$D$5="",0,IF(ISNUMBER(SEARCH(Classifiers!$D$5,E8)),1,0))+IF(Classifiers!$E$5="",0,IF(ISNUMBER(SEARCH(Classifiers!$E$5,E8)),1,0))+IF(Classifiers!$F$5="",0,IF(ISNUMBER(SEARCH(Classifiers!$F$5,E8)),1,0))+IF(Classifiers!$G$5="",0,IF(ISNUMBER(SEARCH(Classifiers!$G$5,E8)),1,0)))>0,1,0)) | K8: =IF(H8<>1,0,IF((IF(Classifiers!$B$6="",0,IF(ISNUMBER(SEARCH(Classifiers!$B$6,E8)),1,0))+IF(Classifiers!$C$6="",0,IF(ISNUMBER(SEARCH(Classifiers!$C$6,E8)),1,0))+IF(Classifiers!$D$6="",0,IF(ISNUMBER(SEARCH(Classifiers!$D$6,E8)),1,0))+IF(Classifiers!$E$6="",0,IF(ISNUMBER(SEARCH(Classifiers!$E$6,E8)),1,0))+IF(Classifiers!$F$6="",0,IF(ISNUMBER(SEARCH(Classifiers!$F$6,E8)),1,0))+IF(Classifiers!$G$6="",0,IF(ISNUMBER(SEARCH(Classifiers!$G$6,E8)),1,0)))>0,1,0)) | L8: =IF(H8<>1,0,IF((IF(Classifiers!$B$7="",0,IF(ISNUMBER(SEARCH(Classifiers!$B$7,E8)),1,0))+IF(Classifiers!$C$7="",0,IF(ISNUMBER(SEARCH(Classifiers!$C$7,E8)),1,0))+IF(Classifiers!$D$7="",0,IF(ISNUMBER(SEARCH(Classifiers!$D$7,E8)),1,0))+IF(Classifiers!$E$7="",0,IF(ISNUMBER(SEARCH(Classifiers!$E$7,E8)),1,0))+IF(Classifiers!$F$7="",0,IF(ISNUMBER(SEARCH(Classifiers!$F$7,E8)),1,0))+IF(Classifiers!$G$7="",0,IF(ISNUMBER(SEARCH(Classifiers!$G$7,E8)),1,0)))>0,1,0)) | M8: =IF(H8<>1,0,IF((IF(Classifiers!$B$8="",0,IF(ISNUMBER(SEARCH(Classifiers!$B$8,E8)),1,0))+IF(Classifiers!$C$8="",0,IF(ISNUMBER(SEARCH(Classifiers!$C$8,E8)),1,0))+IF(Classifiers!$D$8="",0,IF(ISNUMBER(SEARCH(Classifiers!$D$8,E8)),1,0))+IF(Classifiers!$E$8="",0,IF(ISNUMBER(SEARCH(Classifiers!$E$8,E8)),1,0))+IF(Classifiers!$F$8="",0,IF(ISNUMBER(SEARCH(Classifiers!$F$8,E8)),1,0))+IF(Classifiers!$G$8="",0,IF(ISNUMBER(SEARCH(Classifiers!$G$8,E8)),1,0)))>0,1,0)) | N8: =IF(H8<>1,0,IF((IF(Classifiers!$B$9="",0,IF(ISNUMBER(SEARCH(Classifiers!$B$9,E8)),1,0))+IF(Classifiers!$C$9="",0,IF(ISNUMBER(SEARCH(Classifiers!$C$9,E8)),1,0))+IF(Classifiers!$D$9="",0,IF(ISNUMBER(SEARCH(Classifiers!$D$9,E8)),1,0))+IF(Classifiers!$E$9="",0,IF(ISNUMBER(SEARCH(Classifiers!$E$9,E8)),1,0))+IF(Classifiers!$F$9="",0,IF(ISNUMBER(SEARCH(Classifiers!$F$9,E8)),1,0))+IF(Classifiers!$G$9="",0,IF(ISNUMBER(SEARCH(Classifiers!$G$9,E8)),1,0)))>0,1,0)) | O8: =IF(H8<>1,0,IF((IF(Classifiers!$B$10="",0,IF(ISNUMBER(SEARCH(Classifiers!$B$10,E8)),1,0))+IF(Classifiers!$C$10="",0,IF(ISNUMBER(SEARCH(Classifiers!$C$10,E8)),1,0))+IF(Classifiers!$D$10="",0,IF(ISNUMBER(SEARCH(Classifiers!$D$10,E8)),1,0))+IF(Classifiers!$E$10="",0,IF(ISNUMBER(SEARCH(Classifiers!$E$10,E8)),1,0))+IF(Classifiers!$F$10="",0,IF(ISNUMBER(SEARCH(Classifiers!$F$10,E8)),1,0))+IF(Classifiers!$G$10="",0,IF(ISNUMBER(SEARCH(Classifiers!$G$10,E8)),1,0)))>0,1,0)) | P8: =IF(H8<>1,0,IF((IF(Classifiers!$B$11="",0,IF(ISNUMBER(SEARCH(Classifiers!$B$11,E8)),1,0))+IF(Classifiers!$C$11="",0,IF(ISNUMBER(SEARCH(Classifiers!$C$11,E8)),1,0))+IF(Classifiers!$D$11="",0,IF(ISNUMBER(SEARCH(Classifiers!$D$11,E8)),1,0))+IF(Classifiers!$E$11="",0,IF(ISNUMBER(SEARCH(Classifiers!$E$11,E8)),1,0))+IF(Classifiers!$F$11="",0,IF(ISNUMBER(SEARCH(Classifiers!$F$11,E8)),1,0))+IF(Classifiers!$G$11="",0,IF(ISNUMBER(SEARCH(Classifiers!$G$11,E8)),1,0)))>0,1,0)) | Q8: =IF(H8<>1,0,IF((IF(Classifiers!$B$12="",0,IF(ISNUMBER(SEARCH(Classifiers!$B$12,E8)),1,0))+IF(Classifiers!$C$12="",0,IF(ISNUMBER(SEARCH(Classifiers!$C$12,E8)),1,0))+IF(Classifiers!$D$12="",0,IF(ISNUMBER(SEARCH(Classifiers!$D$12,E8)),1,0))+IF(Classifiers!$E$12="",0,IF(ISNUMBER(SEARCH(Classifiers!$E$12,E8)),1,0))+IF(Classifiers!$F$12="",0,IF(ISNUMBER(SEARCH(Classifiers!$F$12,E8)),1,0))+IF(Classifiers!$G$12="",0,IF(ISNUMBER(SEARCH(Classifiers!$G$12,E8)),1,0)))>0,1,0)) | R8: =IF(H8<>1,0,IF((IF(Classifiers!$B$13="",0,IF(ISNUMBER(SEARCH(Classifiers!$B$13,E8)),1,0))+IF(Classifiers!$C$13="",0,IF(ISNUMBER(SEARCH(Classifiers!$C$13,E8)),1,0))+IF(Classifiers!$D$13="",0,IF(ISNUMBER(SEARCH(Classifiers!$D$13,E8)),1,0))+IF(Classifiers!$E$13="",0,IF(ISNUMBER(SEARCH(Classifiers!$E$13,E8)),1,0))+IF(Classifiers!$F$13="",0,IF(ISNUMBER(SEARCH(Classifiers!$F$13,E8)),1,0))+IF(Classifiers!$G$13="",0,IF(ISNUMBER(SEARCH(Classifiers!$G$13,E8)),1,0)))>0,1,0)) | S8: =IF(H8<>1,0,IF((IF(Classifiers!$B$14="",0,IF(ISNUMBER(SEARCH(Classifiers!$B$14,E8)),1,0))+IF(Classifiers!$C$14="",0,IF(ISNUMBER(SEARCH(Classifiers!$C$14,E8)),1,0))+IF(Classifiers!$D$14="",0,IF(ISNUMBER(SEARCH(Classifiers!$D$14,E8)),1,0))+IF(Classifiers!$E$14="",0,IF(ISNUMBER(SEARCH(Classifiers!$E$14,E8)),1,0))+IF(Classifiers!$F$14="",0,IF(ISNUMBER(SEARCH(Classifiers!$F$14,E8)),1,0))+IF(Classifiers!$G$14="",0,IF(ISNUMBER(SEARCH(Classifiers!$G$14,E8)),1,0)))>0,1,0)) | T8: =IF(H8<>1,0,IF((IF(Classifiers!$B$15="",0,IF(ISNUMBER(SEARCH(Classifiers!$B$15,E8)),1,0))+IF(Classifiers!$C$15="",0,IF(ISNUMBER(SEARCH(Classifiers!$C$15,E8)),1,0))+IF(Classifiers!$D$15="",0,IF(ISNUMBER(SEARCH(Classifiers!$D$15,E8)),1,0))+IF(Classifiers!$E$15="",0,IF(ISNUMBER(SEARCH(Classifiers!$E$15,E8)),1,0))+IF(Classifiers!$F$15="",0,IF(ISNUMBER(SEARCH(Classifiers!$F$15,E8)),1,0))+IF(Classifiers!$G$15="",0,IF(ISNUMBER(SEARCH(Classifiers!$G$15,E8)),1,0)))>0,1,0)) | U8: =IF(H8<>1,0,IF((IF(Classifiers!$B$16="",0,IF(ISNUMBER(SEARCH(Classifiers!$B$16,E8)),1,0))+IF(Classifiers!$C$16="",0,IF(ISNUMBER(SEARCH(Classifiers!$C$16,E8)),1,0))+IF(Classifiers!$D$16="",0,IF(ISNUMBER(SEARCH(Classifiers!$D$16,E8)),1,0))+IF(Classifiers!$E$16="",0,IF(ISNUMBER(SEARCH(Classifiers!$E$16,E8)),1,0))+IF(Classifiers!$F$16="",0,IF(ISNUMBER(SEARCH(Classifiers!$F$16,E8)),1,0))+IF(Classifiers!$G$16="",0,IF(ISNUMBER(SEARCH(Classifiers!$G$16,E8)),1,0)))>0,1,0)) | V8: =IF(H8<>1,0,IF((IF(Classifiers!$B$17="",0,IF(ISNUMBER(SEARCH(Classifiers!$B$17,E8)),1,0))+IF(Classifiers!$C$17="",0,IF(ISNUMBER(SEARCH(Classifiers!$C$17,E8)),1,0))+IF(Classifiers!$D$17="",0,IF(ISNUMBER(SEARCH(Classifiers!$D$17,E8)),1,0))+IF(Classifiers!$E$17="",0,IF(ISNUMBER(SEARCH(Classifiers!$E$17,E8)),1,0))+IF(Classifiers!$F$17="",0,IF(ISNUMBER(SEARCH(Classifiers!$F$17,E8)),1,0))+IF(Classifiers!$G$17="",0,IF(ISNUMBER(SEARCH(Classifiers!$G$17,E8)),1,0)))>0,1,0)) | W8: =IF(H8<>1,0,IF((IF(Classifiers!$B$18="",0,IF(ISNUMBER(SEARCH(Classifiers!$B$18,E8)),1,0))+IF(Classifiers!$C$18="",0,IF(ISNUMBER(SEARCH(Classifiers!$C$18,E8)),1,0))+IF(Classifiers!$D$18="",0,IF(ISNUMBER(SEARCH(Classifiers!$D$18,E8)),1,0))+IF(Classifiers!$E$18="",0,IF(ISNUMBER(SEARCH(Classifiers!$E$18,E8)),1,0))+IF(Classifiers!$F$18="",0,IF(ISNUMBER(SEARCH(Classifiers!$F$18,E8)),1,0))+IF(Classifiers!$G$18="",0,IF(ISNUMBER(SEARCH(Classifiers!$G$18,E8)),1,0)))>0,1,0))
C9: =IF(A9="","",TRIM(RIGHT(SUBSTITUTE(A9,"/",REPT(" ",250)),250))) | D9: =IF(C9="","",IF(ISNUMBER(SEARCH(".",C9)),LOWER("."&TRIM(RIGHT(SUBSTITUTE(C9,".",REPT(" ",250)),250))),"")) | E9: =IF(C9="","",TRIM(SUBSTITUTE(SUBSTITUTE(SUBSTITUTE(SUBSTITUTE(SUBSTITUTE(SUBSTITUTE(SUBSTITUTE(SUBSTITUTE(SUBSTITUTE(SUBSTITUTE(SUBSTITUTE(SUBSTITUTE(SUBSTITUTE(SUBSTITUTE(SUBSTITUTE(SUBSTITUTE(SUBSTITUTE(SUBSTITUTE(SUBSTITUTE(SUBSTITUTE(LOWER(LEFT(C9,LEN(C9)-LEN(D9))),"_"," "),"-"," "),"."," "),","," "),"("," "),")"," "),"["," "),"]"," "),"&"," "),"+"," "),"@"," "),"#"," "),"!"," "),"'"," "),"/"," "),":"," "),";"," "),"="," "),"~"," "),"%"," "))) | F9: =IF(C9="","",IF(COUNTIF(Classifiers!$A$23:$A$40,D9)>0,1,0)) | G9: =IF(C9="","",IF(COUNTIF(Classifiers!$C$23:$C$30,D9)>0,IF((IF(ISNUMBER(SEARCH(Classifiers!$E$23,E9)),1,0)+IF(ISNUMBER(SEARCH(Classifiers!$E$24,E9)),1,0)+IF(ISNUMBER(SEARCH(Classifiers!$E$25,E9)),1,0)+IF(ISNUMBER(SEARCH(Classifiers!$E$26,E9)),1,0)+IF(ISNUMBER(SEARCH(Classifiers!$E$27,E9)),1,0)+IF(ISNUMBER(SEARCH(Classifiers!$E$28,E9)),1,0)+IF(ISNUMBER(SEARCH(Classifiers!$E$29,E9)),1,0)+IF(ISNUMBER(SEARCH(Classifiers!$E$30,E9)),1,0))>0,1,0),0)) | H9: =IF(C9="","",IF(OR(LEFT(C9,1)=".",AND(F9=0,G9=0)),0,1)) | I9: =IF(H9<>1,"",IF(SUM(J9:W9)=0,"unclassified",INDEX(Classifiers!$A$5:$A$18,MATCH(1,J9:W9,0),1))) | J9: =IF(H9<>1,0,IF((IF(Classifiers!$B$5="",0,IF(ISNUMBER(SEARCH(Classifiers!$B$5,E9)),1,0))+IF(Classifiers!$C$5="",0,IF(ISNUMBER(SEARCH(Classifiers!$C$5,E9)),1,0))+IF(Classifiers!$D$5="",0,IF(ISNUMBER(SEARCH(Classifiers!$D$5,E9)),1,0))+IF(Classifiers!$E$5="",0,IF(ISNUMBER(SEARCH(Classifiers!$E$5,E9)),1,0))+IF(Classifiers!$F$5="",0,IF(ISNUMBER(SEARCH(Classifiers!$F$5,E9)),1,0))+IF(Classifiers!$G$5="",0,IF(ISNUMBER(SEARCH(Classifiers!$G$5,E9)),1,0)))>0,1,0)) | K9: =IF(H9<>1,0,IF((IF(Classifiers!$B$6="",0,IF(ISNUMBER(SEARCH(Classifiers!$B$6,E9)),1,0))+IF(Classifiers!$C$6="",0,IF(ISNUMBER(SEARCH(Classifiers!$C$6,E9)),1,0))+IF(Classifiers!$D$6="",0,IF(ISNUMBER(SEARCH(Classifiers!$D$6,E9)),1,0))+IF(Classifiers!$E$6="",0,IF(ISNUMBER(SEARCH(Classifiers!$E$6,E9)),1,0))+IF(Classifiers!$F$6="",0,IF(ISNUMBER(SEARCH(Classifiers!$F$6,E9)),1,0))+IF(Classifiers!$G$6="",0,IF(ISNUMBER(SEARCH(Classifiers!$G$6,E9)),1,0)))>0,1,0)) | L9: =IF(H9<>1,0,IF((IF(Classifiers!$B$7="",0,IF(ISNUMBER(SEARCH(Classifiers!$B$7,E9)),1,0))+IF(Classifiers!$C$7="",0,IF(ISNUMBER(SEARCH(Classifiers!$C$7,E9)),1,0))+IF(Classifiers!$D$7="",0,IF(ISNUMBER(SEARCH(Classifiers!$D$7,E9)),1,0))+IF(Classifiers!$E$7="",0,IF(ISNUMBER(SEARCH(Classifiers!$E$7,E9)),1,0))+IF(Classifiers!$F$7="",0,IF(ISNUMBER(SEARCH(Classifiers!$F$7,E9)),1,0))+IF(Classifiers!$G$7="",0,IF(ISNUMBER(SEARCH(Classifiers!$G$7,E9)),1,0)))>0,1,0)) | M9: =IF(H9<>1,0,IF((IF(Classifiers!$B$8="",0,IF(ISNUMBER(SEARCH(Classifiers!$B$8,E9)),1,0))+IF(Classifiers!$C$8="",0,IF(ISNUMBER(SEARCH(Classifiers!$C$8,E9)),1,0))+IF(Classifiers!$D$8="",0,IF(ISNUMBER(SEARCH(Classifiers!$D$8,E9)),1,0))+IF(Classifiers!$E$8="",0,IF(ISNUMBER(SEARCH(Classifiers!$E$8,E9)),1,0))+IF(Classifiers!$F$8="",0,IF(ISNUMBER(SEARCH(Classifiers!$F$8,E9)),1,0))+IF(Classifiers!$G$8="",0,IF(ISNUMBER(SEARCH(Classifiers!$G$8,E9)),1,0)))>0,1,0)) | N9: =IF(H9<>1,0,IF((IF(Classifiers!$B$9="",0,IF(ISNUMBER(SEARCH(Classifiers!$B$9,E9)),1,0))+IF(Classifiers!$C$9="",0,IF(ISNUMBER(SEARCH(Classifiers!$C$9,E9)),1,0))+IF(Classifiers!$D$9="",0,IF(ISNUMBER(SEARCH(Classifiers!$D$9,E9)),1,0))+IF(Classifiers!$E$9="",0,IF(ISNUMBER(SEARCH(Classifiers!$E$9,E9)),1,0))+IF(Classifiers!$F$9="",0,IF(ISNUMBER(SEARCH(Classifiers!$F$9,E9)),1,0))+IF(Classifiers!$G$9="",0,IF(ISNUMBER(SEARCH(Classifiers!$G$9,E9)),1,0)))>0,1,0)) | O9: =IF(H9<>1,0,IF((IF(Classifiers!$B$10="",0,IF(ISNUMBER(SEARCH(Classifiers!$B$10,E9)),1,0))+IF(Classifiers!$C$10="",0,IF(ISNUMBER(SEARCH(Classifiers!$C$10,E9)),1,0))+IF(Classifiers!$D$10="",0,IF(ISNUMBER(SEARCH(Classifiers!$D$10,E9)),1,0))+IF(Classifiers!$E$10="",0,IF(ISNUMBER(SEARCH(Classifiers!$E$10,E9)),1,0))+IF(Classifiers!$F$10="",0,IF(ISNUMBER(SEARCH(Classifiers!$F$10,E9)),1,0))+IF(Classifiers!$G$10="",0,IF(ISNUMBER(SEARCH(Classifiers!$G$10,E9)),1,0)))>0,1,0)) | P9: =IF(H9<>1,0,IF((IF(Classifiers!$B$11="",0,IF(ISNUMBER(SEARCH(Classifiers!$B$11,E9)),1,0))+IF(Classifiers!$C$11="",0,IF(ISNUMBER(SEARCH(Classifiers!$C$11,E9)),1,0))+IF(Classifiers!$D$11="",0,IF(ISNUMBER(SEARCH(Classifiers!$D$11,E9)),1,0))+IF(Classifiers!$E$11="",0,IF(ISNUMBER(SEARCH(Classifiers!$E$11,E9)),1,0))+IF(Classifiers!$F$11="",0,IF(ISNUMBER(SEARCH(Classifiers!$F$11,E9)),1,0))+IF(Classifiers!$G$11="",0,IF(ISNUMBER(SEARCH(Classifiers!$G$11,E9)),1,0)))>0,1,0)) | Q9: =IF(H9<>1,0,IF((IF(Classifiers!$B$12="",0,IF(ISNUMBER(SEARCH(Classifiers!$B$12,E9)),1,0))+IF(Classifiers!$C$12="",0,IF(ISNUMBER(SEARCH(Classifiers!$C$12,E9)),1,0))+IF(Classifiers!$D$12="",0,IF(ISNUMBER(SEARCH(Classifiers!$D$12,E9)),1,0))+IF(Classifiers!$E$12="",0,IF(ISNUMBER(SEARCH(Classifiers!$E$12,E9)),1,0))+IF(Classifiers!$F$12="",0,IF(ISNUMBER(SEARCH(Classifiers!$F$12,E9)),1,0))+IF(Classifiers!$G$12="",0,IF(ISNUMBER(SEARCH(Classifiers!$G$12,E9)),1,0)))>0,1,0)) | R9: =IF(H9<>1,0,IF((IF(Classifiers!$B$13="",0,IF(ISNUMBER(SEARCH(Classifiers!$B$13,E9)),1,0))+IF(Classifiers!$C$13="",0,IF(ISNUMBER(SEARCH(Classifiers!$C$13,E9)),1,0))+IF(Classifiers!$D$13="",0,IF(ISNUMBER(SEARCH(Classifiers!$D$13,E9)),1,0))+IF(Classifiers!$E$13="",0,IF(ISNUMBER(SEARCH(Classifiers!$E$13,E9)),1,0))+IF(Classifiers!$F$13="",0,IF(ISNUMBER(SEARCH(Classifiers!$F$13,E9)),1,0))+IF(Classifiers!$G$13="",0,IF(ISNUMBER(SEARCH(Classifiers!$G$13,E9)),1,0)))>0,1,0)) | S9: =IF(H9<>1,0,IF((IF(Classifiers!$B$14="",0,IF(ISNUMBER(SEARCH(Classifiers!$B$14,E9)),1,0))+IF(Classifiers!$C$14="",0,IF(ISNUMBER(SEARCH(Classifiers!$C$14,E9)),1,0))+IF(Classifiers!$D$14="",0,IF(ISNUMBER(SEARCH(Classifiers!$D$14,E9)),1,0))+IF(Classifiers!$E$14="",0,IF(ISNUMBER(SEARCH(Classifiers!$E$14,E9)),1,0))+IF(Classifiers!$F$14="",0,IF(ISNUMBER(SEARCH(Classifiers!$F$14,E9)),1,0))+IF(Classifiers!$G$14="",0,IF(ISNUMBER(SEARCH(Classifiers!$G$14,E9)),1,0)))>0,1,0)) | T9: =IF(H9<>1,0,IF((IF(Classifiers!$B$15="",0,IF(ISNUMBER(SEARCH(Classifiers!$B$15,E9)),1,0))+IF(Classifiers!$C$15="",0,IF(ISNUMBER(SEARCH(Classifiers!$C$15,E9)),1,0))+IF(Classifiers!$D$15="",0,IF(ISNUMBER(SEARCH(Classifiers!$D$15,E9)),1,0))+IF(Classifiers!$E$15="",0,IF(ISNUMBER(SEARCH(Classifiers!$E$15,E9)),1,0))+IF(Classifiers!$F$15="",0,IF(ISNUMBER(SEARCH(Classifiers!$F$15,E9)),1,0))+IF(Classifiers!$G$15="",0,IF(ISNUMBER(SEARCH(Classifiers!$G$15,E9)),1,0)))>0,1,0)) | U9: =IF(H9<>1,0,IF((IF(Classifiers!$B$16="",0,IF(ISNUMBER(SEARCH(Classifiers!$B$16,E9)),1,0))+IF(Classifiers!$C$16="",0,IF(ISNUMBER(SEARCH(Classifiers!$C$16,E9)),1,0))+IF(Classifiers!$D$16="",0,IF(ISNUMBER(SEARCH(Classifiers!$D$16,E9)),1,0))+IF(Classifiers!$E$16="",0,IF(ISNUMBER(SEARCH(Classifiers!$E$16,E9)),1,0))+IF(Classifiers!$F$16="",0,IF(ISNUMBER(SEARCH(Classifiers!$F$16,E9)),1,0))+IF(Classifiers!$G$16="",0,IF(ISNUMBER(SEARCH(Classifiers!$G$16,E9)),1,0)))>0,1,0)) | V9: =IF(H9<>1,0,IF((IF(Classifiers!$B$17="",0,IF(ISNUMBER(SEARCH(Classifiers!$B$17,E9)),1,0))+IF(Classifiers!$C$17="",0,IF(ISNUMBER(SEARCH(Classifiers!$C$17,E9)),1,0))+IF(Classifiers!$D$17="",0,IF(ISNUMBER(SEARCH(Classifiers!$D$17,E9)),1,0))+IF(Classifiers!$E$17="",0,IF(ISNUMBER(SEARCH(Classifiers!$E$17,E9)),1,0))+IF(Classifiers!$F$17="",0,IF(ISNUMBER(SEARCH(Classifiers!$F$17,E9)),1,0))+IF(Classifiers!$G$17="",0,IF(ISNUMBER(SEARCH(Classifiers!$G$17,E9)),1,0)))>0,1,0)) | W9: =IF(H9<>1,0,IF((IF(Classifiers!$B$18="",0,IF(ISNUMBER(SEARCH(Classifiers!$B$18,E9)),1,0))+IF(Classifiers!$C$18="",0,IF(ISNUMBER(SEARCH(Classifiers!$C$18,E9)),1,0))+IF(Classifiers!$D$18="",0,IF(ISNUMBER(SEARCH(Classifiers!$D$18,E9)),1,0))+IF(Classifiers!$E$18="",0,IF(ISNUMBER(SEARCH(Classifiers!$E$18,E9)),1,0))+IF(Classifiers!$F$18="",0,IF(ISNUMBER(SEARCH(Classifiers!$F$18,E9)),1,0))+IF(Classifiers!$G$18="",0,IF(ISNUMBER(SEARCH(Classifiers!$G$18,E9)),1,0)))>0,1,0))
C10: =IF(A10="","",TRIM(RIGHT(SUBSTITUTE(A10,"/",REPT(" ",250)),250))) | D10: =IF(C10="","",IF(ISNUMBER(SEARCH(".",C10)),LOWER("."&TRIM(RIGHT(SUBSTITUTE(C10,".",REPT(" ",250)),250))),"")) | E10: =IF(C10="","",TRIM(SUBSTITUTE(SUBSTITUTE(SUBSTITUTE(SUBSTITUTE(SUBSTITUTE(SUBSTITUTE(SUBSTITUTE(SUBSTITUTE(SUBSTITUTE(SUBSTITUTE(SUBSTITUTE(SUBSTITUTE(SUBSTITUTE(SUBSTITUTE(SUBSTITUTE(SUBSTITUTE(SUBSTITUTE(SUBSTITUTE(SUBSTITUTE(SUBSTITUTE(LOWER(LEFT(C10,LEN(C10)-LEN(D10))),"_"," "),"-"," "),"."," "),","," "),"("," "),")"," "),"["," "),"]"," "),"&"," "),"+"," "),"@"," "),"#"," "),"!"," "),"'"," "),"/"," "),":"," "),";"," "),"="," "),"~"," "),"%"," "))) | F10: =IF(C10="","",IF(COUNTIF(Classifiers!$A$23:$A$40,D10)>0,1,0)) | G10: =IF(C10="","",IF(COUNTIF(Classifiers!$C$23:$C$30,D10)>0,IF((IF(ISNUMBER(SEARCH(Classifiers!$E$23,E10)),1,0)+IF(ISNUMBER(SEARCH(Classifiers!$E$24,E10)),1,0)+IF(ISNUMBER(SEARCH(Classifiers!$E$25,E10)),1,0)+IF(ISNUMBER(SEARCH(Classifiers!$E$26,E10)),1,0)+IF(ISNUMBER(SEARCH(Classifiers!$E$27,E10)),1,0)+IF(ISNUMBER(SEARCH(Classifiers!$E$28,E10)),1,0)+IF(ISNUMBER(SEARCH(Classifiers!$E$29,E10)),1,0)+IF(ISNUMBER(SEARCH(Classifiers!$E$30,E10)),1,0))>0,1,0),0)) | H10: =IF(C10="","",IF(OR(LEFT(C10,1)=".",AND(F10=0,G10=0)),0,1)) | I10: =IF(H10<>1,"",IF(SUM(J10:W10)=0,"unclassified",INDEX(Classifiers!$A$5:$A$18,MATCH(1,J10:W10,0),1))) | J10: =IF(H10<>1,0,IF((IF(Classifiers!$B$5="",0,IF(ISNUMBER(SEARCH(Classifiers!$B$5,E10)),1,0))+IF(Classifiers!$C$5="",0,IF(ISNUMBER(SEARCH(Classifiers!$C$5,E10)),1,0))+IF(Classifiers!$D$5="",0,IF(ISNUMBER(SEARCH(Classifiers!$D$5,E10)),1,0))+IF(Classifiers!$E$5="",0,IF(ISNUMBER(SEARCH(Classifiers!$E$5,E10)),1,0))+IF(Classifiers!$F$5="",0,IF(ISNUMBER(SEARCH(Classifiers!$F$5,E10)),1,0))+IF(Classifiers!$G$5="",0,IF(ISNUMBER(SEARCH(Classifiers!$G$5,E10)),1,0)))>0,1,0)) | K10: =IF(H10<>1,0,IF((IF(Classifiers!$B$6="",0,IF(ISNUMBER(SEARCH(Classifiers!$B$6,E10)),1,0))+IF(Classifiers!$C$6="",0,IF(ISNUMBER(SEARCH(Classifiers!$C$6,E10)),1,0))+IF(Classifiers!$D$6="",0,IF(ISNUMBER(SEARCH(Classifiers!$D$6,E10)),1,0))+IF(Classifiers!$E$6="",0,IF(ISNUMBER(SEARCH(Classifiers!$E$6,E10)),1,0))+IF(Classifiers!$F$6="",0,IF(ISNUMBER(SEARCH(Classifiers!$F$6,E10)),1,0))+IF(Classifiers!$G$6="",0,IF(ISNUMBER(SEARCH(Classifiers!$G$6,E10)),1,0)))>0,1,0)) | L10: =IF(H10<>1,0,IF((IF(Classifiers!$B$7="",0,IF(ISNUMBER(SEARCH(Classifiers!$B$7,E10)),1,0))+IF(Classifiers!$C$7="",0,IF(ISNUMBER(SEARCH(Classifiers!$C$7,E10)),1,0))+IF(Classifiers!$D$7="",0,IF(ISNUMBER(SEARCH(Classifiers!$D$7,E10)),1,0))+IF(Classifiers!$E$7="",0,IF(ISNUMBER(SEARCH(Classifiers!$E$7,E10)),1,0))+IF(Classifiers!$F$7="",0,IF(ISNUMBER(SEARCH(Classifiers!$F$7,E10)),1,0))+IF(Classifiers!$G$7="",0,IF(ISNUMBER(SEARCH(Classifiers!$G$7,E10)),1,0)))>0,1,0)) | M10: =IF(H10<>1,0,IF((IF(Classifiers!$B$8="",0,IF(ISNUMBER(SEARCH(Classifiers!$B$8,E10)),1,0))+IF(Classifiers!$C$8="",0,IF(ISNUMBER(SEARCH(Classifiers!$C$8,E10)),1,0))+IF(Classifiers!$D$8="",0,IF(ISNUMBER(SEARCH(Classifiers!$D$8,E10)),1,0))+IF(Classifiers!$E$8="",0,IF(ISNUMBER(SEARCH(Classifiers!$E$8,E10)),1,0))+IF(Classifiers!$F$8="",0,IF(ISNUMBER(SEARCH(Classifiers!$F$8,E10)),1,0))+IF(Classifiers!$G$8="",0,IF(ISNUMBER(SEARCH(Classifiers!$G$8,E10)),1,0)))>0,1,0)) | N10: =IF(H10<>1,0,IF((IF(Classifiers!$B$9="",0,IF(ISNUMBER(SEARCH(Classifiers!$B$9,E10)),1,0))+IF(Classifiers!$C$9="",0,IF(ISNUMBER(SEARCH(Classifiers!$C$9,E10)),1,0))+IF(Classifiers!$D$9="",0,IF(ISNUMBER(SEARCH(Classifiers!$D$9,E10)),1,0))+IF(Classifiers!$E$9="",0,IF(ISNUMBER(SEARCH(Classifiers!$E$9,E10)),1,0))+IF(Classifiers!$F$9="",0,IF(ISNUMBER(SEARCH(Classifiers!$F$9,E10)),1,0))+IF(Classifiers!$G$9="",0,IF(ISNUMBER(SEARCH(Classifiers!$G$9,E10)),1,0)))>0,1,0)) | O10: =IF(H10<>1,0,IF((IF(Classifiers!$B$10="",0,IF(ISNUMBER(SEARCH(Classifiers!$B$10,E10)),1,0))+IF(Classifiers!$C$10="",0,IF(ISNUMBER(SEARCH(Classifiers!$C$10,E10)),1,0))+IF(Classifiers!$D$10="",0,IF(ISNUMBER(SEARCH(Classifiers!$D$10,E10)),1,0))+IF(Classifiers!$E$10="",0,IF(ISNUMBER(SEARCH(Classifiers!$E$10,E10)),1,0))+IF(Classifiers!$F$10="",0,IF(ISNUMBER(SEARCH(Classifiers!$F$10,E10)),1,0))+IF(Classifiers!$G$10="",0,IF(ISNUMBER(SEARCH(Classifiers!$G$10,E10)),1,0)))>0,1,0)) | P10: =IF(H10<>1,0,IF((IF(Classifiers!$B$11="",0,IF(ISNUMBER(SEARCH(Classifiers!$B$11,E10)),1,0))+IF(Classifiers!$C$11="",0,IF(ISNUMBER(SEARCH(Classifiers!$C$11,E10)),1,0))+IF(Classifiers!$D$11="",0,IF(ISNUMBER(SEARCH(Classifiers!$D$11,E10)),1,0))+IF(Classifiers!$E$11="",0,IF(ISNUMBER(SEARCH(Classifiers!$E$11,E10)),1,0))+IF(Classifiers!$F$11="",0,IF(ISNUMBER(SEARCH(Classifiers!$F$11,E10)),1,0))+IF(Classifiers!$G$11="",0,IF(ISNUMBER(SEARCH(Classifiers!$G$11,E10)),1,0)))>0,1,0)) | Q10: =IF(H10<>1,0,IF((IF(Classifiers!$B$12="",0,IF(ISNUMBER(SEARCH(Classifiers!$B$12,E10)),1,0))+IF(Classifiers!$C$12="",0,IF(ISNUMBER(SEARCH(Classifiers!$C$12,E10)),1,0))+IF(Classifiers!$D$12="",0,IF(ISNUMBER(SEARCH(Classifiers!$D$12,E10)),1,0))+IF(Classifiers!$E$12="",0,IF(ISNUMBER(SEARCH(Classifiers!$E$12,E10)),1,0))+IF(Classifiers!$F$12="",0,IF(ISNUMBER(SEARCH(Classifiers!$F$12,E10)),1,0))+IF(Classifiers!$G$12="",0,IF(ISNUMBER(SEARCH(Classifiers!$G$12,E10)),1,0)))>0,1,0)) | R10: =IF(H10<>1,0,IF((IF(Classifiers!$B$13="",0,IF(ISNUMBER(SEARCH(Classifiers!$B$13,E10)),1,0))+IF(Classifiers!$C$13="",0,IF(ISNUMBER(SEARCH(Classifiers!$C$13,E10)),1,0))+IF(Classifiers!$D$13="",0,IF(ISNUMBER(SEARCH(Classifiers!$D$13,E10)),1,0))+IF(Classifiers!$E$13="",0,IF(ISNUMBER(SEARCH(Classifiers!$E$13,E10)),1,0))+IF(Classifiers!$F$13="",0,IF(ISNUMBER(SEARCH(Classifiers!$F$13,E10)),1,0))+IF(Classifiers!$G$13="",0,IF(ISNUMBER(SEARCH(Classifiers!$G$13,E10)),1,0)))>0,1,0)) | S10: =IF(H10<>1,0,IF((IF(Classifiers!$B$14="",0,IF(ISNUMBER(SEARCH(Classifiers!$B$14,E10)),1,0))+IF(Classifiers!$C$14="",0,IF(ISNUMBER(SEARCH(Classifiers!$C$14,E10)),1,0))+IF(Classifiers!$D$14="",0,IF(ISNUMBER(SEARCH(Classifiers!$D$14,E10)),1,0))+IF(Classifiers!$E$14="",0,IF(ISNUMBER(SEARCH(Classifiers!$E$14,E10)),1,0))+IF(Classifiers!$F$14="",0,IF(ISNUMBER(SEARCH(Classifiers!$F$14,E10)),1,0))+IF(Classifiers!$G$14="",0,IF(ISNUMBER(SEARCH(Classifiers!$G$14,E10)),1,0)))>0,1,0)) | T10: =IF(H10<>1,0,IF((IF(Classifiers!$B$15="",0,IF(ISNUMBER(SEARCH(Classifiers!$B$15,E10)),1,0))+IF(Classifiers!$C$15="",0,IF(ISNUMBER(SEARCH(Classifiers!$C$15,E10)),1,0))+IF(Classifiers!$D$15="",0,IF(ISNUMBER(SEARCH(Classifiers!$D$15,E10)),1,0))+IF(Classifiers!$E$15="",0,IF(ISNUMBER(SEARCH(Classifiers!$E$15,E10)),1,0))+IF(Classifiers!$F$15="",0,IF(ISNUMBER(SEARCH(Classifiers!$F$15,E10)),1,0))+IF(Classifiers!$G$15="",0,IF(ISNUMBER(SEARCH(Classifiers!$G$15,E10)),1,0)))>0,1,0)) | U10: =IF(H10<>1,0,IF((IF(Classifiers!$B$16="",0,IF(ISNUMBER(SEARCH(Classifiers!$B$16,E10)),1,0))+IF(Classifiers!$C$16="",0,IF(ISNUMBER(SEARCH(Classifiers!$C$16,E10)),1,0))+IF(Classifiers!$D$16="",0,IF(ISNUMBER(SEARCH(Classifiers!$D$16,E10)),1,0))+IF(Classifiers!$E$16="",0,IF(ISNUMBER(SEARCH(Classifiers!$E$16,E10)),1,0))+IF(Classifiers!$F$16="",0,IF(ISNUMBER(SEARCH(Classifiers!$F$16,E10)),1,0))+IF(Classifiers!$G$16="",0,IF(ISNUMBER(SEARCH(Classifiers!$G$16,E10)),1,0)))>0,1,0)) | V10: =IF(H10<>1,0,IF((IF(Classifiers!$B$17="",0,IF(ISNUMBER(SEARCH(Classifiers!$B$17,E10)),1,0))+IF(Classifiers!$C$17="",0,IF(ISNUMBER(SEARCH(Classifiers!$C$17,E10)),1,0))+IF(Classifiers!$D$17="",0,IF(ISNUMBER(SEARCH(Classifiers!$D$17,E10)),1,0))+IF(Classifiers!$E$17="",0,IF(ISNUMBER(SEARCH(Classifiers!$E$17,E10)),1,0))+IF(Classifiers!$F$17="",0,IF(ISNUMBER(SEARCH(Classifiers!$F$17,E10)),1,0))+IF(Classifiers!$G$17="",0,IF(ISNUMBER(SEARCH(Classifiers!$G$17,E10)),1,0)))>0,1,0)) | W10: =IF(H10<>1,0,IF((IF(Classifiers!$B$18="",0,IF(ISNUMBER(SEARCH(Classifiers!$B$18,E10)),1,0))+IF(Classifiers!$C$18="",0,IF(ISNUMBER(SEARCH(Classifiers!$C$18,E10)),1,0))+IF(Classifiers!$D$18="",0,IF(ISNUMBER(SEARCH(Classifiers!$D$18,E10)),1,0))+IF(Classifiers!$E$18="",0,IF(ISNUMBER(SEARCH(Classifiers!$E$18,E10)),1,0))+IF(Classifiers!$F$18="",0,IF(ISNUMBER(SEARCH(Classifiers!$F$18,E10)),1,0))+IF(Classifiers!$G$18="",0,IF(ISNUMBER(SEARCH(Classifiers!$G$18,E10)),1,0)))>0,1,0))
