Workbook
Name corr_key: 'Corrections'!$H$5:$H$64
Name corr_value: 'Corrections'!$G$5:$G$64
Name company_name: 'Effective'!$B$5
Name start_month: 'Effective'!$B$6
Name horizon_months: 'Effective'!$B$7
Name tax_rate: 'Effective'!$B$8
Name da_monthly: 'Effective'!$B$9
Name capex_monthly: 'Effective'!$B$10
Name dso_days: 'Effective'!$B$11
Name dpo_days: 'Effective'!$B$12
Name dio_days: 'Effective'!$B$13
Name open_cash: 'Effective'!$B$14
Name open_ar: 'Effective'!$B$15
Name open_ap: 'Effective'!$B$16
Name open_inventory: 'Effective'!$B$17
Name open_nol: 'Effective'!$B$18
Name currency_code: 'Effective'!$B$19
Name currency_symbol: 'Effective'!$B$20
Name number_style: 'Effective'!$B$21
Name display_divisor: 'Effective'!$B$22
Name display_unit: 'Effective'!$B$23
Name valid_keys: 'ValidKeys'!$A$3:$A$207
Name tot_revenue: 'Summary'!$B$5
Name tot_ebitda: 'Summary'!$B$9
Name tot_net_income: 'Summary'!$B$14
Name tot_ending_cash: 'Summary'!$B$21
Name tot_gross_margin: 'Summary'!$B$26
Name tot_free_cash_flow: 'Summary'!$B$19
Name briefing_lines: 'Briefing'!$D$10:$D$147
Name checks_overall: 'Checks'!$C$3

Sheet README
A1: K01 · Monthly P&L + Cash-Flow Engine (no-code kernel)
A3: Replaces openfpa: pyfpa.cashflow_from_config, revenue/cogs/opex/debt/working_capital/tax models, apply_corrections, model_to_excel, verify_workbook, extract_lines, to_briefing_md, forecast_to_excel.
A4: How an agent uses this workbook
A5: 1. Copy this file into companies/<slug>/models/ (never edit the kernel copy in 02_kernel/).
A6: 2. Type drivers ONLY into pale-yellow cells on 'Assumptions' (scalars, up to 8 channels, 15 opex lines, 5 debt instruments).
A7: 3. Transcribe every memory/corrections/*.md with type: parametric into 'Corrections' (path, value, status, type).
A8: 4. Let the spreadsheet engine recalculate (Excel, LibreOffice Calc, Google Sheets, OnlyOffice, Zoho Sheet, WPS). Never type numbers into white cells.
A9: 5. Read 'Checks' first: OVERALL must be PASS before any number leaves the workbook.
A10: 6. Read results from 'Summary' (headline, Indian-FY and quarterly roll-ups, scoring lines) and 'Briefing' (board markdown).
A11: 7. 'Export_Rows' is the month-per-row fact table for K08 divestiture and the BI layer (05_bi-and-presentation).
A12: Sheet map
A13: Assumptions = inputs · Corrections = parametric overrides · Effective = inputs after corrections (formulas) · Model = the engine (one formula per line per month, up to 120 months) · Summary · Briefing · Export_Rows · Checks · ValidKeys.
... A26: FY2026-27 budget, ₹, Indian FY, one applied parametric correction (dealer November seasonality 1.45). GOLDEN rows = reference-engine results.

Sheet Checks
A1: Checks - schema validation + accounting invariants. OVERALL must be PASS before use.
B3: OVERALL | C3: =IF(COUNTIF(C5:C36,"PASS")=COUNT(A5:A36),"PASS","FAIL") | D3: =COUNTIF(C5:C36,"PASS")&" pass / "&COUNTIF(C5:C36,"FAIL")&" fail / "&(COUNT(A5:A36)-COUNTIF(C5:C36,"PASS")-COUNTIF(C5:C36,"FAIL"))&" error"
A4: # | B4: check | C4: result | D4: detail
A5: 1 | B5: start_month is a date on the 1st of a month | C5: =IF(AND(ISNUMBER(Effective!$B$6),DAY(Effective!$B$6)=1),"PASS","FAIL") | D5: ="start_month="&TEXT(Effective!$B$6,"yyyy-mm-dd")
A6: 2 | B6: horizon_months is an integer 1..120 | C6: =IF(AND(ISNUMBER(Effective!$B$7),Effective!$B$7>=1,Effective!$B$7<=120,INT(Effective!$B$7)=Effective!$B$7),"PASS","FAIL") | D6: =Effective!$B$7
A7: 3 | B7: tax_rate within 0..1 | C7: =IF(AND(Effective!$B$8>=0,Effective!$B$8<=1),"PASS","FAIL") | D7: =Effective!$B$8
A8: 4 | B8: da_monthly, capex_monthly, WC days, opening NOL are >= 0 | C8: =IF(AND(Effective!$B$9>=0,Effective!$B$10>=0,Effective!$B$11>=0,Effective!$B$12>=0,Effective!$B$13>=0,Effective!$B$18>=0),"PASS","FAIL")
A9: 5 | B9: at least one revenue channel | C9: =IF(SUMPRODUCT((Effective!$B$26:$B$33<>"")*1)>=1,"PASS","FAIL") | D9: =SUMPRODUCT((Effective!$B$26:$B$33<>"")*1)&" channels"
A10: 6 | B10: 'total' is not used as a channel or opex name (reserved) | C10: =IF(COUNTIF(Effective!$B$26:$B$33,"total")+COUNTIF(Effective!$B$36:$B$50,"total")=0,"PASS","FAIL")
A11: 7 | B11: channel names unique (case-insensitive) | C11: =IF((IF(Effective!$B$26="",0,IF(COUNTIF(Effective!$B$26:$B$33,Effective!$B$26)>1,1,0))+IF(Effective!$B$27="",0,IF(COUNTIF(Effective!$B$26:$B$33,Effective!$B$27)>1,1,0))+IF(Effective!$B$28="",0,IF(COUNTIF(Effective!$B$26:$B$33,Effective!$B$28)>1,1,0))+IF(Effective!$B$29="",0,IF(COUNTIF(Effective!$B$26:$B$33,Effective!$B$29)>1,1,0))+IF(Effective!$B$30="",0,IF(COUNTIF(Effective!$B$26:$B$33,Effective!$B$30)>1,1,0))+IF(Effective!$B$31="",0,IF(COUNTIF(Effective!$B$26:$B$33,Effective!$B$31)>1,1,0))+IF(Effective!$B$32="",0,IF(COUNTIF(Effective!$B$26:$B$33,Effective!$B$32)>1,1,0))+IF(Effective!$B$33="",0,IF(COUNTIF(Effective!$B$26:$B$33,Effective!$B$33)>1,1,0)))=0,"PASS","FAIL")
A12: 8 | B12: opex names unique (case-insensitive) | C12: =IF((IF(Effective!$B$36="",0,IF(COUNTIF(Effective!$B$36:$B$50,Effective!$B$36)>1,1,0))+IF(Effective!$B$37="",0,IF(COUNTIF(Effective!$B$36:$B$50,Effective!$B$37)>1,1,0))+IF(Effective!$B$38="",0,IF(COUNTIF(Effective!$B$36:$B$50,Effective!$B$38)>1,1,0))+IF(Effective!$B$39="",0,IF(COUNTIF(Effective!$B$36:$B$50,Effective!$B$39)>1,1,0))+IF(Effective!$B$40="",0,IF(COUNTIF(Effective!$B$36:$B$50,Effective!$B$40)>1,1,0))+IF(Effective!$B$41="",0,IF(COUNTIF(Effective!$B$36:$B$50,Effective!$B$41)>1,1,0))+IF(Effective!$B$42="",0,IF(COUNTIF(Effective!$B$36:$B$50,Effective!$B$42)>1,1,0))+IF(Effective!$B$43="",0,IF(COUNTIF(Effective!$B$36:$B$50,Effective!$B$43)>1,1,0))+IF(Effective!$B$44="",0,IF(COUNTIF(Effective!$B$36:$B$50,Effective!$B$44)>1,1,0))+IF(Effective!$B$45="",0,IF(COUNTIF(Effective!$B$36:$B$50,Effective!$B$45)>1,1,0))+IF(Effective!$B$46="",0,IF(COUNTIF(Effective!$B$36:$B$50,Effective!$B$46)>1,1,0))+IF(Effective!$B$47="",0,IF(COUNTIF(Effective!$B$36:$B$50,Effective!$B$47)>1,1,0))+IF(Effective!$B$48="",0,IF(COUNTIF(Effective!$B$36:$B$50,Effective!$B$48)>1,1,0))+IF(Effective!$B$49="",0,IF(COUNTIF(Effective!$B$36:$B$50,Effective!$B$49)>1,1,0))+IF(Effective!$B$50="",0,IF(COUNTIF(Effective!$B$36:$B$50,Effective!$B$50)>1,1,0)))=0,"PASS","FAIL")
A13: 9 | B13: debt names unique (case-insensitive) | C13: =IF((IF(Effective!$B$53="",0,IF(COUNTIF(Effective!$B$53:$B$57,Effective!$B$53)>1,1,0))+IF(Effective!$B$54="",0,IF(COUNTIF(Effective!$B$53:$B$57,Effective!$B$54)>1,1,0))+IF(Effective!$B$55="",0,IF(COUNTIF(Effective!$B$53:$B$57,Effective!$B$55)>1,1,0))+IF(Effective!$B$56="",0,IF(COUNTIF(Effective!$B$53:$B$57,Effective!$B$56)>1,1,0))+IF(Effective!$B$57="",0,IF(COUNTIF(Effective!$B$53:$B$57,Effective!$B$57)>1,1,0)))=0,"PASS","FAIL")
A14: 10 | B14: channel fields valid (revenue>=0, growth>-100%, 0<=cogs_pct<=1, 12 seasonality weights with positive sum; unnamed rows empty) | C14: =IF((IF(Effective!$B$26="",IF(N(Effective!$C$26)<>0,1,0),IF(OR(Effective!$C$26<0,Effective!$D$26<=-1,Effective!$E$26<0,Effective!$E$26>1,SUM(Effective!$F$26:$Q$26)<=0,COUNT(Assumptions!$F$26:$Q$26)<12),1,0))+IF(Effective!$B$27="",IF(N(Effective!$C$27)<>0,1,0),IF(OR(Effective!$C$27<0,Effective!$D$27<=-1,Effective!$E$27<0,Effective!$E$27>1,SUM(Effective!$F$27:$Q$27)<=0,COUNT(Assumptions!$F$27:$Q$27)<12),1,0))+IF(Effective!$B$28="",IF(N(Effective!$C$28)<>0,1,0),IF(OR(Effective!$C$28<0,Effective!$D$28<=-1,Effective!$E$28<0,Effective!$E$28>1,SUM(Effective!$F$28:$Q$28)<=0,COUNT(Assumptions!$F$28:$Q$28)<12),1,0))+IF(Effective!$B$29="",IF(N(Effective!$C$29)<>0,1,0),IF(OR(Effective!$C$29<0,Effective!$D$29<=-1,Effective!$E$29<0,Effective!$E$29>1,SUM(Effective!$F$29:$Q$29)<=0,COUNT(Assumptions!$F$29:$Q$29)<12),1,0))+IF(Effective!$B$30="",IF(N(Effective!$C$30)<>0,1,0),IF(OR(Effective!$C$30<0,Effective!$D$30<=-1,Effective!$E$30<0,Effective!$E$30>1,SUM(Effective!$F$30:$Q$30)<=0,COUNT(Assumptions!$F$30:$Q$30)<12),1,0))+IF(Effective!$B$31="",IF(N(Effective!$C$31)<>0,1,0),IF(OR(Effective!$C$31<0,Effective!$D$31<=-1,Effective!$E$31<0,Effective!$E$31>1,SUM(Effective!$F$31:$Q$31)<=0,COUNT(Assumptions!$F$31:$Q$31)<12),1,0))+IF(Effective!$B$32="",IF(N(Effective!$C$32)<>0,1,0),IF(OR(Effective!$C$32<0,Effective!$D$32<=-1,Effective!$E$32<0,Effective!$E$32>1,SUM(Effective!$F$32:$Q$32)<=0,COUNT(Assumptions!$F$32:$Q$32)<12),1,0))+IF(Effective!$B$33="",IF(N(Effective!$C$33)<>0,1,0),IF(OR(Effective!$C$33<0,Effective!$D$33<=-1,Effective!$E$33<0,Effective!$E$33>1,SUM(Effective!$F$33:$Q$33)<=0,COUNT(Assumptions!$F$33:$Q$33)<12),1,0)))=0,"PASS","FAIL") | D14: =(IF(Effective!$B$26="",IF(N(Effective!$C$26)<>0,1,0),IF(OR(Effective!$C$26<0,Effective!$D$26<=-1,Effective!$E$26<0,Effective!$E$26>1,SUM(Effective!$F$26:$Q$26)<=0,COUNT(Assumptions!$F$26:$Q$26)<12),1,0))+IF(Effective!$B$27="",IF(N(Effective!$C$27)<>0,1,0),IF(OR(Effective!$C$27<0,Effective!$D$27<=-1,Effective!$E$27<0,Effective!$E$27>1,SUM(Effective!$F$27:$Q$27)<=0,COUNT(Assumptions!$F$27:$Q$27)<12),1,0))+IF(Effective!$B$28="",IF(N(Effective!$C$28)<>0,1,0),IF(OR(Effective!$C$28<0,Effective!$D$28<=-1,Effective!$E$28<0,Effective!$E$28>1,SUM(Effective!$F$28:$Q$28)<=0,COUNT(Assumptions!$F$28:$Q$28)<12),1,0))+IF(Effective!$B$29="",IF(N(Effective!$C$29)<>0,1,0),IF(OR(Effective!$C$29<0,Effective!$D$29<=-1,Effective!$E$29<0,Effective!$E$29>1,SUM(Effective!$F$29:$Q$29)<=0,COUNT(Assumptions!$F$29:$Q$29)<12),1,0))+IF(Effective!$B$30="",IF(N(Effective!$C$30)<>0,1,0),IF(OR(Effective!$C$30<0,Effective!$D$30<=-1,Effective!$E$30<0,Effective!$E$30>1,SUM(Effective!$F$30:$Q$30)<=0,COUNT(Assumptions!$F$30:$Q$30)<12),1,0))+IF(Effective!$B$31="",IF(N(Effective!$C$31)<>0,1,0),IF(OR(Effective!$C$31<0,Effective!$D$31<=-1,Effective!$E$31<0,Effective!$E$31>1,SUM(Effective!$F$31:$Q$31)<=0,COUNT(Assumptions!$F$31:$Q$31)<12),1,0))+IF(Effective!$B$32="",IF(N(Effective!$C$32)<>0,1,0),IF(OR(Effective!$C$32<0,Effective!$D$32<=-1,Effective!$E$32<0,Effective!$E$32>1,SUM(Effective!$F$32:$Q$32)<=0,COUNT(Assumptions!$F$32:$Q$32)<12),1,0))+IF(Effective!$B$33="",IF(N(Effective!$C$33)<>0,1,0),IF(OR(Effective!$C$33<0,Effective!$D$33<=-1,Effective!$E$33<0,Effective!$E$33>1,SUM(Effective!$F$33:$Q$33)<=0,COUNT(Assumptions!$F$33:$Q$33)<12),1,0)))&" bad channel rows"
A15: 11 | B15: opex kind is fixed or variable for every named line | C15: =IF((IF(Effective!$B$36="",0,IF(OR(Effective!$C$36="fixed",Effective!$C$36="variable"),0,1))+IF(Effective!$B$37="",0,IF(OR(Effective!$C$37="fixed",Effective!$C$37="variable"),0,1))+IF(Effective!$B$38="",0,IF(OR(Effective!$C$38="fixed",Effective!$C$38="variable"),0,1))+IF(Effective!$B$39="",0,IF(OR(Effective!$C$39="fixed",Effective!$C$39="variable"),0,1))+IF(Effective!$B$40="",0,IF(OR(Effective!$C$40="fixed",Effective!$C$40="variable"),0,1))+IF(Effective!$B$41="",0,IF(OR(Effective!$C$41="fixed",Effective!$C$41="variable"),0,1))+IF(Effective!$B$42="",0,IF(OR(Effective!$C$42="fixed",Effective!$C$42="variable"),0,1))+IF(Effective!$B$43="",0,IF(OR(Effective!$C$43="fixed",Effective!$C$43="variable"),0,1))+IF(Effective!$B$44="",0,IF(OR(Effective!$C$44="fixed",Effective!$C$44="variable"),0,1))+IF(Effective!$B$45="",0,IF(OR(Effective!$C$45="fixed",Effective!$C$45="variable"),0,1))+IF(Effective!$B$46="",0,IF(OR(Effective!$C$46="fixed",Effective!$C$46="variable"),0,1))+IF(Effective!$B$47="",0,IF(OR(Effective!$C$47="fixed",Effective!$C$47="variable"),0,1))+IF(Effective!$B$48="",0,IF(OR(Effective!$C$48="fixed",Effective!$C$48="variable"),0,1))+IF(Effective!$B$49="",0,IF(OR(Effective!$C$49="fixed",Effective!$C$49="variable"),0,1))+IF(Effective!$B$50="",0,IF(OR(Effective!$C$50="fixed",Effective!$C$50="variable"),0,1)))=0,"PASS","FAIL")
A16: 12 | B16: debt kind term_loan/loc and balances/rates/principal >= 0 | C16: =IF((IF(Effective!$B$53="",0,IF(AND(OR(Effective!$C$53="term_loan",Effective!$C$53="loc"),Effective!$D$53>=0,Effective!$E$53>=0,Effective!$F$53>=0),0,1))+IF(Effective!$B$54="",0,IF(AND(OR(Effective!$C$54="term_loan",Effective!$C$54="loc"),Effective!$D$54>=0,Effective!$E$54>=0,Effective!$F$54>=0),0,1))+IF(Effective!$B$55="",0,IF(AND(OR(Effective!$C$55="term_loan",Effective!$C$55="loc"),Effective!$D$55>=0,Effective!$E$55>=0,Effective!$F$55>=0),0,1))+IF(Effective!$B$56="",0,IF(AND(OR(Effective!$C$56="term_loan",Effective!$C$56="loc"),Effective!$D$56>=0,Effective!$E$56>=0,Effective!$F$56>=0),0,1))+IF(Effective!$B$57="",0,IF(AND(OR(Effective!$C$57="term_loan",Effective!$C$57="loc"),Effective!$D$57>=0,Effective!$E$57>=0,Effective!$F$57>=0),0,1)))=0,"PASS","FAIL")
A17: 13 | B17: no two applied parametric corrections on the same path | C17: =IF((IF(RIGHT(Corrections!$H$5,19)="|applied|parametric",IF(COUNTIF(Corrections!$H$5:$H$64,Corrections!$H$5)>1,1,0),0)+IF(RIGHT(Corrections!$H$6,19)="|applied|parametric",IF(COUNTIF(Corrections!$H$5:$H$64,Corrections!$H$6)>1,1,0),0)+IF(RIGHT(Corrections!$H$7,19)="|applied|parametric",IF(COUNTIF(Corrections!$H$5:$H$64,Corrections!$H$7)>1,1,0),0)+IF(RIGHT(Corrections!$H$8,19)="|applied|parametric",IF(COUNTIF(Corrections!$H$5:$H$64,Corrections!$H$8)>1,1,0),0)+IF(RIGHT(Corrections!$H$9,19)="|applied|parametric",IF(COUNTIF(Corrections!$H$5:$H$64,Corrections!$H$9)>1,1,0),0)+IF(RIGHT(Corrections!$H$10,19)="|applied|parametric",IF(COUNTIF(Corrections!$H$5:$H$64,Corrections!$H$10)>1,1,0),0)+IF(RIGHT(Corrections!$H$11,19)="|applied|parametric",IF(COUNTIF(Corrections!$H$5:$H$64,Corrections!$H$11)>1,1,0),0)+IF(RIGHT(Corrections!$H$12,19)="|applied|parametric",IF(COUNTIF(Corrections!$H$5:$H$64,Corrections!$H$12)>1,1,0),0)+IF(RIGHT(Corrections!$H$13,19)="|applied|parametric",IF(COUNTIF(Corrections!$H$5:$H$64,Corrections!$H$13)>1,1,0),0)+IF(RIGHT(Corrections!$H$14,19)="|applied|parametric",IF(COUNTIF(Corrections!$H$5:$H$64,Corrections!$H$14)>1,1,0),0)+IF(RIGHT(Corrections!$H$15,19)="|applied|parametric",IF(COUNTIF(Corrections!$H$5:$H$64,Corrections!$H$15)>1,1,0),0)+IF(RIGHT(Corrections!$H$16,19)="|applied|parametric",IF(COUNTIF(Corrections!$H$5:$H$64,Corrections!$H$16)>1,1,0),0)+IF(RIGHT(Corrections!$H$17,19)="|applied|parametric",IF(COUNTIF(Corrections!$H$5:$H$64,Corrections!$H$17)>1,1,0),0)+IF(RIGHT(Corrections!$H$18,19)="|applied|parametric",IF(COUNTIF(Corrections!$H$5:$H$64,Corrections!$H$18)>1,1,0),0)+IF(RIGHT(Corrections!$H$19,19)="|applied|parametric",IF(COUNTIF(Corrections!$H$5:$H$64,Corrections!$H$19)>1,1,0),0)+IF(RIGHT(Corrections!$H$20,19)="|applied|parametric",IF(COUNTIF(Corrections!$H$5:$H$64,Corrections!$H$20)>1,1,0),0)+IF(RIGHT(Corrections!$H$21,19)="|applied|parametric",IF(COUNTIF(Corrections!$H$5:$H$64,Corrections!$H$21)>1,1,0),0)+IF(RIGHT(Corrections!$H$22,19)="|applied|parametric",IF(COUNTIF(Corrections!$H$5:$H$64,Corrections!$H$22)>1,1,0),0)+IF(RIGHT(Corrections!$H$23,19)="|applied|parametric",IF(COUNTIF(Corrections!$H$5:$H$64,Corrections!$H$23)>1,1,0),0)+IF(RIGHT(Corrections!$H$24,19)="|applied|parametric",IF(COUNTIF(Corrections!$H$5:$H$64,Corrections!$H$24)>1,1,0),0)+IF(RIGHT(Corrections!$H$25,19)="|applied|parametric",IF(COUNTIF(Corrections!$H$5:$H$64,Corrections!$H$25)>1,1,0),0)+IF(RIGHT(Corrections!$H$26,19)="|applied|parametric",IF(COUNTIF(Corrections!$H$5:$H$64,Corrections!$H$26)>1,1,0),0)+IF(RIGHT(Corrections!$H$27,19)="|applied|parametric",IF(COUNTIF(Corrections!$H$5:$H$64,Corrections!$H$27)>1,1,0),0)+IF(RIGHT(Corrections!$H$28,19)="|applied|parametric",IF(COUNTIF(Corrections!$H$5:$H$64,Corrections!$H$28)>1,1,0),0)+IF(RIGHT(Corrections!$H$29,19)="|applied|parametric",IF(COUNTIF(Corrections!$H$5:$H$64,Corrections!$H$29)>1,1,0),0)+IF(RIGHT(Corrections!$H$30,19)="|applied|parametric",IF(COUNTIF(Corrections!$H$5:$H$64,Corrections!$H$30)>1,1,0),0)+IF(RIGHT(Corrections!$H$31,19)="|applied|parametric",IF(COUNTIF(Corrections!$H$5:$H$64,Corrections!$H$31)>1,1,0),0)+IF(RIGHT(Corrections!$H$32,19)="|applied|parametric",IF(COUNTIF(Corrections!$H$5:$H$64,Corrections!$H$32)>1,1,0),0)+IF(RIGHT(Corrections!$H$33,19)="|applied|parametric",IF(COUNTIF(Corrections!$H$5:$H$64,Corrections!$H$33)>1,1,0),0)+IF(RIGHT(Corrections!$H$34,19)="|applied|parametric",IF(COUNTIF(Corrections!$H$5:$H$64,Corrections!$H$34)>1,1,0),0)+IF(RIGHT(Corrections!$H$35,19)="|applied|parametric",IF(COUNTIF(Corrections!$H$5:$H$64,Corrections!$H$35)>1,1,0),0)+IF(RIGHT(Corrections!$H$36,19)="|applied|parametric",IF(COUNTIF(Corrections!$H$5:$H$64,Corrections!$H$36)>1,1,0),0)+IF(RIGHT(Corrections!$H$37,19)="|applied|parametric",IF(COUNTIF(Corrections!$H$5:$H$64,Corrections!$H$37)>1,1,0),0)+IF(RIGHT(Corrections!$H$38,19)="|applied|parametric",IF(COUNTIF(Corrections!$H$5:$H$64,Corrections!$H$38)>1,1,0),0)+IF(RIGHT(Corrections!$H$39,19)="|applied|parametric",IF(COUNTIF(Corrections!$H$5:$H$64,Corrections!$H$39)>1,1,0),0)+IF(RIGHT(Corrections!$H$40,19)="|applied|parametric",IF(COUNTIF(Corrections!$H$5:$H$64,Corrections!$H$40)>1,1,0),0)+IF(RIGHT(Corrections!$H$41,19)="|applied|parametric",IF(COUNTIF(Corrections!$H$5:$H$64,Corrections!$H$41)>1,1,0),0)+IF(RIGHT(Corrections!$H$42,19)="|applied|parametric",IF(COUNTIF(Corrections!$H$5:$H$64,Corrections!$H$42)>1,1,0),0)+IF(RIGHT(Corrections!$H$43,19)="|applied|parametric",IF(COUNTIF(Corrections!$H$5:$H$64,Corrections!$H$43)>1,1,0),0)+IF(RIGHT(Corrections!$H$44,19)="|applied|parametric",IF(COUNTIF(Corrections!$H$5:$H$64,Corrections!$H$44)>1,1,0),0)+IF(RIGHT(Corrections!$H$45,19)="|applied|parametric",IF(COUNTIF(Corrections!$H$5:$H$64,Corrections!$H$45)>1,1,0),0)+IF(RIGHT(Corrections!$H$46,19)="|applied|parametric",IF(COUNTIF(Corrections!$H$5:$H$64,Corrections!$H$46)>1,1,0),0)+IF(RIGHT(Corrections!$H$47,19)="|applied|parametric",IF(COUNTIF(Corrections!$H$5:$H$64,Corrections!$H$47)>1,1,0),0)+IF(RIGHT(Corrections!$H$48,19)="|applied|parametric",IF(COUNTIF(Corrections!$H$5:$H$64,Corrections!$H$48)>1,1,0),0)+IF(RIGHT(Corrections!$H$49,19)="|applied|parametric",IF(COUNTIF(Corrections!$H$5:$H$64,Corrections!$H$49)>1,1,0),0)+IF(RIGHT(Corrections!$H$50,19)="|applied|parametric",IF(COUNTIF(Corrections!$H$5:$H$64,Corrections!$H$50)>1,1,0),0)+IF(RIGHT(Corrections!$H$51,19)="|applied|parametric",IF(COUNTIF(Corrections!$H$5:$H$64,Corrections!$H$51)>1,1,0),0)+IF(RIGHT(Corrections!$H$52,19)="|applied|parametric",IF(COUNTIF(Corrections!$H$5:$H$64,Corrections!$H$52)>1,1,0),0)+IF(RIGHT(Corrections!$H$53,19)="|applied|parametric",IF(COUNTIF(Corrections!$H$5:$H$64,Corrections!$H$53)>1,1,0),0)+IF(RIGHT(Corrections!$H$54,19)="|applied|parametric",IF(COUNTIF(Corrections!$H$5:$H$64,Corrections!$H$54)>1,1,0),0)+IF(RIGHT(Corrections!$H$55,19)="|applied|parametric",IF(COUNTIF(Corrections!$H$5:$H$64,Corrections!$H$55)>1,1,0),0)+IF(RIGHT(Corrections!$H$56,19)="|applied|parametric",IF(COUNTIF(Corrections!$H$5:$H$64,Corrections!$H$56)>1,1,0),0)+IF(RIGHT(Corrections!$H$57,19)="|applied|parametric",IF(COUNTIF(Corrections!$H$5:$H$64,Corrections!$H$57)>1,1,0),0)+IF(RIGHT(Corrections!$H$58,19)="|applied|parametric",IF(COUNTIF(Corrections!$H$5:$H$64,Corrections!$H$58)>1,1,0),0)+IF(RIGHT(Corrections!$H$59,19)="|applied|parametric",IF(COUNTIF(Corrections!$H$5:$H$64,Corrections!$H$59)>1,1,0),0)+IF(RIGHT(Corrections!$H$60,19)="|applied|parametric",IF(COUNTIF(Corrections!$H$5:$H$64,Corrections!$H$60)>1,1,0),0)+IF(RIGHT(Corrections!$H$61,19)="|applied|parametric",IF(COUNTIF(Corrections!$H$5:$H$64,Corrections!$H$61)>1,1,0),0)+IF(RIGHT(Corrections!$H$62,19)="|applied|parametric",IF(COUNTIF(Corrections!$H$5:$H$64,Corrections!$H$62)>1,1,0),0)+IF(RIGHT(Corrections!$H$63,19)="|applied|parametric",IF(COUNTIF(Corrections!$H$5:$H$64,Corrections!$H$63)>1,1,0),0)+IF(RIGHT(Corrections!$H$64,19)="|applied|parametric",IF(COUNTIF(Corrections!$H$5:$H$64,Corrections!$H$64)>1,1,0),0))=0,"PASS","FAIL") | D17: =(IF(RIGHT(Corrections!$H$5,19)="|applied|parametric",IF(COUNTIF(Corrections!$H$5:$H$64,Corrections!$H$5)>1,1,0),0)+IF(RIGHT(Corrections!$H$6,19)="|applied|parametric",IF(COUNTIF(Corrections!$H$5:$H$64,Corrections!$H$6)>1,1,0),0)+IF(RIGHT(Corrections!$H$7,19)="|applied|parametric",IF(COUNTIF(Corrections!$H$5:$H$64,Corrections!$H$7)>1,1,0),0)+IF(RIGHT(Corrections!$H$8,19)="|applied|parametric",IF(COUNTIF(Corrections!$H$5:$H$64,Corrections!$H$8)>1,1,0),0)+IF(RIGHT(Corrections!$H$9,19)="|applied|parametric",IF(COUNTIF(Corrections!$H$5:$H$64,Corrections!$H$9)>1,1,0),0)+IF(RIGHT(Corrections!$H$10,19)="|applied|parametric",IF(COUNTIF(Corrections!$H$5:$H$64,Corrections!$H$10)>1,1,0),0)+IF(RIGHT(Corrections!$H$11,19)="|applied|parametric",IF(COUNTIF(Corrections!$H$5:$H$64,Corrections!$H$11)>1,1,0),0)+IF(RIGHT(Corrections!$H$12,19)="|applied|parametric",IF(COUNTIF(Corrections!$H$5:$H$64,Corrections!$H$12)>1,1,0),0)+IF(RIGHT(Corrections!$H$13,19)="|applied|parametric",IF(COUNTIF(Corrections!$H$5:$H$64,Corrections!$H$13)>1,1,0),0)+IF(RIGHT(Corrections!$H$14,19)="|applied|parametric",IF(COUNTIF(Corrections!$H$5:$H$64,Corrections!$H$14)>1,1,0),0)+IF(RIGHT(Corrections!$H$15,19)="|applied|parametric",IF(COUNTIF(Corrections!$H$5:$H$64,Corrections!$H$15)>1,1,0),0)+IF(RIGHT(Corrections!$H$16,19)="|applied|parametric",IF(COUNTIF(Corrections!$H$5:$H$64,Corrections!$H$16)>1,1,0),0)+IF(RIGHT(Corrections!$H$17,19)="|applied|parametric",IF(COUNTIF(Corrections!$H$5:$H$64,Corrections!$H$17)>1,1,0),0)+IF(RIGHT(Corrections!$H$18,19)="|applied|parametric",IF(COUNTIF(Corrections!$H$5:$H$64,Corrections!$H$18)>1,1,0),0)+IF(RIGHT(Corrections!$H$19,19)="|applied|parametric",IF(COUNTIF(Corrections!$H$5:$H$64,Corrections!$H$19)>1,1,0),0)+IF(RIGHT(Corrections!$H$20,19)="|applied|parametric",IF(COUNTIF(Corrections!$H$5:$H$64,Corrections!$H$20)>1,1,0),0)+IF(RIGHT(Corrections!$H$21,19)="|applied|parametric",IF(COUNTIF(Corrections!$H$5:$H$64,Corrections!$H$21)>1,1,0),0)+IF(RIGHT(Corrections!$H$22,19)="|applied|parametric",IF(COUNTIF(Corrections!$H$5:$H$64,Corrections!$H$22)>1,1,0),0)+IF(RIGHT(Corrections!$H$23,19)="|applied|parametric",IF(COUNTIF(Corrections!$H$5:$H$64,Corrections!$H$23)>1,1,0),0)+IF(RIGHT(Corrections!$H$24,19)="|applied|parametric",IF(COUNTIF(Corrections!$H$5:$H$64,Corrections!$H$24)>1,1,0),0)+IF(RIGHT(Corrections!$H$25,19)="|applied|parametric",IF(COUNTIF(Corrections!$H$5:$H$64,Corrections!$H$25)>1,1,0),0)+IF(RIGHT(Corrections!$H$26,19)="|applied|parametric",IF(COUNTIF(Corrections!$H$5:$H$64,Corrections!$H$26)>1,1,0),0)+IF(RIGHT(Corrections!$H$27,19)="|applied|parametric",IF(COUNTIF(Corrections!$H$5:$H$64,Corrections!$H$27)>1,1,0),0)+IF(RIGHT(Corrections!$H$28,19)="|applied|parametric",IF(COUNTIF(Corrections!$H$5:$H$64,Corrections!$H$28)>1,1,0),0)+IF(RIGHT(Corrections!$H$29,19)="|applied|parametric",IF(COUNTIF(Corrections!$H$5:$H$64,Corrections!$H$29)>1,1,0),0)+IF(RIGHT(Corrections!$H$30,19)="|applied|parametric",IF(COUNTIF(Corrections!$H$5:$H$64,Corrections!$H$30)>1,1,0),0)+IF(RIGHT(Corrections!$H$31,19)="|applied|parametric",IF(COUNTIF(Corrections!$H$5:$H$64,Corrections!$H$31)>1,1,0),0)+IF(RIGHT(Corrections!$H$32,19)="|applied|parametric",IF(COUNTIF(Corrections!$H$5:$H$64,Corrections!$H$32)>1,1,0),0)+IF(RIGHT(Corrections!$H$33,19)="|applied|parametric",IF(COUNTIF(Corrections!$H$5:$H$64,Corrections!$H$33)>1,1,0),0)+IF(RIGHT(Corrections!$H$34,19)="|applied|parametric",IF(COUNTIF(Corrections!$H$5:$H$64,Corrections!$H$34)>1,1,0),0)+IF(RIGHT(Corrections!$H$35,19)="|applied|parametric",IF(COUNTIF(Corrections!$H$5:$H$64,Corrections!$H$35)>1,1,0),0)+IF(RIGHT(Corrections!$H$36,19)="|applied|parametric",IF(COUNTIF(Corrections!$H$5:$H$64,Corrections!$H$36)>1,1,0),0)+IF(RIGHT(Corrections!$H$37,19)="|applied|parametric",IF(COUNTIF(Corrections!$H$5:$H$64,Corrections!$H$37)>1,1,0),0)+IF(RIGHT(Corrections!$H$38,19)="|applied|parametric",IF(COUNTIF(Corrections!$H$5:$H$64,Corrections!$H$38)>1,1,0),0)+IF(RIGHT(Corrections!$H$39,19)="|applied|parametric",IF(COUNTIF(Corrections!$H$5:$H$64,Corrections!$H$39)>1,1,0),0)+IF(RIGHT(Corrections!$H$40,19)="|applied|parametric",IF(COUNTIF(Corrections!$H$5:$H$64,Corrections!$H$40)>1,1,0),0)+IF(RIGHT(Corrections!$H$41,19)="|applied|parametric",IF(COUNTIF(Corrections!$H$5:$H$64,Corrections!$H$41)>1,1,0),0)+IF(RIGHT(Corrections!$H$42,19)="|applied|parametric",IF(COUNTIF(Corrections!$H$5:$H$64,Corrections!$H$42)>1,1,0),0)+IF(RIGHT(Corrections!$H$43,19)="|applied|parametric",IF(COUNTIF(Corrections!$H$5:$H$64,Corrections!$H$43)>1,1,0),0)+IF(RIGHT(Corrections!$H$44,19)="|applied|parametric",IF(COUNTIF(Corrections!$H$5:$H$64,Corrections!$H$44)>1,1,0),0)+IF(RIGHT(Corrections!$H$45,19)="|applied|parametric",IF(COUNTIF(Corrections!$H$5:$H$64,Corrections!$H$45)>1,1,0),0)+IF(RIGHT(Corrections!$H$46,19)="|applied|parametric",IF(COUNTIF(Corrections!$H$5:$H$64,Corrections!$H$46)>1,1,0),0)+IF(RIGHT(Corrections!$H$47,19)="|applied|parametric",IF(COUNTIF(Corrections!$H$5:$H$64,Corrections!$H$47)>1,1,0),0)+IF(RIGHT(Corrections!$H$48,19)="|applied|parametric",IF(COUNTIF(Corrections!$H$5:$H$64,Corrections!$H$48)>1,1,0),0)+IF(RIGHT(Corrections!$H$49,19)="|applied|parametric",IF(COUNTIF(Corrections!$H$5:$H$64,Corrections!$H$49)>1,1,0),0)+IF(RIGHT(Corrections!$H$50,19)="|applied|parametric",IF(COUNTIF(Corrections!$H$5:$H$64,Corrections!$H$50)>1,1,0),0)+IF(RIGHT(Corrections!$H$51,19)="|applied|parametric",IF(COUNTIF(Corrections!$H$5:$H$64,Corrections!$H$51)>1,1,0),0)+IF(RIGHT(Corrections!$H$52,19)="|applied|parametric",IF(COUNTIF(Corrections!$H$5:$H$64,Corrections!$H$52)>1,1,0),0)+IF(RIGHT(Corrections!$H$53,19)="|applied|parametric",IF(COUNTIF(Corrections!$H$5:$H$64,Corrections!$H$53)>1,1,0),0)+IF(RIGHT(Corrections!$H$54,19)="|applied|parametric",IF(COUNTIF(Corrections!$H$5:$H$64,Corrections!$H$54)>1,1,0),0)+IF(RIGHT(Corrections!$H$55,19)="|applied|parametric",IF(COUNTIF(Corrections!$H$5:$H$64,Corrections!$H$55)>1,1,0),0)+IF(RIGHT(Corrections!$H$56,19)="|applied|parametric",IF(COUNTIF(Corrections!$H$5:$H$64,Corrections!$H$56)>1,1,0),0)+IF(RIGHT(Corrections!$H$57,19)="|applied|parametric",IF(COUNTIF(Corrections!$H$5:$H$64,Corrections!$H$57)>1,1,0),0)+IF(RIGHT(Corrections!$H$58,19)="|applied|parametric",IF(COUNTIF(Corrections!$H$5:$H$64,Corrections!$H$58)>1,1,0),0)+IF(RIGHT(Corrections!$H$59,19)="|applied|parametric",IF(COUNTIF(Corrections!$H$5:$H$64,Corrections!$H$59)>1,1,0),0)+IF(RIGHT(Corrections!$H$60,19)="|applied|parametric",IF(COUNTIF(Corrections!$H$5:$H$64,Corrections!$H$60)>1,1,0),0)+IF(RIGHT(Corrections!$H$61,19)="|applied|parametric",IF(COUNTIF(Corrections!$H$5:$H$64,Corrections!$H$61)>1,1,0),0)+IF(RIGHT(Corrections!$H$62,19)="|applied|parametric",IF(COUNTIF(Corrections!$H$5:$H$64,Corrections!$H$62)>1,1,0),0)+IF(RIGHT(Corrections!$H$63,19)="|applied|parametric",IF(COUNTIF(Corrections!$H$5:$H$64,Corrections!$H$63)>1,1,0),0)+IF(RIGHT(Corrections!$H$64,19)="|applied|parametric",IF(COUNTIF(Corrections!$H$5:$H$64,Corrections!$H$64)>1,1,0),0))&" duplicate rows"
A18: 14 | B18: every applied parametric correction path resolves (see ValidKeys) | C18: =IF((IF(RIGHT(Corrections!$H$5,19)="|applied|parametric",IF(COUNTIF(ValidKeys!$A$3:$A$207,LEFT(Corrections!$H$5,LEN(Corrections!$H$5)-19))=0,1,0),0)+IF(RIGHT(Corrections!$H$6,19)="|applied|parametric",IF(COUNTIF(ValidKeys!$A$3:$A$207,LEFT(Corrections!$H$6,LEN(Corrections!$H$6)-19))=0,1,0),0)+IF(RIGHT(Corrections!$H$7,19)="|applied|parametric",IF(COUNTIF(ValidKeys!$A$3:$A$207,LEFT(Corrections!$H$7,LEN(Corrections!$H$7)-19))=0,1,0),0)+IF(RIGHT(Corrections!$H$8,19)="|applied|parametric",IF(COUNTIF(ValidKeys!$A$3:$A$207,LEFT(Corrections!$H$8,LEN(Corrections!$H$8)-19))=0,1,0),0)+IF(RIGHT(Corrections!$H$9,19)="|applied|parametric",IF(COUNTIF(ValidKeys!$A$3:$A$207,LEFT(Corrections!$H$9,LEN(Corrections!$H$9)-19))=0,1,0),0)+IF(RIGHT(Corrections!$H$10,19)="|applied|parametric",IF(COUNTIF(ValidKeys!$A$3:$A$207,LEFT(Corrections!$H$10,LEN(Corrections!$H$10)-19))=0,1,0),0)+IF(RIGHT(Corrections!$H$11,19)="|applied|parametric",IF(COUNTIF(ValidKeys!$A$3:$A$207,LEFT(Corrections!$H$11,LEN(Corrections!$H$11)-19))=0,1,0),0)+IF(RIGHT(Corrections!$H$12,19)="|applied|parametric",IF(COUNTIF(ValidKeys!$A$3:$A$207,LEFT(Corrections!$H$12,LEN(Corrections!$H$12)-19))=0,1,0),0)+IF(RIGHT(Corrections!$H$13,19)="|applied|parametric",IF(COUNTIF(ValidKeys!$A$3:$A$207,LEFT(Corrections!$H$13,LEN(Corrections!$H$13)-19))=0,1,0),0)+IF(RIGHT(Corrections!$H$14,19)="|applied|parametric",IF(COUNTIF(ValidKeys!$A$3:$A$207,LEFT(Corrections!$H$14,LEN(Corrections!$H$14)-19))=0,1,0),0)+IF(RIGHT(Corrections!$H$15,19)="|applied|parametric",IF(COUNTIF(ValidKeys!$A$3:$A$207,LEFT(Corrections!$H$15,LEN(Corrections!$H$15)-19))=0,1,0),0)+IF(RIGHT(Corrections!$H$16,19)="|applied|parametric",IF(COUNTIF(ValidKeys!$A$3:$A$207,LEFT(Corrections!$H$16,LEN(Corrections!$H$16)-19))=0,1,0),0)+IF(RIGHT(Corrections!$H$17,19)="|applied|parametric",IF(COUNTIF(ValidKeys!$A$3:$A$207,LEFT(Corrections!$H$17,LEN(Corrections!$H$17)-19))=0,1,0),0)+IF(RIGHT(Corrections!$H$18,19)="|applied|parametric",IF(COUNTIF(ValidKeys!$A$3:$A$207,LEFT(Corrections!$H$18,LEN(Corrections!$H$18)-19))=0,1,0),0)+IF(RIGHT(Corrections!$H$19,19)="|applied|parametric",IF(COUNTIF(ValidKeys!$A$3:$A$207,LEFT(Corrections!$H$19,LEN(Corrections!$H$19)-19))=0,1,0),0)+IF(RIGHT(Corrections!$H$20,19)="|applied|parametric",IF(COUNTIF(ValidKeys!$A$3:$A$207,LEFT(Corrections!$H$20,LEN(Corrections!$H$20)-19))=0,1,0),0)+IF(RIGHT(Corrections!$H$21,19)="|applied|parametric",IF(COUNTIF(ValidKeys!$A$3:$A$207,LEFT(Corrections!$H$21,LEN(Corrections!$H$21)-19))=0,1,0),0)+IF(RIGHT(Corrections!$H$22,19)="|applied|parametric",IF(COUNTIF(ValidKeys!$A$3:$A$207,LEFT(Corrections!$H$22,LEN(Corrections!$H$22)-19))=0,1,0),0)+IF(RIGHT(Corrections!$H$23,19)="|applied|parametric",IF(COUNTIF(ValidKeys!$A$3:$A$207,LEFT(Corrections!$H$23,LEN(Corrections!$H$23)-19))=0,1,0),0)+IF(RIGHT(Corrections!$H$24,19)="|applied|parametric",IF(COUNTIF(ValidKeys!$A$3:$A$207,LEFT(Corrections!$H$24,LEN(Corrections!$H$24)-19))=0,1,0),0)+IF(RIGHT(Corrections!$H$25,19)="|applied|parametric",IF(COUNTIF(ValidKeys!$A$3:$A$207,LEFT(Corrections!$H$25,LEN(Corrections!$H$25)-19))=0,1,0),0)+IF(RIGHT(Corrections!$H$26,19)="|applied|parametric",IF(COUNTIF(ValidKeys!$A$3:$A$207,LEFT(Corrections!$H$26,LEN(Corrections!$H$26)-19))=0,1,0),0)+IF(RIGHT(Corrections!$H$27,19)="|applied|parametric",IF(COUNTIF(ValidKeys!$A$3:$A$207,LEFT(Corrections!$H$27,LEN(Corrections!$H$27)-19))=0,1,0),0)+IF(RIGHT(Corrections!$H$28,19)="|applied|parametric",IF(COUNTIF(ValidKeys!$A$3:$A$207,LEFT(Corrections!$H$28,LEN(Corrections!$H$28)-19))=0,1,0),0)+IF(RIGHT(Corrections!$H$29,19)="|applied|parametric",IF(COUNTIF(ValidKeys!$A$3:$A$207,LEFT(Corrections!$H$29,LEN(Corrections!$H$29)-19))=0,1,0),0)+IF(RIGHT(Corrections!$H$30,19)="|applied|parametric",IF(COUNTIF(ValidKeys!$A$3:$A$207,LEFT(Corrections!$H$30,LEN(Corrections!$H$30)-19))=0,1,0),0)+IF(RIGHT(Corrections!$H$31,19)="|applied|parametric",IF(COUNTIF(ValidKeys!$A$3:$A$207,LEFT(Corrections!$H$31,LEN(Corrections!$H$31)-19))=0,1,0),0)+IF(RIGHT(Corrections!$H$32,19)="|applied|parametric",IF(COUNTIF(ValidKeys!$A$3:$A$207,LEFT(Corrections!$H$32,LEN(Corrections!$H$32)-19))=0,1,0),0)+IF(RIGHT(Corrections!$H$33,19)="|applied|parametric",IF(COUNTIF(ValidKeys!$A$3:$A$207,LEFT(Corrections!$H$33,LEN(Corrections!$H$33)-19))=0,1,0),0)+IF(RIGHT(Corrections!$H$34,19)="|applied|parametric",IF(COUNTIF(ValidKeys!$A$3:$A$207,LEFT(Corrections!$H$34,LEN(Corrections!$H$34)-19))=0,1,0),0)+IF(RIGHT(Corrections!$H$35,19)="|applied|parametric",IF(COUNTIF(ValidKeys!$A$3:$A$207,LEFT(Corrections!$H$35,LEN(Corrections!$H$35)-19))=0,1,0),0)+IF(RIGHT(Corrections!$H$36,19)="|applied|parametric",IF(COUNTIF(ValidKeys!$A$3:$A$207,LEFT(Corrections!$H$36,LEN(Corrections!$H$36)-19))=0,1,0),0)+IF(RIGHT(Corrections!$H$37,19)="|applied|parametric",IF(COUNTIF(ValidKeys!$A$3:$A$207,LEFT(Corrections!$H$37,LEN(Corrections!$H$37)-19))=0,1,0),0)+IF(RIGHT(Corrections!$H$38,19)="|applied|parametric",IF(COUNTIF(ValidKeys!$A$3:$A$207,LEFT(Corrections!$H$38,LEN(Corrections!$H$38)-19))=0,1,0),0)+IF(RIGHT(Corrections!$H$39,19)="|applied|parametric",IF(COUNTIF(ValidKeys!$A$3:$A$207,LEFT(Corrections!$H$39,LEN(Corrections!$H$39)-19))=0,1,0),0)+IF(RIGHT(Corrections!$H$40,19)="|applied|parametric",IF(COUNTIF(ValidKeys!$A$3:$A$207,LEFT(Corrections!$H$40,LEN(Corrections!$H$40)-19))=0,1,0),0)+IF(RIGHT(Corrections!$H$41,19)="|applied|parametric",IF(COUNTIF(ValidKeys!$A$3:$A$207,LEFT(Corrections!$H$41,LEN(Corrections!$H$41)-19))=0,1,0),0)+IF(RIGHT(Corrections!$H$42,19)="|applied|parametric",IF(COUNTIF(ValidKeys!$A$3:$A$207,LEFT(Corrections!$H$42,LEN(Corrections!$H$42)-19))=0,1,0),0)+IF(RIGHT(Corrections!$H$43,19)="|applied|parametric",IF(COUNTIF(ValidKeys!$A$3:$A$207,LEFT(Corrections!$H$43,LEN(Corrections!$H$43)-19))=0,1,0),0)+IF(RIGHT(Corrections!$H$44,19)="|applied|parametric",IF(COUNTIF(ValidKeys!$A$3:$A$207,LEFT(Corrections!$H$44,LEN(Corrections!$H$44)-19))=0,1,0),0)+IF(RIGHT(Corrections!$H$45,19)="|applied|parametric",IF(COUNTIF(ValidKeys!$A$3:$A$207,LEFT(Corrections!$H$45,LEN(Corrections!$H$45)-19))=0,1,0),0)+IF(RIGHT(Corrections!$H$46,19)="|applied|parametric",IF(COUNTIF(ValidKeys!$A$3:$A$207,LEFT(Corrections!$H$46,LEN(Corrections!$H$46)-19))=0,1,0),0)+IF(RIGHT(Corrections!$H$47,19)="|applied|parametric",IF(COUNTIF(ValidKeys!$A$3:$A$207,LEFT(Corrections!$H$47,LEN(Corrections!$H$47)-19))=0,1,0),0)+IF(RIGHT(Corrections!$H$48,19)="|applied|parametric",IF(COUNTIF(ValidKeys!$A$3:$A$207,LEFT(Corrections!$H$48,LEN(Corrections!$H$48)-19))=0,1,0),0)+IF(RIGHT(Corrections!$H$49,19)="|applied|parametric",IF(COUNTIF(ValidKeys!$A$3:$A$207,LEFT(Corrections!$H$49,LEN(Corrections!$H$49)-19))=0,1,0),0)+IF(RIGHT(Corrections!$H$50,19)="|applied|parametric",IF(COUNTIF(ValidKeys!$A$3:$A$207,LEFT(Corrections!$H$50,LEN(Corrections!$H$50)-19))=0,1,0),0)+IF(RIGHT(Corrections!$H$51,19)="|applied|parametric",IF(COUNTIF(ValidKeys!$A$3:$A$207,LEFT(Corrections!$H$51,LEN(Corrections!$H$51)-19))=0,1,0),0)+IF(RIGHT(Corrections!$H$52,19)="|applied|parametric",IF(COUNTIF(ValidKeys!$A$3:$A$207,LEFT(Corrections!$H$52,LEN(Corrections!$H$52)-19))=0,1,0),0)+IF(RIGHT(Corrections!$H$53,19)="|applied|parametric",IF(COUNTIF(ValidKeys!$A$3:$A$207,LEFT(Corrections!$H$53,LEN(Corrections!$H$53)-19))=0,1,0),0)+IF(RIGHT(Corrections!$H$54,19)="|applied|parametric",IF(COUNTIF(ValidKeys!$A$3:$A$207,LEFT(Corrections!$H$54,LEN(Corrections!$H$54)-19))=0,1,0),0)+IF(RIGHT(Corrections!$H$55,19)="|applied|parametric",IF(COUNTIF(ValidKeys!$A$3:$A$207,LEFT(Corrections!$H$55,LEN(Corrections!$H$55)-19))=0,1,0),0)+IF(RIGHT(Corrections!$H$56,19)="|applied|parametric",IF(COUNTIF(ValidKeys!$A$3:$A$207,LEFT(Corrections!$H$56,LEN(Corrections!$H$56)-19))=0,1,0),0)+IF(RIGHT(Corrections!$H$57,19)="|applied|parametric",IF(COUNTIF(ValidKeys!$A$3:$A$207,LEFT(Corrections!$H$57,LEN(Corrections!$H$57)-19))=0,1,0),0)+IF(RIGHT(Corrections!$H$58,19)="|applied|parametric",IF(COUNTIF(ValidKeys!$A$3:$A$207,LEFT(Corrections!$H$58,LEN(Corrections!$H$58)-19))=0,1,0),0)+IF(RIGHT(Corrections!$H$59,19)="|applied|parametric",IF(COUNTIF(ValidKeys!$A$3:$A$207,LEFT(Corrections!$H$59,LEN(Corrections!$H$59)-19))=0,1,0),0)+IF(RIGHT(Corrections!$H$60,19)="|applied|parametric",IF(COUNTIF(ValidKeys!$A$3:$A$207,LEFT(Corrections!$H$60,LEN(Corrections!$H$60)-19))=0,1,0),0)+IF(RIGHT(Corrections!$H$61,19)="|applied|parametric",IF(COUNTIF(ValidKeys!$A$3:$A$207,LEFT(Corrections!$H$61,LEN(Corrections!$H$61)-19))=0,1,0),0)+IF(RIGHT(Corrections!$H$62,19)="|applied|parametric",IF(COUNTIF(ValidKeys!$A$3:$A$207,LEFT(Corrections!$H$62,LEN(Corrections!$H$62)-19))=0,1,0),0)+IF(RIGHT(Corrections!$H$63,19)="|applied|parametric",IF(COUNTIF(ValidKeys!$A$3:$A$207,LEFT(Corrections!$H$63,LEN(Corrections!$H$63)-19))=0,1,0),0)+IF(RIGHT(Corrections!$H$64,19)="|applied|parametric",IF(COUNTIF(ValidKeys!$A$3:$A$207,LEFT(Corrections!$H$64,LEN(Corrections!$H$64)-19))=0,1,0),0))=0,"PASS","FAIL") | D18: =(IF(RIGHT(Corrections!$H$5,19)="|applied|parametric",IF(COUNTIF(ValidKeys!$A$3:$A$207,LEFT(Corrections!$H$5,LEN(Corrections!$H$5)-19))=0,1,0),0)+IF(RIGHT(Corrections!$H$6,19)="|applied|parametric",IF(COUNTIF(ValidKeys!$A$3:$A$207,LEFT(Corrections!$H$6,LEN(Corrections!$H$6)-19))=0,1,0),0)+IF(RIGHT(Corrections!$H$7,19)="|applied|parametric",IF(COUNTIF(ValidKeys!$A$3:$A$207,LEFT(Corrections!$H$7,LEN(Corrections!$H$7)-19))=0,1,0),0)+IF(RIGHT(Corrections!$H$8,19)="|applied|parametric",IF(COUNTIF(ValidKeys!$A$3:$A$207,LEFT(Corrections!$H$8,LEN(Corrections!$H$8)-19))=0,1,0),0)+IF(RIGHT(Corrections!$H$9,19)="|applied|parametric",IF(COUNTIF(ValidKeys!$A$3:$A$207,LEFT(Corrections!$H$9,LEN(Corrections!$H$9)-19))=0,1,0),0)+IF(RIGHT(Corrections!$H$10,19)="|applied|parametric",IF(COUNTIF(ValidKeys!$A$3:$A$207,LEFT(Corrections!$H$10,LEN(Corrections!$H$10)-19))=0,1,0),0)+IF(RIGHT(Corrections!$H$11,19)="|applied|parametric",IF(COUNTIF(ValidKeys!$A$3:$A$207,LEFT(Corrections!$H$11,LEN(Corrections!$H$11)-19))=0,1,0),0)+IF(RIGHT(Corrections!$H$12,19)="|applied|parametric",IF(COUNTIF(ValidKeys!$A$3:$A$207,LEFT(Corrections!$H$12,LEN(Corrections!$H$12)-19))=0,1,0),0)+IF(RIGHT(Corrections!$H$13,19)="|applied|parametric",IF(COUNTIF(ValidKeys!$A$3:$A$207,LEFT(Corrections!$H$13,LEN(Corrections!$H$13)-19))=0,1,0),0)+IF(RIGHT(Corrections!$H$14,19)="|applied|parametric",IF(COUNTIF(ValidKeys!$A$3:$A$207,LEFT(Corrections!$H$14,LEN(Corrections!$H$14)-19))=0,1,0),0)+IF(RIGHT(Corrections!$H$15,19)="|applied|parametric",IF(COUNTIF(ValidKeys!$A$3:$A$207,LEFT(Corrections!$H$15,LEN(Corrections!$H$15)-19))=0,1,0),0)+IF(RIGHT(Corrections!$H$16,19)="|applied|parametric",IF(COUNTIF(ValidKeys!$A$3:$A$207,LEFT(Corrections!$H$16,LEN(Corrections!$H$16)-19))=0,1,0),0)+IF(RIGHT(Corrections!$H$17,19)="|applied|parametric",IF(COUNTIF(ValidKeys!$A$3:$A$207,LEFT(Corrections!$H$17,LEN(Corrections!$H$17)-19))=0,1,0),0)+IF(RIGHT(Corrections!$H$18,19)="|applied|parametric",IF(COUNTIF(ValidKeys!$A$3:$A$207,LEFT(Corrections!$H$18,LEN(Corrections!$H$18)-19))=0,1,0),0)+IF(RIGHT(Corrections!$H$19,19)="|applied|parametric",IF(COUNTIF(ValidKeys!$A$3:$A$207,LEFT(Corrections!$H$19,LEN(Corrections!$H$19)-19))=0,1,0),0)+IF(RIGHT(Corrections!$H$20,19)="|applied|parametric",IF(COUNTIF(ValidKeys!$A$3:$A$207,LEFT(Corrections!$H$20,LEN(Corrections!$H$20)-19))=0,1,0),0)+IF(RIGHT(Corrections!$H$21,19)="|applied|parametric",IF(COUNTIF(ValidKeys!$A$3:$A$207,LEFT(Corrections!$H$21,LEN(Corrections!$H$21)-19))=0,1,0),0)+IF(RIGHT(Corrections!$H$22,19)="|applied|parametric",IF(COUNTIF(ValidKeys!$A$3:$A$207,LEFT(Corrections!$H$22,LEN(Corrections!$H$22)-19))=0,1,0),0)+IF(RIGHT(Corrections!$H$23,19)="|applied|parametric",IF(COUNTIF(ValidKeys!$A$3:$A$207,LEFT(Corrections!$H$23,LEN(Corrections!$H$23)-19))=0,1,0),0)+IF(RIGHT(Corrections!$H$24,19)="|applied|parametric",IF(COUNTIF(ValidKeys!$A$3:$A$207,LEFT(Corrections!$H$24,LEN(Corrections!$H$24)-19))=0,1,0),0)+IF(RIGHT(Corrections!$H$25,19)="|applied|parametric",IF(COUNTIF(ValidKeys!$A$3:$A$207,LEFT(Corrections!$H$25,LEN(Corrections!$H$25)-19))=0,1,0),0)+IF(RIGHT(Corrections!$H$26,19)="|applied|parametric",IF(COUNTIF(ValidKeys!$A$3:$A$207,LEFT(Corrections!$H$26,LEN(Corrections!$H$26)-19))=0,1,0),0)+IF(RIGHT(Corrections!$H$27,19)="|applied|parametric",IF(COUNTIF(ValidKeys!$A$3:$A$207,LEFT(Corrections!$H$27,LEN(Corrections!$H$27)-19))=0,1,0),0)+IF(RIGHT(Corrections!$H$28,19)="|applied|parametric",IF(COUNTIF(ValidKeys!$A$3:$A$207,LEFT(Corrections!$H$28,LEN(Corrections!$H$28)-19))=0,1,0),0)+IF(RIGHT(Corrections!$H$29,19)="|applied|parametric",IF(COUNTIF(ValidKeys!$A$3:$A$207,LEFT(Corrections!$H$29,LEN(Corrections!$H$29)-19))=0,1,0),0)+IF(RIGHT(Corrections!$H$30,19)="|applied|parametric",IF(COUNTIF(ValidKeys!$A$3:$A$207,LEFT(Corrections!$H$30,LEN(Corrections!$H$30)-19))=0,1,0),0)+IF(RIGHT(Corrections!$H$31,19)="|applied|parametric",IF(COUNTIF(ValidKeys!$A$3:$A$207,LEFT(Corrections!$H$31,LEN(Corrections!$H$31)-19))=0,1,0),0)+IF(RIGHT(Corrections!$H$32,19)="|applied|parametric",IF(COUNTIF(ValidKeys!$A$3:$A$207,LEFT(Corrections!$H$32,LEN(Corrections!$H$32)-19))=0,1,0),0)+IF(RIGHT(Corrections!$H$33,19)="|applied|parametric",IF(COUNTIF(ValidKeys!$A$3:$A$207,LEFT(Corrections!$H$33,LEN(Corrections!$H$33)-19))=0,1,0),0)+IF(RIGHT(Corrections!$H$34,19)="|applied|parametric",IF(COUNTIF(ValidKeys!$A$3:$A$207,LEFT(Corrections!$H$34,LEN(Corrections!$H$34)-19))=0,1,0),0)+IF(RIGHT(Corrections!$H$35,19)="|applied|parametric",IF(COUNTIF(ValidKeys!$A$3:$A$207,LEFT(Corrections!$H$35,LEN(Corrections!$H$35)-19))=0,1,0),0)+IF(RIGHT(Corrections!$H$36,19)="|applied|parametric",IF(COUNTIF(ValidKeys!$A$3:$A$207,LEFT(Corrections!$H$36,LEN(Corrections!$H$36)-19))=0,1,0),0)+IF(RIGHT(Corrections!$H$37,19)="|applied|parametric",IF(COUNTIF(ValidKeys!$A$3:$A$207,LEFT(Corrections!$H$37,LEN(Corrections!$H$37)-19))=0,1,0),0)+IF(RIGHT(Corrections!$H$38,19)="|applied|parametric",IF(COUNTIF(ValidKeys!$A$3:$A$207,LEFT(Corrections!$H$38,LEN(Corrections!$H$38)-19))=0,1,0),0)+IF(RIGHT(Corrections!$H$39,19)="|applied|parametric",IF(COUNTIF(ValidKeys!$A$3:$A$207,LEFT(Corrections!$H$39,LEN(Corrections!$H$39)-19))=0,1,0),0)+IF(RIGHT(Corrections!$H$40,19)="|applied|parametric",IF(COUNTIF(ValidKeys!$A$3:$A$207,LEFT(Corrections!$H$40,LEN(Corrections!$H$40)-19))=0,1,0),0)+IF(RIGHT(Corrections!$H$41,19)="|applied|parametric",IF(COUNTIF(ValidKeys!$A$3:$A$207,LEFT(Corrections!$H$41,LEN(Corrections!$H$41)-19))=0,1,0),0)+IF(RIGHT(Corrections!$H$42,19)="|applied|parametric",IF(COUNTIF(ValidKeys!$A$3:$A$207,LEFT(Corrections!$H$42,LEN(Corrections!$H$42)-19))=0,1,0),0)+IF(RIGHT(Corrections!$H$43,19)="|applied|parametric",IF(COUNTIF(ValidKeys!$A$3:$A$207,LEFT(Corrections!$H$43,LEN(Corrections!$H$43)-19))=0,1,0),0)+IF(RIGHT(Corrections!$H$44,19)="|applied|parametric",IF(COUNTIF(ValidKeys!$A$3:$A$207,LEFT(Corrections!$H$44,LEN(Corrections!$H$44)-19))=0,1,0),0)+IF(RIGHT(Corrections!$H$45,19)="|applied|parametric",IF(COUNTIF(ValidKeys!$A$3:$A$207,LEFT(Corrections!$H$45,LEN(Corrections!$H$45)-19))=0,1,0),0)+IF(RIGHT(Corrections!$H$46,19)="|applied|parametric",IF(COUNTIF(ValidKeys!$A$3:$A$207,LEFT(Corrections!$H$46,LEN(Corrections!$H$46)-19))=0,1,0),0)+IF(RIGHT(Corrections!$H$47,19)="|applied|parametric",IF(COUNTIF(ValidKeys!$A$3:$A$207,LEFT(Corrections!$H$47,LEN(Corrections!$H$47)-19))=0,1,0),0)+IF(RIGHT(Corrections!$H$48,19)="|applied|parametric",IF(COUNTIF(ValidKeys!$A$3:$A$207,LEFT(Corrections!$H$48,LEN(Corrections!$H$48)-19))=0,1,0),0)+IF(RIGHT(Corrections!$H$49,19)="|applied|parametric",IF(COUNTIF(ValidKeys!$A$3:$A$207,LEFT(Corrections!$H$49,LEN(Corrections!$H$49)-19))=0,1,0),0)+IF(RIGHT(Corrections!$H$50,19)="|applied|parametric",IF(COUNTIF(ValidKeys!$A$3:$A$207,LEFT(Corrections!$H$50,LEN(Corrections!$H$50)-19))=0,1,0),0)+IF(RIGHT(Corrections!$H$51,19)="|applied|parametric",IF(COUNTIF(ValidKeys!$A$3:$A$207,LEFT(Corrections!$H$51,LEN(Corrections!$H$51)-19))=0,1,0),0)+IF(RIGHT(Corrections!$H$52,19)="|applied|parametric",IF(COUNTIF(ValidKeys!$A$3:$A$207,LEFT(Corrections!$H$52,LEN(Corrections!$H$52)-19))=0,1,0),0)+IF(RIGHT(Corrections!$H$53,19)="|applied|parametric",IF(COUNTIF(ValidKeys!$A$3:$A$207,LEFT(Corrections!$H$53,LEN(Corrections!$H$53)-19))=0,1,0),0)+IF(RIGHT(Corrections!$H$54,19)="|applied|parametric",IF(COUNTIF(ValidKeys!$A$3:$A$207,LEFT(Corrections!$H$54,LEN(Corrections!$H$54)-19))=0,1,0),0)+IF(RIGHT(Corrections!$H$55,19)="|applied|parametric",IF(COUNTIF(ValidKeys!$A$3:$A$207,LEFT(Corrections!$H$55,LEN(Corrections!$H$55)-19))=0,1,0),0)+IF(RIGHT(Corrections!$H$56,19)="|applied|parametric",IF(COUNTIF(ValidKeys!$A$3:$A$207,LEFT(Corrections!$H$56,LEN(Corrections!$H$56)-19))=0,1,0),0)+IF(RIGHT(Corrections!$H$57,19)="|applied|parametric",IF(COUNTIF(ValidKeys!$A$3:$A$207,LEFT(Corrections!$H$57,LEN(Corrections!$H$57)-19))=0,1,0),0)+IF(RIGHT(Corrections!$H$58,19)="|applied|parametric",IF(COUNTIF(ValidKeys!$A$3:$A$207,LEFT(Corrections!$H$58,LEN(Corrections!$H$58)-19))=0,1,0),0)+IF(RIGHT(Corrections!$H$59,19)="|applied|parametric",IF(COUNTIF(ValidKeys!$A$3:$A$207,LEFT(Corrections!$H$59,LEN(Corrections!$H$59)-19))=0,1,0),0)+IF(RIGHT(Corrections!$H$60,19)="|applied|parametric",IF(COUNTIF(ValidKeys!$A$3:$A$207,LEFT(Corrections!$H$60,LEN(Corrections!$H$60)-19))=0,1,0),0)+IF(RIGHT(Corrections!$H$61,19)="|applied|parametric",IF(COUNTIF(ValidKeys!$A$3:$A$207,LEFT(Corrections!$H$61,LEN(Corrections!$H$61)-19))=0,1,0),0)+IF(RIGHT(Corrections!$H$62,19)="|applied|parametric",IF(COUNTIF(ValidKeys!$A$3:$A$207,LEFT(Corrections!$H$62,LEN(Corrections!$H$62)-19))=0,1,0),0)+IF(RIGHT(Corrections!$H$63,19)="|applied|parametric",IF(COUNTIF(ValidKeys!$A$3:$A$207,LEFT(Corrections!$H$63,LEN(Corrections!$H$63)-19))=0,1,0),0)+IF(RIGHT(Corrections!$H$64,19)="|applied|parametric",IF(COUNTIF(ValidKeys!$A$3:$A$207,LEFT(Corrections!$H$64,LEN(Corrections!$H$64)-19))=0,1,0),0))&" unresolved"
A19: 15 | B19: every applied parametric correction has a numeric value | C19: =IF((IF(RIGHT(Corrections!$H$5,19)="|applied|parametric",IF(ISNUMBER(Corrections!$G$5),0,1),0)+IF(RIGHT(Corrections!$H$6,19)="|applied|parametric",IF(ISNUMBER(Corrections!$G$6),0,1),0)+IF(RIGHT(Corrections!$H$7,19)="|applied|parametric",IF(ISNUMBER(Corrections!$G$7),0,1),0)+IF(RIGHT(Corrections!$H$8,19)="|applied|parametric",IF(ISNUMBER(Corrections!$G$8),0,1),0)+IF(RIGHT(Corrections!$H$9,19)="|applied|parametric",IF(ISNUMBER(Corrections!$G$9),0,1),0)+IF(RIGHT(Corrections!$H$10,19)="|applied|parametric",IF(ISNUMBER(Corrections!$G$10),0,1),0)+IF(RIGHT(Corrections!$H$11,19)="|applied|parametric",IF(ISNUMBER(Corrections!$G$11),0,1),0)+IF(RIGHT(Corrections!$H$12,19)="|applied|parametric",IF(ISNUMBER(Corrections!$G$12),0,1),0)+IF(RIGHT(Corrections!$H$13,19)="|applied|parametric",IF(ISNUMBER(Corrections!$G$13),0,1),0)+IF(RIGHT(Corrections!$H$14,19)="|applied|parametric",IF(ISNUMBER(Corrections!$G$14),0,1),0)+IF(RIGHT(Corrections!$H$15,19)="|applied|parametric",IF(ISNUMBER(Corrections!$G$15),0,1),0)+IF(RIGHT(Corrections!$H$16,19)="|applied|parametric",IF(ISNUMBER(Corrections!$G$16),0,1),0)+IF(RIGHT(Corrections!$H$17,19)="|applied|parametric",IF(ISNUMBER(Corrections!$G$17),0,1),0)+IF(RIGHT(Corrections!$H$18,19)="|applied|parametric",IF(ISNUMBER(Corrections!$G$18),0,1),0)+IF(RIGHT(Corrections!$H$19,19)="|applied|parametric",IF(ISNUMBER(Corrections!$G$19),0,1),0)+IF(RIGHT(Corrections!$H$20,19)="|applied|parametric",IF(ISNUMBER(Corrections!$G$20),0,1),0)+IF(RIGHT(Corrections!$H$21,19)="|applied|parametric",IF(ISNUMBER(Corrections!$G$21),0,1),0)+IF(RIGHT(Corrections!$H$22,19)="|applied|parametric",IF(ISNUMBER(Corrections!$G$22),0,1),0)+IF(RIGHT(Corrections!$H$23,19)="|applied|parametric",IF(ISNUMBER(Corrections!$G$23),0,1),0)+IF(RIGHT(Corrections!$H$24,19)="|applied|parametric",IF(ISNUMBER(Corrections!$G$24),0,1),0)+IF(RIGHT(Corrections!$H$25,19)="|applied|parametric",IF(ISNUMBER(Corrections!$G$25),0,1),0)+IF(RIGHT(Corrections!$H$26,19)="|applied|parametric",IF(ISNUMBER(Corrections!$G$26),0,1),0)+IF(RIGHT(Corrections!$H$27,19)="|applied|parametric",IF(ISNUMBER(Corrections!$G$27),0,1),0)+IF(RIGHT(Corrections!$H$28,19)="|applied|parametric",IF(ISNUMBER(Corrections!$G$28),0,1),0)+IF(RIGHT(Corrections!$H$29,19)="|applied|parametric",IF(ISNUMBER(Corrections!$G$29),0,1),0)+IF(RIGHT(Corrections!$H$30,19)="|applied|parametric",IF(ISNUMBER(Corrections!$G$30),0,1),0)+IF(RIGHT(Corrections!$H$31,19)="|applied|parametric",IF(ISNUMBER(Corrections!$G$31),0,1),0)+IF(RIGHT(Corrections!$H$32,19)="|applied|parametric",IF(ISNUMBER(Corrections!$G$32),0,1),0)+IF(RIGHT(Corrections!$H$33,19)="|applied|parametric",IF(ISNUMBER(Corrections!$G$33),0,1),0)+IF(RIGHT(Corrections!$H$34,19)="|applied|parametric",IF(ISNUMBER(Corrections!$G$34),0,1),0)+IF(RIGHT(Corrections!$H$35,19)="|applied|parametric",IF(ISNUMBER(Corrections!$G$35),0,1),0)+IF(RIGHT(Corrections!$H$36,19)="|applied|parametric",IF(ISNUMBER(Corrections!$G$36),0,1),0)+IF(RIGHT(Corrections!$H$37,19)="|applied|parametric",IF(ISNUMBER(Corrections!$G$37),0,1),0)+IF(RIGHT(Corrections!$H$38,19)="|applied|parametric",IF(ISNUMBER(Corrections!$G$38),0,1),0)+IF(RIGHT(Corrections!$H$39,19)="|applied|parametric",IF(ISNUMBER(Corrections!$G$39),0,1),0)+IF(RIGHT(Corrections!$H$40,19)="|applied|parametric",IF(ISNUMBER(Corrections!$G$40),0,1),0)+IF(RIGHT(Corrections!$H$41,19)="|applied|parametric",IF(ISNUMBER(Corrections!$G$41),0,1),0)+IF(RIGHT(Corrections!$H$42,19)="|applied|parametric",IF(ISNUMBER(Corrections!$G$42),0,1),0)+IF(RIGHT(Corrections!$H$43,19)="|applied|parametric",IF(ISNUMBER(Corrections!$G$43),0,1),0)+IF(RIGHT(Corrections!$H$44,19)="|applied|parametric",IF(ISNUMBER(Corrections!$G$44),0,1),0)+IF(RIGHT(Corrections!$H$45,19)="|applied|parametric",IF(ISNUMBER(Corrections!$G$45),0,1),0)+IF(RIGHT(Corrections!$H$46,19)="|applied|parametric",IF(ISNUMBER(Corrections!$G$46),0,1),0)+IF(RIGHT(Corrections!$H$47,19)="|applied|parametric",IF(ISNUMBER(Corrections!$G$47),0,1),0)+IF(RIGHT(Corrections!$H$48,19)="|applied|parametric",IF(ISNUMBER(Corrections!$G$48),0,1),0)+IF(RIGHT(Corrections!$H$49,19)="|applied|parametric",IF(ISNUMBER(Corrections!$G$49),0,1),0)+IF(RIGHT(Corrections!$H$50,19)="|applied|parametric",IF(ISNUMBER(Corrections!$G$50),0,1),0)+IF(RIGHT(Corrections!$H$51,19)="|applied|parametric",IF(ISNUMBER(Corrections!$G$51),0,1),0)+IF(RIGHT(Corrections!$H$52,19)="|applied|parametric",IF(ISNUMBER(Corrections!$G$52),0,1),0)+IF(RIGHT(Corrections!$H$53,19)="|applied|parametric",IF(ISNUMBER(Corrections!$G$53),0,1),0)+IF(RIGHT(Corrections!$H$54,19)="|applied|parametric",IF(ISNUMBER(Corrections!$G$54),0,1),0)+IF(RIGHT(Corrections!$H$55,19)="|applied|parametric",IF(ISNUMBER(Corrections!$G$55),0,1),0)+IF(RIGHT(Corrections!$H$56,19)="|applied|parametric",IF(ISNUMBER(Corrections!$G$56),0,1),0)+IF(RIGHT(Corrections!$H$57,19)="|applied|parametric",IF(ISNUMBER(Corrections!$G$57),0,1),0)+IF(RIGHT(Corrections!$H$58,19)="|applied|parametric",IF(ISNUMBER(Corrections!$G$58),0,1),0)+IF(RIGHT(Corrections!$H$59,19)="|applied|parametric",IF(ISNUMBER(Corrections!$G$59),0,1),0)+IF(RIGHT(Corrections!$H$60,19)="|applied|parametric",IF(ISNUMBER(Corrections!$G$60),0,1),0)+IF(RIGHT(Corrections!$H$61,19)="|applied|parametric",IF(ISNUMBER(Corrections!$G$61),0,1),0)+IF(RIGHT(Corrections!$H$62,19)="|applied|parametric",IF(ISNUMBER(Corrections!$G$62),0,1),0)+IF(RIGHT(Corrections!$H$63,19)="|applied|parametric",IF(ISNUMBER(Corrections!$G$63),0,1),0)+IF(RIGHT(Corrections!$H$64,19)="|applied|parametric",IF(ISNUMBER(Corrections!$G$64),0,1),0))=0,"PASS","FAIL")
A20: 16 | B20: revenue = sum of channel revenue (every month) | C20: =IF(MAX($E$60:$DS$60)<=0.005,"PASS","FAIL") | D20: =ROUND(MAX($E$60:$DS$60),6)
A21: 17 | B21: gross_profit = revenue - cogs (every month) | C21: =IF(MAX($E$61:$DS$61)<=0.005,"PASS","FAIL") | D21: =ROUND(MAX($E$61:$DS$61),6)
A22: 18 | B22: ebitda = gross_profit - opex (every month) | C22: =IF(MAX($E$62:$DS$62)<=0.005,"PASS","FAIL") | D22: =ROUND(MAX($E$62:$DS$62),6)
A23: 19 | B23: pretax = ebitda - da - interest (every month) | C23: =IF(MAX($E$63:$DS$63)<=0.005,"PASS","FAIL") | D23: =ROUND(MAX($E$63:$DS$63),6)
A24: 20 | B24: net_income = pretax - tax (every month) | C24: =IF(MAX($E$64:$DS$64)<=0.005,"PASS","FAIL") | D24: =ROUND(MAX($E$64:$DS$64),6)
A25: 21 | B25: operating_cash_flow = net_income + da + wc_cash_impact (every month) | C25: =IF(MAX($E$65:$DS$65)<=0.005,"PASS","FAIL") | D25: =ROUND(MAX($E$65:$DS$65),6)
A26: 22 | B26: free_cash_flow = ocf - capex (every month) | C26: =IF(MAX($E$66:$DS$66)<=0.005,"PASS","FAIL") | D26: =ROUND(MAX($E$66:$DS$66),6)
A27: 23 | B27: change_in_cash = fcf - principal (every month) | C27: =IF(MAX($E$67:$DS$67)<=0.005,"PASS","FAIL") | D27: =ROUND(MAX($E$67:$DS$67),6)
A28: 24 | B28: tax is never negative (every month) | C28: =IF(MAX($E$68:$DS$68)<=0.005,"PASS","FAIL") | D28: =ROUND(MAX($E$68:$DS$68),6)
A29: 25 | B29: tax-loss carryforward never negative (every month) | C29: =IF(MAX($E$69:$DS$69)<=0.005,"PASS","FAIL") | D29: =ROUND(MAX($E$69:$DS$69),6)
A30: 26 | B30: ending cash = opening cash + cumulative change in cash | C30: =IF(ABS(Summary!$B$21-(Effective!$B$14+SUM(Model!$C$78:$DR$78)))<=0.005,"PASS","FAIL") | D30: =ROUND(ABS(Summary!$B$21-(Effective!$B$14+SUM(Model!$C$78:$DR$78))),6)
A31: 27 | B31: debt roll-forward: sum opening debt - principal paid = ending debt | C31: =IF(ABS(INDEX(Model!$C$64:$DR$64,1,Effective!$B$7)-(SUM(Effective!$D$53:$D$57)-SUM(Model!$C$63:$DR$63)))<=0.005,"PASS","FAIL") | D31: =ROUND(ABS(INDEX(Model!$C$64:$DR$64,1,Effective!$B$7)-(SUM(Effective!$D$53:$D$57)-SUM(Model!$C$63:$DR$63))),6)
A32: 28 | B32: cumulative WC impact = -(closing AR - open AR) + (closing AP - open AP) - (closing inv - open inv) | C32: =IF(ABS(SUM(Model!$C$74:$DR$74)-(-(INDEX(Model!$C$71:$DR$71,1,Effective!$B$7)-Effective!$B$15)+(INDEX(Model!$C$72:$DR$72,1,Effective!$B$7)-Effective!$B$16)-(INDEX(Model!$C$73:$DR$73,1,Effective!$B$7)-Effective!$B$17)))<=0.005,"PASS","FAIL") | D32: =ROUND(ABS(SUM(Model!$C$74:$DR$74)-(-(INDEX(Model!$C$71:$DR$71,1,Effective!$B$7)-Effective!$B$15)+(INDEX(Model!$C$72:$DR$72,1,Effective!$B$7)-Effective!$B$16)-(INDEX(Model!$C$73:$DR$73,1,Effective!$B$7)-Effective!$B$17))),6)
A33: 29 | B33: GOLDEN parity with original openfpa output: revenue = 350,000,000 | C33: =IF(ABS(ROUND(Summary!$B$5,0)-(350000000))<=1,"PASS","FAIL") | D33: =ROUND(Summary!$B$5,0)
A34: 30 | B34: GOLDEN parity with original openfpa output: ebitda = 62,900,000 | C34: =IF(ABS(ROUND(Summary!$B$9,0)-(62900000))<=1,"PASS","FAIL") | D34: =ROUND(Summary!$B$9,0)
A35: 31 | B35: GOLDEN parity with original openfpa output: net_income = 35,022,779 | C35: =IF(ABS(ROUND(Summary!$B$14,0)-(35022779))<=1,"PASS","FAIL") | D35: =ROUND(Summary!$B$14,0)
A36: 32 | B36: GOLDEN parity with original openfpa output: ending_cash = 45,445,776 | C36: =IF(ABS(ROUND(Summary!$B$21,0)-(45445776))<=1,"PASS","FAIL") | D36: =ROUND(Summary!$B$21,0)
A59: Identity helper rows (absolute deviation per month)
B60: revenue = sum of channel revenue | E60: =ABS(Model!C18-SUM(Model!C10:C17)) | F60: =ABS(Model!D18-SUM(Model!D10:D17)) | G60: =ABS(Model!E18-SUM(Model!E10:E17)) | H60: =ABS(Model!F18-SUM(Model!F10:F17)) | I60: =ABS(Model!G18-SUM(Model!G10:G17)) | J60: =ABS(Model!H18-SUM(Model!H10:H17)) | K60: =ABS(Model!I18-SUM(Model!I10:I17)) | L60: =ABS(Model!J18-SUM(Model!J10:J17)) | ... DT60: =ABS(Model!DR18-SUM(Model!DR10:DR17))
B61: gross_profit = revenue - cogs | E61: =ABS(Model!C28-(Model!C18-Model!C27)) | F61: =ABS(Model!D28-(Model!D18-Model!D27)) | G61: =ABS(Model!E28-(Model!E18-Model!E27)) | H61: =ABS(Model!F28-(Model!F18-Model!F27)) | I61: =ABS(Model!G28-(Model!G18-Model!G27)) | J61: =ABS(Model!H28-(Model!H18-Model!H27)) | K61: =ABS(Model!I28-(Model!I18-Model!I27)) | L61: =ABS(Model!J28-(Model!J18-Model!J27)) | ... DT61: =ABS(Model!DR28-(Model!DR18-Model!DR27))
B62: ebitda = gross_profit - opex | E62: =ABS(Model!C45-(Model!C28-Model!C44)) | F62: =ABS(Model!D45-(Model!D28-Model!D44)) | G62: =ABS(Model!E45-(Model!E28-Model!E44)) | H62: =ABS(Model!F45-(Model!F28-Model!F44)) | I62: =ABS(Model!G45-(Model!G28-Model!G44)) | J62: =ABS(Model!H45-(Model!H28-Model!H44)) | K62: =ABS(Model!I45-(Model!I28-Model!I44)) | L62: =ABS(Model!J45-(Model!J28-Model!J44)) | ... DT62: =ABS(Model!DR45-(Model!DR28-Model!DR44))
B63: pretax = ebitda - da - interest | E63: =ABS(Model!C65-(Model!C45-Model!C46-Model!C62)) | F63: =ABS(Model!D65-(Model!D45-Model!D46-Model!D62)) | G63: =ABS(Model!E65-(Model!E45-Model!E46-Model!E62)) | H63: =ABS(Model!F65-(Model!F45-Model!F46-Model!F62)) | I63: =ABS(Model!G65-(Model!G45-Model!G46-Model!G62)) | J63: =ABS(Model!H65-(Model!H45-Model!H46-Model!H62)) | K63: =ABS(Model!I65-(Model!I45-Model!I46-Model!I62)) | L63: =ABS(Model!J65-(Model!J45-Model!J46-Model!J62)) | ... DT63: =ABS(Model!DR65-(Model!DR45-Model!DR46-Model!DR62))
...

Sheet Assumptions
A1: Assumptions (inputs only - pale yellow)
A2: Edit here. Everything else is formula-driven. Keys in column A are the correction paths.
A4: key (correction path) | B4: value | C4: meaning
A5: name | B5: Kaveri Chairs Pvt Ltd (Coimbatore) - FY2026-27 budget | C5: Company / entity name
A6: start_month | B6: 46113 | C6: First forecast month (enter 1st of month)
A7: horizon_months | B7: 12 | C7: Horizon (months, 1-120)
A8: tax_rate | B8: 0.25168 | C8: Tax rate on positive pre-tax income
A9: da_monthly | B9: 900000 | C9: Depreciation & amortisation per month
A10: capex_monthly | B10: 600000 | C10: Capital expenditure per month
A11: working_capital.dso_days | B11: 52 | C11: DSO days (AR = revenue x DSO/30)
A12: working_capital.dpo_days | B12: 48 | C12: DPO days (AP = COGS x DPO/30)
A13: working_capital.dio_days | B13: 85 | C13: DIO days (Inventory = COGS x DIO/30)
A14: opening_balances.cash | B14: 11000000 | C14: Opening cash
A15: opening_balances.ar | B15: 52563570 | C15: Opening AR
A16: opening_balances.ap | B16: 28071727 | C16: Opening AP
A17: opening_balances.inventory | B17: 49710349 | C17: Opening inventory
A18: opening_balances.nol | B18: 0 | C18: Opening tax-loss carryforward (unabsorbed loss)
A19: currency_code | B19: INR | C19: Currency (ISO)
A20: currency_symbol | B20: ₹ | C20: Currency symbol for reports
A21: number_style | B21: indian | C21: Report digit grouping: indian / western
A22: display_divisor | B22: 100000 | C22: Report unit divisor (1, 1000, 100000=lakh, 10000000=crore)
A23: display_unit | B23: ₹ lakh | C23: Report unit label
A25: idx | B25: channel name | C25: annual_revenue | D25: growth_rate | E25: cogs_pct | F25: season Jan | G25: season Feb | H25: season Mar | I25: season Apr | J25: season May | K25: season Jun | L25: season Jul | M25: season Aug | N25: season Sep | O25: season Oct | P25: season Nov | Q25: season Dec
A26: 0 | B26: Dealer network (TN & Kerala) | C26: 180000000 | D26: 0.12 | E26: 0.58 | F26: 1.1 | G26: 0.85 | H26: 1 | I26: 1.05 | J26: 0.95 | K26: 0.85 | L26: 0.75 | M26: 0.9 | N26: 1.05 | O26: 1.4 | P26: 1.25 | Q26: 0.85
A27: 1 | B27: Online marketplaces (Amazon.in / Flipkart) | C27: 90000000 | D27: 0.25 | E27: 0.62 | F27: 1 | G27: 0.85 | H27: 0.95 | I27: 1 | J27: 0.95 | K27: 0.85 | L27: 0.95 | M27: 1.05 | N27: 1.15 | O27: 1.35 | P27: 1.05 | Q27: 0.85
A28: 2 | B28: D2C website & Coimbatore experience store | C28: 45000000 | D28: 0.18 | E28: 0.45 | F28: 1.15 | G28: 0.9 | H28: 0.95 | I28: 1.1 | J28: 1 | K28: 0.85 | L28: 0.75 | M28: 0.9 | N28: 1 | O28: 1.3 | P28: 1.2 | Q28: 0.9
A29: 3 | B29: Institutional (schools, hotels, offices) | C29: 35000000 | D29: 0.05 | E29: 0.64 | F29: 0.7 | G29: 0.8 | H29: 1.4 | I29: 1.1 | J29: 1.4 | K29: 1.5 | L29: 0.9 | M29: 0.8 | N29: 0.8 | O29: 0.8 | P29: 0.9 | Q29: 0.9
A30: 4
A31: 5
A32: 6
A33: 7
A35: idx | B35: opex line name | C35: kind (fixed/variable) | D35: monthly_amount | E35: pct_of_revenue
A36: 0 | B36: Payroll & benefits (from D04) | C36: fixed | D36: 3200000 | E36: 0
A37: 1 | B37: Marketing & dealer promotion | C37: variable | D37: 0 | E37: 0.06
A38: 2 | B38: Freight outward | C38: variable | D38: 0 | E38: 0.035
A39: 3 | B39: Rent & facilities (from D18) | C39: fixed | D39: 650000 | E39: 0
A40: 4 | B40: Admin, software & professional fees | C40: fixed | D40: 400000 | E40: 0
A41: 5
A42: 6
A43: 7
...

Sheet Corrections
A1: Corrections (transcribed from memory/corrections/*.md)
A2: One row per correction file. Only applied + parametric rows change the model. Home of the fact = the .md file.
A4: slug | B4: type | C4: target | D4: status | E4: date | F4: override_path | G4: override_value | H4: key (formula)
A5: 2026-03-20-dealer-november-deepavali | B5: parametric | C5: channels[0].seasonality[10] | D5: applied | E5: 2026-03-20 | F5: channels[0].seasonality[10] | G5: 1.45 | H5: =IF(F5="","",SUBSTITUTE(SUBSTITUTE(F5," ",""),"*","ALL")&"|"&LOWER(D5)&"|"&LOWER(B5))
A6: 2025-12-05-cyclone-dispatch-delay | B6: context | C6: FY2025-26 November-December dealer revenue | D6: applied | E6: 2025-12-05 | H6: =IF(F6="","",SUBSTITUTE(SUBSTITUTE(F6," ",""),"*","ALL")&"|"&LOWER(D6)&"|"&LOWER(B6))
H7: =IF(F7="","",SUBSTITUTE(SUBSTITUTE(F7," ",""),"*","ALL")&"|"&LOWER(D7)&"|"&LOWER(B7))
H8: =IF(F8="","",SUBSTITUTE(SUBSTITUTE(F8," ",""),"*","ALL")&"|"&LOWER(D8)&"|"&LOWER(B8))
H9: =IF(F9="","",SUBSTITUTE(SUBSTITUTE(F9," ",""),"*","ALL")&"|"&LOWER(D9)&"|"&LOWER(B9))
H10: =IF(F10="","",SUBSTITUTE(SUBSTITUTE(F10," ",""),"*","ALL")&"|"&LOWER(D10)&"|"&LOWER(B10))
H11: =IF(F11="","",SUBSTITUTE(SUBSTITUTE(F11," ",""),"*","ALL")&"|"&LOWER(D11)&"|"&LOWER(B11))
H12: =IF(F12="","",SUBSTITUTE(SUBSTITUTE(F12," ",""),"*","ALL")&"|"&LOWER(D12)&"|"&LOWER(B12))
H13: =IF(F13="","",SUBSTITUTE(SUBSTITUTE(F13," ",""),"*","ALL")&"|"&LOWER(D13)&"|"&LOWER(B13))
H14: =IF(F14="","",SUBSTITUTE(SUBSTITUTE(F14," ",""),"*","ALL")&"|"&LOWER(D14)&"|"&LOWER(B14))
