Workbook
Name c13_open: 'Setup'!$B$4
Name c13_weeks: 'Setup'!$B$5
Name c13_start: 'Setup'!$B$6
Name c13_buffer: 'Setup'!$B$7
Name rw_min_cash: 'Runway'!$B$4
Name rw_min_week: 'Runway'!$B$5
Name rw_first_negative: 'Runway'!$B$6

Sheet README
A1: K02 · 13-Week Direct Cash Forecast + Runway (no-code kernel)
A3: Replaces openfpa: pyfpa.cash13 (WeeklyFlow, Cash13Config, expand_flow, cash13_forecast) and runway_summary.
A4: How an agent uses this workbook
A5: 1. Copy into companies/<slug>/models/. Enter opening_cash, weeks (default 13, max 52) and week-1 start date on 'Setup'.
A6: 2. List every KNOWN lumpy receipt and disbursement on 'Flows' (direction, name, amount as a positive magnitude, start_week, recurrence once/weekly/biweekly, optional end_week).
A7: Use 'DateToWeek' to convert a calendar due date (e.g. GST GSTR-3B on the 20th, TDS on the 7th, PF/ESI on the 15th, advance tax 15 Jun/Sep/Dec/Mar) into a week number.
A8: 3. Recalculate. Read 'Runway': min_cash, min_week, first_negative_week, and the suggested credit line (trough + buffer).
A9: 4. The position is RAW / UNFINANCED: no automatic overdraft or cash-credit draws. A visible shortfall is the point - it sizes the line (W05 cash runway).
A10: Rules (identical to openfpa)
A11: once = only start_week; weekly = every week start..end; biweekly = every 2nd week start..end; end defaults to the horizon; weeks outside 1..weeks are ignored.
A12: net = receipts - disbursements; ending cash is cumulative from opening cash. min_week is the FIRST week at the minimum; first_negative_week is the first week ending below zero (blank = none).
A13: Amounts must be >= 0 and end_week >= start_week - see Checks.

Sheet Checks
A1: Checks - schema validation. OVERALL must be PASS.
B3: OVERALL | C3: =IF(COUNTIF(C5:C13,"PASS")=COUNT(A5:A13),"PASS","FAIL")
A4: # | B4: check | C4: result | D4: detail
A5: 1 | B5: weeks is an integer 1..52 | C5: =IF(AND(Setup!$B$5>=1,Setup!$B$5<=52,INT(Setup!$B$5)=Setup!$B$5),"PASS","FAIL") | D5: =Setup!$B$5
A6: 2 | B6: opening_cash is a number | C6: =IF(ISNUMBER(Setup!$B$4),"PASS","FAIL")
A7: 3 | B7: every direction is receipt or disbursement | C7: =IF(SUMPRODUCT((Flows!$A$5:$A$84<>"")*1)=COUNTIF(Flows!$A$5:$A$84,"receipt")+COUNTIF(Flows!$A$5:$A$84,"disbursement"),"PASS","FAIL")
A8: 4 | B8: each flow: amount >= 0, start_week >= 1, valid recurrence, end_week >= start_week | C8: =IF((IF(Flows!A5="",0,IF(AND(ISNUMBER(Flows!C5),Flows!C5>=0,ISNUMBER(Flows!D5),Flows!D5>=1,OR(Flows!E5="",Flows!E5="once",Flows!E5="weekly",Flows!E5="biweekly"),OR(Flows!F5="",AND(ISNUMBER(Flows!F5),Flows!F5>=Flows!D5))),0,1))+IF(Flows!A6="",0,IF(AND(ISNUMBER(Flows!C6),Flows!C6>=0,ISNUMBER(Flows!D6),Flows!D6>=1,OR(Flows!E6="",Flows!E6="once",Flows!E6="weekly",Flows!E6="biweekly"),OR(Flows!F6="",AND(ISNUMBER(Flows!F6),Flows!F6>=Flows!D6))),0,1))+IF(Flows!A7="",0,IF(AND(ISNUMBER(Flows!C7),Flows!C7>=0,ISNUMBER(Flows!D7),Flows!D7>=1,OR(Flows!E7="",Flows!E7="once",Flows!E7="weekly",Flows!E7="biweekly"),OR(Flows!F7="",AND(ISNUMBER(Flows!F7),Flows!F7>=Flows!D7))),0,1))+IF(Flows!A8="",0,IF(AND(ISNUMBER(Flows!C8),Flows!C8>=0,ISNUMBER(Flows!D8),Flows!D8>=1,OR(Flows!E8="",Flows!E8="once",Flows!E8="weekly",Flows!E8="biweekly"),OR(Flows!F8="",AND(ISNUMBER(Flows!F8),Flows!F8>=Flows!D8))),0,1))+IF(Flows!A9="",0,IF(AND(ISNUMBER(Flows!C9),Flows!C9>=0,ISNUMBER(Flows!D9),Flows!D9>=1,OR(Flows!E9="",Flows!E9="once",Flows!E9="weekly",Flows!E9="biweekly"),OR(Flows!F9="",AND(ISNUMBER(Flows!F9),Flows!F9>=Flows!D9))),0,1))+IF(Flows!A10="",0,IF(AND(ISNUMBER(Flows!C10),Flows!C10>=0,ISNUMBER(Flows!D10),Flows!D10>=1,OR(Flows!E10="",Flows!E10="once",Flows!E10="weekly",Flows!E10="biweekly"),OR(Flows!F10="",AND(ISNUMBER(Flows!F10),Flows!F10>=Flows!D10))),0,1))+IF(Flows!A11="",0,IF(AND(ISNUMBER(Flows!C11),Flows!C11>=0,ISNUMBER(Flows!D11),Flows!D11>=1,OR(Flows!E11="",Flows!E11="once",Flows!E11="weekly",Flows!E11="biweekly"),OR(Flows!F11="",AND(ISNUMBER(Flows!F11),Flows!F11>=Flows!D11))),0,1))+IF(Flows!A12="",0,IF(AND(ISNUMBER(Flows!C12),Flows!C12>=0,ISNUMBER(Flows!D12),Flows!D12>=1,OR(Flows!E12="",Flows!E12="once",Flows!E12="weekly",Flows!E12="biweekly"),OR(Flows!F12="",AND(ISNUMBER(Flows!F12),Flows!F12>=Flows!D12))),0,1))+IF(Flows!A13="",0,IF(AND(ISNUMBER(Flows!C13),Flows!C13>=0,ISNUMBER(Flows!D13),Flows!D13>=1,OR(Flows!E13="",Flows!E13="once",Flows!E13="weekly",Flows!E13="biweekly"),OR(Flows!F13="",AND(ISNUMBER(Flows!F13),Flows!F13>=Flows!D13))),0,1))+IF(Flows!A14="",0,IF(AND(ISNUMBER(Flows!C14),Flows!C14>=0,ISNUMBER(Flows!D14),Flows!D14>=1,OR(Flows!E14="",Flows!E14="once",Flows!E14="weekly",Flows!E14="biweekly"),OR(Flows!F14="",AND(ISNUMBER(Flows!F14),Flows!F14>=Flows!D14))),0,1))+IF(Flows!A15="",0,IF(AND(ISNUMBER(Flows!C15),Flows!C15>=0,ISNUMBER(Flows!D15),Flows!D15>=1,OR(Flows!E15="",Flows!E15="once",Flows!E15="weekly",Flows!E15="biweekly"),OR(Flows!F15="",AND(ISNUMBER(Flows!F15),Flows!F15>=Flows!D15))),0,1))+IF(Flows!A16="",0,IF(AND(ISNUMBER(Flows!C16),Flows!C16>=0,ISNUMBER(Flows!D16),Flows!D16>=1,OR(Flows!E16="",Flows!E16="once",Flows!E16="weekly",Flows!E16="biweekly"),OR(Flows!F16="",AND(ISNUMBER(Flows!F16),Flows!F16>=Flows!D16))),0,1))+IF(Flows!A17="",0,IF(AND(ISNUMBER(Flows!C17),Flows!C17>=0,ISNUMBER(Flows!D17),Flows!D17>=1,OR(Flows!E17="",Flows!E17="once",Flows!E17="weekly",Flows!E17="biweekly"),OR(Flows!F17="",AND(ISNUMBER(Flows!F17),Flows!F17>=Flows!D17))),0,1))+IF(Flows!A18="",0,IF(AND(ISNUMBER(Flows!C18),Flows!C18>=0,ISNUMBER(Flows!D18),Flows!D18>=1,OR(Flows!E18="",Flows!E18="once",Flows!E18="weekly",Flows!E18="biweekly"),OR(Flows!F18="",AND(ISNUMBER(Flows!F18),Flows!F18>=Flows!D18))),0,1))+IF(Flows!A19="",0,IF(AND(ISNUMBER(Flows!C19),Flows!C19>=0,ISNUMBER(Flows!D19),Flows!D19>=1,OR(Flows!E19="",Flows!E19="once",Flows!E19="weekly",Flows!E19="biweekly"),OR(Flows!F19="",AND(ISNUMBER(Flows!F19),Flows!F19>=Flows!D19))),0,1))+IF(Flows!A20="",0,IF(AND(ISNUMBER(Flows!C20),Flows!C20>=0,ISNUMBER(Flows!D20),Flows!D20>=1,OR(Flows!E20="",Flows!E20="once",Flows!E20="weekly",Flows!E20="biweekly"),OR(Flows!F20="",AND(ISNUMBER(Flows!F20),Flows!F20>=Flows!D20))),0,1))+IF(Flows!A21="",0,IF(AND(ISNUMBER(Flows!C21),Flows!C21>=0,ISNUMBER(Flows!D21),Flows!D21>=1,OR(Flows!E21="",Flows!E21="once",Flows!E21="weekly",Flows!E21="biweekly"),OR(Flows!F21="",AND(ISNUMBER(Flows!F21),Flows!F21>=Flows!D21))),0,1))+IF(Flows!A22="",0,IF(AND(ISNUMBER(Flows!C22),Flows!C22>=0,ISNUMBER(Flows!D22),Flows!D22>=1,OR(Flows!E22="",Flows!E22="once",Flows!E22="weekly",Flows!E22="biweekly"),OR(Flows!F22="",AND(ISNUMBER(Flows!F22),Flows!F22>=Flows!D22))),0,1))+IF(Flows!A23="",0,IF(AND(ISNUMBER(Flows!C23),Flows!C23>=0,ISNUMBER(Flows!D23),Flows!D23>=1,OR(Flows!E23="",Flows!E23="once",Flows!E23="weekly",Flows!E23="biweekly"),OR(Flows!F23="",AND(ISNUMBER(Flows!F23),Flows!F23>=Flows!D23))),0,1))+IF(Flows!A24="",0,IF(AND(ISNUMBER(Flows!C24),Flows!C24>=0,ISNUMBER(Flows!D24),Flows!D24>=1,OR(Flows!E24="",Flows!E24="once",Flows!E24="weekly",Flows!E24="biweekly"),OR(Flows!F24="",AND(ISNUMBER(Flows!F24),Flows!F24>=Flows!D24))),0,1))+IF(Flows!A25="",0,IF(AND(ISNUMBER(Flows!C25),Flows!C25>=0,ISNUMBER(Flows!D25),Flows!D25>=1,OR(Flows!E25="",Flows!E25="once",Flows!E25="weekly",Flows!E25="biweekly"),OR(Flows!F25="",AND(ISNUMBER(Flows!F25),Flows!F25>=Flows!D25))),0,1))+IF(Flows!A26="",0,IF(AND(ISNUMBER(Flows!C26),Flows!C26>=0,ISNUMBER(Flows!D26),Flows!D26>=1,OR(Flows!E26="",Flows!E26="once",Flows!E26="weekly",Flows!E26="biweekly"),OR(Flows!F26="",AND(ISNUMBER(Flows!F26),Flows!F26>=Flows!D26))),0,1))+IF(Flows!A27="",0,IF(AND(ISNUMBER(Flows!C27),Flows!C27>=0,ISNUMBER(Flows!D27),Flows!D27>=1,OR(Flows!E27="",Flows!E27="once",Flows!E27="weekly",Flows!E27="biweekly"),OR(Flows!F27="",AND(ISNUMBER(Flows!F27),Flows!F27>=Flows!D27))),0,1))+IF(Flows!A28="",0,IF(AND(ISNUMBER(Flows!C28),Flows!C28>=0,ISNUMBER(Flows!D28),Flows!D28>=1,OR(Flows!E28="",Flows!E28="once",Flows!E28="weekly",Flows!E28="biweekly"),OR(Flows!F28="",AND(ISNUMBER(Flows!F28),Flows!F28>=Flows!D28))),0,1))+IF(Flows!A29="",0,IF(AND(ISNUMBER(Flows!C29),Flows!C29>=0,ISNUMBER(Flows!D29),Flows!D29>=1,OR(Flows!E29="",Flows!E29="once",Flows!E29="weekly",Flows!E29="biweekly"),OR(Flows!F29="",AND(ISNUMBER(Flows!F29),Flows!F29>=Flows!D29))),0,1))+IF(Flows!A30="",0,IF(AND(ISNUMBER(Flows!C30),Flows!C30>=0,ISNUMBER(Flows!D30),Flows!D30>=1,OR(Flows!E30="",Flows!E30="once",Flows!E30="weekly",Flows!E30="biweekly"),OR(Flows!F30="",AND(ISNUMBER(Flows!F30),Flows!F30>=Flows!D30))),0,1))+IF(Flows!A31="",0,IF(AND(ISNUMBER(Flows!C31),Flows!C31>=0,ISNUMBER(Flows!D31),Flows!D31>=1,OR(Flows!E31="",Flows!E31="once",Flows!E31="weekly",Flows!E31="biweekly"),OR(Flows!F31="",AND(ISNUMBER(Flows!F31),Flows!F31>=Flows!D31))),0,1))+IF(Flows!A32="",0,IF(AND(ISNUMBER(Flows!C32),Flows!C32>=0,ISNUMBER(Flows!D32),Flows!D32>=1,OR(Flows!E32="",Flows!E32="once",Flows!E32="weekly",Flows!E32="biweekly"),OR(Flows!F32="",AND(ISNUMBER(Flows!F32),Flows!F32>=Flows!D32))),0,1))+IF(Flows!A33="",0,IF(AND(ISNUMBER(Flows!C33),Flows!C33>=0,ISNUMBER(Flows!D33),Flows!D33>=1,OR(Flows!E33="",Flows!E33="once",Flows!E33="weekly",Flows!E33="biweekly"),OR(Flows!F33="",AND(ISNUMBER(Flows!F33),Flows!F33>=Flows!D33))),0,1))+IF(Flows!A34="",0,IF(AND(ISNUMBER(Flows!C34),Flows!C34>=0,ISNUMBER(Flows!D34),Flows!D34>=1,OR(Flows!E34="",Flows!E34="once",Flows!E34="weekly",Flows!E34="biweekly"),OR(Flows!F34="",AND(ISNUMBER(Flows!F34),Flows!F34>=Flows!D34))),0,1))+IF(Flows!A35="",0,IF(AND(ISNUMBER(Flows!C35),Flows!C35>=0,ISNUMBER(Flows!D35),Flows!D35>=1,OR(Flows!E35="",Flows!E35="once",Flows!E35="weekly",Flows!E35="biweekly"),OR(Flows!F35="",AND(ISNUMBER(Flows!F35),Flows!F35>=Flows!D35))),0,1))+IF(Flows!A36="",0,IF(AND(ISNUMBER(Flows!C36),Flows!C36>=0,ISNUMBER(Flows!D36),Flows!D36>=1,OR(Flows!E36="",Flows!E36="once",Flows!E36="weekly",Flows!E36="biweekly"),OR(Flows!F36="",AND(ISNUMBER(Flows!F36),Flows!F36>=Flows!D36))),0,1))+IF(Flows!A37="",0,IF(AND(ISNUMBER(Flows!C37),Flows!C37>=0,ISNUMBER(Flows!D37),Flows!D37>=1,OR(Flows!E37="",Flows!E37="once",Flows!E37="weekly",Flows!E37="biweekly"),OR(Flows!F37="",AND(ISNUMBER(Flows!F37),Flows!F37>=Flows!D37))),0,1))+IF(Flows!A38="",0,IF(AND(ISNUMBER(Flows!C38),Flows!C38>=0,ISNUMBER(Flows!D38),Flows!D38>=1,OR(Flows!E38="",Flows!E38="once",Flows!E38="weekly",Flows!E38="biweekly"),OR(Flows!F38="",AND(ISNUMBER(Flows!F38),Flows!F38>=Flows!D38))),0,1))+IF(Flows!A39="",0,IF(AND(ISNUMBER(Flows!C39),Flows!C39>=0,ISNUMBER(Flows!D39),Flows!D39>=1,OR(Flows!E39="",Flows!E39="once",Flows!E39="weekly",Flows!E39="biweekly"),OR(Flows!F39="",AND(ISNUMBER(Flows!F39),Flows!F39>=Flows!D39))),0,1))+IF(Flows!A40="",0,IF(AND(ISNUMBER(Flows!C40),Flows!C40>=0,ISNUMBER(Flows!D40),Flows!D40>=1,OR(Flows!E40="",Flows!E40="once",Flows!E40="weekly",Flows!E40="biweekly"),OR(Flows!F40="",AND(ISNUMBER(Flows!F40),Flows!F40>=Flows!D40))),0,1))+IF(Flows!A41="",0,IF(AND(ISNUMBER(Flows!C41),Flows!C41>=0,ISNUMBER(Flows!D41),Flows!D41>=1,OR(Flows!E41="",Flows!E41="once",Flows!E41="weekly",Flows!E41="biweekly"),OR(Flows!F41="",AND(ISNUMBER(Flows!F41),Flows!F41>=Flows!D41))),0,1))+IF(Flows!A42="",0,IF(AND(ISNUMBER(Flows!C42),Flows!C42>=0,ISNUMBER(Flows!D42),Flows!D42>=1,OR(Flows!E42="",Flows!E42="once",Flows!E42="weekly",Flows!E42="biweekly"),OR(Flows!F42="",AND(ISNUMBER(Flows!F42),Flows!F42>=Flows!D42))),0,1))+IF(Flows!A43="",0,IF(AND(ISNUMBER(Flows!C43),Flows!C43>=0,ISNUMBER(Flows!D43),Flows!D43>=1,OR(Flows!E43="",Flows!E43="once",Flows!E43="weekly",Flows!E43="biweekly"),OR(Flows!F43="",AND(ISNUMBER(Flows!F43),Flows!F43>=Flows!D43))),0,1))+IF(Flows!A44="",0,IF(AND(ISNUMBER(Flows!C44),Flows!C44>=0,ISNUMBER(Flows!D44),Flows!D44>=1,OR(Flows!E44="",Flows!E44="once",Flows!E44="weekly",Flows!E44="biweekly"),OR(Flows!F44="",AND(ISNUMBER(Flows!F44),Flows!F44>=Flows!D44))),0,1))+IF(Flows!A45="",0,IF(AND(ISNUMBER(Flows!C45),Flows!C45>=0,ISNUMBER(Flows!D45),Flows!D45>=1,OR(Flows!E45="",Flows!E45="once",Flows!E45="weekly",Flows!E45="biweekly"),OR(Flows!F45="",AND(ISNUMBER(Flows!F45),Flows!F45>=Flows!D45))),0,1))+IF(Flows!A46="",0,IF(AND(ISNUMBER(Flows!C46),Flows!C46>=0,ISNUMBER(Flows!D46),Flows!D46>=1,OR(Flows!E46="",Flows!E46="once",Flows!E46="weekly",Flows!E46="biweekly"),OR(Flows!F46="",AND(ISNUMBER(Flows!F46),Flows!F46>=Flows!D46))),0,1))+IF(Flows!A47="",0,IF(AND(ISNUMBER(Flows!C47),Flows!C47>=0,ISNUMBER(Flows!D47),Flows!D47>=1,OR(Flows!E47="",Flows!E47="once",Flows!E47="weekly",Flows!E47="biweekly"),OR(Flows!F47="",AND(ISNUMBER(Flows!F47),Flows!F47>=Flows!D47))),0,1))+IF(Flows!A48="",0,IF(AND(ISNUMBER(Flows!C48),Flows!C48>=0,ISNUMBER(Flows!D48),Flows!D48>=1,OR(Flows!E48="",Flows!E48="once",Flows!E48="weekly",Flows!E48="biweekly"),OR(Flows!F48="",AND(ISNUMBER(Flows!F48),Flows!F48>=Flows!D48))),0,1))+IF(Flows!A49="",0,IF(AND(ISNUMBER(Flows!C49),Flows!C49>=0,ISNUMBER(Flows!D49),Flows!D49>=1,OR(Flows!E49="",Flows!E49="once",Flows!E49="weekly",Flows!E49="biweekly"),OR(Flows!F49="",AND(ISNUMBER(Flows!F49),Flows!F49>=Flows!D49))),0,1))+IF(Flows!A50="",0,IF(AND(ISNUMBER(Flows!C50),Flows!C50>=0,ISNUMBER(Flows!D50),Flows!D50>=1,OR(Flows!E50="",Flows!E50="once",Flows!E50="weekly",Flows!E50="biweekly"),OR(Flows!F50="",AND(ISNUMBER(Flows!F50),Flows!F50>=Flows!D50))),0,1))+IF(Flows!A51="",0,IF(AND(ISNUMBER(Flows!C51),Flows!C51>=0,ISNUMBER(Flows!D51),Flows!D51>=1,OR(Flows!E51="",Flows!E51="once",Flows!E51="weekly",Flows!E51="biweekly"),OR(Flows!F51="",AND(ISNUMBER(Flows!F51),Flows!F51>=Flows!D51))),0,1))+IF(Flows!A52="",0,IF(AND(ISNUMBER(Flows!C52),Flows!C52>=0,ISNUMBER(Flows!D52),Flows!D52>=1,OR(Flows!E52="",Flows!E52="once",Flows!E52="weekly",Flows!E52="biweekly"),OR(Flows!F52="",AND(ISNUMBER(Flows!F52),Flows!F52>=Flows!D52))),0,1))+IF(Flows!A53="",0,IF(AND(ISNUMBER(Flows!C53),Flows!C53>=0,ISNUMBER(Flows!D53),Flows!D53>=1,OR(Flows!E53="",Flows!E53="once",Flows!E53="weekly",Flows!E53="biweekly"),OR(Flows!F53="",AND(ISNUMBER(Flows!F53),Flows!F53>=Flows!D53))),0,1))+IF(Flows!A54="",0,IF(AND(ISNUMBER(Flows!C54),Flows!C54>=0,ISNUMBER(Flows!D54),Flows!D54>=1,OR(Flows!E54="",Flows!E54="once",Flows!E54="weekly",Flows!E54="biweekly"),OR(Flows!F54="",AND(ISNUMBER(Flows!F54),Flows!F54>=Flows!D54))),0,1))+IF(Flows!A55="",0,IF(AND(ISNUMBER(Flows!C55),Flows!C55>=0,ISNUMBER(Flows!D55),Flows!D55>=1,OR(Flows!E55="",Flows!E55="once",Flows!E55="weekly",Flows!E55="biweekly"),OR(Flows!F55="",AND(ISNUMBER(Flows!F55),Flows!F55>=Flows!D55))),0,1))+IF(Flows!A56="",0,IF(AND(ISNUMBER(Flows!C56),Flows!C56>=0,ISNUMBER(Flows!D56),Flows!D56>=1,OR(Flows!E56="",Flows!E56="once",Flows!E56="weekly",Flows!E56="biweekly"),OR(Flows!F56="",AND(ISNUMBER(Flows!F56),Flows!F56>=Flows!D56))),0,1))+IF(Flows!A57="",0,IF(AND(ISNUMBER(Flows!C57),Flows!C57>=0,ISNUMBER(Flows!D57),Flows!D57>=1,OR(Flows!E57="",Flows!E57="once",Flows!E57="weekly",Flows!E57="biweekly"),OR(Flows!F57="",AND(ISNUMBER(Flows!F57),Flows!F57>=Flows!D57))),0,1))+IF(Flows!A58="",0,IF(AND(ISNUMBER(Flows!C58),Flows!C58>=0,ISNUMBER(Flows!D58),Flows!D58>=1,OR(Flows!E58="",Flows!E58="once",Flows!E58="weekly",Flows!E58="biweekly"),OR(Flows!F58="",AND(ISNUMBER(Flows!F58),Flows!F58>=Flows!D58))),0,1))+IF(Flows!A59="",0,IF(AND(ISNUMBER(Flows!C59),Flows!C59>=0,ISNUMBER(Flows!D59),Flows!D59>=1,OR(Flows!E59="",Flows!E59="once",Flows!E59="weekly",Flows!E59="biweekly"),OR(Flows!F59="",AND(ISNUMBER(Flows!F59),Flows!F59>=Flows!D59))),0,1))+IF(Flows!A60="",0,IF(AND(ISNUMBER(Flows!C60),Flows!C60>=0,ISNUMBER(Flows!D60),Flows!D60>=1,OR(Flows!E60="",Flows!E60="once",Flows!E60="weekly",Flows!E60="biweekly"),OR(Flows!F60="",AND(ISNUMBER(Flows!F60),Flows!F60>=Flows!D60))),0,1))+IF(Flows!A61="",0,IF(AND(ISNUMBER(Flows!C61),Flows!C61>=0,ISNUMBER(Flows!D61),Flows!D61>=1,OR(Flows!E61="",Flows!E61="once",Flows!E61="weekly",Flows!E61="biweekly"),OR(Flows!F61="",AND(ISNUMBER(Flows!F61),Flows!F61>=Flows!D61))),0,1))+IF(Flows!A62="",0,IF(AND(ISNUMBER(Flows!C62),Flows!C62>=0,ISNUMBER(Flows!D62),Flows!D62>=1,OR(Flows!E62="",Flows!E62="once",Flows!E62="weekly",Flows!E62="biweekly"),OR(Flows!F62="",AND(ISNUMBER(Flows!F62),Flows!F62>=Flows!D62))),0,1))+IF(Flows!A63="",0,IF(AND(ISNUMBER(Flows!C63),Flows!C63>=0,ISNUMBER(Flows!D63),Flows!D63>=1,OR(Flows!E63="",Flows!E63="once",Flows!E63="weekly",Flows!E63="biweekly"),OR(Flows!F63="",AND(ISNUMBER(Flows!F63),Flows!F63>=Flows!D63))),0,1))+IF(Flows!A64="",0,IF(AND(ISNUMBER(Flows!C64),Flows!C64>=0,ISNUMBER(Flows!D64),Flows!D64>=1,OR(Flows!E64="",Flows!E64="once",Flows!E64="weekly",Flows!E64="biweekly"),OR(Flows!F64="",AND(ISNUMBER(Flows!F64),Flows!F64>=Flows!D64))),0,1))+IF(Flows!A65="",0,IF(AND(ISNUMBER(Flows!C65),Flows!C65>=0,ISNUMBER(Flows!D65),Flows!D65>=1,OR(Flows!E65="",Flows!E65="once",Flows!E65="weekly",Flows!E65="biweekly"),OR(Flows!F65="",AND(ISNUMBER(Flows!F65),Flows!F65>=Flows!D65))),0,1))+IF(Flows!A66="",0,IF(AND(ISNUMBER(Flows!C66),Flows!C66>=0,ISNUMBER(Flows!D66),Flows!D66>=1,OR(Flows!E66="",Flows!E66="once",Flows!E66="weekly",Flows!E66="biweekly"),OR(Flows!F66="",AND(ISNUMBER(Flows!F66),Flows!F66>=Flows!D66))),0,1))+IF(Flows!A67="",0,IF(AND(ISNUMBER(Flows!C67),Flows!C67>=0,ISNUMBER(Flows!D67),Flows!D67>=1,OR(Flows!E67="",Flows!E67="once",Flows!E67="weekly",Flows!E67="biweekly"),OR(Flows!F67="",AND(ISNUMBER(Flows!F67),Flows!F67>=Flows!D67))),0,1))+IF(Flows!A68="",0,IF(AND(ISNUMBER(Flows!C68),Flows!C68>=0,ISNUMBER(Flows!D68),Flows!D68>=1,OR(Flows!E68="",Flows!E68="once",Flows!E68="weekly",Flows!E68="biweekly"),OR(Flows!F68="",AND(ISNUMBER(Flows!F68),Flows!F68>=Flows!D68))),0,1))+IF(Flows!A69="",0,IF(AND(ISNUMBER(Flows!C69),Flows!C69>=0,ISNUMBER(Flows!D69),Flows!D69>=1,OR(Flows!E69="",Flows!E69="once",Flows!E69="weekly",Flows!E69="biweekly"),OR(Flows!F69="",AND(ISNUMBER(Flows!F69),Flows!F69>=Flows!D69))),0,1))+IF(Flows!A70="",0,IF(AND(ISNUMBER(Flows!C70),Flows!C70>=0,ISNUMBER(Flows!D70),Flows!D70>=1,OR(Flows!E70="",Flows!E70="once",Flows!E70="weekly",Flows!E70="biweekly"),OR(Flows!F70="",AND(ISNUMBER(Flows!F70),Flows!F70>=Flows!D70))),0,1))+IF(Flows!A71="",0,IF(AND(ISNUMBER(Flows!C71),Flows!C71>=0,ISNUMBER(Flows!D71),Flows!D71>=1,OR(Flows!E71="",Flows!E71="once",Flows!E71="weekly",Flows!E71="biweekly"),OR(Flows!F71="",AND(ISNUMBER(Flows!F71),Flows!F71>=Flows!D71))),0,1))+IF(Flows!A72="",0,IF(AND(ISNUMBER(Flows!C72),Flows!C72>=0,ISNUMBER(Flows!D72),Flows!D72>=1,OR(Flows!E72="",Flows!E72="once",Flows!E72="weekly",Flows!E72="biweekly"),OR(Flows!F72="",AND(ISNUMBER(Flows!F72),Flows!F72>=Flows!D72))),0,1))+IF(Flows!A73="",0,IF(AND(ISNUMBER(Flows!C73),Flows!C73>=0,ISNUMBER(Flows!D73),Flows!D73>=1,OR(Flows!E73="",Flows!E73="once",Flows!E73="weekly",Flows!E73="biweekly"),OR(Flows!F73="",AND(ISNUMBER(Flows!F73),Flows!F73>=Flows!D73))),0,1))+IF(Flows!A74="",0,IF(AND(ISNUMBER(Flows!C74),Flows!C74>=0,ISNUMBER(Flows!D74),Flows!D74>=1,OR(Flows!E74="",Flows!E74="once",Flows!E74="weekly",Flows!E74="biweekly"),OR(Flows!F74="",AND(ISNUMBER(Flows!F74),Flows!F74>=Flows!D74))),0,1))+IF(Flows!A75="",0,IF(AND(ISNUMBER(Flows!C75),Flows!C75>=0,ISNUMBER(Flows!D75),Flows!D75>=1,OR(Flows!E75="",Flows!E75="once",Flows!E75="weekly",Flows!E75="biweekly"),OR(Flows!F75="",AND(ISNUMBER(Flows!F75),Flows!F75>=Flows!D75))),0,1))+IF(Flows!A76="",0,IF(AND(ISNUMBER(Flows!C76),Flows!C76>=0,ISNUMBER(Flows!D76),Flows!D76>=1,OR(Flows!E76="",Flows!E76="once",Flows!E76="weekly",Flows!E76="biweekly"),OR(Flows!F76="",AND(ISNUMBER(Flows!F76),Flows!F76>=Flows!D76))),0,1))+IF(Flows!A77="",0,IF(AND(ISNUMBER(Flows!C77),Flows!C77>=0,ISNUMBER(Flows!D77),Flows!D77>=1,OR(Flows!E77="",Flows!E77="once",Flows!E77="weekly",Flows!E77="biweekly"),OR(Flows!F77="",AND(ISNUMBER(Flows!F77),Flows!F77>=Flows!D77))),0,1))+IF(Flows!A78="",0,IF(AND(ISNUMBER(Flows!C78),Flows!C78>=0,ISNUMBER(Flows!D78),Flows!D78>=1,OR(Flows!E78="",Flows!E78="once",Flows!E78="weekly",Flows!E78="biweekly"),OR(Flows!F78="",AND(ISNUMBER(Flows!F78),Flows!F78>=Flows!D78))),0,1))+IF(Flows!A79="",0,IF(AND(ISNUMBER(Flows!C79),Flows!C79>=0,ISNUMBER(Flows!D79),Flows!D79>=1,OR(Flows!E79="",Flows!E79="once",Flows!E79="weekly",Flows!E79="biweekly"),OR(Flows!F79="",AND(ISNUMBER(Flows!F79),Flows!F79>=Flows!D79))),0,1))+IF(Flows!A80="",0,IF(AND(ISNUMBER(Flows!C80),Flows!C80>=0,ISNUMBER(Flows!D80),Flows!D80>=1,OR(Flows!E80="",Flows!E80="once",Flows!E80="weekly",Flows!E80="biweekly"),OR(Flows!F80="",AND(ISNUMBER(Flows!F80),Flows!F80>=Flows!D80))),0,1))+IF(Flows!A81="",0,IF(AND(ISNUMBER(Flows!C81),Flows!C81>=0,ISNUMBER(Flows!D81),Flows!D81>=1,OR(Flows!E81="",Flows!E81="once",Flows!E81="weekly",Flows!E81="biweekly"),OR(Flows!F81="",AND(ISNUMBER(Flows!F81),Flows!F81>=Flows!D81))),0,1))+IF(Flows!A82="",0,IF(AND(ISNUMBER(Flows!C82),Flows!C82>=0,ISNUMBER(Flows!D82),Flows!D82>=1,OR(Flows!E82="",Flows!E82="once",Flows!E82="weekly",Flows!E82="biweekly"),OR(Flows!F82="",AND(ISNUMBER(Flows!F82),Flows!F82>=Flows!D82))),0,1))+IF(Flows!A83="",0,IF(AND(ISNUMBER(Flows!C83),Flows!C83>=0,ISNUMBER(Flows!D83),Flows!D83>=1,OR(Flows!E83="",Flows!E83="once",Flows!E83="weekly",Flows!E83="biweekly"),OR(Flows!F83="",AND(ISNUMBER(Flows!F83),Flows!F83>=Flows!D83))),0,1))+IF(Flows!A84="",0,IF(AND(ISNUMBER(Flows!C84),Flows!C84>=0,ISNUMBER(Flows!D84),Flows!D84>=1,OR(Flows!E84="",Flows!E84="once",Flows!E84="weekly",Flows!E84="biweekly"),OR(Flows!F84="",AND(ISNUMBER(Flows!F84),Flows!F84>=Flows!D84))),0,1)))=0,"PASS","FAIL") | D8: =(IF(Flows!A5="",0,IF(AND(ISNUMBER(Flows!C5),Flows!C5>=0,ISNUMBER(Flows!D5),Flows!D5>=1,OR(Flows!E5="",Flows!E5="once",Flows!E5="weekly",Flows!E5="biweekly"),OR(Flows!F5="",AND(ISNUMBER(Flows!F5),Flows!F5>=Flows!D5))),0,1))+IF(Flows!A6="",0,IF(AND(ISNUMBER(Flows!C6),Flows!C6>=0,ISNUMBER(Flows!D6),Flows!D6>=1,OR(Flows!E6="",Flows!E6="once",Flows!E6="weekly",Flows!E6="biweekly"),OR(Flows!F6="",AND(ISNUMBER(Flows!F6),Flows!F6>=Flows!D6))),0,1))+IF(Flows!A7="",0,IF(AND(ISNUMBER(Flows!C7),Flows!C7>=0,ISNUMBER(Flows!D7),Flows!D7>=1,OR(Flows!E7="",Flows!E7="once",Flows!E7="weekly",Flows!E7="biweekly"),OR(Flows!F7="",AND(ISNUMBER(Flows!F7),Flows!F7>=Flows!D7))),0,1))+IF(Flows!A8="",0,IF(AND(ISNUMBER(Flows!C8),Flows!C8>=0,ISNUMBER(Flows!D8),Flows!D8>=1,OR(Flows!E8="",Flows!E8="once",Flows!E8="weekly",Flows!E8="biweekly"),OR(Flows!F8="",AND(ISNUMBER(Flows!F8),Flows!F8>=Flows!D8))),0,1))+IF(Flows!A9="",0,IF(AND(ISNUMBER(Flows!C9),Flows!C9>=0,ISNUMBER(Flows!D9),Flows!D9>=1,OR(Flows!E9="",Flows!E9="once",Flows!E9="weekly",Flows!E9="biweekly"),OR(Flows!F9="",AND(ISNUMBER(Flows!F9),Flows!F9>=Flows!D9))),0,1))+IF(Flows!A10="",0,IF(AND(ISNUMBER(Flows!C10),Flows!C10>=0,ISNUMBER(Flows!D10),Flows!D10>=1,OR(Flows!E10="",Flows!E10="once",Flows!E10="weekly",Flows!E10="biweekly"),OR(Flows!F10="",AND(ISNUMBER(Flows!F10),Flows!F10>=Flows!D10))),0,1))+IF(Flows!A11="",0,IF(AND(ISNUMBER(Flows!C11),Flows!C11>=0,ISNUMBER(Flows!D11),Flows!D11>=1,OR(Flows!E11="",Flows!E11="once",Flows!E11="weekly",Flows!E11="biweekly"),OR(Flows!F11="",AND(ISNUMBER(Flows!F11),Flows!F11>=Flows!D11))),0,1))+IF(Flows!A12="",0,IF(AND(ISNUMBER(Flows!C12),Flows!C12>=0,ISNUMBER(Flows!D12),Flows!D12>=1,OR(Flows!E12="",Flows!E12="once",Flows!E12="weekly",Flows!E12="biweekly"),OR(Flows!F12="",AND(ISNUMBER(Flows!F12),Flows!F12>=Flows!D12))),0,1))+IF(Flows!A13="",0,IF(AND(ISNUMBER(Flows!C13),Flows!C13>=0,ISNUMBER(Flows!D13),Flows!D13>=1,OR(Flows!E13="",Flows!E13="once",Flows!E13="weekly",Flows!E13="biweekly"),OR(Flows!F13="",AND(ISNUMBER(Flows!F13),Flows!F13>=Flows!D13))),0,1))+IF(Flows!A14="",0,IF(AND(ISNUMBER(Flows!C14),Flows!C14>=0,ISNUMBER(Flows!D14),Flows!D14>=1,OR(Flows!E14="",Flows!E14="once",Flows!E14="weekly",Flows!E14="biweekly"),OR(Flows!F14="",AND(ISNUMBER(Flows!F14),Flows!F14>=Flows!D14))),0,1))+IF(Flows!A15="",0,IF(AND(ISNUMBER(Flows!C15),Flows!C15>=0,ISNUMBER(Flows!D15),Flows!D15>=1,OR(Flows!E15="",Flows!E15="once",Flows!E15="weekly",Flows!E15="biweekly"),OR(Flows!F15="",AND(ISNUMBER(Flows!F15),Flows!F15>=Flows!D15))),0,1))+IF(Flows!A16="",0,IF(AND(ISNUMBER(Flows!C16),Flows!C16>=0,ISNUMBER(Flows!D16),Flows!D16>=1,OR(Flows!E16="",Flows!E16="once",Flows!E16="weekly",Flows!E16="biweekly"),OR(Flows!F16="",AND(ISNUMBER(Flows!F16),Flows!F16>=Flows!D16))),0,1))+IF(Flows!A17="",0,IF(AND(ISNUMBER(Flows!C17),Flows!C17>=0,ISNUMBER(Flows!D17),Flows!D17>=1,OR(Flows!E17="",Flows!E17="once",Flows!E17="weekly",Flows!E17="biweekly"),OR(Flows!F17="",AND(ISNUMBER(Flows!F17),Flows!F17>=Flows!D17))),0,1))+IF(Flows!A18="",0,IF(AND(ISNUMBER(Flows!C18),Flows!C18>=0,ISNUMBER(Flows!D18),Flows!D18>=1,OR(Flows!E18="",Flows!E18="once",Flows!E18="weekly",Flows!E18="biweekly"),OR(Flows!F18="",AND(ISNUMBER(Flows!F18),Flows!F18>=Flows!D18))),0,1))+IF(Flows!A19="",0,IF(AND(ISNUMBER(Flows!C19),Flows!C19>=0,ISNUMBER(Flows!D19),Flows!D19>=1,OR(Flows!E19="",Flows!E19="once",Flows!E19="weekly",Flows!E19="biweekly"),OR(Flows!F19="",AND(ISNUMBER(Flows!F19),Flows!F19>=Flows!D19))),0,1))+IF(Flows!A20="",0,IF(AND(ISNUMBER(Flows!C20),Flows!C20>=0,ISNUMBER(Flows!D20),Flows!D20>=1,OR(Flows!E20="",Flows!E20="once",Flows!E20="weekly",Flows!E20="biweekly"),OR(Flows!F20="",AND(ISNUMBER(Flows!F20),Flows!F20>=Flows!D20))),0,1))+IF(Flows!A21="",0,IF(AND(ISNUMBER(Flows!C21),Flows!C21>=0,ISNUMBER(Flows!D21),Flows!D21>=1,OR(Flows!E21="",Flows!E21="once",Flows!E21="weekly",Flows!E21="biweekly"),OR(Flows!F21="",AND(ISNUMBER(Flows!F21),Flows!F21>=Flows!D21))),0,1))+IF(Flows!A22="",0,IF(AND(ISNUMBER(Flows!C22),Flows!C22>=0,ISNUMBER(Flows!D22),Flows!D22>=1,OR(Flows!E22="",Flows!E22="once",Flows!E22="weekly",Flows!E22="biweekly"),OR(Flows!F22="",AND(ISNUMBER(Flows!F22),Flows!F22>=Flows!D22))),0,1))+IF(Flows!A23="",0,IF(AND(ISNUMBER(Flows!C23),Flows!C23>=0,ISNUMBER(Flows!D23),Flows!D23>=1,OR(Flows!E23="",Flows!E23="once",Flows!E23="weekly",Flows!E23="biweekly"),OR(Flows!F23="",AND(ISNUMBER(Flows!F23),Flows!F23>=Flows!D23))),0,1))+IF(Flows!A24="",0,IF(AND(ISNUMBER(Flows!C24),Flows!C24>=0,ISNUMBER(Flows!D24),Flows!D24>=1,OR(Flows!E24="",Flows!E24="once",Flows!E24="weekly",Flows!E24="biweekly"),OR(Flows!F24="",AND(ISNUMBER(Flows!F24),Flows!F24>=Flows!D24))),0,1))+IF(Flows!A25="",0,IF(AND(ISNUMBER(Flows!C25),Flows!C25>=0,ISNUMBER(Flows!D25),Flows!D25>=1,OR(Flows!E25="",Flows!E25="once",Flows!E25="weekly",Flows!E25="biweekly"),OR(Flows!F25="",AND(ISNUMBER(Flows!F25),Flows!F25>=Flows!D25))),0,1))+IF(Flows!A26="",0,IF(AND(ISNUMBER(Flows!C26),Flows!C26>=0,ISNUMBER(Flows!D26),Flows!D26>=1,OR(Flows!E26="",Flows!E26="once",Flows!E26="weekly",Flows!E26="biweekly"),OR(Flows!F26="",AND(ISNUMBER(Flows!F26),Flows!F26>=Flows!D26))),0,1))+IF(Flows!A27="",0,IF(AND(ISNUMBER(Flows!C27),Flows!C27>=0,ISNUMBER(Flows!D27),Flows!D27>=1,OR(Flows!E27="",Flows!E27="once",Flows!E27="weekly",Flows!E27="biweekly"),OR(Flows!F27="",AND(ISNUMBER(Flows!F27),Flows!F27>=Flows!D27))),0,1))+IF(Flows!A28="",0,IF(AND(ISNUMBER(Flows!C28),Flows!C28>=0,ISNUMBER(Flows!D28),Flows!D28>=1,OR(Flows!E28="",Flows!E28="once",Flows!E28="weekly",Flows!E28="biweekly"),OR(Flows!F28="",AND(ISNUMBER(Flows!F28),Flows!F28>=Flows!D28))),0,1))+IF(Flows!A29="",0,IF(AND(ISNUMBER(Flows!C29),Flows!C29>=0,ISNUMBER(Flows!D29),Flows!D29>=1,OR(Flows!E29="",Flows!E29="once",Flows!E29="weekly",Flows!E29="biweekly"),OR(Flows!F29="",AND(ISNUMBER(Flows!F29),Flows!F29>=Flows!D29))),0,1))+IF(Flows!A30="",0,IF(AND(ISNUMBER(Flows!C30),Flows!C30>=0,ISNUMBER(Flows!D30),Flows!D30>=1,OR(Flows!E30="",Flows!E30="once",Flows!E30="weekly",Flows!E30="biweekly"),OR(Flows!F30="",AND(ISNUMBER(Flows!F30),Flows!F30>=Flows!D30))),0,1))+IF(Flows!A31="",0,IF(AND(ISNUMBER(Flows!C31),Flows!C31>=0,ISNUMBER(Flows!D31),Flows!D31>=1,OR(Flows!E31="",Flows!E31="once",Flows!E31="weekly",Flows!E31="biweekly"),OR(Flows!F31="",AND(ISNUMBER(Flows!F31),Flows!F31>=Flows!D31))),0,1))+IF(Flows!A32="",0,IF(AND(ISNUMBER(Flows!C32),Flows!C32>=0,ISNUMBER(Flows!D32),Flows!D32>=1,OR(Flows!E32="",Flows!E32="once",Flows!E32="weekly",Flows!E32="biweekly"),OR(Flows!F32="",AND(ISNUMBER(Flows!F32),Flows!F32>=Flows!D32))),0,1))+IF(Flows!A33="",0,IF(AND(ISNUMBER(Flows!C33),Flows!C33>=0,ISNUMBER(Flows!D33),Flows!D33>=1,OR(Flows!E33="",Flows!E33="once",Flows!E33="weekly",Flows!E33="biweekly"),OR(Flows!F33="",AND(ISNUMBER(Flows!F33),Flows!F33>=Flows!D33))),0,1))+IF(Flows!A34="",0,IF(AND(ISNUMBER(Flows!C34),Flows!C34>=0,ISNUMBER(Flows!D34),Flows!D34>=1,OR(Flows!E34="",Flows!E34="once",Flows!E34="weekly",Flows!E34="biweekly"),OR(Flows!F34="",AND(ISNUMBER(Flows!F34),Flows!F34>=Flows!D34))),0,1))+IF(Flows!A35="",0,IF(AND(ISNUMBER(Flows!C35),Flows!C35>=0,ISNUMBER(Flows!D35),Flows!D35>=1,OR(Flows!E35="",Flows!E35="once",Flows!E35="weekly",Flows!E35="biweekly"),OR(Flows!F35="",AND(ISNUMBER(Flows!F35),Flows!F35>=Flows!D35))),0,1))+IF(Flows!A36="",0,IF(AND(ISNUMBER(Flows!C36),Flows!C36>=0,ISNUMBER(Flows!D36),Flows!D36>=1,OR(Flows!E36="",Flows!E36="once",Flows!E36="weekly",Flows!E36="biweekly"),OR(Flows!F36="",AND(ISNUMBER(Flows!F36),Flows!F36>=Flows!D36))),0,1))+IF(Flows!A37="",0,IF(AND(ISNUMBER(Flows!C37),Flows!C37>=0,ISNUMBER(Flows!D37),Flows!D37>=1,OR(Flows!E37="",Flows!E37="once",Flows!E37="weekly",Flows!E37="biweekly"),OR(Flows!F37="",AND(ISNUMBER(Flows!F37),Flows!F37>=Flows!D37))),0,1))+IF(Flows!A38="",0,IF(AND(ISNUMBER(Flows!C38),Flows!C38>=0,ISNUMBER(Flows!D38),Flows!D38>=1,OR(Flows!E38="",Flows!E38="once",Flows!E38="weekly",Flows!E38="biweekly"),OR(Flows!F38="",AND(ISNUMBER(Flows!F38),Flows!F38>=Flows!D38))),0,1))+IF(Flows!A39="",0,IF(AND(ISNUMBER(Flows!C39),Flows!C39>=0,ISNUMBER(Flows!D39),Flows!D39>=1,OR(Flows!E39="",Flows!E39="once",Flows!E39="weekly",Flows!E39="biweekly"),OR(Flows!F39="",AND(ISNUMBER(Flows!F39),Flows!F39>=Flows!D39))),0,1))+IF(Flows!A40="",0,IF(AND(ISNUMBER(Flows!C40),Flows!C40>=0,ISNUMBER(Flows!D40),Flows!D40>=1,OR(Flows!E40="",Flows!E40="once",Flows!E40="weekly",Flows!E40="biweekly"),OR(Flows!F40="",AND(ISNUMBER(Flows!F40),Flows!F40>=Flows!D40))),0,1))+IF(Flows!A41="",0,IF(AND(ISNUMBER(Flows!C41),Flows!C41>=0,ISNUMBER(Flows!D41),Flows!D41>=1,OR(Flows!E41="",Flows!E41="once",Flows!E41="weekly",Flows!E41="biweekly"),OR(Flows!F41="",AND(ISNUMBER(Flows!F41),Flows!F41>=Flows!D41))),0,1))+IF(Flows!A42="",0,IF(AND(ISNUMBER(Flows!C42),Flows!C42>=0,ISNUMBER(Flows!D42),Flows!D42>=1,OR(Flows!E42="",Flows!E42="once",Flows!E42="weekly",Flows!E42="biweekly"),OR(Flows!F42="",AND(ISNUMBER(Flows!F42),Flows!F42>=Flows!D42))),0,1))+IF(Flows!A43="",0,IF(AND(ISNUMBER(Flows!C43),Flows!C43>=0,ISNUMBER(Flows!D43),Flows!D43>=1,OR(Flows!E43="",Flows!E43="once",Flows!E43="weekly",Flows!E43="biweekly"),OR(Flows!F43="",AND(ISNUMBER(Flows!F43),Flows!F43>=Flows!D43))),0,1))+IF(Flows!A44="",0,IF(AND(ISNUMBER(Flows!C44),Flows!C44>=0,ISNUMBER(Flows!D44),Flows!D44>=1,OR(Flows!E44="",Flows!E44="once",Flows!E44="weekly",Flows!E44="biweekly"),OR(Flows!F44="",AND(ISNUMBER(Flows!F44),Flows!F44>=Flows!D44))),0,1))+IF(Flows!A45="",0,IF(AND(ISNUMBER(Flows!C45),Flows!C45>=0,ISNUMBER(Flows!D45),Flows!D45>=1,OR(Flows!E45="",Flows!E45="once",Flows!E45="weekly",Flows!E45="biweekly"),OR(Flows!F45="",AND(ISNUMBER(Flows!F45),Flows!F45>=Flows!D45))),0,1))+IF(Flows!A46="",0,IF(AND(ISNUMBER(Flows!C46),Flows!C46>=0,ISNUMBER(Flows!D46),Flows!D46>=1,OR(Flows!E46="",Flows!E46="once",Flows!E46="weekly",Flows!E46="biweekly"),OR(Flows!F46="",AND(ISNUMBER(Flows!F46),Flows!F46>=Flows!D46))),0,1))+IF(Flows!A47="",0,IF(AND(ISNUMBER(Flows!C47),Flows!C47>=0,ISNUMBER(Flows!D47),Flows!D47>=1,OR(Flows!E47="",Flows!E47="once",Flows!E47="weekly",Flows!E47="biweekly"),OR(Flows!F47="",AND(ISNUMBER(Flows!F47),Flows!F47>=Flows!D47))),0,1))+IF(Flows!A48="",0,IF(AND(ISNUMBER(Flows!C48),Flows!C48>=0,ISNUMBER(Flows!D48),Flows!D48>=1,OR(Flows!E48="",Flows!E48="once",Flows!E48="weekly",Flows!E48="biweekly"),OR(Flows!F48="",AND(ISNUMBER(Flows!F48),Flows!F48>=Flows!D48))),0,1))+IF(Flows!A49="",0,IF(AND(ISNUMBER(Flows!C49),Flows!C49>=0,ISNUMBER(Flows!D49),Flows!D49>=1,OR(Flows!E49="",Flows!E49="once",Flows!E49="weekly",Flows!E49="biweekly"),OR(Flows!F49="",AND(ISNUMBER(Flows!F49),Flows!F49>=Flows!D49))),0,1))+IF(Flows!A50="",0,IF(AND(ISNUMBER(Flows!C50),Flows!C50>=0,ISNUMBER(Flows!D50),Flows!D50>=1,OR(Flows!E50="",Flows!E50="once",Flows!E50="weekly",Flows!E50="biweekly"),OR(Flows!F50="",AND(ISNUMBER(Flows!F50),Flows!F50>=Flows!D50))),0,1))+IF(Flows!A51="",0,IF(AND(ISNUMBER(Flows!C51),Flows!C51>=0,ISNUMBER(Flows!D51),Flows!D51>=1,OR(Flows!E51="",Flows!E51="once",Flows!E51="weekly",Flows!E51="biweekly"),OR(Flows!F51="",AND(ISNUMBER(Flows!F51),Flows!F51>=Flows!D51))),0,1))+IF(Flows!A52="",0,IF(AND(ISNUMBER(Flows!C52),Flows!C52>=0,ISNUMBER(Flows!D52),Flows!D52>=1,OR(Flows!E52="",Flows!E52="once",Flows!E52="weekly",Flows!E52="biweekly"),OR(Flows!F52="",AND(ISNUMBER(Flows!F52),Flows!F52>=Flows!D52))),0,1))+IF(Flows!A53="",0,IF(AND(ISNUMBER(Flows!C53),Flows!C53>=0,ISNUMBER(Flows!D53),Flows!D53>=1,OR(Flows!E53="",Flows!E53="once",Flows!E53="weekly",Flows!E53="biweekly"),OR(Flows!F53="",AND(ISNUMBER(Flows!F53),Flows!F53>=Flows!D53))),0,1))+IF(Flows!A54="",0,IF(AND(ISNUMBER(Flows!C54),Flows!C54>=0,ISNUMBER(Flows!D54),Flows!D54>=1,OR(Flows!E54="",Flows!E54="once",Flows!E54="weekly",Flows!E54="biweekly"),OR(Flows!F54="",AND(ISNUMBER(Flows!F54),Flows!F54>=Flows!D54))),0,1))+IF(Flows!A55="",0,IF(AND(ISNUMBER(Flows!C55),Flows!C55>=0,ISNUMBER(Flows!D55),Flows!D55>=1,OR(Flows!E55="",Flows!E55="once",Flows!E55="weekly",Flows!E55="biweekly"),OR(Flows!F55="",AND(ISNUMBER(Flows!F55),Flows!F55>=Flows!D55))),0,1))+IF(Flows!A56="",0,IF(AND(ISNUMBER(Flows!C56),Flows!C56>=0,ISNUMBER(Flows!D56),Flows!D56>=1,OR(Flows!E56="",Flows!E56="once",Flows!E56="weekly",Flows!E56="biweekly"),OR(Flows!F56="",AND(ISNUMBER(Flows!F56),Flows!F56>=Flows!D56))),0,1))+IF(Flows!A57="",0,IF(AND(ISNUMBER(Flows!C57),Flows!C57>=0,ISNUMBER(Flows!D57),Flows!D57>=1,OR(Flows!E57="",Flows!E57="once",Flows!E57="weekly",Flows!E57="biweekly"),OR(Flows!F57="",AND(ISNUMBER(Flows!F57),Flows!F57>=Flows!D57))),0,1))+IF(Flows!A58="",0,IF(AND(ISNUMBER(Flows!C58),Flows!C58>=0,ISNUMBER(Flows!D58),Flows!D58>=1,OR(Flows!E58="",Flows!E58="once",Flows!E58="weekly",Flows!E58="biweekly"),OR(Flows!F58="",AND(ISNUMBER(Flows!F58),Flows!F58>=Flows!D58))),0,1))+IF(Flows!A59="",0,IF(AND(ISNUMBER(Flows!C59),Flows!C59>=0,ISNUMBER(Flows!D59),Flows!D59>=1,OR(Flows!E59="",Flows!E59="once",Flows!E59="weekly",Flows!E59="biweekly"),OR(Flows!F59="",AND(ISNUMBER(Flows!F59),Flows!F59>=Flows!D59))),0,1))+IF(Flows!A60="",0,IF(AND(ISNUMBER(Flows!C60),Flows!C60>=0,ISNUMBER(Flows!D60),Flows!D60>=1,OR(Flows!E60="",Flows!E60="once",Flows!E60="weekly",Flows!E60="biweekly"),OR(Flows!F60="",AND(ISNUMBER(Flows!F60),Flows!F60>=Flows!D60))),0,1))+IF(Flows!A61="",0,IF(AND(ISNUMBER(Flows!C61),Flows!C61>=0,ISNUMBER(Flows!D61),Flows!D61>=1,OR(Flows!E61="",Flows!E61="once",Flows!E61="weekly",Flows!E61="biweekly"),OR(Flows!F61="",AND(ISNUMBER(Flows!F61),Flows!F61>=Flows!D61))),0,1))+IF(Flows!A62="",0,IF(AND(ISNUMBER(Flows!C62),Flows!C62>=0,ISNUMBER(Flows!D62),Flows!D62>=1,OR(Flows!E62="",Flows!E62="once",Flows!E62="weekly",Flows!E62="biweekly"),OR(Flows!F62="",AND(ISNUMBER(Flows!F62),Flows!F62>=Flows!D62))),0,1))+IF(Flows!A63="",0,IF(AND(ISNUMBER(Flows!C63),Flows!C63>=0,ISNUMBER(Flows!D63),Flows!D63>=1,OR(Flows!E63="",Flows!E63="once",Flows!E63="weekly",Flows!E63="biweekly"),OR(Flows!F63="",AND(ISNUMBER(Flows!F63),Flows!F63>=Flows!D63))),0,1))+IF(Flows!A64="",0,IF(AND(ISNUMBER(Flows!C64),Flows!C64>=0,ISNUMBER(Flows!D64),Flows!D64>=1,OR(Flows!E64="",Flows!E64="once",Flows!E64="weekly",Flows!E64="biweekly"),OR(Flows!F64="",AND(ISNUMBER(Flows!F64),Flows!F64>=Flows!D64))),0,1))+IF(Flows!A65="",0,IF(AND(ISNUMBER(Flows!C65),Flows!C65>=0,ISNUMBER(Flows!D65),Flows!D65>=1,OR(Flows!E65="",Flows!E65="once",Flows!E65="weekly",Flows!E65="biweekly"),OR(Flows!F65="",AND(ISNUMBER(Flows!F65),Flows!F65>=Flows!D65))),0,1))+IF(Flows!A66="",0,IF(AND(ISNUMBER(Flows!C66),Flows!C66>=0,ISNUMBER(Flows!D66),Flows!D66>=1,OR(Flows!E66="",Flows!E66="once",Flows!E66="weekly",Flows!E66="biweekly"),OR(Flows!F66="",AND(ISNUMBER(Flows!F66),Flows!F66>=Flows!D66))),0,1))+IF(Flows!A67="",0,IF(AND(ISNUMBER(Flows!C67),Flows!C67>=0,ISNUMBER(Flows!D67),Flows!D67>=1,OR(Flows!E67="",Flows!E67="once",Flows!E67="weekly",Flows!E67="biweekly"),OR(Flows!F67="",AND(ISNUMBER(Flows!F67),Flows!F67>=Flows!D67))),0,1))+IF(Flows!A68="",0,IF(AND(ISNUMBER(Flows!C68),Flows!C68>=0,ISNUMBER(Flows!D68),Flows!D68>=1,OR(Flows!E68="",Flows!E68="once",Flows!E68="weekly",Flows!E68="biweekly"),OR(Flows!F68="",AND(ISNUMBER(Flows!F68),Flows!F68>=Flows!D68))),0,1))+IF(Flows!A69="",0,IF(AND(ISNUMBER(Flows!C69),Flows!C69>=0,ISNUMBER(Flows!D69),Flows!D69>=1,OR(Flows!E69="",Flows!E69="once",Flows!E69="weekly",Flows!E69="biweekly"),OR(Flows!F69="",AND(ISNUMBER(Flows!F69),Flows!F69>=Flows!D69))),0,1))+IF(Flows!A70="",0,IF(AND(ISNUMBER(Flows!C70),Flows!C70>=0,ISNUMBER(Flows!D70),Flows!D70>=1,OR(Flows!E70="",Flows!E70="once",Flows!E70="weekly",Flows!E70="biweekly"),OR(Flows!F70="",AND(ISNUMBER(Flows!F70),Flows!F70>=Flows!D70))),0,1))+IF(Flows!A71="",0,IF(AND(ISNUMBER(Flows!C71),Flows!C71>=0,ISNUMBER(Flows!D71),Flows!D71>=1,OR(Flows!E71="",Flows!E71="once",Flows!E71="weekly",Flows!E71="biweekly"),OR(Flows!F71="",AND(ISNUMBER(Flows!F71),Flows!F71>=Flows!D71))),0,1))+IF(Flows!A72="",0,IF(AND(ISNUMBER(Flows!C72),Flows!C72>=0,ISNUMBER(Flows!D72),Flows!D72>=1,OR(Flows!E72="",Flows!E72="once",Flows!E72="weekly",Flows!E72="biweekly"),OR(Flows!F72="",AND(ISNUMBER(Flows!F72),Flows!F72>=Flows!D72))),0,1))+IF(Flows!A73="",0,IF(AND(ISNUMBER(Flows!C73),Flows!C73>=0,ISNUMBER(Flows!D73),Flows!D73>=1,OR(Flows!E73="",Flows!E73="once",Flows!E73="weekly",Flows!E73="biweekly"),OR(Flows!F73="",AND(ISNUMBER(Flows!F73),Flows!F73>=Flows!D73))),0,1))+IF(Flows!A74="",0,IF(AND(ISNUMBER(Flows!C74),Flows!C74>=0,ISNUMBER(Flows!D74),Flows!D74>=1,OR(Flows!E74="",Flows!E74="once",Flows!E74="weekly",Flows!E74="biweekly"),OR(Flows!F74="",AND(ISNUMBER(Flows!F74),Flows!F74>=Flows!D74))),0,1))+IF(Flows!A75="",0,IF(AND(ISNUMBER(Flows!C75),Flows!C75>=0,ISNUMBER(Flows!D75),Flows!D75>=1,OR(Flows!E75="",Flows!E75="once",Flows!E75="weekly",Flows!E75="biweekly"),OR(Flows!F75="",AND(ISNUMBER(Flows!F75),Flows!F75>=Flows!D75))),0,1))+IF(Flows!A76="",0,IF(AND(ISNUMBER(Flows!C76),Flows!C76>=0,ISNUMBER(Flows!D76),Flows!D76>=1,OR(Flows!E76="",Flows!E76="once",Flows!E76="weekly",Flows!E76="biweekly"),OR(Flows!F76="",AND(ISNUMBER(Flows!F76),Flows!F76>=Flows!D76))),0,1))+IF(Flows!A77="",0,IF(AND(ISNUMBER(Flows!C77),Flows!C77>=0,ISNUMBER(Flows!D77),Flows!D77>=1,OR(Flows!E77="",Flows!E77="once",Flows!E77="weekly",Flows!E77="biweekly"),OR(Flows!F77="",AND(ISNUMBER(Flows!F77),Flows!F77>=Flows!D77))),0,1))+IF(Flows!A78="",0,IF(AND(ISNUMBER(Flows!C78),Flows!C78>=0,ISNUMBER(Flows!D78),Flows!D78>=1,OR(Flows!E78="",Flows!E78="once",Flows!E78="weekly",Flows!E78="biweekly"),OR(Flows!F78="",AND(ISNUMBER(Flows!F78),Flows!F78>=Flows!D78))),0,1))+IF(Flows!A79="",0,IF(AND(ISNUMBER(Flows!C79),Flows!C79>=0,ISNUMBER(Flows!D79),Flows!D79>=1,OR(Flows!E79="",Flows!E79="once",Flows!E79="weekly",Flows!E79="biweekly"),OR(Flows!F79="",AND(ISNUMBER(Flows!F79),Flows!F79>=Flows!D79))),0,1))+IF(Flows!A80="",0,IF(AND(ISNUMBER(Flows!C80),Flows!C80>=0,ISNUMBER(Flows!D80),Flows!D80>=1,OR(Flows!E80="",Flows!E80="once",Flows!E80="weekly",Flows!E80="biweekly"),OR(Flows!F80="",AND(ISNUMBER(Flows!F80),Flows!F80>=Flows!D80))),0,1))+IF(Flows!A81="",0,IF(AND(ISNUMBER(Flows!C81),Flows!C81>=0,ISNUMBER(Flows!D81),Flows!D81>=1,OR(Flows!E81="",Flows!E81="once",Flows!E81="weekly",Flows!E81="biweekly"),OR(Flows!F81="",AND(ISNUMBER(Flows!F81),Flows!F81>=Flows!D81))),0,1))+IF(Flows!A82="",0,IF(AND(ISNUMBER(Flows!C82),Flows!C82>=0,ISNUMBER(Flows!D82),Flows!D82>=1,OR(Flows!E82="",Flows!E82="once",Flows!E82="weekly",Flows!E82="biweekly"),OR(Flows!F82="",AND(ISNUMBER(Flows!F82),Flows!F82>=Flows!D82))),0,1))+IF(Flows!A83="",0,IF(AND(ISNUMBER(Flows!C83),Flows!C83>=0,ISNUMBER(Flows!D83),Flows!D83>=1,OR(Flows!E83="",Flows!E83="once",Flows!E83="weekly",Flows!E83="biweekly"),OR(Flows!F83="",AND(ISNUMBER(Flows!F83),Flows!F83>=Flows!D83))),0,1))+IF(Flows!A84="",0,IF(AND(ISNUMBER(Flows!C84),Flows!C84>=0,ISNUMBER(Flows!D84),Flows!D84>=1,OR(Flows!E84="",Flows!E84="once",Flows!E84="weekly",Flows!E84="biweekly"),OR(Flows!F84="",AND(ISNUMBER(Flows!F84),Flows!F84>=Flows!D84))),0,1)))&" bad rows"
A9: 5 | B9: ending cash roll-forward = opening + sum(net) | C9: =IF(ABS(Runway!B8-(Setup!$B$4+SUMPRODUCT(Weekly!E5:E56*Weekly!G5:G56)))<0.005,"PASS","FAIL")
A10: 6 | B10: receipts + disbursements in grid = weekly totals | C10: =IF(ABS(SUM(Weekly!C5:D56)-SUM(Grid!F4:BE83))<0.005,"PASS","FAIL")
A11: 7 | B11: GOLDEN parity with original openfpa: min_cash = -146000 | C11: =IF(ABS(Runway!$B$4-(-146000))<0.005,"PASS","FAIL") | D11: =Runway!$B$4
A12: 8 | B12: GOLDEN parity with original openfpa: min_week = 7 | C12: =IF(ABS(Runway!$B$5-(7))<0.005,"PASS","FAIL") | D12: =Runway!$B$5
A13: 9 | B13: GOLDEN parity with original openfpa: first_negative_week = 3 | C13: =IF(ABS(Runway!$B$6-(3))<0.005,"PASS","FAIL") | D13: =Runway!$B$6

Sheet Setup
A1: Setup
A4: opening_cash | B4: 150000
A5: weeks (1-52) | B5: 13
A6: week 1 start date (Monday recommended) | B6: 46027
A7: credit-line buffer over trough | B7: 0.15
A8: currency symbol | B8: ₹

Sheet Flows
A1: Flows (one row per scheduled flow; amount is a positive magnitude)
A4: direction (receipt/disbursement) | B4: name | C4: amount | D4: start_week | E4: recurrence (once/weekly/biweekly) | F4: end_week (optional) | G4: category (optional) | H4: source / evidence
A5: receipt | B5: D2C daily sales | C5: 38000 | D5: 1 | E5: weekly
A6: receipt | B6: Amazon payout | C6: 95000 | D6: 2 | E6: biweekly
A7: receipt | B7: Wholesale AR collection | C7: 120000 | D7: 4 | E7: once
A8: receipt | B8: Wholesale AR collection | C8: 120000 | D8: 9 | E8: once
A9: disbursement | B9: Payroll | C9: 55000 | D9: 1 | E9: biweekly
A10: disbursement | B10: Inventory PO deposit | C10: 220000 | D10: 3 | E10: once
A11: disbursement | B11: Inventory PO balance | C11: 240000 | D11: 6 | E11: once
A12: disbursement | B12: Operating overhead | C12: 23000 | D12: 1 | E12: weekly
A13: disbursement | B13: Marketing | C13: 18000 | D13: 1 | E13: weekly
A14: disbursement | B14: Quarterly tax estimate | C14: 60000 | D14: 11 | E14: once

Sheet Grid
A1: Grid - expand_flow: amount landing in each week per flow (formulas)
A3: direction | B3: name | C3: start | D3: end (resolved) | E3: recurrence | F3: 1 | G3: 2 | H3: 3 | I3: 4 | J3: 5 | K3: 6 | L3: 7 | M3: 8 | N3: 9 | O3: 10 | P3: 11 | Q3: 12 | R3: 13 | S3: 14 | T3: 15 | U3: 16 | V3: 17 | W3: 18 | X3: 19 | Y3: 20 | Z3: 21 | AA3: 22 | AB3: 23 | AC3: 24 | AD3: 25 | AE3: 26 | AF3: 27 | AG3: 28 | AH3: 29 | AI3: 30 | AJ3: 31 | AK3: 32 | AL3: 33 | AM3: 34 | AN3: 35 | AO3: 36 | AP3: 37 | AQ3: 38 | AR3: 39 | AS3: 40 | AT3: 41 | AU3: 42 | AV3: 43 | AW3: 44 | AX3: 45 | AY3: 46 | AZ3: 47 | BA3: 48 | BB3: 49 | BC3: 50 | BD3: 51 | BE3: 52
A4: =IF(Flows!A5="","",LOWER(Flows!A5)) | B4: =IF(Flows!B5="","",Flows!B5) | C4: =N(Flows!D5) | D4: =IF(Flows!F5="",Setup!$B$5,Flows!F5) | E4: =IF(Flows!E5="","once",LOWER(Flows!E5)) | F4: =IF(OR($A4="",Flows!$C5=""),0,IF(AND(1<=Setup!$B$5,1>=$C4,OR(AND($E4="once",1=$C4),AND($E4="weekly",1<=$D4),AND($E4="biweekly",1<=$D4,MOD(1-$C4,2)=0))),Flows!$C5,0)) | G4: =IF(OR($A4="",Flows!$C5=""),0,IF(AND(2<=Setup!$B$5,2>=$C4,OR(AND($E4="once",2=$C4),AND($E4="weekly",2<=$D4),AND($E4="biweekly",2<=$D4,MOD(2-$C4,2)=0))),Flows!$C5,0)) | H4: =IF(OR($A4="",Flows!$C5=""),0,IF(AND(3<=Setup!$B$5,3>=$C4,OR(AND($E4="once",3=$C4),AND($E4="weekly",3<=$D4),AND($E4="biweekly",3<=$D4,MOD(3-$C4,2)=0))),Flows!$C5,0)) | I4: =IF(OR($A4="",Flows!$C5=""),0,IF(AND(4<=Setup!$B$5,4>=$C4,OR(AND($E4="once",4=$C4),AND($E4="weekly",4<=$D4),AND($E4="biweekly",4<=$D4,MOD(4-$C4,2)=0))),Flows!$C5,0)) | J4: =IF(OR($A4="",Flows!$C5=""),0,IF(AND(5<=Setup!$B$5,5>=$C4,OR(AND($E4="once",5=$C4),AND($E4="weekly",5<=$D4),AND($E4="biweekly",5<=$D4,MOD(5-$C4,2)=0))),Flows!$C5,0)) | K4: =IF(OR($A4="",Flows!$C5=""),0,IF(AND(6<=Setup!$B$5,6>=$C4,OR(AND($E4="once",6=$C4),AND($E4="weekly",6<=$D4),AND($E4="biweekly",6<=$D4,MOD(6-$C4,2)=0))),Flows!$C5,0)) | L4: =IF(OR($A4="",Flows!$C5=""),0,IF(AND(7<=Setup!$B$5,7>=$C4,OR(AND($E4="once",7=$C4),AND($E4="weekly",7<=$D4),AND($E4="biweekly",7<=$D4,MOD(7-$C4,2)=0))),Flows!$C5,0)) | M4: =IF(OR($A4="",Flows!$C5=""),0,IF(AND(8<=Setup!$B$5,8>=$C4,OR(AND($E4="once",8=$C4),AND($E4="weekly",8<=$D4),AND($E4="biweekly",8<=$D4,MOD(8-$C4,2)=0))),Flows!$C5,0)) | N4: =IF(OR($A4="",Flows!$C5=""),0,IF(AND(9<=Setup!$B$5,9>=$C4,OR(AND($E4="once",9=$C4),AND($E4="weekly",9<=$D4),AND($E4="biweekly",9<=$D4,MOD(9-$C4,2)=0))),Flows!$C5,0)) | O4: =IF(OR($A4="",Flows!$C5=""),0,IF(AND(10<=Setup!$B$5,10>=$C4,OR(AND($E4="once",10=$C4),AND($E4="weekly",10<=$D4),AND($E4="biweekly",10<=$D4,MOD(10-$C4,2)=0))),Flows!$C5,0)) | P4: =IF(OR($A4="",Flows!$C5=""),0,IF(AND(11<=Setup!$B$5,11>=$C4,OR(AND($E4="once",11=$C4),AND($E4="weekly",11<=$D4),AND($E4="biweekly",11<=$D4,MOD(11-$C4,2)=0))),Flows!$C5,0)) | Q4: =IF(OR($A4="",Flows!$C5=""),0,IF(AND(12<=Setup!$B$5,12>=$C4,OR(AND($E4="once",12=$C4),AND($E4="weekly",12<=$D4),AND($E4="biweekly",12<=$D4,MOD(12-$C4,2)=0))),Flows!$C5,0)) | R4: =IF(OR($A4="",Flows!$C5=""),0,IF(AND(13<=Setup!$B$5,13>=$C4,OR(AND($E4="once",13=$C4),AND($E4="weekly",13<=$D4),AND($E4="biweekly",13<=$D4,MOD(13-$C4,2)=0))),Flows!$C5,0)) | S4: =IF(OR($A4="",Flows!$C5=""),0,IF(AND(14<=Setup!$B$5,14>=$C4,OR(AND($E4="once",14=$C4),AND($E4="weekly",14<=$D4),AND($E4="biweekly",14<=$D4,MOD(14-$C4,2)=0))),Flows!$C5,0)) | T4: =IF(OR($A4="",Flows!$C5=""),0,IF(AND(15<=Setup!$B$5,15>=$C4,OR(AND($E4="once",15=$C4),AND($E4="weekly",15<=$D4),AND($E4="biweekly",15<=$D4,MOD(15-$C4,2)=0))),Flows!$C5,0)) | U4: =IF(OR($A4="",Flows!$C5=""),0,IF(AND(16<=Setup!$B$5,16>=$C4,OR(AND($E4="once",16=$C4),AND($E4="weekly",16<=$D4),AND($E4="biweekly",16<=$D4,MOD(16-$C4,2)=0))),Flows!$C5,0)) | V4: =IF(OR($A4="",Flows!$C5=""),0,IF(AND(17<=Setup!$B$5,17>=$C4,OR(AND($E4="once",17=$C4),AND($E4="weekly",17<=$D4),AND($E4="biweekly",17<=$D4,MOD(17-$C4,2)=0))),Flows!$C5,0)) | W4: =IF(OR($A4="",Flows!$C5=""),0,IF(AND(18<=Setup!$B$5,18>=$C4,OR(AND($E4="once",18=$C4),AND($E4="weekly",18<=$D4),AND($E4="biweekly",18<=$D4,MOD(18-$C4,2)=0))),Flows!$C5,0)) | X4: =IF(OR($A4="",Flows!$C5=""),0,IF(AND(19<=Setup!$B$5,19>=$C4,OR(AND($E4="once",19=$C4),AND($E4="weekly",19<=$D4),AND($E4="biweekly",19<=$D4,MOD(19-$C4,2)=0))),Flows!$C5,0)) | Y4: =IF(OR($A4="",Flows!$C5=""),0,IF(AND(20<=Setup!$B$5,20>=$C4,OR(AND($E4="once",20=$C4),AND($E4="weekly",20<=$D4),AND($E4="biweekly",20<=$D4,MOD(20-$C4,2)=0))),Flows!$C5,0)) | Z4: =IF(OR($A4="",Flows!$C5=""),0,IF(AND(21<=Setup!$B$5,21>=$C4,OR(AND($E4="once",21=$C4),AND($E4="weekly",21<=$D4),AND($E4="biweekly",21<=$D4,MOD(21-$C4,2)=0))),Flows!$C5,0)) | AA4: =IF(OR($A4="",Flows!$C5=""),0,IF(AND(22<=Setup!$B$5,22>=$C4,OR(AND($E4="once",22=$C4),AND($E4="weekly",22<=$D4),AND($E4="biweekly",22<=$D4,MOD(22-$C4,2)=0))),Flows!$C5,0)) | AB4: =IF(OR($A4="",Flows!$C5=""),0,IF(AND(23<=Setup!$B$5,23>=$C4,OR(AND($E4="once",23=$C4),AND($E4="weekly",23<=$D4),AND($E4="biweekly",23<=$D4,MOD(23-$C4,2)=0))),Flows!$C5,0)) | AC4: =IF(OR($A4="",Flows!$C5=""),0,IF(AND(24<=Setup!$B$5,24>=$C4,OR(AND($E4="once",24=$C4),AND($E4="weekly",24<=$D4),AND($E4="biweekly",24<=$D4,MOD(24-$C4,2)=0))),Flows!$C5,0)) | AD4: =IF(OR($A4="",Flows!$C5=""),0,IF(AND(25<=Setup!$B$5,25>=$C4,OR(AND($E4="once",25=$C4),AND($E4="weekly",25<=$D4),AND($E4="biweekly",25<=$D4,MOD(25-$C4,2)=0))),Flows!$C5,0)) | AE4: =IF(OR($A4="",Flows!$C5=""),0,IF(AND(26<=Setup!$B$5,26>=$C4,OR(AND($E4="once",26=$C4),AND($E4="weekly",26<=$D4),AND($E4="biweekly",26<=$D4,MOD(26-$C4,2)=0))),Flows!$C5,0)) | AF4: =IF(OR($A4="",Flows!$C5=""),0,IF(AND(27<=Setup!$B$5,27>=$C4,OR(AND($E4="once",27=$C4),AND($E4="weekly",27<=$D4),AND($E4="biweekly",27<=$D4,MOD(27-$C4,2)=0))),Flows!$C5,0)) | AG4: =IF(OR($A4="",Flows!$C5=""),0,IF(AND(28<=Setup!$B$5,28>=$C4,OR(AND($E4="once",28=$C4),AND($E4="weekly",28<=$D4),AND($E4="biweekly",28<=$D4,MOD(28-$C4,2)=0))),Flows!$C5,0)) | AH4: =IF(OR($A4="",Flows!$C5=""),0,IF(AND(29<=Setup!$B$5,29>=$C4,OR(AND($E4="once",29=$C4),AND($E4="weekly",29<=$D4),AND($E4="biweekly",29<=$D4,MOD(29-$C4,2)=0))),Flows!$C5,0)) | AI4: =IF(OR($A4="",Flows!$C5=""),0,IF(AND(30<=Setup!$B$5,30>=$C4,OR(AND($E4="once",30=$C4),AND($E4="weekly",30<=$D4),AND($E4="biweekly",30<=$D4,MOD(30-$C4,2)=0))),Flows!$C5,0)) | AJ4: =IF(OR($A4="",Flows!$C5=""),0,IF(AND(31<=Setup!$B$5,31>=$C4,OR(AND($E4="once",31=$C4),AND($E4="weekly",31<=$D4),AND($E4="biweekly",31<=$D4,MOD(31-$C4,2)=0))),Flows!$C5,0)) | AK4: =IF(OR($A4="",Flows!$C5=""),0,IF(AND(32<=Setup!$B$5,32>=$C4,OR(AND($E4="once",32=$C4),AND($E4="weekly",32<=$D4),AND($E4="biweekly",32<=$D4,MOD(32-$C4,2)=0))),Flows!$C5,0)) | AL4: =IF(OR($A4="",Flows!$C5=""),0,IF(AND(33<=Setup!$B$5,33>=$C4,OR(AND($E4="once",33=$C4),AND($E4="weekly",33<=$D4),AND($E4="biweekly",33<=$D4,MOD(33-$C4,2)=0))),Flows!$C5,0)) | AM4: =IF(OR($A4="",Flows!$C5=""),0,IF(AND(34<=Setup!$B$5,34>=$C4,OR(AND($E4="once",34=$C4),AND($E4="weekly",34<=$D4),AND($E4="biweekly",34<=$D4,MOD(34-$C4,2)=0))),Flows!$C5,0)) | AN4: =IF(OR($A4="",Flows!$C5=""),0,IF(AND(35<=Setup!$B$5,35>=$C4,OR(AND($E4="once",35=$C4),AND($E4="weekly",35<=$D4),AND($E4="biweekly",35<=$D4,MOD(35-$C4,2)=0))),Flows!$C5,0)) | AO4: =IF(OR($A4="",Flows!$C5=""),0,IF(AND(36<=Setup!$B$5,36>=$C4,OR(AND($E4="once",36=$C4),AND($E4="weekly",36<=$D4),AND($E4="biweekly",36<=$D4,MOD(36-$C4,2)=0))),Flows!$C5,0)) | AP4: =IF(OR($A4="",Flows!$C5=""),0,IF(AND(37<=Setup!$B$5,37>=$C4,OR(AND($E4="once",37=$C4),AND($E4="weekly",37<=$D4),AND($E4="biweekly",37<=$D4,MOD(37-$C4,2)=0))),Flows!$C5,0)) | AQ4: =IF(OR($A4="",Flows!$C5=""),0,IF(AND(38<=Setup!$B$5,38>=$C4,OR(AND($E4="once",38=$C4),AND($E4="weekly",38<=$D4),AND($E4="biweekly",38<=$D4,MOD(38-$C4,2)=0))),Flows!$C5,0)) | AR4: =IF(OR($A4="",Flows!$C5=""),0,IF(AND(39<=Setup!$B$5,39>=$C4,OR(AND($E4="once",39=$C4),AND($E4="weekly",39<=$D4),AND($E4="biweekly",39<=$D4,MOD(39-$C4,2)=0))),Flows!$C5,0)) | AS4: =IF(OR($A4="",Flows!$C5=""),0,IF(AND(40<=Setup!$B$5,40>=$C4,OR(AND($E4="once",40=$C4),AND($E4="weekly",40<=$D4),AND($E4="biweekly",40<=$D4,MOD(40-$C4,2)=0))),Flows!$C5,0)) | AT4: =IF(OR($A4="",Flows!$C5=""),0,IF(AND(41<=Setup!$B$5,41>=$C4,OR(AND($E4="once",41=$C4),AND($E4="weekly",41<=$D4),AND($E4="biweekly",41<=$D4,MOD(41-$C4,2)=0))),Flows!$C5,0)) | AU4: =IF(OR($A4="",Flows!$C5=""),0,IF(AND(42<=Setup!$B$5,42>=$C4,OR(AND($E4="once",42=$C4),AND($E4="weekly",42<=$D4),AND($E4="biweekly",42<=$D4,MOD(42-$C4,2)=0))),Flows!$C5,0)) | AV4: =IF(OR($A4="",Flows!$C5=""),0,IF(AND(43<=Setup!$B$5,43>=$C4,OR(AND($E4="once",43=$C4),AND($E4="weekly",43<=$D4),AND($E4="biweekly",43<=$D4,MOD(43-$C4,2)=0))),Flows!$C5,0)) | AW4: =IF(OR($A4="",Flows!$C5=""),0,IF(AND(44<=Setup!$B$5,44>=$C4,OR(AND($E4="once",44=$C4),AND($E4="weekly",44<=$D4),AND($E4="biweekly",44<=$D4,MOD(44-$C4,2)=0))),Flows!$C5,0)) | AX4: =IF(OR($A4="",Flows!$C5=""),0,IF(AND(45<=Setup!$B$5,45>=$C4,OR(AND($E4="once",45=$C4),AND($E4="weekly",45<=$D4),AND($E4="biweekly",45<=$D4,MOD(45-$C4,2)=0))),Flows!$C5,0)) | AY4: =IF(OR($A4="",Flows!$C5=""),0,IF(AND(46<=Setup!$B$5,46>=$C4,OR(AND($E4="once",46=$C4),AND($E4="weekly",46<=$D4),AND($E4="biweekly",46<=$D4,MOD(46-$C4,2)=0))),Flows!$C5,0)) | AZ4: =IF(OR($A4="",Flows!$C5=""),0,IF(AND(47<=Setup!$B$5,47>=$C4,OR(AND($E4="once",47=$C4),AND($E4="weekly",47<=$D4),AND($E4="biweekly",47<=$D4,MOD(47-$C4,2)=0))),Flows!$C5,0)) | BA4: =IF(OR($A4="",Flows!$C5=""),0,IF(AND(48<=Setup!$B$5,48>=$C4,OR(AND($E4="once",48=$C4),AND($E4="weekly",48<=$D4),AND($E4="biweekly",48<=$D4,MOD(48-$C4,2)=0))),Flows!$C5,0)) | BB4: =IF(OR($A4="",Flows!$C5=""),0,IF(AND(49<=Setup!$B$5,49>=$C4,OR(AND($E4="once",49=$C4),AND($E4="weekly",49<=$D4),AND($E4="biweekly",49<=$D4,MOD(49-$C4,2)=0))),Flows!$C5,0)) | BC4: =IF(OR($A4="",Flows!$C5=""),0,IF(AND(50<=Setup!$B$5,50>=$C4,OR(AND($E4="once",50=$C4),AND($E4="weekly",50<=$D4),AND($E4="biweekly",50<=$D4,MOD(50-$C4,2)=0))),Flows!$C5,0)) | BD4: =IF(OR($A4="",Flows!$C5=""),0,IF(AND(51<=Setup!$B$5,51>=$C4,OR(AND($E4="once",51=$C4),AND($E4="weekly",51<=$D4),AND($E4="biweekly",51<=$D4,MOD(51-$C4,2)=0))),Flows!$C5,0)) | BE4: =IF(OR($A4="",Flows!$C5=""),0,IF(AND(52<=Setup!$B$5,52>=$C4,OR(AND($E4="once",52=$C4),AND($E4="weekly",52<=$D4),AND($E4="biweekly",52<=$D4,MOD(52-$C4,2)=0))),Flows!$C5,0))
