Workbook
Name fitness: 'Score'!$C$17

Sheet README
A1: K04 · Forecast Scoring, Holdout Backtest & Scorecard (no-code kernel)
A3: Replaces openfpa: pyfpa.backtest (extract_lines, aggregate_periods, score_forecast, holdout_backtest, snapshot_forecast, render_scorecard, persistent_miss, magnitude_cap) and portfolio.recover_actuals / best_snapshot; CLI scorecard-render.
A4: Score (score_forecast)
A5: Lines (default ending_cash 0.4, ebitda 0.3, revenue 0.2, gross_margin 0.1). A line is scored only if it has a predicted value, an actual value, a positive weight and a NON-ZERO actual.
A6: Per-line error = predicted/actual - 1 (signed). Weights are renormalised over scored lines. Fitness = sum(weight x |error|) = weighted MAPE; LOWER is better. No scorable line = ERROR (missing evidence is never perfect performance).
A7: Holdout (holdout_backtest)
A8: Paste actuals by period (chronological). Set holdout N. The last N periods are held out; the model must be fitted ONLY on the fit periods (copy K01, set drivers from fit periods, paste its predicted lines here). Aggregation: flows summed, stock = last period, gross_margin = sum GP / sum revenue.
A9: Snapshots and scorecard (render_scorecard)
A10: One row per memory/forecasts/<label>.snapshot.md. After close, paste the score. 'Scorecard' renders the markdown for memory/scorecard.md (never hand-edit that file).
A11: Learning guards
A12: persistent_miss: TRUE when the last K errors of a line are all the same sign and all exceed the threshold (default K=2, threshold 0). magnitude_cap: clamp a proposed driver to +/-25% of the old value per cycle (old = 0 passes through).
A13: recover_actuals: actual = predicted / (1 + error) for scored lines (error = -1 is unrecoverable). best_snapshot = lowest fitness scored snapshot.

Sheet Checks
A1: Checks - OVERALL must be PASS
B3: OVERALL | C3: =IF(COUNTIF(C5:C7,"PASS")=COUNT(A5:A7),"PASS","FAIL") | D3: =COUNTIF(C5:C7,"PASS")&" pass / "&COUNTIF(C5:C7,"FAIL")&" fail / "&(COUNT(A5:A7)-COUNTIF(C5:C7,"PASS")-COUNTIF(C5:C7,"FAIL"))&" error"
A4: # | B4: check | C4: result | D4: detail
A5: 1 | B5: at least one scorable line | C5: =IF(Score!C18>0,"PASS","FAIL") | D5: =Score!C18
A6: 2 | B6: weights used sum to 1 | C6: =IF(OR(Score!C18=0,ABS(SUM(Score!G5:G14)-1)<1E-9),"PASS","FAIL") | D6: =SUM(Score!G5:G14)
A7: 3 | B7: holdout split valid (when used) | C7: =IF(OR(Holdout!B4=0,Holdout!B5="PASS"),"PASS","FAIL") | D7: =Holdout!B4&" periods"

Sheet Score
A1: Score (score_forecast)
A4: line | B4: kind (flow/stock/ratio) | C4: weight | D4: predicted | E4: actual | F4: scorable? | G4: weight used | H4: error (pred/act - 1) | I4: weighted |error|
A5: ending_cash | B5: stock | C5: 0.4 | F5: =IF(AND(A5<>"",ISNUMBER(C5),C5>0,ISNUMBER(D5),ISNUMBER(E5)),IF(E5<>0,1,0),0) | G5: =IF(F5=1,C5/SUMPRODUCT($C$5:$C$14*$F$5:$F$14),0) | H5: =IF(F5=1,(D5-E5)/E5,"") | I5: =IF(F5=1,G5*ABS(H5),0)
A6: ebitda | B6: flow | C6: 0.3 | F6: =IF(AND(A6<>"",ISNUMBER(C6),C6>0,ISNUMBER(D6),ISNUMBER(E6)),IF(E6<>0,1,0),0) | G6: =IF(F6=1,C6/SUMPRODUCT($C$5:$C$14*$F$5:$F$14),0) | H6: =IF(F6=1,(D6-E6)/E6,"") | I6: =IF(F6=1,G6*ABS(H6),0)
A7: revenue | B7: flow | C7: 0.2 | F7: =IF(AND(A7<>"",ISNUMBER(C7),C7>0,ISNUMBER(D7),ISNUMBER(E7)),IF(E7<>0,1,0),0) | G7: =IF(F7=1,C7/SUMPRODUCT($C$5:$C$14*$F$5:$F$14),0) | H7: =IF(F7=1,(D7-E7)/E7,"") | I7: =IF(F7=1,G7*ABS(H7),0)
A8: gross_margin | B8: ratio | C8: 0.1 | F8: =IF(AND(A8<>"",ISNUMBER(C8),C8>0,ISNUMBER(D8),ISNUMBER(E8)),IF(E8<>0,1,0),0) | G8: =IF(F8=1,C8/SUMPRODUCT($C$5:$C$14*$F$5:$F$14),0) | H8: =IF(F8=1,(D8-E8)/E8,"") | I8: =IF(F8=1,G8*ABS(H8),0)
F9: =IF(AND(A9<>"",ISNUMBER(C9),C9>0,ISNUMBER(D9),ISNUMBER(E9)),IF(E9<>0,1,0),0) | G9: =IF(F9=1,C9/SUMPRODUCT($C$5:$C$14*$F$5:$F$14),0) | H9: =IF(F9=1,(D9-E9)/E9,"") | I9: =IF(F9=1,G9*ABS(H9),0)
F10: =IF(AND(A10<>"",ISNUMBER(C10),C10>0,ISNUMBER(D10),ISNUMBER(E10)),IF(E10<>0,1,0),0) | G10: =IF(F10=1,C10/SUMPRODUCT($C$5:$C$14*$F$5:$F$14),0) | H10: =IF(F10=1,(D10-E10)/E10,"") | I10: =IF(F10=1,G10*ABS(H10),0)
F11: =IF(AND(A11<>"",ISNUMBER(C11),C11>0,ISNUMBER(D11),ISNUMBER(E11)),IF(E11<>0,1,0),0) | G11: =IF(F11=1,C11/SUMPRODUCT($C$5:$C$14*$F$5:$F$14),0) | H11: =IF(F11=1,(D11-E11)/E11,"") | I11: =IF(F11=1,G11*ABS(H11),0)
F12: =IF(AND(A12<>"",ISNUMBER(C12),C12>0,ISNUMBER(D12),ISNUMBER(E12)),IF(E12<>0,1,0),0) | G12: =IF(F12=1,C12/SUMPRODUCT($C$5:$C$14*$F$5:$F$14),0) | H12: =IF(F12=1,(D12-E12)/E12,"") | I12: =IF(F12=1,G12*ABS(H12),0)
F13: =IF(AND(A13<>"",ISNUMBER(C13),C13>0,ISNUMBER(D13),ISNUMBER(E13)),IF(E13<>0,1,0),0) | G13: =IF(F13=1,C13/SUMPRODUCT($C$5:$C$14*$F$5:$F$14),0) | H13: =IF(F13=1,(D13-E13)/E13,"") | I13: =IF(F13=1,G13*ABS(H13),0)
F14: =IF(AND(A14<>"",ISNUMBER(C14),C14>0,ISNUMBER(D14),ISNUMBER(E14)),IF(E14<>0,1,0),0) | G14: =IF(F14=1,C14/SUMPRODUCT($C$5:$C$14*$F$5:$F$14),0) | H14: =IF(F14=1,(D14-E14)/E14,"") | I14: =IF(F14=1,G14*ABS(H14),0)
A17: FITNESS (weighted MAPE, lower = better) | C17: =IF(SUM(F5:F14)=0,"ERROR: no scorable lines",SUM(I5:I14))
A18: scored lines | C18: =SUM(F5:F14)

Sheet Holdout
A1: Holdout backtest: chronological actuals; last N periods held out
A3: holdout periods N | B3: 3
A4: periods supplied | B4: =SUMPRODUCT((A8:A127<>"")*1)
A5: valid split? (need more periods than N) | B5: =IF(B4>B3,"PASS","FAIL")
A7: period | B7: revenue | C7: gross_profit | D7: ebitda | E7: ending_cash | F7: net_income | G7: free_cash_flow | H7: role (formula) | I7: order | K7: holdout aggregate line | L7: actual (aggregated) | M7: rule
H8: =IF(A8="","",IF(I8>$B$4-$B$3,"holdout","fit")) | I8: =IF(A8="","",SUMPRODUCT(($A$8:A8<>"")*1)) | K8: revenue | L8: =SUMIF($H$8:$H$127,"holdout",B8:B127) | M8: flow
H9: =IF(A9="","",IF(I9>$B$4-$B$3,"holdout","fit")) | I9: =IF(A9="","",SUMPRODUCT(($A$8:A9<>"")*1)) | K9: gross_profit | L9: =SUMIF($H$8:$H$127,"holdout",C8:C127) | M9: flow
H10: =IF(A10="","",IF(I10>$B$4-$B$3,"holdout","fit")) | I10: =IF(A10="","",SUMPRODUCT(($A$8:A10<>"")*1)) | K10: ebitda | L10: =SUMIF($H$8:$H$127,"holdout",D8:D127) | M10: flow
H11: =IF(A11="","",IF(I11>$B$4-$B$3,"holdout","fit")) | I11: =IF(A11="","",SUMPRODUCT(($A$8:A11<>"")*1)) | K11: ending_cash | L11: =IFERROR(INDEX(E8:E127,MATCH($B$4,$I$8:$I$127,0)),0) | M11: stock
H12: =IF(A12="","",IF(I12>$B$4-$B$3,"holdout","fit")) | I12: =IF(A12="","",SUMPRODUCT(($A$8:A12<>"")*1)) | K12: net_income | L12: =SUMIF($H$8:$H$127,"holdout",F8:F127) | M12: flow
H13: =IF(A13="","",IF(I13>$B$4-$B$3,"holdout","fit")) | I13: =IF(A13="","",SUMPRODUCT(($A$8:A13<>"")*1)) | K13: free_cash_flow | L13: =SUMIF($H$8:$H$127,"holdout",G8:G127) | M13: flow
H14: =IF(A14="","",IF(I14>$B$4-$B$3,"holdout","fit")) | I14: =IF(A14="","",SUMPRODUCT(($A$8:A14<>"")*1)) | K14: gross_margin | L14: =IF(L8=0,0,L9/L8) | M14: ratio
H15: =IF(A15="","",IF(I15>$B$4-$B$3,"holdout","fit")) | I15: =IF(A15="","",SUMPRODUCT(($A$8:A15<>"")*1))
H16: =IF(A16="","",IF(I16>$B$4-$B$3,"holdout","fit")) | I16: =IF(A16="","",SUMPRODUCT(($A$8:A16<>"")*1)) | K16: Paste these aggregated actuals into Score!E and the fit-only model's predictions into Score!D.
H17: =IF(A17="","",IF(I17>$B$4-$B$3,"holdout","fit")) | I17: =IF(A17="","",SUMPRODUCT(($A$8:A17<>"")*1))
H18: =IF(A18="","",IF(I18>$B$4-$B$3,"holdout","fit")) | I18: =IF(A18="","",SUMPRODUCT(($A$8:A18<>"")*1))
H19: =IF(A19="","",IF(I19>$B$4-$B$3,"holdout","fit")) | I19: =IF(A19="","",SUMPRODUCT(($A$8:A19<>"")*1))
H20: =IF(A20="","",IF(I20>$B$4-$B$3,"holdout","fit")) | I20: =IF(A20="","",SUMPRODUCT(($A$8:A20<>"")*1))
H21: =IF(A21="","",IF(I21>$B$4-$B$3,"holdout","fit")) | I21: =IF(A21="","",SUMPRODUCT(($A$8:A21<>"")*1))
H22: =IF(A22="","",IF(I22>$B$4-$B$3,"holdout","fit")) | I22: =IF(A22="","",SUMPRODUCT(($A$8:A22<>"")*1))
H23: =IF(A23="","",IF(I23>$B$4-$B$3,"holdout","fit")) | I23: =IF(A23="","",SUMPRODUCT(($A$8:A23<>"")*1))
H24: =IF(A24="","",IF(I24>$B$4-$B$3,"holdout","fit")) | I24: =IF(A24="","",SUMPRODUCT(($A$8:A24<>"")*1))
H25: =IF(A25="","",IF(I25>$B$4-$B$3,"holdout","fit")) | I25: =IF(A25="","",SUMPRODUCT(($A$8:A25<>"")*1))
H26: =IF(A26="","",IF(I26>$B$4-$B$3,"holdout","fit")) | I26: =IF(A26="","",SUMPRODUCT(($A$8:A26<>"")*1))
H27: =IF(A27="","",IF(I27>$B$4-$B$3,"holdout","fit")) | I27: =IF(A27="","",SUMPRODUCT(($A$8:A27<>"")*1))
H28: =IF(A28="","",IF(I28>$B$4-$B$3,"holdout","fit")) | I28: =IF(A28="","",SUMPRODUCT(($A$8:A28<>"")*1))
... H127: =IF(A127="","",IF(I127>$B$4-$B$3,"holdout","fit")) | I127: =IF(A127="","",SUMPRODUCT(($A$8:A127<>"")*1))

Sheet Snapshots
A1: Snapshot ledger (one row per memory/forecasts/*.snapshot.md, chronological)
F2: best_snapshot (lowest fitness among scored): | I2: =IFERROR(SMALL(D5:D104,1),"") | J2: =IF(I2="","none",INDEX(A5:A104,MATCH(I2,D5:D104,0)))
A4: label | B4: created | C4: scored? (y/n) | D4: fitness | E4: err ending_cash | F4: err ebitda | G4: err revenue | H4: err gross_margin | I4: pred ending_cash | J4: pred ebitda | K4: pred revenue | L4: pred gross_margin | M4: recovered actual ending_cash | N4: recovered actual ebitda | O4: recovered actual revenue | P4: recovered actual gross_margin | Q4: scorecard row (markdown)
M5: =IF(OR(E5="",I5="",E5=-1),"",I5/(1+E5)) | N5: =IF(OR(F5="",J5="",F5=-1),"",J5/(1+F5)) | O5: =IF(OR(G5="",K5="",G5=-1),"",K5/(1+G5)) | P5: =IF(OR(H5="",L5="",H5=-1),"",L5/(1+H5)) | Q5: =IF(OR(A5="",LOWER(C5)<>"y"),"","| "&A5&" | "&TEXT(D5,"0.0000")&" | "&IF(E5="","","ending_cash "&IF(E5<0,"-","+")&TEXT(ABS(E5)*100,"0.0")&"%")&IF(AND(LEN(IF(E5="","","ending_cash "&IF(E5<0,"-","+")&TEXT(ABS(E5)*100,"0.0")&"%"))>0,LEN(IF(F5="","","ebitda "&IF(F5<0,"-","+")&TEXT(ABS(F5)*100,"0.0")&"%"))>0),", ","")&IF(F5="","","ebitda "&IF(F5<0,"-","+")&TEXT(ABS(F5)*100,"0.0")&"%")&IF(AND(LEN(IF(E5="","","ending_cash "&IF(E5<0,"-","+")&TEXT(ABS(E5)*100,"0.0")&"%")&IF(AND(LEN(IF(E5="","","ending_cash "&IF(E5<0,"-","+")&TEXT(ABS(E5)*100,"0.0")&"%"))>0,LEN(IF(F5="","","ebitda "&IF(F5<0,"-","+")&TEXT(ABS(F5)*100,"0.0")&"%"))>0),", ","")&IF(F5="","","ebitda "&IF(F5<0,"-","+")&TEXT(ABS(F5)*100,"0.0")&"%"))>0,LEN(IF(G5="","","revenue "&IF(G5<0,"-","+")&TEXT(ABS(G5)*100,"0.0")&"%"))>0),", ","")&IF(G5="","","revenue "&IF(G5<0,"-","+")&TEXT(ABS(G5)*100,"0.0")&"%")&IF(AND(LEN(IF(E5="","","ending_cash "&IF(E5<0,"-","+")&TEXT(ABS(E5)*100,"0.0")&"%")&IF(AND(LEN(IF(E5="","","ending_cash "&IF(E5<0,"-","+")&TEXT(ABS(E5)*100,"0.0")&"%"))>0,LEN(IF(F5="","","ebitda "&IF(F5<0,"-","+")&TEXT(ABS(F5)*100,"0.0")&"%"))>0),", ","")&IF(F5="","","ebitda "&IF(F5<0,"-","+")&TEXT(ABS(F5)*100,"0.0")&"%")&IF(AND(LEN(IF(E5="","","ending_cash "&IF(E5<0,"-","+")&TEXT(ABS(E5)*100,"0.0")&"%")&IF(AND(LEN(IF(E5="","","ending_cash "&IF(E5<0,"-","+")&TEXT(ABS(E5)*100,"0.0")&"%"))>0,LEN(IF(F5="","","ebitda "&IF(F5<0,"-","+")&TEXT(ABS(F5)*100,"0.0")&"%"))>0),", ","")&IF(F5="","","ebitda "&IF(F5<0,"-","+")&TEXT(ABS(F5)*100,"0.0")&"%"))>0,LEN(IF(G5="","","revenue "&IF(G5<0,"-","+")&TEXT(ABS(G5)*100,"0.0")&"%"))>0),", ","")&IF(G5="","","revenue "&IF(G5<0,"-","+")&TEXT(ABS(G5)*100,"0.0")&"%"))>0,LEN(IF(H5="","","gross_margin "&IF(H5<0,"-","+")&TEXT(ABS(H5)*100,"0.0")&"%"))>0),", ","")&IF(H5="","","gross_margin "&IF(H5<0,"-","+")&TEXT(ABS(H5)*100,"0.0")&"%")&" |") | R5: =IF(Q5="","",ROW()-4)
M6: =IF(OR(E6="",I6="",E6=-1),"",I6/(1+E6)) | N6: =IF(OR(F6="",J6="",F6=-1),"",J6/(1+F6)) | O6: =IF(OR(G6="",K6="",G6=-1),"",K6/(1+G6)) | P6: =IF(OR(H6="",L6="",H6=-1),"",L6/(1+H6)) | Q6: =IF(OR(A6="",LOWER(C6)<>"y"),"","| "&A6&" | "&TEXT(D6,"0.0000")&" | "&IF(E6="","","ending_cash "&IF(E6<0,"-","+")&TEXT(ABS(E6)*100,"0.0")&"%")&IF(AND(LEN(IF(E6="","","ending_cash "&IF(E6<0,"-","+")&TEXT(ABS(E6)*100,"0.0")&"%"))>0,LEN(IF(F6="","","ebitda "&IF(F6<0,"-","+")&TEXT(ABS(F6)*100,"0.0")&"%"))>0),", ","")&IF(F6="","","ebitda "&IF(F6<0,"-","+")&TEXT(ABS(F6)*100,"0.0")&"%")&IF(AND(LEN(IF(E6="","","ending_cash "&IF(E6<0,"-","+")&TEXT(ABS(E6)*100,"0.0")&"%")&IF(AND(LEN(IF(E6="","","ending_cash "&IF(E6<0,"-","+")&TEXT(ABS(E6)*100,"0.0")&"%"))>0,LEN(IF(F6="","","ebitda "&IF(F6<0,"-","+")&TEXT(ABS(F6)*100,"0.0")&"%"))>0),", ","")&IF(F6="","","ebitda "&IF(F6<0,"-","+")&TEXT(ABS(F6)*100,"0.0")&"%"))>0,LEN(IF(G6="","","revenue "&IF(G6<0,"-","+")&TEXT(ABS(G6)*100,"0.0")&"%"))>0),", ","")&IF(G6="","","revenue "&IF(G6<0,"-","+")&TEXT(ABS(G6)*100,"0.0")&"%")&IF(AND(LEN(IF(E6="","","ending_cash "&IF(E6<0,"-","+")&TEXT(ABS(E6)*100,"0.0")&"%")&IF(AND(LEN(IF(E6="","","ending_cash "&IF(E6<0,"-","+")&TEXT(ABS(E6)*100,"0.0")&"%"))>0,LEN(IF(F6="","","ebitda "&IF(F6<0,"-","+")&TEXT(ABS(F6)*100,"0.0")&"%"))>0),", ","")&IF(F6="","","ebitda "&IF(F6<0,"-","+")&TEXT(ABS(F6)*100,"0.0")&"%")&IF(AND(LEN(IF(E6="","","ending_cash "&IF(E6<0,"-","+")&TEXT(ABS(E6)*100,"0.0")&"%")&IF(AND(LEN(IF(E6="","","ending_cash "&IF(E6<0,"-","+")&TEXT(ABS(E6)*100,"0.0")&"%"))>0,LEN(IF(F6="","","ebitda "&IF(F6<0,"-","+")&TEXT(ABS(F6)*100,"0.0")&"%"))>0),", ","")&IF(F6="","","ebitda "&IF(F6<0,"-","+")&TEXT(ABS(F6)*100,"0.0")&"%"))>0,LEN(IF(G6="","","revenue "&IF(G6<0,"-","+")&TEXT(ABS(G6)*100,"0.0")&"%"))>0),", ","")&IF(G6="","","revenue "&IF(G6<0,"-","+")&TEXT(ABS(G6)*100,"0.0")&"%"))>0,LEN(IF(H6="","","gross_margin "&IF(H6<0,"-","+")&TEXT(ABS(H6)*100,"0.0")&"%"))>0),", ","")&IF(H6="","","gross_margin "&IF(H6<0,"-","+")&TEXT(ABS(H6)*100,"0.0")&"%")&" |") | R6: =IF(Q6="","",ROW()-4)
M7: =IF(OR(E7="",I7="",E7=-1),"",I7/(1+E7)) | N7: =IF(OR(F7="",J7="",F7=-1),"",J7/(1+F7)) | O7: =IF(OR(G7="",K7="",G7=-1),"",K7/(1+G7)) | P7: =IF(OR(H7="",L7="",H7=-1),"",L7/(1+H7)) | Q7: =IF(OR(A7="",LOWER(C7)<>"y"),"","| "&A7&" | "&TEXT(D7,"0.0000")&" | "&IF(E7="","","ending_cash "&IF(E7<0,"-","+")&TEXT(ABS(E7)*100,"0.0")&"%")&IF(AND(LEN(IF(E7="","","ending_cash "&IF(E7<0,"-","+")&TEXT(ABS(E7)*100,"0.0")&"%"))>0,LEN(IF(F7="","","ebitda "&IF(F7<0,"-","+")&TEXT(ABS(F7)*100,"0.0")&"%"))>0),", ","")&IF(F7="","","ebitda "&IF(F7<0,"-","+")&TEXT(ABS(F7)*100,"0.0")&"%")&IF(AND(LEN(IF(E7="","","ending_cash "&IF(E7<0,"-","+")&TEXT(ABS(E7)*100,"0.0")&"%")&IF(AND(LEN(IF(E7="","","ending_cash "&IF(E7<0,"-","+")&TEXT(ABS(E7)*100,"0.0")&"%"))>0,LEN(IF(F7="","","ebitda "&IF(F7<0,"-","+")&TEXT(ABS(F7)*100,"0.0")&"%"))>0),", ","")&IF(F7="","","ebitda "&IF(F7<0,"-","+")&TEXT(ABS(F7)*100,"0.0")&"%"))>0,LEN(IF(G7="","","revenue "&IF(G7<0,"-","+")&TEXT(ABS(G7)*100,"0.0")&"%"))>0),", ","")&IF(G7="","","revenue "&IF(G7<0,"-","+")&TEXT(ABS(G7)*100,"0.0")&"%")&IF(AND(LEN(IF(E7="","","ending_cash "&IF(E7<0,"-","+")&TEXT(ABS(E7)*100,"0.0")&"%")&IF(AND(LEN(IF(E7="","","ending_cash "&IF(E7<0,"-","+")&TEXT(ABS(E7)*100,"0.0")&"%"))>0,LEN(IF(F7="","","ebitda "&IF(F7<0,"-","+")&TEXT(ABS(F7)*100,"0.0")&"%"))>0),", ","")&IF(F7="","","ebitda "&IF(F7<0,"-","+")&TEXT(ABS(F7)*100,"0.0")&"%")&IF(AND(LEN(IF(E7="","","ending_cash "&IF(E7<0,"-","+")&TEXT(ABS(E7)*100,"0.0")&"%")&IF(AND(LEN(IF(E7="","","ending_cash "&IF(E7<0,"-","+")&TEXT(ABS(E7)*100,"0.0")&"%"))>0,LEN(IF(F7="","","ebitda "&IF(F7<0,"-","+")&TEXT(ABS(F7)*100,"0.0")&"%"))>0),", ","")&IF(F7="","","ebitda "&IF(F7<0,"-","+")&TEXT(ABS(F7)*100,"0.0")&"%"))>0,LEN(IF(G7="","","revenue "&IF(G7<0,"-","+")&TEXT(ABS(G7)*100,"0.0")&"%"))>0),", ","")&IF(G7="","","revenue "&IF(G7<0,"-","+")&TEXT(ABS(G7)*100,"0.0")&"%"))>0,LEN(IF(H7="","","gross_margin "&IF(H7<0,"-","+")&TEXT(ABS(H7)*100,"0.0")&"%"))>0),", ","")&IF(H7="","","gross_margin "&IF(H7<0,"-","+")&TEXT(ABS(H7)*100,"0.0")&"%")&" |") | R7: =IF(Q7="","",ROW()-4)
M8: =IF(OR(E8="",I8="",E8=-1),"",I8/(1+E8)) | N8: =IF(OR(F8="",J8="",F8=-1),"",J8/(1+F8)) | O8: =IF(OR(G8="",K8="",G8=-1),"",K8/(1+G8)) | P8: =IF(OR(H8="",L8="",H8=-1),"",L8/(1+H8)) | Q8: =IF(OR(A8="",LOWER(C8)<>"y"),"","| "&A8&" | "&TEXT(D8,"0.0000")&" | "&IF(E8="","","ending_cash "&IF(E8<0,"-","+")&TEXT(ABS(E8)*100,"0.0")&"%")&IF(AND(LEN(IF(E8="","","ending_cash "&IF(E8<0,"-","+")&TEXT(ABS(E8)*100,"0.0")&"%"))>0,LEN(IF(F8="","","ebitda "&IF(F8<0,"-","+")&TEXT(ABS(F8)*100,"0.0")&"%"))>0),", ","")&IF(F8="","","ebitda "&IF(F8<0,"-","+")&TEXT(ABS(F8)*100,"0.0")&"%")&IF(AND(LEN(IF(E8="","","ending_cash "&IF(E8<0,"-","+")&TEXT(ABS(E8)*100,"0.0")&"%")&IF(AND(LEN(IF(E8="","","ending_cash "&IF(E8<0,"-","+")&TEXT(ABS(E8)*100,"0.0")&"%"))>0,LEN(IF(F8="","","ebitda "&IF(F8<0,"-","+")&TEXT(ABS(F8)*100,"0.0")&"%"))>0),", ","")&IF(F8="","","ebitda "&IF(F8<0,"-","+")&TEXT(ABS(F8)*100,"0.0")&"%"))>0,LEN(IF(G8="","","revenue "&IF(G8<0,"-","+")&TEXT(ABS(G8)*100,"0.0")&"%"))>0),", ","")&IF(G8="","","revenue "&IF(G8<0,"-","+")&TEXT(ABS(G8)*100,"0.0")&"%")&IF(AND(LEN(IF(E8="","","ending_cash "&IF(E8<0,"-","+")&TEXT(ABS(E8)*100,"0.0")&"%")&IF(AND(LEN(IF(E8="","","ending_cash "&IF(E8<0,"-","+")&TEXT(ABS(E8)*100,"0.0")&"%"))>0,LEN(IF(F8="","","ebitda "&IF(F8<0,"-","+")&TEXT(ABS(F8)*100,"0.0")&"%"))>0),", ","")&IF(F8="","","ebitda "&IF(F8<0,"-","+")&TEXT(ABS(F8)*100,"0.0")&"%")&IF(AND(LEN(IF(E8="","","ending_cash "&IF(E8<0,"-","+")&TEXT(ABS(E8)*100,"0.0")&"%")&IF(AND(LEN(IF(E8="","","ending_cash "&IF(E8<0,"-","+")&TEXT(ABS(E8)*100,"0.0")&"%"))>0,LEN(IF(F8="","","ebitda "&IF(F8<0,"-","+")&TEXT(ABS(F8)*100,"0.0")&"%"))>0),", ","")&IF(F8="","","ebitda "&IF(F8<0,"-","+")&TEXT(ABS(F8)*100,"0.0")&"%"))>0,LEN(IF(G8="","","revenue "&IF(G8<0,"-","+")&TEXT(ABS(G8)*100,"0.0")&"%"))>0),", ","")&IF(G8="","","revenue "&IF(G8<0,"-","+")&TEXT(ABS(G8)*100,"0.0")&"%"))>0,LEN(IF(H8="","","gross_margin "&IF(H8<0,"-","+")&TEXT(ABS(H8)*100,"0.0")&"%"))>0),", ","")&IF(H8="","","gross_margin "&IF(H8<0,"-","+")&TEXT(ABS(H8)*100,"0.0")&"%")&" |") | R8: =IF(Q8="","",ROW()-4)
M9: =IF(OR(E9="",I9="",E9=-1),"",I9/(1+E9)) | N9: =IF(OR(F9="",J9="",F9=-1),"",J9/(1+F9)) | O9: =IF(OR(G9="",K9="",G9=-1),"",K9/(1+G9)) | P9: =IF(OR(H9="",L9="",H9=-1),"",L9/(1+H9)) | Q9: =IF(OR(A9="",LOWER(C9)<>"y"),"","| "&A9&" | "&TEXT(D9,"0.0000")&" | "&IF(E9="","","ending_cash "&IF(E9<0,"-","+")&TEXT(ABS(E9)*100,"0.0")&"%")&IF(AND(LEN(IF(E9="","","ending_cash "&IF(E9<0,"-","+")&TEXT(ABS(E9)*100,"0.0")&"%"))>0,LEN(IF(F9="","","ebitda "&IF(F9<0,"-","+")&TEXT(ABS(F9)*100,"0.0")&"%"))>0),", ","")&IF(F9="","","ebitda "&IF(F9<0,"-","+")&TEXT(ABS(F9)*100,"0.0")&"%")&IF(AND(LEN(IF(E9="","","ending_cash "&IF(E9<0,"-","+")&TEXT(ABS(E9)*100,"0.0")&"%")&IF(AND(LEN(IF(E9="","","ending_cash "&IF(E9<0,"-","+")&TEXT(ABS(E9)*100,"0.0")&"%"))>0,LEN(IF(F9="","","ebitda "&IF(F9<0,"-","+")&TEXT(ABS(F9)*100,"0.0")&"%"))>0),", ","")&IF(F9="","","ebitda "&IF(F9<0,"-","+")&TEXT(ABS(F9)*100,"0.0")&"%"))>0,LEN(IF(G9="","","revenue "&IF(G9<0,"-","+")&TEXT(ABS(G9)*100,"0.0")&"%"))>0),", ","")&IF(G9="","","revenue "&IF(G9<0,"-","+")&TEXT(ABS(G9)*100,"0.0")&"%")&IF(AND(LEN(IF(E9="","","ending_cash "&IF(E9<0,"-","+")&TEXT(ABS(E9)*100,"0.0")&"%")&IF(AND(LEN(IF(E9="","","ending_cash "&IF(E9<0,"-","+")&TEXT(ABS(E9)*100,"0.0")&"%"))>0,LEN(IF(F9="","","ebitda "&IF(F9<0,"-","+")&TEXT(ABS(F9)*100,"0.0")&"%"))>0),", ","")&IF(F9="","","ebitda "&IF(F9<0,"-","+")&TEXT(ABS(F9)*100,"0.0")&"%")&IF(AND(LEN(IF(E9="","","ending_cash "&IF(E9<0,"-","+")&TEXT(ABS(E9)*100,"0.0")&"%")&IF(AND(LEN(IF(E9="","","ending_cash "&IF(E9<0,"-","+")&TEXT(ABS(E9)*100,"0.0")&"%"))>0,LEN(IF(F9="","","ebitda "&IF(F9<0,"-","+")&TEXT(ABS(F9)*100,"0.0")&"%"))>0),", ","")&IF(F9="","","ebitda "&IF(F9<0,"-","+")&TEXT(ABS(F9)*100,"0.0")&"%"))>0,LEN(IF(G9="","","revenue "&IF(G9<0,"-","+")&TEXT(ABS(G9)*100,"0.0")&"%"))>0),", ","")&IF(G9="","","revenue "&IF(G9<0,"-","+")&TEXT(ABS(G9)*100,"0.0")&"%"))>0,LEN(IF(H9="","","gross_margin "&IF(H9<0,"-","+")&TEXT(ABS(H9)*100,"0.0")&"%"))>0),", ","")&IF(H9="","","gross_margin "&IF(H9<0,"-","+")&TEXT(ABS(H9)*100,"0.0")&"%")&" |") | R9: =IF(Q9="","",ROW()-4)
M10: =IF(OR(E10="",I10="",E10=-1),"",I10/(1+E10)) | N10: =IF(OR(F10="",J10="",F10=-1),"",J10/(1+F10)) | O10: =IF(OR(G10="",K10="",G10=-1),"",K10/(1+G10)) | P10: =IF(OR(H10="",L10="",H10=-1),"",L10/(1+H10)) | Q10: =IF(OR(A10="",LOWER(C10)<>"y"),"","| "&A10&" | "&TEXT(D10,"0.0000")&" | "&IF(E10="","","ending_cash "&IF(E10<0,"-","+")&TEXT(ABS(E10)*100,"0.0")&"%")&IF(AND(LEN(IF(E10="","","ending_cash "&IF(E10<0,"-","+")&TEXT(ABS(E10)*100,"0.0")&"%"))>0,LEN(IF(F10="","","ebitda "&IF(F10<0,"-","+")&TEXT(ABS(F10)*100,"0.0")&"%"))>0),", ","")&IF(F10="","","ebitda "&IF(F10<0,"-","+")&TEXT(ABS(F10)*100,"0.0")&"%")&IF(AND(LEN(IF(E10="","","ending_cash "&IF(E10<0,"-","+")&TEXT(ABS(E10)*100,"0.0")&"%")&IF(AND(LEN(IF(E10="","","ending_cash "&IF(E10<0,"-","+")&TEXT(ABS(E10)*100,"0.0")&"%"))>0,LEN(IF(F10="","","ebitda "&IF(F10<0,"-","+")&TEXT(ABS(F10)*100,"0.0")&"%"))>0),", ","")&IF(F10="","","ebitda "&IF(F10<0,"-","+")&TEXT(ABS(F10)*100,"0.0")&"%"))>0,LEN(IF(G10="","","revenue "&IF(G10<0,"-","+")&TEXT(ABS(G10)*100,"0.0")&"%"))>0),", ","")&IF(G10="","","revenue "&IF(G10<0,"-","+")&TEXT(ABS(G10)*100,"0.0")&"%")&IF(AND(LEN(IF(E10="","","ending_cash "&IF(E10<0,"-","+")&TEXT(ABS(E10)*100,"0.0")&"%")&IF(AND(LEN(IF(E10="","","ending_cash "&IF(E10<0,"-","+")&TEXT(ABS(E10)*100,"0.0")&"%"))>0,LEN(IF(F10="","","ebitda "&IF(F10<0,"-","+")&TEXT(ABS(F10)*100,"0.0")&"%"))>0),", ","")&IF(F10="","","ebitda "&IF(F10<0,"-","+")&TEXT(ABS(F10)*100,"0.0")&"%")&IF(AND(LEN(IF(E10="","","ending_cash "&IF(E10<0,"-","+")&TEXT(ABS(E10)*100,"0.0")&"%")&IF(AND(LEN(IF(E10="","","ending_cash "&IF(E10<0,"-","+")&TEXT(ABS(E10)*100,"0.0")&"%"))>0,LEN(IF(F10="","","ebitda "&IF(F10<0,"-","+")&TEXT(ABS(F10)*100,"0.0")&"%"))>0),", ","")&IF(F10="","","ebitda "&IF(F10<0,"-","+")&TEXT(ABS(F10)*100,"0.0")&"%"))>0,LEN(IF(G10="","","revenue "&IF(G10<0,"-","+")&TEXT(ABS(G10)*100,"0.0")&"%"))>0),", ","")&IF(G10="","","revenue "&IF(G10<0,"-","+")&TEXT(ABS(G10)*100,"0.0")&"%"))>0,LEN(IF(H10="","","gross_margin "&IF(H10<0,"-","+")&TEXT(ABS(H10)*100,"0.0")&"%"))>0),", ","")&IF(H10="","","gross_margin "&IF(H10<0,"-","+")&TEXT(ABS(H10)*100,"0.0")&"%")&" |") | R10: =IF(Q10="","",ROW()-4)
M11: =IF(OR(E11="",I11="",E11=-1),"",I11/(1+E11)) | N11: =IF(OR(F11="",J11="",F11=-1),"",J11/(1+F11)) | O11: =IF(OR(G11="",K11="",G11=-1),"",K11/(1+G11)) | P11: =IF(OR(H11="",L11="",H11=-1),"",L11/(1+H11)) | Q11: =IF(OR(A11="",LOWER(C11)<>"y"),"","| "&A11&" | "&TEXT(D11,"0.0000")&" | "&IF(E11="","","ending_cash "&IF(E11<0,"-","+")&TEXT(ABS(E11)*100,"0.0")&"%")&IF(AND(LEN(IF(E11="","","ending_cash "&IF(E11<0,"-","+")&TEXT(ABS(E11)*100,"0.0")&"%"))>0,LEN(IF(F11="","","ebitda "&IF(F11<0,"-","+")&TEXT(ABS(F11)*100,"0.0")&"%"))>0),", ","")&IF(F11="","","ebitda "&IF(F11<0,"-","+")&TEXT(ABS(F11)*100,"0.0")&"%")&IF(AND(LEN(IF(E11="","","ending_cash "&IF(E11<0,"-","+")&TEXT(ABS(E11)*100,"0.0")&"%")&IF(AND(LEN(IF(E11="","","ending_cash "&IF(E11<0,"-","+")&TEXT(ABS(E11)*100,"0.0")&"%"))>0,LEN(IF(F11="","","ebitda "&IF(F11<0,"-","+")&TEXT(ABS(F11)*100,"0.0")&"%"))>0),", ","")&IF(F11="","","ebitda "&IF(F11<0,"-","+")&TEXT(ABS(F11)*100,"0.0")&"%"))>0,LEN(IF(G11="","","revenue "&IF(G11<0,"-","+")&TEXT(ABS(G11)*100,"0.0")&"%"))>0),", ","")&IF(G11="","","revenue "&IF(G11<0,"-","+")&TEXT(ABS(G11)*100,"0.0")&"%")&IF(AND(LEN(IF(E11="","","ending_cash "&IF(E11<0,"-","+")&TEXT(ABS(E11)*100,"0.0")&"%")&IF(AND(LEN(IF(E11="","","ending_cash "&IF(E11<0,"-","+")&TEXT(ABS(E11)*100,"0.0")&"%"))>0,LEN(IF(F11="","","ebitda "&IF(F11<0,"-","+")&TEXT(ABS(F11)*100,"0.0")&"%"))>0),", ","")&IF(F11="","","ebitda "&IF(F11<0,"-","+")&TEXT(ABS(F11)*100,"0.0")&"%")&IF(AND(LEN(IF(E11="","","ending_cash "&IF(E11<0,"-","+")&TEXT(ABS(E11)*100,"0.0")&"%")&IF(AND(LEN(IF(E11="","","ending_cash "&IF(E11<0,"-","+")&TEXT(ABS(E11)*100,"0.0")&"%"))>0,LEN(IF(F11="","","ebitda "&IF(F11<0,"-","+")&TEXT(ABS(F11)*100,"0.0")&"%"))>0),", ","")&IF(F11="","","ebitda "&IF(F11<0,"-","+")&TEXT(ABS(F11)*100,"0.0")&"%"))>0,LEN(IF(G11="","","revenue "&IF(G11<0,"-","+")&TEXT(ABS(G11)*100,"0.0")&"%"))>0),", ","")&IF(G11="","","revenue "&IF(G11<0,"-","+")&TEXT(ABS(G11)*100,"0.0")&"%"))>0,LEN(IF(H11="","","gross_margin "&IF(H11<0,"-","+")&TEXT(ABS(H11)*100,"0.0")&"%"))>0),", ","")&IF(H11="","","gross_margin "&IF(H11<0,"-","+")&TEXT(ABS(H11)*100,"0.0")&"%")&" |") | R11: =IF(Q11="","",ROW()-4)
M12: =IF(OR(E12="",I12="",E12=-1),"",I12/(1+E12)) | N12: =IF(OR(F12="",J12="",F12=-1),"",J12/(1+F12)) | O12: =IF(OR(G12="",K12="",G12=-1),"",K12/(1+G12)) | P12: =IF(OR(H12="",L12="",H12=-1),"",L12/(1+H12)) | Q12: =IF(OR(A12="",LOWER(C12)<>"y"),"","| "&A12&" | "&TEXT(D12,"0.0000")&" | "&IF(E12="","","ending_cash "&IF(E12<0,"-","+")&TEXT(ABS(E12)*100,"0.0")&"%")&IF(AND(LEN(IF(E12="","","ending_cash "&IF(E12<0,"-","+")&TEXT(ABS(E12)*100,"0.0")&"%"))>0,LEN(IF(F12="","","ebitda "&IF(F12<0,"-","+")&TEXT(ABS(F12)*100,"0.0")&"%"))>0),", ","")&IF(F12="","","ebitda "&IF(F12<0,"-","+")&TEXT(ABS(F12)*100,"0.0")&"%")&IF(AND(LEN(IF(E12="","","ending_cash "&IF(E12<0,"-","+")&TEXT(ABS(E12)*100,"0.0")&"%")&IF(AND(LEN(IF(E12="","","ending_cash "&IF(E12<0,"-","+")&TEXT(ABS(E12)*100,"0.0")&"%"))>0,LEN(IF(F12="","","ebitda "&IF(F12<0,"-","+")&TEXT(ABS(F12)*100,"0.0")&"%"))>0),", ","")&IF(F12="","","ebitda "&IF(F12<0,"-","+")&TEXT(ABS(F12)*100,"0.0")&"%"))>0,LEN(IF(G12="","","revenue "&IF(G12<0,"-","+")&TEXT(ABS(G12)*100,"0.0")&"%"))>0),", ","")&IF(G12="","","revenue "&IF(G12<0,"-","+")&TEXT(ABS(G12)*100,"0.0")&"%")&IF(AND(LEN(IF(E12="","","ending_cash "&IF(E12<0,"-","+")&TEXT(ABS(E12)*100,"0.0")&"%")&IF(AND(LEN(IF(E12="","","ending_cash "&IF(E12<0,"-","+")&TEXT(ABS(E12)*100,"0.0")&"%"))>0,LEN(IF(F12="","","ebitda "&IF(F12<0,"-","+")&TEXT(ABS(F12)*100,"0.0")&"%"))>0),", ","")&IF(F12="","","ebitda "&IF(F12<0,"-","+")&TEXT(ABS(F12)*100,"0.0")&"%")&IF(AND(LEN(IF(E12="","","ending_cash "&IF(E12<0,"-","+")&TEXT(ABS(E12)*100,"0.0")&"%")&IF(AND(LEN(IF(E12="","","ending_cash "&IF(E12<0,"-","+")&TEXT(ABS(E12)*100,"0.0")&"%"))>0,LEN(IF(F12="","","ebitda "&IF(F12<0,"-","+")&TEXT(ABS(F12)*100,"0.0")&"%"))>0),", ","")&IF(F12="","","ebitda "&IF(F12<0,"-","+")&TEXT(ABS(F12)*100,"0.0")&"%"))>0,LEN(IF(G12="","","revenue "&IF(G12<0,"-","+")&TEXT(ABS(G12)*100,"0.0")&"%"))>0),", ","")&IF(G12="","","revenue "&IF(G12<0,"-","+")&TEXT(ABS(G12)*100,"0.0")&"%"))>0,LEN(IF(H12="","","gross_margin "&IF(H12<0,"-","+")&TEXT(ABS(H12)*100,"0.0")&"%"))>0),", ","")&IF(H12="","","gross_margin "&IF(H12<0,"-","+")&TEXT(ABS(H12)*100,"0.0")&"%")&" |") | R12: =IF(Q12="","",ROW()-4)
M13: =IF(OR(E13="",I13="",E13=-1),"",I13/(1+E13)) | N13: =IF(OR(F13="",J13="",F13=-1),"",J13/(1+F13)) | O13: =IF(OR(G13="",K13="",G13=-1),"",K13/(1+G13)) | P13: =IF(OR(H13="",L13="",H13=-1),"",L13/(1+H13)) | Q13: =IF(OR(A13="",LOWER(C13)<>"y"),"","| "&A13&" | "&TEXT(D13,"0.0000")&" | "&IF(E13="","","ending_cash "&IF(E13<0,"-","+")&TEXT(ABS(E13)*100,"0.0")&"%")&IF(AND(LEN(IF(E13="","","ending_cash "&IF(E13<0,"-","+")&TEXT(ABS(E13)*100,"0.0")&"%"))>0,LEN(IF(F13="","","ebitda "&IF(F13<0,"-","+")&TEXT(ABS(F13)*100,"0.0")&"%"))>0),", ","")&IF(F13="","","ebitda "&IF(F13<0,"-","+")&TEXT(ABS(F13)*100,"0.0")&"%")&IF(AND(LEN(IF(E13="","","ending_cash "&IF(E13<0,"-","+")&TEXT(ABS(E13)*100,"0.0")&"%")&IF(AND(LEN(IF(E13="","","ending_cash "&IF(E13<0,"-","+")&TEXT(ABS(E13)*100,"0.0")&"%"))>0,LEN(IF(F13="","","ebitda "&IF(F13<0,"-","+")&TEXT(ABS(F13)*100,"0.0")&"%"))>0),", ","")&IF(F13="","","ebitda "&IF(F13<0,"-","+")&TEXT(ABS(F13)*100,"0.0")&"%"))>0,LEN(IF(G13="","","revenue "&IF(G13<0,"-","+")&TEXT(ABS(G13)*100,"0.0")&"%"))>0),", ","")&IF(G13="","","revenue "&IF(G13<0,"-","+")&TEXT(ABS(G13)*100,"0.0")&"%")&IF(AND(LEN(IF(E13="","","ending_cash "&IF(E13<0,"-","+")&TEXT(ABS(E13)*100,"0.0")&"%")&IF(AND(LEN(IF(E13="","","ending_cash "&IF(E13<0,"-","+")&TEXT(ABS(E13)*100,"0.0")&"%"))>0,LEN(IF(F13="","","ebitda "&IF(F13<0,"-","+")&TEXT(ABS(F13)*100,"0.0")&"%"))>0),", ","")&IF(F13="","","ebitda "&IF(F13<0,"-","+")&TEXT(ABS(F13)*100,"0.0")&"%")&IF(AND(LEN(IF(E13="","","ending_cash "&IF(E13<0,"-","+")&TEXT(ABS(E13)*100,"0.0")&"%")&IF(AND(LEN(IF(E13="","","ending_cash "&IF(E13<0,"-","+")&TEXT(ABS(E13)*100,"0.0")&"%"))>0,LEN(IF(F13="","","ebitda "&IF(F13<0,"-","+")&TEXT(ABS(F13)*100,"0.0")&"%"))>0),", ","")&IF(F13="","","ebitda "&IF(F13<0,"-","+")&TEXT(ABS(F13)*100,"0.0")&"%"))>0,LEN(IF(G13="","","revenue "&IF(G13<0,"-","+")&TEXT(ABS(G13)*100,"0.0")&"%"))>0),", ","")&IF(G13="","","revenue "&IF(G13<0,"-","+")&TEXT(ABS(G13)*100,"0.0")&"%"))>0,LEN(IF(H13="","","gross_margin "&IF(H13<0,"-","+")&TEXT(ABS(H13)*100,"0.0")&"%"))>0),", ","")&IF(H13="","","gross_margin "&IF(H13<0,"-","+")&TEXT(ABS(H13)*100,"0.0")&"%")&" |") | R13: =IF(Q13="","",ROW()-4)
M14: =IF(OR(E14="",I14="",E14=-1),"",I14/(1+E14)) | N14: =IF(OR(F14="",J14="",F14=-1),"",J14/(1+F14)) | O14: =IF(OR(G14="",K14="",G14=-1),"",K14/(1+G14)) | P14: =IF(OR(H14="",L14="",H14=-1),"",L14/(1+H14)) | Q14: =IF(OR(A14="",LOWER(C14)<>"y"),"","| "&A14&" | "&TEXT(D14,"0.0000")&" | "&IF(E14="","","ending_cash "&IF(E14<0,"-","+")&TEXT(ABS(E14)*100,"0.0")&"%")&IF(AND(LEN(IF(E14="","","ending_cash "&IF(E14<0,"-","+")&TEXT(ABS(E14)*100,"0.0")&"%"))>0,LEN(IF(F14="","","ebitda "&IF(F14<0,"-","+")&TEXT(ABS(F14)*100,"0.0")&"%"))>0),", ","")&IF(F14="","","ebitda "&IF(F14<0,"-","+")&TEXT(ABS(F14)*100,"0.0")&"%")&IF(AND(LEN(IF(E14="","","ending_cash "&IF(E14<0,"-","+")&TEXT(ABS(E14)*100,"0.0")&"%")&IF(AND(LEN(IF(E14="","","ending_cash "&IF(E14<0,"-","+")&TEXT(ABS(E14)*100,"0.0")&"%"))>0,LEN(IF(F14="","","ebitda "&IF(F14<0,"-","+")&TEXT(ABS(F14)*100,"0.0")&"%"))>0),", ","")&IF(F14="","","ebitda "&IF(F14<0,"-","+")&TEXT(ABS(F14)*100,"0.0")&"%"))>0,LEN(IF(G14="","","revenue "&IF(G14<0,"-","+")&TEXT(ABS(G14)*100,"0.0")&"%"))>0),", ","")&IF(G14="","","revenue "&IF(G14<0,"-","+")&TEXT(ABS(G14)*100,"0.0")&"%")&IF(AND(LEN(IF(E14="","","ending_cash "&IF(E14<0,"-","+")&TEXT(ABS(E14)*100,"0.0")&"%")&IF(AND(LEN(IF(E14="","","ending_cash "&IF(E14<0,"-","+")&TEXT(ABS(E14)*100,"0.0")&"%"))>0,LEN(IF(F14="","","ebitda "&IF(F14<0,"-","+")&TEXT(ABS(F14)*100,"0.0")&"%"))>0),", ","")&IF(F14="","","ebitda "&IF(F14<0,"-","+")&TEXT(ABS(F14)*100,"0.0")&"%")&IF(AND(LEN(IF(E14="","","ending_cash "&IF(E14<0,"-","+")&TEXT(ABS(E14)*100,"0.0")&"%")&IF(AND(LEN(IF(E14="","","ending_cash "&IF(E14<0,"-","+")&TEXT(ABS(E14)*100,"0.0")&"%"))>0,LEN(IF(F14="","","ebitda "&IF(F14<0,"-","+")&TEXT(ABS(F14)*100,"0.0")&"%"))>0),", ","")&IF(F14="","","ebitda "&IF(F14<0,"-","+")&TEXT(ABS(F14)*100,"0.0")&"%"))>0,LEN(IF(G14="","","revenue "&IF(G14<0,"-","+")&TEXT(ABS(G14)*100,"0.0")&"%"))>0),", ","")&IF(G14="","","revenue "&IF(G14<0,"-","+")&TEXT(ABS(G14)*100,"0.0")&"%"))>0,LEN(IF(H14="","","gross_margin "&IF(H14<0,"-","+")&TEXT(ABS(H14)*100,"0.0")&"%"))>0),", ","")&IF(H14="","","gross_margin "&IF(H14<0,"-","+")&TEXT(ABS(H14)*100,"0.0")&"%")&" |") | R14: =IF(Q14="","",ROW()-4)
M15: =IF(OR(E15="",I15="",E15=-1),"",I15/(1+E15)) | N15: =IF(OR(F15="",J15="",F15=-1),"",J15/(1+F15)) | O15: =IF(OR(G15="",K15="",G15=-1),"",K15/(1+G15)) | P15: =IF(OR(H15="",L15="",H15=-1),"",L15/(1+H15)) | Q15: =IF(OR(A15="",LOWER(C15)<>"y"),"","| "&A15&" | "&TEXT(D15,"0.0000")&" | "&IF(E15="","","ending_cash "&IF(E15<0,"-","+")&TEXT(ABS(E15)*100,"0.0")&"%")&IF(AND(LEN(IF(E15="","","ending_cash "&IF(E15<0,"-","+")&TEXT(ABS(E15)*100,"0.0")&"%"))>0,LEN(IF(F15="","","ebitda "&IF(F15<0,"-","+")&TEXT(ABS(F15)*100,"0.0")&"%"))>0),", ","")&IF(F15="","","ebitda "&IF(F15<0,"-","+")&TEXT(ABS(F15)*100,"0.0")&"%")&IF(AND(LEN(IF(E15="","","ending_cash "&IF(E15<0,"-","+")&TEXT(ABS(E15)*100,"0.0")&"%")&IF(AND(LEN(IF(E15="","","ending_cash "&IF(E15<0,"-","+")&TEXT(ABS(E15)*100,"0.0")&"%"))>0,LEN(IF(F15="","","ebitda "&IF(F15<0,"-","+")&TEXT(ABS(F15)*100,"0.0")&"%"))>0),", ","")&IF(F15="","","ebitda "&IF(F15<0,"-","+")&TEXT(ABS(F15)*100,"0.0")&"%"))>0,LEN(IF(G15="","","revenue "&IF(G15<0,"-","+")&TEXT(ABS(G15)*100,"0.0")&"%"))>0),", ","")&IF(G15="","","revenue "&IF(G15<0,"-","+")&TEXT(ABS(G15)*100,"0.0")&"%")&IF(AND(LEN(IF(E15="","","ending_cash "&IF(E15<0,"-","+")&TEXT(ABS(E15)*100,"0.0")&"%")&IF(AND(LEN(IF(E15="","","ending_cash "&IF(E15<0,"-","+")&TEXT(ABS(E15)*100,"0.0")&"%"))>0,LEN(IF(F15="","","ebitda "&IF(F15<0,"-","+")&TEXT(ABS(F15)*100,"0.0")&"%"))>0),", ","")&IF(F15="","","ebitda "&IF(F15<0,"-","+")&TEXT(ABS(F15)*100,"0.0")&"%")&IF(AND(LEN(IF(E15="","","ending_cash "&IF(E15<0,"-","+")&TEXT(ABS(E15)*100,"0.0")&"%")&IF(AND(LEN(IF(E15="","","ending_cash "&IF(E15<0,"-","+")&TEXT(ABS(E15)*100,"0.0")&"%"))>0,LEN(IF(F15="","","ebitda "&IF(F15<0,"-","+")&TEXT(ABS(F15)*100,"0.0")&"%"))>0),", ","")&IF(F15="","","ebitda "&IF(F15<0,"-","+")&TEXT(ABS(F15)*100,"0.0")&"%"))>0,LEN(IF(G15="","","revenue "&IF(G15<0,"-","+")&TEXT(ABS(G15)*100,"0.0")&"%"))>0),", ","")&IF(G15="","","revenue "&IF(G15<0,"-","+")&TEXT(ABS(G15)*100,"0.0")&"%"))>0,LEN(IF(H15="","","gross_margin "&IF(H15<0,"-","+")&TEXT(ABS(H15)*100,"0.0")&"%"))>0),", ","")&IF(H15="","","gross_margin "&IF(H15<0,"-","+")&TEXT(ABS(H15)*100,"0.0")&"%")&" |") | R15: =IF(Q15="","",ROW()-4)
M16: =IF(OR(E16="",I16="",E16=-1),"",I16/(1+E16)) | N16: =IF(OR(F16="",J16="",F16=-1),"",J16/(1+F16)) | O16: =IF(OR(G16="",K16="",G16=-1),"",K16/(1+G16)) | P16: =IF(OR(H16="",L16="",H16=-1),"",L16/(1+H16)) | Q16: =IF(OR(A16="",LOWER(C16)<>"y"),"","| "&A16&" | "&TEXT(D16,"0.0000")&" | "&IF(E16="","","ending_cash "&IF(E16<0,"-","+")&TEXT(ABS(E16)*100,"0.0")&"%")&IF(AND(LEN(IF(E16="","","ending_cash "&IF(E16<0,"-","+")&TEXT(ABS(E16)*100,"0.0")&"%"))>0,LEN(IF(F16="","","ebitda "&IF(F16<0,"-","+")&TEXT(ABS(F16)*100,"0.0")&"%"))>0),", ","")&IF(F16="","","ebitda "&IF(F16<0,"-","+")&TEXT(ABS(F16)*100,"0.0")&"%")&IF(AND(LEN(IF(E16="","","ending_cash "&IF(E16<0,"-","+")&TEXT(ABS(E16)*100,"0.0")&"%")&IF(AND(LEN(IF(E16="","","ending_cash "&IF(E16<0,"-","+")&TEXT(ABS(E16)*100,"0.0")&"%"))>0,LEN(IF(F16="","","ebitda "&IF(F16<0,"-","+")&TEXT(ABS(F16)*100,"0.0")&"%"))>0),", ","")&IF(F16="","","ebitda "&IF(F16<0,"-","+")&TEXT(ABS(F16)*100,"0.0")&"%"))>0,LEN(IF(G16="","","revenue "&IF(G16<0,"-","+")&TEXT(ABS(G16)*100,"0.0")&"%"))>0),", ","")&IF(G16="","","revenue "&IF(G16<0,"-","+")&TEXT(ABS(G16)*100,"0.0")&"%")&IF(AND(LEN(IF(E16="","","ending_cash "&IF(E16<0,"-","+")&TEXT(ABS(E16)*100,"0.0")&"%")&IF(AND(LEN(IF(E16="","","ending_cash "&IF(E16<0,"-","+")&TEXT(ABS(E16)*100,"0.0")&"%"))>0,LEN(IF(F16="","","ebitda "&IF(F16<0,"-","+")&TEXT(ABS(F16)*100,"0.0")&"%"))>0),", ","")&IF(F16="","","ebitda "&IF(F16<0,"-","+")&TEXT(ABS(F16)*100,"0.0")&"%")&IF(AND(LEN(IF(E16="","","ending_cash "&IF(E16<0,"-","+")&TEXT(ABS(E16)*100,"0.0")&"%")&IF(AND(LEN(IF(E16="","","ending_cash "&IF(E16<0,"-","+")&TEXT(ABS(E16)*100,"0.0")&"%"))>0,LEN(IF(F16="","","ebitda "&IF(F16<0,"-","+")&TEXT(ABS(F16)*100,"0.0")&"%"))>0),", ","")&IF(F16="","","ebitda "&IF(F16<0,"-","+")&TEXT(ABS(F16)*100,"0.0")&"%"))>0,LEN(IF(G16="","","revenue "&IF(G16<0,"-","+")&TEXT(ABS(G16)*100,"0.0")&"%"))>0),", ","")&IF(G16="","","revenue "&IF(G16<0,"-","+")&TEXT(ABS(G16)*100,"0.0")&"%"))>0,LEN(IF(H16="","","gross_margin "&IF(H16<0,"-","+")&TEXT(ABS(H16)*100,"0.0")&"%"))>0),", ","")&IF(H16="","","gross_margin "&IF(H16<0,"-","+")&TEXT(ABS(H16)*100,"0.0")&"%")&" |") | R16: =IF(Q16="","",ROW()-4)
... M104: =IF(OR(E104="",I104="",E104=-1),"",I104/(1+E104)) | N104: =IF(OR(F104="",J104="",F104=-1),"",J104/(1+F104)) | O104: =IF(OR(G104="",K104="",G104=-1),"",K104/(1+G104)) | P104: =IF(OR(H104="",L104="",H104=-1),"",L104/(1+H104)) | Q104: =IF(OR(A104="",LOWER(C104)<>"y"),"","| "&A104&" | "&TEXT(D104,"0.0000")&" | "&IF(E104="","","ending_cash "&IF(E104<0,"-","+")&TEXT(ABS(E104)*100,"0.0")&"%")&IF(AND(LEN(IF(E104="","","ending_cash "&IF(E104<0,"-","+")&TEXT(ABS(E104)*100,"0.0")&"%"))>0,LEN(IF(F104="","","ebitda "&IF(F104<0,"-","+")&TEXT(ABS(F104)*100,"0.0")&"%"))>0),", ","")&IF(F104="","","ebitda "&IF(F104<0,"-","+")&TEXT(ABS(F104)*100,"0.0")&"%")&IF(AND(LEN(IF(E104="","","ending_cash "&IF(E104<0,"-","+")&TEXT(ABS(E104)*100,"0.0")&"%")&IF(AND(LEN(IF(E104="","","ending_cash "&IF(E104<0,"-","+")&TEXT(ABS(E104)*100,"0.0")&"%"))>0,LEN(IF(F104="","","ebitda "&IF(F104<0,"-","+")&TEXT(ABS(F104)*100,"0.0")&"%"))>0),", ","")&IF(F104="","","ebitda "&IF(F104<0,"-","+")&TEXT(ABS(F104)*100,"0.0")&"%"))>0,LEN(IF(G104="","","revenue "&IF(G104<0,"-","+")&TEXT(ABS(G104)*100,"0.0")&"%"))>0),", ","")&IF(G104="","","revenue "&IF(G104<0,"-","+")&TEXT(ABS(G104)*100,"0.0")&"%")&IF(AND(LEN(IF(E104="","","ending_cash "&IF(E104<0,"-","+")&TEXT(ABS(E104)*100,"0.0")&"%")&IF(AND(LEN(IF(E104="","","ending_cash "&IF(E104<0,"-","+")&TEXT(ABS(E104)*100,"0.0")&"%"))>0,LEN(IF(F104="","","ebitda "&IF(F104<0,"-","+")&TEXT(ABS(F104)*100,"0.0")&"%"))>0),", ","")&IF(F104="","","ebitda "&IF(F104<0,"-","+")&TEXT(ABS(F104)*100,"0.0")&"%")&IF(AND(LEN(IF(E104="","","ending_cash "&IF(E104<0,"-","+")&TEXT(ABS(E104)*100,"0.0")&"%")&IF(AND(LEN(IF(E104="","","ending_cash "&IF(E104<0,"-","+")&TEXT(ABS(E104)*100,"0.0")&"%"))>0,LEN(IF(F104="","","ebitda "&IF(F104<0,"-","+")&TEXT(ABS(F104)*100,"0.0")&"%"))>0),", ","")&IF(F104="","","ebitda "&IF(F104<0,"-","+")&TEXT(ABS(F104)*100,"0.0")&"%"))>0,LEN(IF(G104="","","revenue "&IF(G104<0,"-","+")&TEXT(ABS(G104)*100,"0.0")&"%"))>0),", ","")&IF(G104="","","revenue "&IF(G104<0,"-","+")&TEXT(ABS(G104)*100,"0.0")&"%"))>0,LEN(IF(H104="","","gross_margin "&IF(H104<0,"-","+")&TEXT(ABS(H104)*100,"0.0")&"%"))>0),", ","")&IF(H104="","","gross_margin "&IF(H104<0,"-","+")&TEXT(ABS(H104)*100,"0.0")&"%")&" |") | R104: =IF(Q104="","",ROW()-4)

Sheet Scorecard
A1: Scorecard markdown (paste column A rows 4+ into memory/scorecard.md; never hand-edit that file)
A4: # Forecast Scorecard
A6: | Period | Fitness (lower=better) | Per-line error |
A7: |---|--:|---|
A8: =IFERROR(INDEX(Snapshots!$Q$5:$Q$104,SMALL(Snapshots!$R$5:$R$104,1)),"")
A9: =IFERROR(INDEX(Snapshots!$Q$5:$Q$104,SMALL(Snapshots!$R$5:$R$104,2)),"")
A10: =IFERROR(INDEX(Snapshots!$Q$5:$Q$104,SMALL(Snapshots!$R$5:$R$104,3)),"")
A11: =IFERROR(INDEX(Snapshots!$Q$5:$Q$104,SMALL(Snapshots!$R$5:$R$104,4)),"")
A12: =IFERROR(INDEX(Snapshots!$Q$5:$Q$104,SMALL(Snapshots!$R$5:$R$104,5)),"")
A13: =IFERROR(INDEX(Snapshots!$Q$5:$Q$104,SMALL(Snapshots!$R$5:$R$104,6)),"")
A14: =IFERROR(INDEX(Snapshots!$Q$5:$Q$104,SMALL(Snapshots!$R$5:$R$104,7)),"")
A15: =IFERROR(INDEX(Snapshots!$Q$5:$Q$104,SMALL(Snapshots!$R$5:$R$104,8)),"")
A16: =IFERROR(INDEX(Snapshots!$Q$5:$Q$104,SMALL(Snapshots!$R$5:$R$104,9)),"")
A17: =IFERROR(INDEX(Snapshots!$Q$5:$Q$104,SMALL(Snapshots!$R$5:$R$104,10)),"")
A18: =IFERROR(INDEX(Snapshots!$Q$5:$Q$104,SMALL(Snapshots!$R$5:$R$104,11)),"")
A19: =IFERROR(INDEX(Snapshots!$Q$5:$Q$104,SMALL(Snapshots!$R$5:$R$104,12)),"")
A20: =IFERROR(INDEX(Snapshots!$Q$5:$Q$104,SMALL(Snapshots!$R$5:$R$104,13)),"")
A21: =IFERROR(INDEX(Snapshots!$Q$5:$Q$104,SMALL(Snapshots!$R$5:$R$104,14)),"")
A22: =IFERROR(INDEX(Snapshots!$Q$5:$Q$104,SMALL(Snapshots!$R$5:$R$104,15)),"")
A23: =IFERROR(INDEX(Snapshots!$Q$5:$Q$104,SMALL(Snapshots!$R$5:$R$104,16)),"")
A24: =IFERROR(INDEX(Snapshots!$Q$5:$Q$104,SMALL(Snapshots!$R$5:$R$104,17)),"")
A25: =IFERROR(INDEX(Snapshots!$Q$5:$Q$104,SMALL(Snapshots!$R$5:$R$104,18)),"")
A26: =IFERROR(INDEX(Snapshots!$Q$5:$Q$104,SMALL(Snapshots!$R$5:$R$104,19)),"")
A27: =IFERROR(INDEX(Snapshots!$Q$5:$Q$104,SMALL(Snapshots!$R$5:$R$104,20)),"")
A28: =IFERROR(INDEX(Snapshots!$Q$5:$Q$104,SMALL(Snapshots!$R$5:$R$104,21)),"")
A29: =IFERROR(INDEX(Snapshots!$Q$5:$Q$104,SMALL(Snapshots!$R$5:$R$104,22)),"")
A30: =IFERROR(INDEX(Snapshots!$Q$5:$Q$104,SMALL(Snapshots!$R$5:$R$104,23)),"")
A31: =IFERROR(INDEX(Snapshots!$Q$5:$Q$104,SMALL(Snapshots!$R$5:$R$104,24)),"")
A32: =IFERROR(INDEX(Snapshots!$Q$5:$Q$104,SMALL(Snapshots!$R$5:$R$104,25)),"")
A33: =IFERROR(INDEX(Snapshots!$Q$5:$Q$104,SMALL(Snapshots!$R$5:$R$104,26)),"")
A34: =IFERROR(INDEX(Snapshots!$Q$5:$Q$104,SMALL(Snapshots!$R$5:$R$104,27)),"")
A35: =IFERROR(INDEX(Snapshots!$Q$5:$Q$104,SMALL(Snapshots!$R$5:$R$104,28)),"")
A36: =IFERROR(INDEX(Snapshots!$Q$5:$Q$104,SMALL(Snapshots!$R$5:$R$104,29)),"")
A37: =IFERROR(INDEX(Snapshots!$Q$5:$Q$104,SMALL(Snapshots!$R$5:$R$104,30)),"")
A38: =IFERROR(INDEX(Snapshots!$Q$5:$Q$104,SMALL(Snapshots!$R$5:$R$104,31)),"")
A39: =IFERROR(INDEX(Snapshots!$Q$5:$Q$104,SMALL(Snapshots!$R$5:$R$104,32)),"")
A40: =IFERROR(INDEX(Snapshots!$Q$5:$Q$104,SMALL(Snapshots!$R$5:$R$104,33)),"")
A41: =IFERROR(INDEX(Snapshots!$Q$5:$Q$104,SMALL(Snapshots!$R$5:$R$104,34)),"")
A42: =IFERROR(INDEX(Snapshots!$Q$5:$Q$104,SMALL(Snapshots!$R$5:$R$104,35)),"")
A43: =IFERROR(INDEX(Snapshots!$Q$5:$Q$104,SMALL(Snapshots!$R$5:$R$104,36)),"")
...

Sheet Learning_Guards
A1: persistent_miss and magnitude_cap
A3: K (closes) | B3: 2
A4: threshold (absolute error) | B4: 0
J5: helper: scored errors in order per line (values) and their ordinal
A6: line | B6: scored snapshots | C6: last K same sign & > threshold (persistent_miss) | D6: signs of last K | J6: err ending_cash | K6: err ebitda | L6: err revenue | M6: err gross_margin | N6: ordinal ending_cash | O6: ordinal ebitda | P6: ordinal revenue | Q6: ordinal gross_margin
A7: ending_cash | B7: =COUNT(Snapshots!$E$5:$E$104) | C7: =IF(B7<$B$3,FALSE,OR(COUNTIFS(J$7:J$106,">"&$B$4,N$7:N$106,">"&(B7-$B$3))=$B$3,COUNTIFS(J$7:J$106,"<"&-$B$4,N$7:N$106,">"&(B7-$B$3))=$B$3)) | J7: =IF(ISNUMBER(Snapshots!E5),Snapshots!E5,"") | K7: =IF(ISNUMBER(Snapshots!F5),Snapshots!F5,"") | L7: =IF(ISNUMBER(Snapshots!G5),Snapshots!G5,"") | M7: =IF(ISNUMBER(Snapshots!H5),Snapshots!H5,"") | N7: =IF(ISNUMBER(Snapshots!E5),COUNT(Snapshots!$E$5:E5),"") | O7: =IF(ISNUMBER(Snapshots!F5),COUNT(Snapshots!$F$5:F5),"") | P7: =IF(ISNUMBER(Snapshots!G5),COUNT(Snapshots!$G$5:G5),"") | Q7: =IF(ISNUMBER(Snapshots!H5),COUNT(Snapshots!$H$5:H5),"")
A8: ebitda | B8: =COUNT(Snapshots!$F$5:$F$104) | C8: =IF(B8<$B$3,FALSE,OR(COUNTIFS(K$7:K$106,">"&$B$4,O$7:O$106,">"&(B8-$B$3))=$B$3,COUNTIFS(K$7:K$106,"<"&-$B$4,O$7:O$106,">"&(B8-$B$3))=$B$3)) | J8: =IF(ISNUMBER(Snapshots!E6),Snapshots!E6,"") | K8: =IF(ISNUMBER(Snapshots!F6),Snapshots!F6,"") | L8: =IF(ISNUMBER(Snapshots!G6),Snapshots!G6,"") | M8: =IF(ISNUMBER(Snapshots!H6),Snapshots!H6,"") | N8: =IF(ISNUMBER(Snapshots!E6),COUNT(Snapshots!$E$5:E6),"") | O8: =IF(ISNUMBER(Snapshots!F6),COUNT(Snapshots!$F$5:F6),"") | P8: =IF(ISNUMBER(Snapshots!G6),COUNT(Snapshots!$G$5:G6),"") | Q8: =IF(ISNUMBER(Snapshots!H6),COUNT(Snapshots!$H$5:H6),"")
A9: revenue | B9: =COUNT(Snapshots!$G$5:$G$104) | C9: =IF(B9<$B$3,FALSE,OR(COUNTIFS(L$7:L$106,">"&$B$4,P$7:P$106,">"&(B9-$B$3))=$B$3,COUNTIFS(L$7:L$106,"<"&-$B$4,P$7:P$106,">"&(B9-$B$3))=$B$3)) | J9: =IF(ISNUMBER(Snapshots!E7),Snapshots!E7,"") | K9: =IF(ISNUMBER(Snapshots!F7),Snapshots!F7,"") | L9: =IF(ISNUMBER(Snapshots!G7),Snapshots!G7,"") | M9: =IF(ISNUMBER(Snapshots!H7),Snapshots!H7,"") | N9: =IF(ISNUMBER(Snapshots!E7),COUNT(Snapshots!$E$5:E7),"") | O9: =IF(ISNUMBER(Snapshots!F7),COUNT(Snapshots!$F$5:F7),"") | P9: =IF(ISNUMBER(Snapshots!G7),COUNT(Snapshots!$G$5:G7),"") | Q9: =IF(ISNUMBER(Snapshots!H7),COUNT(Snapshots!$H$5:H7),"")
A10: gross_margin | B10: =COUNT(Snapshots!$H$5:$H$104) | C10: =IF(B10<$B$3,FALSE,OR(COUNTIFS(M$7:M$106,">"&$B$4,Q$7:Q$106,">"&(B10-$B$3))=$B$3,COUNTIFS(M$7:M$106,"<"&-$B$4,Q$7:Q$106,">"&(B10-$B$3))=$B$3)) | J10: =IF(ISNUMBER(Snapshots!E8),Snapshots!E8,"") | K10: =IF(ISNUMBER(Snapshots!F8),Snapshots!F8,"") | L10: =IF(ISNUMBER(Snapshots!G8),Snapshots!G8,"") | M10: =IF(ISNUMBER(Snapshots!H8),Snapshots!H8,"") | N10: =IF(ISNUMBER(Snapshots!E8),COUNT(Snapshots!$E$5:E8),"") | O10: =IF(ISNUMBER(Snapshots!F8),COUNT(Snapshots!$F$5:F8),"") | P10: =IF(ISNUMBER(Snapshots!G8),COUNT(Snapshots!$G$5:G8),"") | Q10: =IF(ISNUMBER(Snapshots!H8),COUNT(Snapshots!$H$5:H8),"")
J11: =IF(ISNUMBER(Snapshots!E9),Snapshots!E9,"") | K11: =IF(ISNUMBER(Snapshots!F9),Snapshots!F9,"") | L11: =IF(ISNUMBER(Snapshots!G9),Snapshots!G9,"") | M11: =IF(ISNUMBER(Snapshots!H9),Snapshots!H9,"") | N11: =IF(ISNUMBER(Snapshots!E9),COUNT(Snapshots!$E$5:E9),"") | O11: =IF(ISNUMBER(Snapshots!F9),COUNT(Snapshots!$F$5:F9),"") | P11: =IF(ISNUMBER(Snapshots!G9),COUNT(Snapshots!$G$5:G9),"") | Q11: =IF(ISNUMBER(Snapshots!H9),COUNT(Snapshots!$H$5:H9),"")
J12: =IF(ISNUMBER(Snapshots!E10),Snapshots!E10,"") | K12: =IF(ISNUMBER(Snapshots!F10),Snapshots!F10,"") | L12: =IF(ISNUMBER(Snapshots!G10),Snapshots!G10,"") | M12: =IF(ISNUMBER(Snapshots!H10),Snapshots!H10,"") | N12: =IF(ISNUMBER(Snapshots!E10),COUNT(Snapshots!$E$5:E10),"") | O12: =IF(ISNUMBER(Snapshots!F10),COUNT(Snapshots!$F$5:F10),"") | P12: =IF(ISNUMBER(Snapshots!G10),COUNT(Snapshots!$G$5:G10),"") | Q12: =IF(ISNUMBER(Snapshots!H10),COUNT(Snapshots!$H$5:H10),"")
A13: magnitude_cap | B13: value | J13: =IF(ISNUMBER(Snapshots!E11),Snapshots!E11,"") | K13: =IF(ISNUMBER(Snapshots!F11),Snapshots!F11,"") | L13: =IF(ISNUMBER(Snapshots!G11),Snapshots!G11,"") | M13: =IF(ISNUMBER(Snapshots!H11),Snapshots!H11,"") | N13: =IF(ISNUMBER(Snapshots!E11),COUNT(Snapshots!$E$5:E11),"") | O13: =IF(ISNUMBER(Snapshots!F11),COUNT(Snapshots!$F$5:F11),"") | P13: =IF(ISNUMBER(Snapshots!G11),COUNT(Snapshots!$G$5:G11),"") | Q13: =IF(ISNUMBER(Snapshots!H11),COUNT(Snapshots!$H$5:H11),"")
A14: old value | J14: =IF(ISNUMBER(Snapshots!E12),Snapshots!E12,"") | K14: =IF(ISNUMBER(Snapshots!F12),Snapshots!F12,"") | L14: =IF(ISNUMBER(Snapshots!G12),Snapshots!G12,"") | M14: =IF(ISNUMBER(Snapshots!H12),Snapshots!H12,"") | N14: =IF(ISNUMBER(Snapshots!E12),COUNT(Snapshots!$E$5:E12),"") | O14: =IF(ISNUMBER(Snapshots!F12),COUNT(Snapshots!$F$5:F12),"") | P14: =IF(ISNUMBER(Snapshots!G12),COUNT(Snapshots!$G$5:G12),"") | Q14: =IF(ISNUMBER(Snapshots!H12),COUNT(Snapshots!$H$5:H12),"")
A15: proposed new value | J15: =IF(ISNUMBER(Snapshots!E13),Snapshots!E13,"") | K15: =IF(ISNUMBER(Snapshots!F13),Snapshots!F13,"") | L15: =IF(ISNUMBER(Snapshots!G13),Snapshots!G13,"") | M15: =IF(ISNUMBER(Snapshots!H13),Snapshots!H13,"") | N15: =IF(ISNUMBER(Snapshots!E13),COUNT(Snapshots!$E$5:E13),"") | O15: =IF(ISNUMBER(Snapshots!F13),COUNT(Snapshots!$F$5:F13),"") | P15: =IF(ISNUMBER(Snapshots!G13),COUNT(Snapshots!$G$5:G13),"") | Q15: =IF(ISNUMBER(Snapshots!H13),COUNT(Snapshots!$H$5:H13),"")
A16: cap (relative) | B16: 0.25 | J16: =IF(ISNUMBER(Snapshots!E14),Snapshots!E14,"") | K16: =IF(ISNUMBER(Snapshots!F14),Snapshots!F14,"") | L16: =IF(ISNUMBER(Snapshots!G14),Snapshots!G14,"") | M16: =IF(ISNUMBER(Snapshots!H14),Snapshots!H14,"") | N16: =IF(ISNUMBER(Snapshots!E14),COUNT(Snapshots!$E$5:E14),"") | O16: =IF(ISNUMBER(Snapshots!F14),COUNT(Snapshots!$F$5:F14),"") | P16: =IF(ISNUMBER(Snapshots!G14),COUNT(Snapshots!$G$5:G14),"") | Q16: =IF(ISNUMBER(Snapshots!H14),COUNT(Snapshots!$H$5:H14),"")
A17: capped value (use this) | B17: =IF(N(B14)=0,B15,MAX(MIN(B14*(1-B16),B14*(1+B16)),MIN(B15,MAX(B14*(1-B16),B14*(1+B16))))) | J17: =IF(ISNUMBER(Snapshots!E15),Snapshots!E15,"") | K17: =IF(ISNUMBER(Snapshots!F15),Snapshots!F15,"") | L17: =IF(ISNUMBER(Snapshots!G15),Snapshots!G15,"") | M17: =IF(ISNUMBER(Snapshots!H15),Snapshots!H15,"") | N17: =IF(ISNUMBER(Snapshots!E15),COUNT(Snapshots!$E$5:E15),"") | O17: =IF(ISNUMBER(Snapshots!F15),COUNT(Snapshots!$F$5:F15),"") | P17: =IF(ISNUMBER(Snapshots!G15),COUNT(Snapshots!$G$5:G15),"") | Q17: =IF(ISNUMBER(Snapshots!H15),COUNT(Snapshots!$H$5:H15),"")
J18: =IF(ISNUMBER(Snapshots!E16),Snapshots!E16,"") | K18: =IF(ISNUMBER(Snapshots!F16),Snapshots!F16,"") | L18: =IF(ISNUMBER(Snapshots!G16),Snapshots!G16,"") | M18: =IF(ISNUMBER(Snapshots!H16),Snapshots!H16,"") | N18: =IF(ISNUMBER(Snapshots!E16),COUNT(Snapshots!$E$5:E16),"") | O18: =IF(ISNUMBER(Snapshots!F16),COUNT(Snapshots!$F$5:F16),"") | P18: =IF(ISNUMBER(Snapshots!G16),COUNT(Snapshots!$G$5:G16),"") | Q18: =IF(ISNUMBER(Snapshots!H16),COUNT(Snapshots!$H$5:H16),"")
J19: =IF(ISNUMBER(Snapshots!E17),Snapshots!E17,"") | K19: =IF(ISNUMBER(Snapshots!F17),Snapshots!F17,"") | L19: =IF(ISNUMBER(Snapshots!G17),Snapshots!G17,"") | M19: =IF(ISNUMBER(Snapshots!H17),Snapshots!H17,"") | N19: =IF(ISNUMBER(Snapshots!E17),COUNT(Snapshots!$E$5:E17),"") | O19: =IF(ISNUMBER(Snapshots!F17),COUNT(Snapshots!$F$5:F17),"") | P19: =IF(ISNUMBER(Snapshots!G17),COUNT(Snapshots!$G$5:G17),"") | Q19: =IF(ISNUMBER(Snapshots!H17),COUNT(Snapshots!$H$5:H17),"")
J20: =IF(ISNUMBER(Snapshots!E18),Snapshots!E18,"") | K20: =IF(ISNUMBER(Snapshots!F18),Snapshots!F18,"") | L20: =IF(ISNUMBER(Snapshots!G18),Snapshots!G18,"") | M20: =IF(ISNUMBER(Snapshots!H18),Snapshots!H18,"") | N20: =IF(ISNUMBER(Snapshots!E18),COUNT(Snapshots!$E$5:E18),"") | O20: =IF(ISNUMBER(Snapshots!F18),COUNT(Snapshots!$F$5:F18),"") | P20: =IF(ISNUMBER(Snapshots!G18),COUNT(Snapshots!$G$5:G18),"") | Q20: =IF(ISNUMBER(Snapshots!H18),COUNT(Snapshots!$H$5:H18),"")
J21: =IF(ISNUMBER(Snapshots!E19),Snapshots!E19,"") | K21: =IF(ISNUMBER(Snapshots!F19),Snapshots!F19,"") | L21: =IF(ISNUMBER(Snapshots!G19),Snapshots!G19,"") | M21: =IF(ISNUMBER(Snapshots!H19),Snapshots!H19,"") | N21: =IF(ISNUMBER(Snapshots!E19),COUNT(Snapshots!$E$5:E19),"") | O21: =IF(ISNUMBER(Snapshots!F19),COUNT(Snapshots!$F$5:F19),"") | P21: =IF(ISNUMBER(Snapshots!G19),COUNT(Snapshots!$G$5:G19),"") | Q21: =IF(ISNUMBER(Snapshots!H19),COUNT(Snapshots!$H$5:H19),"")
J22: =IF(ISNUMBER(Snapshots!E20),Snapshots!E20,"") | K22: =IF(ISNUMBER(Snapshots!F20),Snapshots!F20,"") | L22: =IF(ISNUMBER(Snapshots!G20),Snapshots!G20,"") | M22: =IF(ISNUMBER(Snapshots!H20),Snapshots!H20,"") | N22: =IF(ISNUMBER(Snapshots!E20),COUNT(Snapshots!$E$5:E20),"") | O22: =IF(ISNUMBER(Snapshots!F20),COUNT(Snapshots!$F$5:F20),"") | P22: =IF(ISNUMBER(Snapshots!G20),COUNT(Snapshots!$G$5:G20),"") | Q22: =IF(ISNUMBER(Snapshots!H20),COUNT(Snapshots!$H$5:H20),"")
J23: =IF(ISNUMBER(Snapshots!E21),Snapshots!E21,"") | K23: =IF(ISNUMBER(Snapshots!F21),Snapshots!F21,"") | L23: =IF(ISNUMBER(Snapshots!G21),Snapshots!G21,"") | M23: =IF(ISNUMBER(Snapshots!H21),Snapshots!H21,"") | N23: =IF(ISNUMBER(Snapshots!E21),COUNT(Snapshots!$E$5:E21),"") | O23: =IF(ISNUMBER(Snapshots!F21),COUNT(Snapshots!$F$5:F21),"") | P23: =IF(ISNUMBER(Snapshots!G21),COUNT(Snapshots!$G$5:G21),"") | Q23: =IF(ISNUMBER(Snapshots!H21),COUNT(Snapshots!$H$5:H21),"")
J24: =IF(ISNUMBER(Snapshots!E22),Snapshots!E22,"") | K24: =IF(ISNUMBER(Snapshots!F22),Snapshots!F22,"") | L24: =IF(ISNUMBER(Snapshots!G22),Snapshots!G22,"") | M24: =IF(ISNUMBER(Snapshots!H22),Snapshots!H22,"") | N24: =IF(ISNUMBER(Snapshots!E22),COUNT(Snapshots!$E$5:E22),"") | O24: =IF(ISNUMBER(Snapshots!F22),COUNT(Snapshots!$F$5:F22),"") | P24: =IF(ISNUMBER(Snapshots!G22),COUNT(Snapshots!$G$5:G22),"") | Q24: =IF(ISNUMBER(Snapshots!H22),COUNT(Snapshots!$H$5:H22),"")
J25: =IF(ISNUMBER(Snapshots!E23),Snapshots!E23,"") | K25: =IF(ISNUMBER(Snapshots!F23),Snapshots!F23,"") | L25: =IF(ISNUMBER(Snapshots!G23),Snapshots!G23,"") | M25: =IF(ISNUMBER(Snapshots!H23),Snapshots!H23,"") | N25: =IF(ISNUMBER(Snapshots!E23),COUNT(Snapshots!$E$5:E23),"") | O25: =IF(ISNUMBER(Snapshots!F23),COUNT(Snapshots!$F$5:F23),"") | P25: =IF(ISNUMBER(Snapshots!G23),COUNT(Snapshots!$G$5:G23),"") | Q25: =IF(ISNUMBER(Snapshots!H23),COUNT(Snapshots!$H$5:H23),"")
J26: =IF(ISNUMBER(Snapshots!E24),Snapshots!E24,"") | K26: =IF(ISNUMBER(Snapshots!F24),Snapshots!F24,"") | L26: =IF(ISNUMBER(Snapshots!G24),Snapshots!G24,"") | M26: =IF(ISNUMBER(Snapshots!H24),Snapshots!H24,"") | N26: =IF(ISNUMBER(Snapshots!E24),COUNT(Snapshots!$E$5:E24),"") | O26: =IF(ISNUMBER(Snapshots!F24),COUNT(Snapshots!$F$5:F24),"") | P26: =IF(ISNUMBER(Snapshots!G24),COUNT(Snapshots!$G$5:G24),"") | Q26: =IF(ISNUMBER(Snapshots!H24),COUNT(Snapshots!$H$5:H24),"")
J27: =IF(ISNUMBER(Snapshots!E25),Snapshots!E25,"") | K27: =IF(ISNUMBER(Snapshots!F25),Snapshots!F25,"") | L27: =IF(ISNUMBER(Snapshots!G25),Snapshots!G25,"") | M27: =IF(ISNUMBER(Snapshots!H25),Snapshots!H25,"") | N27: =IF(ISNUMBER(Snapshots!E25),COUNT(Snapshots!$E$5:E25),"") | O27: =IF(ISNUMBER(Snapshots!F25),COUNT(Snapshots!$F$5:F25),"") | P27: =IF(ISNUMBER(Snapshots!G25),COUNT(Snapshots!$G$5:G25),"") | Q27: =IF(ISNUMBER(Snapshots!H25),COUNT(Snapshots!$H$5:H25),"")
J28: =IF(ISNUMBER(Snapshots!E26),Snapshots!E26,"") | K28: =IF(ISNUMBER(Snapshots!F26),Snapshots!F26,"") | L28: =IF(ISNUMBER(Snapshots!G26),Snapshots!G26,"") | M28: =IF(ISNUMBER(Snapshots!H26),Snapshots!H26,"") | N28: =IF(ISNUMBER(Snapshots!E26),COUNT(Snapshots!$E$5:E26),"") | O28: =IF(ISNUMBER(Snapshots!F26),COUNT(Snapshots!$F$5:F26),"") | P28: =IF(ISNUMBER(Snapshots!G26),COUNT(Snapshots!$G$5:G26),"") | Q28: =IF(ISNUMBER(Snapshots!H26),COUNT(Snapshots!$H$5:H26),"")
J29: =IF(ISNUMBER(Snapshots!E27),Snapshots!E27,"") | K29: =IF(ISNUMBER(Snapshots!F27),Snapshots!F27,"") | L29: =IF(ISNUMBER(Snapshots!G27),Snapshots!G27,"") | M29: =IF(ISNUMBER(Snapshots!H27),Snapshots!H27,"") | N29: =IF(ISNUMBER(Snapshots!E27),COUNT(Snapshots!$E$5:E27),"") | O29: =IF(ISNUMBER(Snapshots!F27),COUNT(Snapshots!$F$5:F27),"") | P29: =IF(ISNUMBER(Snapshots!G27),COUNT(Snapshots!$G$5:G27),"") | Q29: =IF(ISNUMBER(Snapshots!H27),COUNT(Snapshots!$H$5:H27),"")
... J106: =IF(ISNUMBER(Snapshots!E104),Snapshots!E104,"") | K106: =IF(ISNUMBER(Snapshots!F104),Snapshots!F104,"") | L106: =IF(ISNUMBER(Snapshots!G104),Snapshots!G104,"") | M106: =IF(ISNUMBER(Snapshots!H104),Snapshots!H104,"") | N106: =IF(ISNUMBER(Snapshots!E104),COUNT(Snapshots!$E$5:E104),"") | O106: =IF(ISNUMBER(Snapshots!F104),COUNT(Snapshots!$F$5:F104),"") | P106: =IF(ISNUMBER(Snapshots!G104),COUNT(Snapshots!$G$5:G104),"") | Q106: =IF(ISNUMBER(Snapshots!H104),COUNT(Snapshots!$H$5:H104),"")
