Workbook
Name pareto_breakpoint: 'Ranked'!$E$3

Sheet README
A1: K06 · SKU Profitability & Pareto (no-code kernel)
A3: Replaces openfpa: pyfpa.analysis.sku (Sku, sku_profitability, pareto_breakpoint) and the generated sku-profitability skill.
A4: Enter annual units, selling price and unit cost per SKU (up to 300). Revenue = units x price; COGS = units x unit cost; gross profit; gross margin (0 if revenue 0).
A5: 'Ranked' sorts by gross profit DESC (ties keep input order), adds revenue share and cumulative revenue % (Pareto). pareto_breakpoint = number of SKUs whose cumulative revenue first reaches the threshold (default 80%).
A6: Judgment: gross margin here is price minus unit cost only - it excludes marketplace commission (Amazon.in/Flipkart), GST input-credit leakage, returns, freight and fulfilment. Weigh contribution rupees, not just %.

Sheet Checks
A1: Checks - OVERALL must be PASS
B3: OVERALL | C3: =IF(COUNTIF(C5:C7,"PASS")=COUNT(A5:A7),"PASS","FAIL") | D3: =COUNTIF(C5:C7,"PASS")&" pass / "&COUNTIF(C5:C7,"FAIL")&" fail / "&(COUNT(A5:A7)-COUNTIF(C5:C7,"PASS")-COUNTIF(C5:C7,"FAIL"))&" error"
A4: # | B4: check | C4: result | D4: detail
A5: 1 | B5: units, price, unit_cost >= 0 for every SKU | C5: =IF(AND(COUNTIF(SKUs!B5:D304,"<0")=0),"PASS","FAIL")
A6: 2 | B6: SKU names unique | C6: =IF(SUMPRODUCT((SKUs!A5:A304<>"")*(COUNTIF(SKUs!A5:A304,SKUs!A5:A304)>1))=0,"PASS","FAIL")
A7: 3 | B7: cumulative revenue % ends at 100% (when revenue > 0) | C7: =IF(OR(SUM(SKUs!E5:E304)=0,ABS(MAX(Ranked!I6:I305)-1)<1E-9),"PASS","FAIL")

Sheet SKUs
A1: SKU inputs
A4: sku name | B4: units (annual) | C4: price | D4: unit_cost | E4: revenue | F4: cogs | G4: gross_profit | H4: gross_margin | I4: rank by GP (desc, stable)
E5: =IF(A5="","",B5*C5) | F5: =IF(A5="","",B5*D5) | G5: =IF(A5="","",E5-F5) | H5: =IF(A5="","",IF(E5=0,0,G5/E5)) | I5: =IF(A5="","",COUNTIF($G$5:$G$304,">"&G5)+COUNTIF($G$5:G5,G5))
E6: =IF(A6="","",B6*C6) | F6: =IF(A6="","",B6*D6) | G6: =IF(A6="","",E6-F6) | H6: =IF(A6="","",IF(E6=0,0,G6/E6)) | I6: =IF(A6="","",COUNTIF($G$5:$G$304,">"&G6)+COUNTIF($G$5:G6,G6))
E7: =IF(A7="","",B7*C7) | F7: =IF(A7="","",B7*D7) | G7: =IF(A7="","",E7-F7) | H7: =IF(A7="","",IF(E7=0,0,G7/E7)) | I7: =IF(A7="","",COUNTIF($G$5:$G$304,">"&G7)+COUNTIF($G$5:G7,G7))
E8: =IF(A8="","",B8*C8) | F8: =IF(A8="","",B8*D8) | G8: =IF(A8="","",E8-F8) | H8: =IF(A8="","",IF(E8=0,0,G8/E8)) | I8: =IF(A8="","",COUNTIF($G$5:$G$304,">"&G8)+COUNTIF($G$5:G8,G8))
E9: =IF(A9="","",B9*C9) | F9: =IF(A9="","",B9*D9) | G9: =IF(A9="","",E9-F9) | H9: =IF(A9="","",IF(E9=0,0,G9/E9)) | I9: =IF(A9="","",COUNTIF($G$5:$G$304,">"&G9)+COUNTIF($G$5:G9,G9))
E10: =IF(A10="","",B10*C10) | F10: =IF(A10="","",B10*D10) | G10: =IF(A10="","",E10-F10) | H10: =IF(A10="","",IF(E10=0,0,G10/E10)) | I10: =IF(A10="","",COUNTIF($G$5:$G$304,">"&G10)+COUNTIF($G$5:G10,G10))
E11: =IF(A11="","",B11*C11) | F11: =IF(A11="","",B11*D11) | G11: =IF(A11="","",E11-F11) | H11: =IF(A11="","",IF(E11=0,0,G11/E11)) | I11: =IF(A11="","",COUNTIF($G$5:$G$304,">"&G11)+COUNTIF($G$5:G11,G11))
E12: =IF(A12="","",B12*C12) | F12: =IF(A12="","",B12*D12) | G12: =IF(A12="","",E12-F12) | H12: =IF(A12="","",IF(E12=0,0,G12/E12)) | I12: =IF(A12="","",COUNTIF($G$5:$G$304,">"&G12)+COUNTIF($G$5:G12,G12))
E13: =IF(A13="","",B13*C13) | F13: =IF(A13="","",B13*D13) | G13: =IF(A13="","",E13-F13) | H13: =IF(A13="","",IF(E13=0,0,G13/E13)) | I13: =IF(A13="","",COUNTIF($G$5:$G$304,">"&G13)+COUNTIF($G$5:G13,G13))
E14: =IF(A14="","",B14*C14) | F14: =IF(A14="","",B14*D14) | G14: =IF(A14="","",E14-F14) | H14: =IF(A14="","",IF(E14=0,0,G14/E14)) | I14: =IF(A14="","",COUNTIF($G$5:$G$304,">"&G14)+COUNTIF($G$5:G14,G14))
E15: =IF(A15="","",B15*C15) | F15: =IF(A15="","",B15*D15) | G15: =IF(A15="","",E15-F15) | H15: =IF(A15="","",IF(E15=0,0,G15/E15)) | I15: =IF(A15="","",COUNTIF($G$5:$G$304,">"&G15)+COUNTIF($G$5:G15,G15))
E16: =IF(A16="","",B16*C16) | F16: =IF(A16="","",B16*D16) | G16: =IF(A16="","",E16-F16) | H16: =IF(A16="","",IF(E16=0,0,G16/E16)) | I16: =IF(A16="","",COUNTIF($G$5:$G$304,">"&G16)+COUNTIF($G$5:G16,G16))
... E304: =IF(A304="","",B304*C304) | F304: =IF(A304="","",B304*D304) | G304: =IF(A304="","",E304-F304) | H304: =IF(A304="","",IF(E304=0,0,G304/E304)) | I304: =IF(A304="","",COUNTIF($G$5:$G$304,">"&G304)+COUNTIF($G$5:G304,G304))

Sheet Ranked
A1: Ranked by gross profit (sku_profitability output)
A3: Pareto threshold | B3: 0.8 | D3: pareto_breakpoint (SKU count) | E3: =IF(COUNT(A6:A305)=0,0,IFERROR(MATCH(1,J6:J305,0),COUNT(A6:A305)))
A5: rank | B5: sku | C5: units | D5: revenue | E5: cogs | F5: gross_profit | G5: gross_margin | H5: revenue_share | I5: cumulative_revenue_pct | J5: reaches threshold?
A6: =IF(1>COUNT(SKUs!$I$5:$I$304),"",1) | B6: =IF(A6="","",INDEX(SKUs!$A$5:$A$304,MATCH(A6,SKUs!$I$5:$I$304,0))) | C6: =IF(A6="","",INDEX(SKUs!$B$5:$B$304,MATCH(A6,SKUs!$I$5:$I$304,0))) | D6: =IF(A6="","",INDEX(SKUs!$E$5:$E$304,MATCH(A6,SKUs!$I$5:$I$304,0))) | E6: =IF(A6="","",INDEX(SKUs!$F$5:$F$304,MATCH(A6,SKUs!$I$5:$I$304,0))) | F6: =IF(A6="","",INDEX(SKUs!$G$5:$G$304,MATCH(A6,SKUs!$I$5:$I$304,0))) | G6: =IF(A6="","",INDEX(SKUs!$H$5:$H$304,MATCH(A6,SKUs!$I$5:$I$304,0))) | H6: =IF(A6="","",IF(SUM(SKUs!$E$5:$E$304)=0,0,D6/SUM(SKUs!$E$5:$E$304))) | I6: =IF(A6="","",SUM($H$6:H6)) | J6: =IF(A6="","",IF(I6>=$B$3,1,0))
A7: =IF(2>COUNT(SKUs!$I$5:$I$304),"",2) | B7: =IF(A7="","",INDEX(SKUs!$A$5:$A$304,MATCH(A7,SKUs!$I$5:$I$304,0))) | C7: =IF(A7="","",INDEX(SKUs!$B$5:$B$304,MATCH(A7,SKUs!$I$5:$I$304,0))) | D7: =IF(A7="","",INDEX(SKUs!$E$5:$E$304,MATCH(A7,SKUs!$I$5:$I$304,0))) | E7: =IF(A7="","",INDEX(SKUs!$F$5:$F$304,MATCH(A7,SKUs!$I$5:$I$304,0))) | F7: =IF(A7="","",INDEX(SKUs!$G$5:$G$304,MATCH(A7,SKUs!$I$5:$I$304,0))) | G7: =IF(A7="","",INDEX(SKUs!$H$5:$H$304,MATCH(A7,SKUs!$I$5:$I$304,0))) | H7: =IF(A7="","",IF(SUM(SKUs!$E$5:$E$304)=0,0,D7/SUM(SKUs!$E$5:$E$304))) | I7: =IF(A7="","",SUM($H$6:H7)) | J7: =IF(A7="","",IF(I7>=$B$3,1,0))
A8: =IF(3>COUNT(SKUs!$I$5:$I$304),"",3) | B8: =IF(A8="","",INDEX(SKUs!$A$5:$A$304,MATCH(A8,SKUs!$I$5:$I$304,0))) | C8: =IF(A8="","",INDEX(SKUs!$B$5:$B$304,MATCH(A8,SKUs!$I$5:$I$304,0))) | D8: =IF(A8="","",INDEX(SKUs!$E$5:$E$304,MATCH(A8,SKUs!$I$5:$I$304,0))) | E8: =IF(A8="","",INDEX(SKUs!$F$5:$F$304,MATCH(A8,SKUs!$I$5:$I$304,0))) | F8: =IF(A8="","",INDEX(SKUs!$G$5:$G$304,MATCH(A8,SKUs!$I$5:$I$304,0))) | G8: =IF(A8="","",INDEX(SKUs!$H$5:$H$304,MATCH(A8,SKUs!$I$5:$I$304,0))) | H8: =IF(A8="","",IF(SUM(SKUs!$E$5:$E$304)=0,0,D8/SUM(SKUs!$E$5:$E$304))) | I8: =IF(A8="","",SUM($H$6:H8)) | J8: =IF(A8="","",IF(I8>=$B$3,1,0))
A9: =IF(4>COUNT(SKUs!$I$5:$I$304),"",4) | B9: =IF(A9="","",INDEX(SKUs!$A$5:$A$304,MATCH(A9,SKUs!$I$5:$I$304,0))) | C9: =IF(A9="","",INDEX(SKUs!$B$5:$B$304,MATCH(A9,SKUs!$I$5:$I$304,0))) | D9: =IF(A9="","",INDEX(SKUs!$E$5:$E$304,MATCH(A9,SKUs!$I$5:$I$304,0))) | E9: =IF(A9="","",INDEX(SKUs!$F$5:$F$304,MATCH(A9,SKUs!$I$5:$I$304,0))) | F9: =IF(A9="","",INDEX(SKUs!$G$5:$G$304,MATCH(A9,SKUs!$I$5:$I$304,0))) | G9: =IF(A9="","",INDEX(SKUs!$H$5:$H$304,MATCH(A9,SKUs!$I$5:$I$304,0))) | H9: =IF(A9="","",IF(SUM(SKUs!$E$5:$E$304)=0,0,D9/SUM(SKUs!$E$5:$E$304))) | I9: =IF(A9="","",SUM($H$6:H9)) | J9: =IF(A9="","",IF(I9>=$B$3,1,0))
A10: =IF(5>COUNT(SKUs!$I$5:$I$304),"",5) | B10: =IF(A10="","",INDEX(SKUs!$A$5:$A$304,MATCH(A10,SKUs!$I$5:$I$304,0))) | C10: =IF(A10="","",INDEX(SKUs!$B$5:$B$304,MATCH(A10,SKUs!$I$5:$I$304,0))) | D10: =IF(A10="","",INDEX(SKUs!$E$5:$E$304,MATCH(A10,SKUs!$I$5:$I$304,0))) | E10: =IF(A10="","",INDEX(SKUs!$F$5:$F$304,MATCH(A10,SKUs!$I$5:$I$304,0))) | F10: =IF(A10="","",INDEX(SKUs!$G$5:$G$304,MATCH(A10,SKUs!$I$5:$I$304,0))) | G10: =IF(A10="","",INDEX(SKUs!$H$5:$H$304,MATCH(A10,SKUs!$I$5:$I$304,0))) | H10: =IF(A10="","",IF(SUM(SKUs!$E$5:$E$304)=0,0,D10/SUM(SKUs!$E$5:$E$304))) | I10: =IF(A10="","",SUM($H$6:H10)) | J10: =IF(A10="","",IF(I10>=$B$3,1,0))
A11: =IF(6>COUNT(SKUs!$I$5:$I$304),"",6) | B11: =IF(A11="","",INDEX(SKUs!$A$5:$A$304,MATCH(A11,SKUs!$I$5:$I$304,0))) | C11: =IF(A11="","",INDEX(SKUs!$B$5:$B$304,MATCH(A11,SKUs!$I$5:$I$304,0))) | D11: =IF(A11="","",INDEX(SKUs!$E$5:$E$304,MATCH(A11,SKUs!$I$5:$I$304,0))) | E11: =IF(A11="","",INDEX(SKUs!$F$5:$F$304,MATCH(A11,SKUs!$I$5:$I$304,0))) | F11: =IF(A11="","",INDEX(SKUs!$G$5:$G$304,MATCH(A11,SKUs!$I$5:$I$304,0))) | G11: =IF(A11="","",INDEX(SKUs!$H$5:$H$304,MATCH(A11,SKUs!$I$5:$I$304,0))) | H11: =IF(A11="","",IF(SUM(SKUs!$E$5:$E$304)=0,0,D11/SUM(SKUs!$E$5:$E$304))) | I11: =IF(A11="","",SUM($H$6:H11)) | J11: =IF(A11="","",IF(I11>=$B$3,1,0))
A12: =IF(7>COUNT(SKUs!$I$5:$I$304),"",7) | B12: =IF(A12="","",INDEX(SKUs!$A$5:$A$304,MATCH(A12,SKUs!$I$5:$I$304,0))) | C12: =IF(A12="","",INDEX(SKUs!$B$5:$B$304,MATCH(A12,SKUs!$I$5:$I$304,0))) | D12: =IF(A12="","",INDEX(SKUs!$E$5:$E$304,MATCH(A12,SKUs!$I$5:$I$304,0))) | E12: =IF(A12="","",INDEX(SKUs!$F$5:$F$304,MATCH(A12,SKUs!$I$5:$I$304,0))) | F12: =IF(A12="","",INDEX(SKUs!$G$5:$G$304,MATCH(A12,SKUs!$I$5:$I$304,0))) | G12: =IF(A12="","",INDEX(SKUs!$H$5:$H$304,MATCH(A12,SKUs!$I$5:$I$304,0))) | H12: =IF(A12="","",IF(SUM(SKUs!$E$5:$E$304)=0,0,D12/SUM(SKUs!$E$5:$E$304))) | I12: =IF(A12="","",SUM($H$6:H12)) | J12: =IF(A12="","",IF(I12>=$B$3,1,0))
A13: =IF(8>COUNT(SKUs!$I$5:$I$304),"",8) | B13: =IF(A13="","",INDEX(SKUs!$A$5:$A$304,MATCH(A13,SKUs!$I$5:$I$304,0))) | C13: =IF(A13="","",INDEX(SKUs!$B$5:$B$304,MATCH(A13,SKUs!$I$5:$I$304,0))) | D13: =IF(A13="","",INDEX(SKUs!$E$5:$E$304,MATCH(A13,SKUs!$I$5:$I$304,0))) | E13: =IF(A13="","",INDEX(SKUs!$F$5:$F$304,MATCH(A13,SKUs!$I$5:$I$304,0))) | F13: =IF(A13="","",INDEX(SKUs!$G$5:$G$304,MATCH(A13,SKUs!$I$5:$I$304,0))) | G13: =IF(A13="","",INDEX(SKUs!$H$5:$H$304,MATCH(A13,SKUs!$I$5:$I$304,0))) | H13: =IF(A13="","",IF(SUM(SKUs!$E$5:$E$304)=0,0,D13/SUM(SKUs!$E$5:$E$304))) | I13: =IF(A13="","",SUM($H$6:H13)) | J13: =IF(A13="","",IF(I13>=$B$3,1,0))
A14: =IF(9>COUNT(SKUs!$I$5:$I$304),"",9) | B14: =IF(A14="","",INDEX(SKUs!$A$5:$A$304,MATCH(A14,SKUs!$I$5:$I$304,0))) | C14: =IF(A14="","",INDEX(SKUs!$B$5:$B$304,MATCH(A14,SKUs!$I$5:$I$304,0))) | D14: =IF(A14="","",INDEX(SKUs!$E$5:$E$304,MATCH(A14,SKUs!$I$5:$I$304,0))) | E14: =IF(A14="","",INDEX(SKUs!$F$5:$F$304,MATCH(A14,SKUs!$I$5:$I$304,0))) | F14: =IF(A14="","",INDEX(SKUs!$G$5:$G$304,MATCH(A14,SKUs!$I$5:$I$304,0))) | G14: =IF(A14="","",INDEX(SKUs!$H$5:$H$304,MATCH(A14,SKUs!$I$5:$I$304,0))) | H14: =IF(A14="","",IF(SUM(SKUs!$E$5:$E$304)=0,0,D14/SUM(SKUs!$E$5:$E$304))) | I14: =IF(A14="","",SUM($H$6:H14)) | J14: =IF(A14="","",IF(I14>=$B$3,1,0))
A15: =IF(10>COUNT(SKUs!$I$5:$I$304),"",10) | B15: =IF(A15="","",INDEX(SKUs!$A$5:$A$304,MATCH(A15,SKUs!$I$5:$I$304,0))) | C15: =IF(A15="","",INDEX(SKUs!$B$5:$B$304,MATCH(A15,SKUs!$I$5:$I$304,0))) | D15: =IF(A15="","",INDEX(SKUs!$E$5:$E$304,MATCH(A15,SKUs!$I$5:$I$304,0))) | E15: =IF(A15="","",INDEX(SKUs!$F$5:$F$304,MATCH(A15,SKUs!$I$5:$I$304,0))) | F15: =IF(A15="","",INDEX(SKUs!$G$5:$G$304,MATCH(A15,SKUs!$I$5:$I$304,0))) | G15: =IF(A15="","",INDEX(SKUs!$H$5:$H$304,MATCH(A15,SKUs!$I$5:$I$304,0))) | H15: =IF(A15="","",IF(SUM(SKUs!$E$5:$E$304)=0,0,D15/SUM(SKUs!$E$5:$E$304))) | I15: =IF(A15="","",SUM($H$6:H15)) | J15: =IF(A15="","",IF(I15>=$B$3,1,0))
A16: =IF(11>COUNT(SKUs!$I$5:$I$304),"",11) | B16: =IF(A16="","",INDEX(SKUs!$A$5:$A$304,MATCH(A16,SKUs!$I$5:$I$304,0))) | C16: =IF(A16="","",INDEX(SKUs!$B$5:$B$304,MATCH(A16,SKUs!$I$5:$I$304,0))) | D16: =IF(A16="","",INDEX(SKUs!$E$5:$E$304,MATCH(A16,SKUs!$I$5:$I$304,0))) | E16: =IF(A16="","",INDEX(SKUs!$F$5:$F$304,MATCH(A16,SKUs!$I$5:$I$304,0))) | F16: =IF(A16="","",INDEX(SKUs!$G$5:$G$304,MATCH(A16,SKUs!$I$5:$I$304,0))) | G16: =IF(A16="","",INDEX(SKUs!$H$5:$H$304,MATCH(A16,SKUs!$I$5:$I$304,0))) | H16: =IF(A16="","",IF(SUM(SKUs!$E$5:$E$304)=0,0,D16/SUM(SKUs!$E$5:$E$304))) | I16: =IF(A16="","",SUM($H$6:H16)) | J16: =IF(A16="","",IF(I16>=$B$3,1,0))
A17: =IF(12>COUNT(SKUs!$I$5:$I$304),"",12) | B17: =IF(A17="","",INDEX(SKUs!$A$5:$A$304,MATCH(A17,SKUs!$I$5:$I$304,0))) | C17: =IF(A17="","",INDEX(SKUs!$B$5:$B$304,MATCH(A17,SKUs!$I$5:$I$304,0))) | D17: =IF(A17="","",INDEX(SKUs!$E$5:$E$304,MATCH(A17,SKUs!$I$5:$I$304,0))) | E17: =IF(A17="","",INDEX(SKUs!$F$5:$F$304,MATCH(A17,SKUs!$I$5:$I$304,0))) | F17: =IF(A17="","",INDEX(SKUs!$G$5:$G$304,MATCH(A17,SKUs!$I$5:$I$304,0))) | G17: =IF(A17="","",INDEX(SKUs!$H$5:$H$304,MATCH(A17,SKUs!$I$5:$I$304,0))) | H17: =IF(A17="","",IF(SUM(SKUs!$E$5:$E$304)=0,0,D17/SUM(SKUs!$E$5:$E$304))) | I17: =IF(A17="","",SUM($H$6:H17)) | J17: =IF(A17="","",IF(I17>=$B$3,1,0))
A18: =IF(13>COUNT(SKUs!$I$5:$I$304),"",13) | B18: =IF(A18="","",INDEX(SKUs!$A$5:$A$304,MATCH(A18,SKUs!$I$5:$I$304,0))) | C18: =IF(A18="","",INDEX(SKUs!$B$5:$B$304,MATCH(A18,SKUs!$I$5:$I$304,0))) | D18: =IF(A18="","",INDEX(SKUs!$E$5:$E$304,MATCH(A18,SKUs!$I$5:$I$304,0))) | E18: =IF(A18="","",INDEX(SKUs!$F$5:$F$304,MATCH(A18,SKUs!$I$5:$I$304,0))) | F18: =IF(A18="","",INDEX(SKUs!$G$5:$G$304,MATCH(A18,SKUs!$I$5:$I$304,0))) | G18: =IF(A18="","",INDEX(SKUs!$H$5:$H$304,MATCH(A18,SKUs!$I$5:$I$304,0))) | H18: =IF(A18="","",IF(SUM(SKUs!$E$5:$E$304)=0,0,D18/SUM(SKUs!$E$5:$E$304))) | I18: =IF(A18="","",SUM($H$6:H18)) | J18: =IF(A18="","",IF(I18>=$B$3,1,0))
A19: =IF(14>COUNT(SKUs!$I$5:$I$304),"",14) | B19: =IF(A19="","",INDEX(SKUs!$A$5:$A$304,MATCH(A19,SKUs!$I$5:$I$304,0))) | C19: =IF(A19="","",INDEX(SKUs!$B$5:$B$304,MATCH(A19,SKUs!$I$5:$I$304,0))) | D19: =IF(A19="","",INDEX(SKUs!$E$5:$E$304,MATCH(A19,SKUs!$I$5:$I$304,0))) | E19: =IF(A19="","",INDEX(SKUs!$F$5:$F$304,MATCH(A19,SKUs!$I$5:$I$304,0))) | F19: =IF(A19="","",INDEX(SKUs!$G$5:$G$304,MATCH(A19,SKUs!$I$5:$I$304,0))) | G19: =IF(A19="","",INDEX(SKUs!$H$5:$H$304,MATCH(A19,SKUs!$I$5:$I$304,0))) | H19: =IF(A19="","",IF(SUM(SKUs!$E$5:$E$304)=0,0,D19/SUM(SKUs!$E$5:$E$304))) | I19: =IF(A19="","",SUM($H$6:H19)) | J19: =IF(A19="","",IF(I19>=$B$3,1,0))
A20: =IF(15>COUNT(SKUs!$I$5:$I$304),"",15) | B20: =IF(A20="","",INDEX(SKUs!$A$5:$A$304,MATCH(A20,SKUs!$I$5:$I$304,0))) | C20: =IF(A20="","",INDEX(SKUs!$B$5:$B$304,MATCH(A20,SKUs!$I$5:$I$304,0))) | D20: =IF(A20="","",INDEX(SKUs!$E$5:$E$304,MATCH(A20,SKUs!$I$5:$I$304,0))) | E20: =IF(A20="","",INDEX(SKUs!$F$5:$F$304,MATCH(A20,SKUs!$I$5:$I$304,0))) | F20: =IF(A20="","",INDEX(SKUs!$G$5:$G$304,MATCH(A20,SKUs!$I$5:$I$304,0))) | G20: =IF(A20="","",INDEX(SKUs!$H$5:$H$304,MATCH(A20,SKUs!$I$5:$I$304,0))) | H20: =IF(A20="","",IF(SUM(SKUs!$E$5:$E$304)=0,0,D20/SUM(SKUs!$E$5:$E$304))) | I20: =IF(A20="","",SUM($H$6:H20)) | J20: =IF(A20="","",IF(I20>=$B$3,1,0))
A21: =IF(16>COUNT(SKUs!$I$5:$I$304),"",16) | B21: =IF(A21="","",INDEX(SKUs!$A$5:$A$304,MATCH(A21,SKUs!$I$5:$I$304,0))) | C21: =IF(A21="","",INDEX(SKUs!$B$5:$B$304,MATCH(A21,SKUs!$I$5:$I$304,0))) | D21: =IF(A21="","",INDEX(SKUs!$E$5:$E$304,MATCH(A21,SKUs!$I$5:$I$304,0))) | E21: =IF(A21="","",INDEX(SKUs!$F$5:$F$304,MATCH(A21,SKUs!$I$5:$I$304,0))) | F21: =IF(A21="","",INDEX(SKUs!$G$5:$G$304,MATCH(A21,SKUs!$I$5:$I$304,0))) | G21: =IF(A21="","",INDEX(SKUs!$H$5:$H$304,MATCH(A21,SKUs!$I$5:$I$304,0))) | H21: =IF(A21="","",IF(SUM(SKUs!$E$5:$E$304)=0,0,D21/SUM(SKUs!$E$5:$E$304))) | I21: =IF(A21="","",SUM($H$6:H21)) | J21: =IF(A21="","",IF(I21>=$B$3,1,0))
A22: =IF(17>COUNT(SKUs!$I$5:$I$304),"",17) | B22: =IF(A22="","",INDEX(SKUs!$A$5:$A$304,MATCH(A22,SKUs!$I$5:$I$304,0))) | C22: =IF(A22="","",INDEX(SKUs!$B$5:$B$304,MATCH(A22,SKUs!$I$5:$I$304,0))) | D22: =IF(A22="","",INDEX(SKUs!$E$5:$E$304,MATCH(A22,SKUs!$I$5:$I$304,0))) | E22: =IF(A22="","",INDEX(SKUs!$F$5:$F$304,MATCH(A22,SKUs!$I$5:$I$304,0))) | F22: =IF(A22="","",INDEX(SKUs!$G$5:$G$304,MATCH(A22,SKUs!$I$5:$I$304,0))) | G22: =IF(A22="","",INDEX(SKUs!$H$5:$H$304,MATCH(A22,SKUs!$I$5:$I$304,0))) | H22: =IF(A22="","",IF(SUM(SKUs!$E$5:$E$304)=0,0,D22/SUM(SKUs!$E$5:$E$304))) | I22: =IF(A22="","",SUM($H$6:H22)) | J22: =IF(A22="","",IF(I22>=$B$3,1,0))
A23: =IF(18>COUNT(SKUs!$I$5:$I$304),"",18) | B23: =IF(A23="","",INDEX(SKUs!$A$5:$A$304,MATCH(A23,SKUs!$I$5:$I$304,0))) | C23: =IF(A23="","",INDEX(SKUs!$B$5:$B$304,MATCH(A23,SKUs!$I$5:$I$304,0))) | D23: =IF(A23="","",INDEX(SKUs!$E$5:$E$304,MATCH(A23,SKUs!$I$5:$I$304,0))) | E23: =IF(A23="","",INDEX(SKUs!$F$5:$F$304,MATCH(A23,SKUs!$I$5:$I$304,0))) | F23: =IF(A23="","",INDEX(SKUs!$G$5:$G$304,MATCH(A23,SKUs!$I$5:$I$304,0))) | G23: =IF(A23="","",INDEX(SKUs!$H$5:$H$304,MATCH(A23,SKUs!$I$5:$I$304,0))) | H23: =IF(A23="","",IF(SUM(SKUs!$E$5:$E$304)=0,0,D23/SUM(SKUs!$E$5:$E$304))) | I23: =IF(A23="","",SUM($H$6:H23)) | J23: =IF(A23="","",IF(I23>=$B$3,1,0))
A24: =IF(19>COUNT(SKUs!$I$5:$I$304),"",19) | B24: =IF(A24="","",INDEX(SKUs!$A$5:$A$304,MATCH(A24,SKUs!$I$5:$I$304,0))) | C24: =IF(A24="","",INDEX(SKUs!$B$5:$B$304,MATCH(A24,SKUs!$I$5:$I$304,0))) | D24: =IF(A24="","",INDEX(SKUs!$E$5:$E$304,MATCH(A24,SKUs!$I$5:$I$304,0))) | E24: =IF(A24="","",INDEX(SKUs!$F$5:$F$304,MATCH(A24,SKUs!$I$5:$I$304,0))) | F24: =IF(A24="","",INDEX(SKUs!$G$5:$G$304,MATCH(A24,SKUs!$I$5:$I$304,0))) | G24: =IF(A24="","",INDEX(SKUs!$H$5:$H$304,MATCH(A24,SKUs!$I$5:$I$304,0))) | H24: =IF(A24="","",IF(SUM(SKUs!$E$5:$E$304)=0,0,D24/SUM(SKUs!$E$5:$E$304))) | I24: =IF(A24="","",SUM($H$6:H24)) | J24: =IF(A24="","",IF(I24>=$B$3,1,0))
A25: =IF(20>COUNT(SKUs!$I$5:$I$304),"",20) | B25: =IF(A25="","",INDEX(SKUs!$A$5:$A$304,MATCH(A25,SKUs!$I$5:$I$304,0))) | C25: =IF(A25="","",INDEX(SKUs!$B$5:$B$304,MATCH(A25,SKUs!$I$5:$I$304,0))) | D25: =IF(A25="","",INDEX(SKUs!$E$5:$E$304,MATCH(A25,SKUs!$I$5:$I$304,0))) | E25: =IF(A25="","",INDEX(SKUs!$F$5:$F$304,MATCH(A25,SKUs!$I$5:$I$304,0))) | F25: =IF(A25="","",INDEX(SKUs!$G$5:$G$304,MATCH(A25,SKUs!$I$5:$I$304,0))) | G25: =IF(A25="","",INDEX(SKUs!$H$5:$H$304,MATCH(A25,SKUs!$I$5:$I$304,0))) | H25: =IF(A25="","",IF(SUM(SKUs!$E$5:$E$304)=0,0,D25/SUM(SKUs!$E$5:$E$304))) | I25: =IF(A25="","",SUM($H$6:H25)) | J25: =IF(A25="","",IF(I25>=$B$3,1,0))
A26: =IF(21>COUNT(SKUs!$I$5:$I$304),"",21) | B26: =IF(A26="","",INDEX(SKUs!$A$5:$A$304,MATCH(A26,SKUs!$I$5:$I$304,0))) | C26: =IF(A26="","",INDEX(SKUs!$B$5:$B$304,MATCH(A26,SKUs!$I$5:$I$304,0))) | D26: =IF(A26="","",INDEX(SKUs!$E$5:$E$304,MATCH(A26,SKUs!$I$5:$I$304,0))) | E26: =IF(A26="","",INDEX(SKUs!$F$5:$F$304,MATCH(A26,SKUs!$I$5:$I$304,0))) | F26: =IF(A26="","",INDEX(SKUs!$G$5:$G$304,MATCH(A26,SKUs!$I$5:$I$304,0))) | G26: =IF(A26="","",INDEX(SKUs!$H$5:$H$304,MATCH(A26,SKUs!$I$5:$I$304,0))) | H26: =IF(A26="","",IF(SUM(SKUs!$E$5:$E$304)=0,0,D26/SUM(SKUs!$E$5:$E$304))) | I26: =IF(A26="","",SUM($H$6:H26)) | J26: =IF(A26="","",IF(I26>=$B$3,1,0))
A27: =IF(22>COUNT(SKUs!$I$5:$I$304),"",22) | B27: =IF(A27="","",INDEX(SKUs!$A$5:$A$304,MATCH(A27,SKUs!$I$5:$I$304,0))) | C27: =IF(A27="","",INDEX(SKUs!$B$5:$B$304,MATCH(A27,SKUs!$I$5:$I$304,0))) | D27: =IF(A27="","",INDEX(SKUs!$E$5:$E$304,MATCH(A27,SKUs!$I$5:$I$304,0))) | E27: =IF(A27="","",INDEX(SKUs!$F$5:$F$304,MATCH(A27,SKUs!$I$5:$I$304,0))) | F27: =IF(A27="","",INDEX(SKUs!$G$5:$G$304,MATCH(A27,SKUs!$I$5:$I$304,0))) | G27: =IF(A27="","",INDEX(SKUs!$H$5:$H$304,MATCH(A27,SKUs!$I$5:$I$304,0))) | H27: =IF(A27="","",IF(SUM(SKUs!$E$5:$E$304)=0,0,D27/SUM(SKUs!$E$5:$E$304))) | I27: =IF(A27="","",SUM($H$6:H27)) | J27: =IF(A27="","",IF(I27>=$B$3,1,0))
A28: =IF(23>COUNT(SKUs!$I$5:$I$304),"",23) | B28: =IF(A28="","",INDEX(SKUs!$A$5:$A$304,MATCH(A28,SKUs!$I$5:$I$304,0))) | C28: =IF(A28="","",INDEX(SKUs!$B$5:$B$304,MATCH(A28,SKUs!$I$5:$I$304,0))) | D28: =IF(A28="","",INDEX(SKUs!$E$5:$E$304,MATCH(A28,SKUs!$I$5:$I$304,0))) | E28: =IF(A28="","",INDEX(SKUs!$F$5:$F$304,MATCH(A28,SKUs!$I$5:$I$304,0))) | F28: =IF(A28="","",INDEX(SKUs!$G$5:$G$304,MATCH(A28,SKUs!$I$5:$I$304,0))) | G28: =IF(A28="","",INDEX(SKUs!$H$5:$H$304,MATCH(A28,SKUs!$I$5:$I$304,0))) | H28: =IF(A28="","",IF(SUM(SKUs!$E$5:$E$304)=0,0,D28/SUM(SKUs!$E$5:$E$304))) | I28: =IF(A28="","",SUM($H$6:H28)) | J28: =IF(A28="","",IF(I28>=$B$3,1,0))
A29: =IF(24>COUNT(SKUs!$I$5:$I$304),"",24) | B29: =IF(A29="","",INDEX(SKUs!$A$5:$A$304,MATCH(A29,SKUs!$I$5:$I$304,0))) | C29: =IF(A29="","",INDEX(SKUs!$B$5:$B$304,MATCH(A29,SKUs!$I$5:$I$304,0))) | D29: =IF(A29="","",INDEX(SKUs!$E$5:$E$304,MATCH(A29,SKUs!$I$5:$I$304,0))) | E29: =IF(A29="","",INDEX(SKUs!$F$5:$F$304,MATCH(A29,SKUs!$I$5:$I$304,0))) | F29: =IF(A29="","",INDEX(SKUs!$G$5:$G$304,MATCH(A29,SKUs!$I$5:$I$304,0))) | G29: =IF(A29="","",INDEX(SKUs!$H$5:$H$304,MATCH(A29,SKUs!$I$5:$I$304,0))) | H29: =IF(A29="","",IF(SUM(SKUs!$E$5:$E$304)=0,0,D29/SUM(SKUs!$E$5:$E$304))) | I29: =IF(A29="","",SUM($H$6:H29)) | J29: =IF(A29="","",IF(I29>=$B$3,1,0))
A30: =IF(25>COUNT(SKUs!$I$5:$I$304),"",25) | B30: =IF(A30="","",INDEX(SKUs!$A$5:$A$304,MATCH(A30,SKUs!$I$5:$I$304,0))) | C30: =IF(A30="","",INDEX(SKUs!$B$5:$B$304,MATCH(A30,SKUs!$I$5:$I$304,0))) | D30: =IF(A30="","",INDEX(SKUs!$E$5:$E$304,MATCH(A30,SKUs!$I$5:$I$304,0))) | E30: =IF(A30="","",INDEX(SKUs!$F$5:$F$304,MATCH(A30,SKUs!$I$5:$I$304,0))) | F30: =IF(A30="","",INDEX(SKUs!$G$5:$G$304,MATCH(A30,SKUs!$I$5:$I$304,0))) | G30: =IF(A30="","",INDEX(SKUs!$H$5:$H$304,MATCH(A30,SKUs!$I$5:$I$304,0))) | H30: =IF(A30="","",IF(SUM(SKUs!$E$5:$E$304)=0,0,D30/SUM(SKUs!$E$5:$E$304))) | I30: =IF(A30="","",SUM($H$6:H30)) | J30: =IF(A30="","",IF(I30>=$B$3,1,0))
A31: =IF(26>COUNT(SKUs!$I$5:$I$304),"",26) | B31: =IF(A31="","",INDEX(SKUs!$A$5:$A$304,MATCH(A31,SKUs!$I$5:$I$304,0))) | C31: =IF(A31="","",INDEX(SKUs!$B$5:$B$304,MATCH(A31,SKUs!$I$5:$I$304,0))) | D31: =IF(A31="","",INDEX(SKUs!$E$5:$E$304,MATCH(A31,SKUs!$I$5:$I$304,0))) | E31: =IF(A31="","",INDEX(SKUs!$F$5:$F$304,MATCH(A31,SKUs!$I$5:$I$304,0))) | F31: =IF(A31="","",INDEX(SKUs!$G$5:$G$304,MATCH(A31,SKUs!$I$5:$I$304,0))) | G31: =IF(A31="","",INDEX(SKUs!$H$5:$H$304,MATCH(A31,SKUs!$I$5:$I$304,0))) | H31: =IF(A31="","",IF(SUM(SKUs!$E$5:$E$304)=0,0,D31/SUM(SKUs!$E$5:$E$304))) | I31: =IF(A31="","",SUM($H$6:H31)) | J31: =IF(A31="","",IF(I31>=$B$3,1,0))
A32: =IF(27>COUNT(SKUs!$I$5:$I$304),"",27) | B32: =IF(A32="","",INDEX(SKUs!$A$5:$A$304,MATCH(A32,SKUs!$I$5:$I$304,0))) | C32: =IF(A32="","",INDEX(SKUs!$B$5:$B$304,MATCH(A32,SKUs!$I$5:$I$304,0))) | D32: =IF(A32="","",INDEX(SKUs!$E$5:$E$304,MATCH(A32,SKUs!$I$5:$I$304,0))) | E32: =IF(A32="","",INDEX(SKUs!$F$5:$F$304,MATCH(A32,SKUs!$I$5:$I$304,0))) | F32: =IF(A32="","",INDEX(SKUs!$G$5:$G$304,MATCH(A32,SKUs!$I$5:$I$304,0))) | G32: =IF(A32="","",INDEX(SKUs!$H$5:$H$304,MATCH(A32,SKUs!$I$5:$I$304,0))) | H32: =IF(A32="","",IF(SUM(SKUs!$E$5:$E$304)=0,0,D32/SUM(SKUs!$E$5:$E$304))) | I32: =IF(A32="","",SUM($H$6:H32)) | J32: =IF(A32="","",IF(I32>=$B$3,1,0))
A33: =IF(28>COUNT(SKUs!$I$5:$I$304),"",28) | B33: =IF(A33="","",INDEX(SKUs!$A$5:$A$304,MATCH(A33,SKUs!$I$5:$I$304,0))) | C33: =IF(A33="","",INDEX(SKUs!$B$5:$B$304,MATCH(A33,SKUs!$I$5:$I$304,0))) | D33: =IF(A33="","",INDEX(SKUs!$E$5:$E$304,MATCH(A33,SKUs!$I$5:$I$304,0))) | E33: =IF(A33="","",INDEX(SKUs!$F$5:$F$304,MATCH(A33,SKUs!$I$5:$I$304,0))) | F33: =IF(A33="","",INDEX(SKUs!$G$5:$G$304,MATCH(A33,SKUs!$I$5:$I$304,0))) | G33: =IF(A33="","",INDEX(SKUs!$H$5:$H$304,MATCH(A33,SKUs!$I$5:$I$304,0))) | H33: =IF(A33="","",IF(SUM(SKUs!$E$5:$E$304)=0,0,D33/SUM(SKUs!$E$5:$E$304))) | I33: =IF(A33="","",SUM($H$6:H33)) | J33: =IF(A33="","",IF(I33>=$B$3,1,0))
A34: =IF(29>COUNT(SKUs!$I$5:$I$304),"",29) | B34: =IF(A34="","",INDEX(SKUs!$A$5:$A$304,MATCH(A34,SKUs!$I$5:$I$304,0))) | C34: =IF(A34="","",INDEX(SKUs!$B$5:$B$304,MATCH(A34,SKUs!$I$5:$I$304,0))) | D34: =IF(A34="","",INDEX(SKUs!$E$5:$E$304,MATCH(A34,SKUs!$I$5:$I$304,0))) | E34: =IF(A34="","",INDEX(SKUs!$F$5:$F$304,MATCH(A34,SKUs!$I$5:$I$304,0))) | F34: =IF(A34="","",INDEX(SKUs!$G$5:$G$304,MATCH(A34,SKUs!$I$5:$I$304,0))) | G34: =IF(A34="","",INDEX(SKUs!$H$5:$H$304,MATCH(A34,SKUs!$I$5:$I$304,0))) | H34: =IF(A34="","",IF(SUM(SKUs!$E$5:$E$304)=0,0,D34/SUM(SKUs!$E$5:$E$304))) | I34: =IF(A34="","",SUM($H$6:H34)) | J34: =IF(A34="","",IF(I34>=$B$3,1,0))
A35: =IF(30>COUNT(SKUs!$I$5:$I$304),"",30) | B35: =IF(A35="","",INDEX(SKUs!$A$5:$A$304,MATCH(A35,SKUs!$I$5:$I$304,0))) | C35: =IF(A35="","",INDEX(SKUs!$B$5:$B$304,MATCH(A35,SKUs!$I$5:$I$304,0))) | D35: =IF(A35="","",INDEX(SKUs!$E$5:$E$304,MATCH(A35,SKUs!$I$5:$I$304,0))) | E35: =IF(A35="","",INDEX(SKUs!$F$5:$F$304,MATCH(A35,SKUs!$I$5:$I$304,0))) | F35: =IF(A35="","",INDEX(SKUs!$G$5:$G$304,MATCH(A35,SKUs!$I$5:$I$304,0))) | G35: =IF(A35="","",INDEX(SKUs!$H$5:$H$304,MATCH(A35,SKUs!$I$5:$I$304,0))) | H35: =IF(A35="","",IF(SUM(SKUs!$E$5:$E$304)=0,0,D35/SUM(SKUs!$E$5:$E$304))) | I35: =IF(A35="","",SUM($H$6:H35)) | J35: =IF(A35="","",IF(I35>=$B$3,1,0))
A36: =IF(31>COUNT(SKUs!$I$5:$I$304),"",31) | B36: =IF(A36="","",INDEX(SKUs!$A$5:$A$304,MATCH(A36,SKUs!$I$5:$I$304,0))) | C36: =IF(A36="","",INDEX(SKUs!$B$5:$B$304,MATCH(A36,SKUs!$I$5:$I$304,0))) | D36: =IF(A36="","",INDEX(SKUs!$E$5:$E$304,MATCH(A36,SKUs!$I$5:$I$304,0))) | E36: =IF(A36="","",INDEX(SKUs!$F$5:$F$304,MATCH(A36,SKUs!$I$5:$I$304,0))) | F36: =IF(A36="","",INDEX(SKUs!$G$5:$G$304,MATCH(A36,SKUs!$I$5:$I$304,0))) | G36: =IF(A36="","",INDEX(SKUs!$H$5:$H$304,MATCH(A36,SKUs!$I$5:$I$304,0))) | H36: =IF(A36="","",IF(SUM(SKUs!$E$5:$E$304)=0,0,D36/SUM(SKUs!$E$5:$E$304))) | I36: =IF(A36="","",SUM($H$6:H36)) | J36: =IF(A36="","",IF(I36>=$B$3,1,0))
A37: =IF(32>COUNT(SKUs!$I$5:$I$304),"",32) | B37: =IF(A37="","",INDEX(SKUs!$A$5:$A$304,MATCH(A37,SKUs!$I$5:$I$304,0))) | C37: =IF(A37="","",INDEX(SKUs!$B$5:$B$304,MATCH(A37,SKUs!$I$5:$I$304,0))) | D37: =IF(A37="","",INDEX(SKUs!$E$5:$E$304,MATCH(A37,SKUs!$I$5:$I$304,0))) | E37: =IF(A37="","",INDEX(SKUs!$F$5:$F$304,MATCH(A37,SKUs!$I$5:$I$304,0))) | F37: =IF(A37="","",INDEX(SKUs!$G$5:$G$304,MATCH(A37,SKUs!$I$5:$I$304,0))) | G37: =IF(A37="","",INDEX(SKUs!$H$5:$H$304,MATCH(A37,SKUs!$I$5:$I$304,0))) | H37: =IF(A37="","",IF(SUM(SKUs!$E$5:$E$304)=0,0,D37/SUM(SKUs!$E$5:$E$304))) | I37: =IF(A37="","",SUM($H$6:H37)) | J37: =IF(A37="","",IF(I37>=$B$3,1,0))
A38: =IF(33>COUNT(SKUs!$I$5:$I$304),"",33) | B38: =IF(A38="","",INDEX(SKUs!$A$5:$A$304,MATCH(A38,SKUs!$I$5:$I$304,0))) | C38: =IF(A38="","",INDEX(SKUs!$B$5:$B$304,MATCH(A38,SKUs!$I$5:$I$304,0))) | D38: =IF(A38="","",INDEX(SKUs!$E$5:$E$304,MATCH(A38,SKUs!$I$5:$I$304,0))) | E38: =IF(A38="","",INDEX(SKUs!$F$5:$F$304,MATCH(A38,SKUs!$I$5:$I$304,0))) | F38: =IF(A38="","",INDEX(SKUs!$G$5:$G$304,MATCH(A38,SKUs!$I$5:$I$304,0))) | G38: =IF(A38="","",INDEX(SKUs!$H$5:$H$304,MATCH(A38,SKUs!$I$5:$I$304,0))) | H38: =IF(A38="","",IF(SUM(SKUs!$E$5:$E$304)=0,0,D38/SUM(SKUs!$E$5:$E$304))) | I38: =IF(A38="","",SUM($H$6:H38)) | J38: =IF(A38="","",IF(I38>=$B$3,1,0))
A39: =IF(34>COUNT(SKUs!$I$5:$I$304),"",34) | B39: =IF(A39="","",INDEX(SKUs!$A$5:$A$304,MATCH(A39,SKUs!$I$5:$I$304,0))) | C39: =IF(A39="","",INDEX(SKUs!$B$5:$B$304,MATCH(A39,SKUs!$I$5:$I$304,0))) | D39: =IF(A39="","",INDEX(SKUs!$E$5:$E$304,MATCH(A39,SKUs!$I$5:$I$304,0))) | E39: =IF(A39="","",INDEX(SKUs!$F$5:$F$304,MATCH(A39,SKUs!$I$5:$I$304,0))) | F39: =IF(A39="","",INDEX(SKUs!$G$5:$G$304,MATCH(A39,SKUs!$I$5:$I$304,0))) | G39: =IF(A39="","",INDEX(SKUs!$H$5:$H$304,MATCH(A39,SKUs!$I$5:$I$304,0))) | H39: =IF(A39="","",IF(SUM(SKUs!$E$5:$E$304)=0,0,D39/SUM(SKUs!$E$5:$E$304))) | I39: =IF(A39="","",SUM($H$6:H39)) | J39: =IF(A39="","",IF(I39>=$B$3,1,0))
A40: =IF(35>COUNT(SKUs!$I$5:$I$304),"",35) | B40: =IF(A40="","",INDEX(SKUs!$A$5:$A$304,MATCH(A40,SKUs!$I$5:$I$304,0))) | C40: =IF(A40="","",INDEX(SKUs!$B$5:$B$304,MATCH(A40,SKUs!$I$5:$I$304,0))) | D40: =IF(A40="","",INDEX(SKUs!$E$5:$E$304,MATCH(A40,SKUs!$I$5:$I$304,0))) | E40: =IF(A40="","",INDEX(SKUs!$F$5:$F$304,MATCH(A40,SKUs!$I$5:$I$304,0))) | F40: =IF(A40="","",INDEX(SKUs!$G$5:$G$304,MATCH(A40,SKUs!$I$5:$I$304,0))) | G40: =IF(A40="","",INDEX(SKUs!$H$5:$H$304,MATCH(A40,SKUs!$I$5:$I$304,0))) | H40: =IF(A40="","",IF(SUM(SKUs!$E$5:$E$304)=0,0,D40/SUM(SKUs!$E$5:$E$304))) | I40: =IF(A40="","",SUM($H$6:H40)) | J40: =IF(A40="","",IF(I40>=$B$3,1,0))
A41: =IF(36>COUNT(SKUs!$I$5:$I$304),"",36) | B41: =IF(A41="","",INDEX(SKUs!$A$5:$A$304,MATCH(A41,SKUs!$I$5:$I$304,0))) | C41: =IF(A41="","",INDEX(SKUs!$B$5:$B$304,MATCH(A41,SKUs!$I$5:$I$304,0))) | D41: =IF(A41="","",INDEX(SKUs!$E$5:$E$304,MATCH(A41,SKUs!$I$5:$I$304,0))) | E41: =IF(A41="","",INDEX(SKUs!$F$5:$F$304,MATCH(A41,SKUs!$I$5:$I$304,0))) | F41: =IF(A41="","",INDEX(SKUs!$G$5:$G$304,MATCH(A41,SKUs!$I$5:$I$304,0))) | G41: =IF(A41="","",INDEX(SKUs!$H$5:$H$304,MATCH(A41,SKUs!$I$5:$I$304,0))) | H41: =IF(A41="","",IF(SUM(SKUs!$E$5:$E$304)=0,0,D41/SUM(SKUs!$E$5:$E$304))) | I41: =IF(A41="","",SUM($H$6:H41)) | J41: =IF(A41="","",IF(I41>=$B$3,1,0))
A42: =IF(37>COUNT(SKUs!$I$5:$I$304),"",37) | B42: =IF(A42="","",INDEX(SKUs!$A$5:$A$304,MATCH(A42,SKUs!$I$5:$I$304,0))) | C42: =IF(A42="","",INDEX(SKUs!$B$5:$B$304,MATCH(A42,SKUs!$I$5:$I$304,0))) | D42: =IF(A42="","",INDEX(SKUs!$E$5:$E$304,MATCH(A42,SKUs!$I$5:$I$304,0))) | E42: =IF(A42="","",INDEX(SKUs!$F$5:$F$304,MATCH(A42,SKUs!$I$5:$I$304,0))) | F42: =IF(A42="","",INDEX(SKUs!$G$5:$G$304,MATCH(A42,SKUs!$I$5:$I$304,0))) | G42: =IF(A42="","",INDEX(SKUs!$H$5:$H$304,MATCH(A42,SKUs!$I$5:$I$304,0))) | H42: =IF(A42="","",IF(SUM(SKUs!$E$5:$E$304)=0,0,D42/SUM(SKUs!$E$5:$E$304))) | I42: =IF(A42="","",SUM($H$6:H42)) | J42: =IF(A42="","",IF(I42>=$B$3,1,0))
...
