Workbook

Sheet README
A1: K09 · Portfolio Learning - priors across same-type clients (no-code kernel)
A3: Replaces openfpa: pyfpa.portfolio (load_portfolio, clients_of_type, best_snapshot, client_driver_value, mine_priors, validate_prior, find_recurring_skills, promote_prior, promote_skill, seed_from_library).
A4: Clients: one row per client workspace listed in portfolio/portfolio.csv with its business type, best (lowest-fitness scored) snapshot and the six mineable driver values from that snapshot - overridden by an APPLIED PARAMETRIC correction on the exact same path.
A5: Mine: for the chosen type, a driver is a prior candidate when >= min_support clients have it AND the coefficient of variation (population stdev / |mean|) <= dispersion_max (default 3 and 0.15; unanimous values = 0). Candidate value = MEDIAN.
A6: Validate (leave-one-out): for each usable client, the peer median (all OTHER same-type clients) is the prior value; re-run that client's K01 copy with the driver overridden, score it with K04 over the SAME lines/weights against recovered actuals, and enter the new fitness. delta = new - original. validated when >= 2 folds and mean delta <= tolerance (default 0).
A7: Skills: a generated skill folder name recurring in >= 3 same-type clients is a candidate. Structural corrections that repeat are an extra human signal.
A8: Everything stays local. Humans ratify every promotion into portfolio/library/ (priors/<type>.csv + library-log.md). Priors are SEEDS; each client's own loop refines them.

Sheet Checks
A1: Checks - OVERALL must be PASS
B3: OVERALL | C3: =IF(COUNTIF(C5:C7,"PASS")=COUNT(A5:A7),"PASS","FAIL") | D3: =COUNTIF(C5:C7,"PASS")&" pass / "&COUNTIF(C5:C7,"FAIL")&" fail / "&(COUNT(A5:A7)-COUNTIF(C5:C7,"PASS")-COUNTIF(C5:C7,"FAIL"))&" error"
A4: # | B4: check | C4: result | D4: detail
A5: 1 | B5: business type chosen | C5: =IF(Setup!B4<>"","PASS","FAIL") | D5: =Setup!B4
A6: 2 | B6: min_support >= 1 and dispersion_max >= 0 | C6: =IF(AND(Setup!B5>=1,Setup!B6>=0),"PASS","FAIL")
A7: 3 | B7: client paths unique | C7: =IF(SUMPRODUCT((Clients!A5:A54<>"")*(COUNTIF(Clients!A5:A54,Clients!A5:A54)>1))=0,"PASS","FAIL")

Sheet Setup
A1: Setup
A4: business type to mine
A5: min_support | B5: 3
A6: dispersion_max (CoV) | B6: 0.15
A7: driver to validate (one of the six) | B7: working_capital.dso_days
A8: validation tolerance | B8: 0

Sheet Clients
A1: Clients (portfolio manifest + best snapshot driver values after applied corrections)
A4: client path | B4: business type | C4: best snapshot label | D4: best fitness | E4: working_capital.dso_days | F4: working_capital.dio_days | G4: working_capital.dpo_days | H4: tax_rate | I4: da_monthly | J4: capex_monthly | K4: of chosen type? | L4: typed working_capital.dso_days | M4: typed working_capital.dio_days | N4: typed working_capital.dpo_days | O4: typed tax_rate | P4: typed da_monthly | Q4: typed capex_monthly
K5: =IF(AND(A5<>"",B5=Setup!$B$4),1,0) | L5: =IF(AND(K5=1,ISNUMBER(E5)),E5,"") | M5: =IF(AND(K5=1,ISNUMBER(F5)),F5,"") | N5: =IF(AND(K5=1,ISNUMBER(G5)),G5,"") | O5: =IF(AND(K5=1,ISNUMBER(H5)),H5,"") | P5: =IF(AND(K5=1,ISNUMBER(I5)),I5,"") | Q5: =IF(AND(K5=1,ISNUMBER(J5)),J5,"")
K6: =IF(AND(A6<>"",B6=Setup!$B$4),1,0) | L6: =IF(AND(K6=1,ISNUMBER(E6)),E6,"") | M6: =IF(AND(K6=1,ISNUMBER(F6)),F6,"") | N6: =IF(AND(K6=1,ISNUMBER(G6)),G6,"") | O6: =IF(AND(K6=1,ISNUMBER(H6)),H6,"") | P6: =IF(AND(K6=1,ISNUMBER(I6)),I6,"") | Q6: =IF(AND(K6=1,ISNUMBER(J6)),J6,"")
K7: =IF(AND(A7<>"",B7=Setup!$B$4),1,0) | L7: =IF(AND(K7=1,ISNUMBER(E7)),E7,"") | M7: =IF(AND(K7=1,ISNUMBER(F7)),F7,"") | N7: =IF(AND(K7=1,ISNUMBER(G7)),G7,"") | O7: =IF(AND(K7=1,ISNUMBER(H7)),H7,"") | P7: =IF(AND(K7=1,ISNUMBER(I7)),I7,"") | Q7: =IF(AND(K7=1,ISNUMBER(J7)),J7,"")
K8: =IF(AND(A8<>"",B8=Setup!$B$4),1,0) | L8: =IF(AND(K8=1,ISNUMBER(E8)),E8,"") | M8: =IF(AND(K8=1,ISNUMBER(F8)),F8,"") | N8: =IF(AND(K8=1,ISNUMBER(G8)),G8,"") | O8: =IF(AND(K8=1,ISNUMBER(H8)),H8,"") | P8: =IF(AND(K8=1,ISNUMBER(I8)),I8,"") | Q8: =IF(AND(K8=1,ISNUMBER(J8)),J8,"")
K9: =IF(AND(A9<>"",B9=Setup!$B$4),1,0) | L9: =IF(AND(K9=1,ISNUMBER(E9)),E9,"") | M9: =IF(AND(K9=1,ISNUMBER(F9)),F9,"") | N9: =IF(AND(K9=1,ISNUMBER(G9)),G9,"") | O9: =IF(AND(K9=1,ISNUMBER(H9)),H9,"") | P9: =IF(AND(K9=1,ISNUMBER(I9)),I9,"") | Q9: =IF(AND(K9=1,ISNUMBER(J9)),J9,"")
K10: =IF(AND(A10<>"",B10=Setup!$B$4),1,0) | L10: =IF(AND(K10=1,ISNUMBER(E10)),E10,"") | M10: =IF(AND(K10=1,ISNUMBER(F10)),F10,"") | N10: =IF(AND(K10=1,ISNUMBER(G10)),G10,"") | O10: =IF(AND(K10=1,ISNUMBER(H10)),H10,"") | P10: =IF(AND(K10=1,ISNUMBER(I10)),I10,"") | Q10: =IF(AND(K10=1,ISNUMBER(J10)),J10,"")
K11: =IF(AND(A11<>"",B11=Setup!$B$4),1,0) | L11: =IF(AND(K11=1,ISNUMBER(E11)),E11,"") | M11: =IF(AND(K11=1,ISNUMBER(F11)),F11,"") | N11: =IF(AND(K11=1,ISNUMBER(G11)),G11,"") | O11: =IF(AND(K11=1,ISNUMBER(H11)),H11,"") | P11: =IF(AND(K11=1,ISNUMBER(I11)),I11,"") | Q11: =IF(AND(K11=1,ISNUMBER(J11)),J11,"")
K12: =IF(AND(A12<>"",B12=Setup!$B$4),1,0) | L12: =IF(AND(K12=1,ISNUMBER(E12)),E12,"") | M12: =IF(AND(K12=1,ISNUMBER(F12)),F12,"") | N12: =IF(AND(K12=1,ISNUMBER(G12)),G12,"") | O12: =IF(AND(K12=1,ISNUMBER(H12)),H12,"") | P12: =IF(AND(K12=1,ISNUMBER(I12)),I12,"") | Q12: =IF(AND(K12=1,ISNUMBER(J12)),J12,"")
K13: =IF(AND(A13<>"",B13=Setup!$B$4),1,0) | L13: =IF(AND(K13=1,ISNUMBER(E13)),E13,"") | M13: =IF(AND(K13=1,ISNUMBER(F13)),F13,"") | N13: =IF(AND(K13=1,ISNUMBER(G13)),G13,"") | O13: =IF(AND(K13=1,ISNUMBER(H13)),H13,"") | P13: =IF(AND(K13=1,ISNUMBER(I13)),I13,"") | Q13: =IF(AND(K13=1,ISNUMBER(J13)),J13,"")
K14: =IF(AND(A14<>"",B14=Setup!$B$4),1,0) | L14: =IF(AND(K14=1,ISNUMBER(E14)),E14,"") | M14: =IF(AND(K14=1,ISNUMBER(F14)),F14,"") | N14: =IF(AND(K14=1,ISNUMBER(G14)),G14,"") | O14: =IF(AND(K14=1,ISNUMBER(H14)),H14,"") | P14: =IF(AND(K14=1,ISNUMBER(I14)),I14,"") | Q14: =IF(AND(K14=1,ISNUMBER(J14)),J14,"")
K15: =IF(AND(A15<>"",B15=Setup!$B$4),1,0) | L15: =IF(AND(K15=1,ISNUMBER(E15)),E15,"") | M15: =IF(AND(K15=1,ISNUMBER(F15)),F15,"") | N15: =IF(AND(K15=1,ISNUMBER(G15)),G15,"") | O15: =IF(AND(K15=1,ISNUMBER(H15)),H15,"") | P15: =IF(AND(K15=1,ISNUMBER(I15)),I15,"") | Q15: =IF(AND(K15=1,ISNUMBER(J15)),J15,"")
K16: =IF(AND(A16<>"",B16=Setup!$B$4),1,0) | L16: =IF(AND(K16=1,ISNUMBER(E16)),E16,"") | M16: =IF(AND(K16=1,ISNUMBER(F16)),F16,"") | N16: =IF(AND(K16=1,ISNUMBER(G16)),G16,"") | O16: =IF(AND(K16=1,ISNUMBER(H16)),H16,"") | P16: =IF(AND(K16=1,ISNUMBER(I16)),I16,"") | Q16: =IF(AND(K16=1,ISNUMBER(J16)),J16,"")
... K54: =IF(AND(A54<>"",B54=Setup!$B$4),1,0) | L54: =IF(AND(K54=1,ISNUMBER(E54)),E54,"") | M54: =IF(AND(K54=1,ISNUMBER(F54)),F54,"") | N54: =IF(AND(K54=1,ISNUMBER(G54)),G54,"") | O54: =IF(AND(K54=1,ISNUMBER(H54)),H54,"") | P54: =IF(AND(K54=1,ISNUMBER(I54)),I54,"") | Q54: =IF(AND(K54=1,ISNUMBER(J54)),J54,"")

Sheet Mine
A1: mine_priors for the chosen type
A4: driver | B4: support (clients with value) | C4: mean | D4: population stdev | E4: CoV | F4: median (prior value) | G4: candidate?
A5: working_capital.dso_days | B5: =SUMPRODUCT(Clients!$K$5:$K$54*ISNUMBER(Clients!$E$5:$E$54)) | C5: =IF(B5=0,"",AVERAGE(Clients!$L$5:$L$54)) | D5: =IF(B5=0,"",STDEVP(Clients!$L$5:$L$54)) | E5: =IF(B5=0,"",IF(D5=0,0,IF(C5=0,"inf",D5/ABS(C5)))) | F5: =IF(B5=0,"",MEDIAN(Clients!$L$5:$L$54)) | G5: =IF(B5=0,FALSE,AND(B5>=Setup!$B$5,E5<>"inf",N(E5)<=Setup!$B$6))
A6: working_capital.dio_days | B6: =SUMPRODUCT(Clients!$K$5:$K$54*ISNUMBER(Clients!$F$5:$F$54)) | C6: =IF(B6=0,"",AVERAGE(Clients!$M$5:$M$54)) | D6: =IF(B6=0,"",STDEVP(Clients!$M$5:$M$54)) | E6: =IF(B6=0,"",IF(D6=0,0,IF(C6=0,"inf",D6/ABS(C6)))) | F6: =IF(B6=0,"",MEDIAN(Clients!$M$5:$M$54)) | G6: =IF(B6=0,FALSE,AND(B6>=Setup!$B$5,E6<>"inf",N(E6)<=Setup!$B$6))
A7: working_capital.dpo_days | B7: =SUMPRODUCT(Clients!$K$5:$K$54*ISNUMBER(Clients!$G$5:$G$54)) | C7: =IF(B7=0,"",AVERAGE(Clients!$N$5:$N$54)) | D7: =IF(B7=0,"",STDEVP(Clients!$N$5:$N$54)) | E7: =IF(B7=0,"",IF(D7=0,0,IF(C7=0,"inf",D7/ABS(C7)))) | F7: =IF(B7=0,"",MEDIAN(Clients!$N$5:$N$54)) | G7: =IF(B7=0,FALSE,AND(B7>=Setup!$B$5,E7<>"inf",N(E7)<=Setup!$B$6))
A8: tax_rate | B8: =SUMPRODUCT(Clients!$K$5:$K$54*ISNUMBER(Clients!$H$5:$H$54)) | C8: =IF(B8=0,"",AVERAGE(Clients!$O$5:$O$54)) | D8: =IF(B8=0,"",STDEVP(Clients!$O$5:$O$54)) | E8: =IF(B8=0,"",IF(D8=0,0,IF(C8=0,"inf",D8/ABS(C8)))) | F8: =IF(B8=0,"",MEDIAN(Clients!$O$5:$O$54)) | G8: =IF(B8=0,FALSE,AND(B8>=Setup!$B$5,E8<>"inf",N(E8)<=Setup!$B$6))
A9: da_monthly | B9: =SUMPRODUCT(Clients!$K$5:$K$54*ISNUMBER(Clients!$I$5:$I$54)) | C9: =IF(B9=0,"",AVERAGE(Clients!$P$5:$P$54)) | D9: =IF(B9=0,"",STDEVP(Clients!$P$5:$P$54)) | E9: =IF(B9=0,"",IF(D9=0,0,IF(C9=0,"inf",D9/ABS(C9)))) | F9: =IF(B9=0,"",MEDIAN(Clients!$P$5:$P$54)) | G9: =IF(B9=0,FALSE,AND(B9>=Setup!$B$5,E9<>"inf",N(E9)<=Setup!$B$6))
A10: capex_monthly | B10: =SUMPRODUCT(Clients!$K$5:$K$54*ISNUMBER(Clients!$J$5:$J$54)) | C10: =IF(B10=0,"",AVERAGE(Clients!$Q$5:$Q$54)) | D10: =IF(B10=0,"",STDEVP(Clients!$Q$5:$Q$54)) | E10: =IF(B10=0,"",IF(D10=0,0,IF(C10=0,"inf",D10/ABS(C10)))) | F10: =IF(B10=0,"",MEDIAN(Clients!$Q$5:$Q$54)) | G10: =IF(B10=0,FALSE,AND(B10>=Setup!$B$5,E10<>"inf",N(E10)<=Setup!$B$6))

Sheet Validate
A1: validate_prior (leave-one-out) for the driver on Setup!B7
J3: helper matrix: values of usable clients excluding the fold row
A4: fold client | B4: usable? (type, snapshot, value) | C4: own value | D4: peer median (prior for this fold) | E4: original fitness | F4: new fitness (enter after re-run) | G4: delta = new - original | J4: fold 1 | K4: fold 2 | L4: fold 3 | M4: fold 4 | N4: fold 5 | O4: fold 6 | P4: fold 7 | Q4: fold 8 | R4: fold 9 | S4: fold 10 | T4: fold 11 | U4: fold 12 | V4: fold 13 | W4: fold 14 | X4: fold 15 | Y4: fold 16 | Z4: fold 17 | AA4: fold 18 | AB4: fold 19 | AC4: fold 20 | AD4: fold 21 | AE4: fold 22 | AF4: fold 23 | AG4: fold 24 | AH4: fold 25 | AI4: fold 26 | AJ4: fold 27 | AK4: fold 28 | AL4: fold 29 | AM4: fold 30 | AN4: fold 31 | AO4: fold 32 | AP4: fold 33 | AQ4: fold 34 | AR4: fold 35 | AS4: fold 36 | AT4: fold 37 | AU4: fold 38 | AV4: fold 39 | AW4: fold 40 | AX4: fold 41 | AY4: fold 42 | AZ4: fold 43 | BA4: fold 44 | BB4: fold 45 | BC4: fold 46 | BD4: fold 47 | BE4: fold 48 | BF4: fold 49 | BG4: fold 50
A5: =IF(Clients!A5="","",Clients!A5) | B5: =IF(A5="",0,IF(AND(Clients!K5=1,ISNUMBER(Clients!D5),ISNUMBER(INDEX(Clients!E5:J5,1,MATCH(Setup!$B$7,Clients!$E$4:$J$4,0)))),1,0)) | C5: =IF(B5=1,INDEX(Clients!E5:J5,1,MATCH(Setup!$B$7,Clients!$E$4:$J$4,0)),"") | D5: =IF(B5<>1,"",IF(COUNT(J5:J54)=0,"",MEDIAN(J5:J54))) | E5: =IF(B5=1,Clients!D5,"") | G5: =IF(AND(B5=1,ISNUMBER(F5)),F5-E5,"") | J5: =IF(OR(0=0,$B$5<>1),"",$C$5) | K5: =IF(OR(0=1,$B$5<>1),"",$C$5) | L5: =IF(OR(0=2,$B$5<>1),"",$C$5) | M5: =IF(OR(0=3,$B$5<>1),"",$C$5) | N5: =IF(OR(0=4,$B$5<>1),"",$C$5) | O5: =IF(OR(0=5,$B$5<>1),"",$C$5) | P5: =IF(OR(0=6,$B$5<>1),"",$C$5) | Q5: =IF(OR(0=7,$B$5<>1),"",$C$5) | R5: =IF(OR(0=8,$B$5<>1),"",$C$5) | S5: =IF(OR(0=9,$B$5<>1),"",$C$5) | T5: =IF(OR(0=10,$B$5<>1),"",$C$5) | U5: =IF(OR(0=11,$B$5<>1),"",$C$5) | V5: =IF(OR(0=12,$B$5<>1),"",$C$5) | W5: =IF(OR(0=13,$B$5<>1),"",$C$5) | X5: =IF(OR(0=14,$B$5<>1),"",$C$5) | Y5: =IF(OR(0=15,$B$5<>1),"",$C$5) | Z5: =IF(OR(0=16,$B$5<>1),"",$C$5) | AA5: =IF(OR(0=17,$B$5<>1),"",$C$5) | AB5: =IF(OR(0=18,$B$5<>1),"",$C$5) | AC5: =IF(OR(0=19,$B$5<>1),"",$C$5) | AD5: =IF(OR(0=20,$B$5<>1),"",$C$5) | AE5: =IF(OR(0=21,$B$5<>1),"",$C$5) | AF5: =IF(OR(0=22,$B$5<>1),"",$C$5) | AG5: =IF(OR(0=23,$B$5<>1),"",$C$5) | AH5: =IF(OR(0=24,$B$5<>1),"",$C$5) | AI5: =IF(OR(0=25,$B$5<>1),"",$C$5) | AJ5: =IF(OR(0=26,$B$5<>1),"",$C$5) | AK5: =IF(OR(0=27,$B$5<>1),"",$C$5) | AL5: =IF(OR(0=28,$B$5<>1),"",$C$5) | AM5: =IF(OR(0=29,$B$5<>1),"",$C$5) | AN5: =IF(OR(0=30,$B$5<>1),"",$C$5) | AO5: =IF(OR(0=31,$B$5<>1),"",$C$5) | AP5: =IF(OR(0=32,$B$5<>1),"",$C$5) | AQ5: =IF(OR(0=33,$B$5<>1),"",$C$5) | AR5: =IF(OR(0=34,$B$5<>1),"",$C$5) | AS5: =IF(OR(0=35,$B$5<>1),"",$C$5) | AT5: =IF(OR(0=36,$B$5<>1),"",$C$5) | AU5: =IF(OR(0=37,$B$5<>1),"",$C$5) | AV5: =IF(OR(0=38,$B$5<>1),"",$C$5) | AW5: =IF(OR(0=39,$B$5<>1),"",$C$5) | AX5: =IF(OR(0=40,$B$5<>1),"",$C$5) | AY5: =IF(OR(0=41,$B$5<>1),"",$C$5) | AZ5: =IF(OR(0=42,$B$5<>1),"",$C$5) | BA5: =IF(OR(0=43,$B$5<>1),"",$C$5) | BB5: =IF(OR(0=44,$B$5<>1),"",$C$5) | BC5: =IF(OR(0=45,$B$5<>1),"",$C$5) | BD5: =IF(OR(0=46,$B$5<>1),"",$C$5) | BE5: =IF(OR(0=47,$B$5<>1),"",$C$5) | BF5: =IF(OR(0=48,$B$5<>1),"",$C$5) | BG5: =IF(OR(0=49,$B$5<>1),"",$C$5)
A6: =IF(Clients!A6="","",Clients!A6) | B6: =IF(A6="",0,IF(AND(Clients!K6=1,ISNUMBER(Clients!D6),ISNUMBER(INDEX(Clients!E6:J6,1,MATCH(Setup!$B$7,Clients!$E$4:$J$4,0)))),1,0)) | C6: =IF(B6=1,INDEX(Clients!E6:J6,1,MATCH(Setup!$B$7,Clients!$E$4:$J$4,0)),"") | D6: =IF(B6<>1,"",IF(COUNT(K5:K54)=0,"",MEDIAN(K5:K54))) | E6: =IF(B6=1,Clients!D6,"") | G6: =IF(AND(B6=1,ISNUMBER(F6)),F6-E6,"") | J6: =IF(OR(1=0,$B$6<>1),"",$C$6) | K6: =IF(OR(1=1,$B$6<>1),"",$C$6) | L6: =IF(OR(1=2,$B$6<>1),"",$C$6) | M6: =IF(OR(1=3,$B$6<>1),"",$C$6) | N6: =IF(OR(1=4,$B$6<>1),"",$C$6) | O6: =IF(OR(1=5,$B$6<>1),"",$C$6) | P6: =IF(OR(1=6,$B$6<>1),"",$C$6) | Q6: =IF(OR(1=7,$B$6<>1),"",$C$6) | R6: =IF(OR(1=8,$B$6<>1),"",$C$6) | S6: =IF(OR(1=9,$B$6<>1),"",$C$6) | T6: =IF(OR(1=10,$B$6<>1),"",$C$6) | U6: =IF(OR(1=11,$B$6<>1),"",$C$6) | V6: =IF(OR(1=12,$B$6<>1),"",$C$6) | W6: =IF(OR(1=13,$B$6<>1),"",$C$6) | X6: =IF(OR(1=14,$B$6<>1),"",$C$6) | Y6: =IF(OR(1=15,$B$6<>1),"",$C$6) | Z6: =IF(OR(1=16,$B$6<>1),"",$C$6) | AA6: =IF(OR(1=17,$B$6<>1),"",$C$6) | AB6: =IF(OR(1=18,$B$6<>1),"",$C$6) | AC6: =IF(OR(1=19,$B$6<>1),"",$C$6) | AD6: =IF(OR(1=20,$B$6<>1),"",$C$6) | AE6: =IF(OR(1=21,$B$6<>1),"",$C$6) | AF6: =IF(OR(1=22,$B$6<>1),"",$C$6) | AG6: =IF(OR(1=23,$B$6<>1),"",$C$6) | AH6: =IF(OR(1=24,$B$6<>1),"",$C$6) | AI6: =IF(OR(1=25,$B$6<>1),"",$C$6) | AJ6: =IF(OR(1=26,$B$6<>1),"",$C$6) | AK6: =IF(OR(1=27,$B$6<>1),"",$C$6) | AL6: =IF(OR(1=28,$B$6<>1),"",$C$6) | AM6: =IF(OR(1=29,$B$6<>1),"",$C$6) | AN6: =IF(OR(1=30,$B$6<>1),"",$C$6) | AO6: =IF(OR(1=31,$B$6<>1),"",$C$6) | AP6: =IF(OR(1=32,$B$6<>1),"",$C$6) | AQ6: =IF(OR(1=33,$B$6<>1),"",$C$6) | AR6: =IF(OR(1=34,$B$6<>1),"",$C$6) | AS6: =IF(OR(1=35,$B$6<>1),"",$C$6) | AT6: =IF(OR(1=36,$B$6<>1),"",$C$6) | AU6: =IF(OR(1=37,$B$6<>1),"",$C$6) | AV6: =IF(OR(1=38,$B$6<>1),"",$C$6) | AW6: =IF(OR(1=39,$B$6<>1),"",$C$6) | AX6: =IF(OR(1=40,$B$6<>1),"",$C$6) | AY6: =IF(OR(1=41,$B$6<>1),"",$C$6) | AZ6: =IF(OR(1=42,$B$6<>1),"",$C$6) | BA6: =IF(OR(1=43,$B$6<>1),"",$C$6) | BB6: =IF(OR(1=44,$B$6<>1),"",$C$6) | BC6: =IF(OR(1=45,$B$6<>1),"",$C$6) | BD6: =IF(OR(1=46,$B$6<>1),"",$C$6) | BE6: =IF(OR(1=47,$B$6<>1),"",$C$6) | BF6: =IF(OR(1=48,$B$6<>1),"",$C$6) | BG6: =IF(OR(1=49,$B$6<>1),"",$C$6)
A7: =IF(Clients!A7="","",Clients!A7) | B7: =IF(A7="",0,IF(AND(Clients!K7=1,ISNUMBER(Clients!D7),ISNUMBER(INDEX(Clients!E7:J7,1,MATCH(Setup!$B$7,Clients!$E$4:$J$4,0)))),1,0)) | C7: =IF(B7=1,INDEX(Clients!E7:J7,1,MATCH(Setup!$B$7,Clients!$E$4:$J$4,0)),"") | D7: =IF(B7<>1,"",IF(COUNT(L5:L54)=0,"",MEDIAN(L5:L54))) | E7: =IF(B7=1,Clients!D7,"") | G7: =IF(AND(B7=1,ISNUMBER(F7)),F7-E7,"") | J7: =IF(OR(2=0,$B$7<>1),"",$C$7) | K7: =IF(OR(2=1,$B$7<>1),"",$C$7) | L7: =IF(OR(2=2,$B$7<>1),"",$C$7) | M7: =IF(OR(2=3,$B$7<>1),"",$C$7) | N7: =IF(OR(2=4,$B$7<>1),"",$C$7) | O7: =IF(OR(2=5,$B$7<>1),"",$C$7) | P7: =IF(OR(2=6,$B$7<>1),"",$C$7) | Q7: =IF(OR(2=7,$B$7<>1),"",$C$7) | R7: =IF(OR(2=8,$B$7<>1),"",$C$7) | S7: =IF(OR(2=9,$B$7<>1),"",$C$7) | T7: =IF(OR(2=10,$B$7<>1),"",$C$7) | U7: =IF(OR(2=11,$B$7<>1),"",$C$7) | V7: =IF(OR(2=12,$B$7<>1),"",$C$7) | W7: =IF(OR(2=13,$B$7<>1),"",$C$7) | X7: =IF(OR(2=14,$B$7<>1),"",$C$7) | Y7: =IF(OR(2=15,$B$7<>1),"",$C$7) | Z7: =IF(OR(2=16,$B$7<>1),"",$C$7) | AA7: =IF(OR(2=17,$B$7<>1),"",$C$7) | AB7: =IF(OR(2=18,$B$7<>1),"",$C$7) | AC7: =IF(OR(2=19,$B$7<>1),"",$C$7) | AD7: =IF(OR(2=20,$B$7<>1),"",$C$7) | AE7: =IF(OR(2=21,$B$7<>1),"",$C$7) | AF7: =IF(OR(2=22,$B$7<>1),"",$C$7) | AG7: =IF(OR(2=23,$B$7<>1),"",$C$7) | AH7: =IF(OR(2=24,$B$7<>1),"",$C$7) | AI7: =IF(OR(2=25,$B$7<>1),"",$C$7) | AJ7: =IF(OR(2=26,$B$7<>1),"",$C$7) | AK7: =IF(OR(2=27,$B$7<>1),"",$C$7) | AL7: =IF(OR(2=28,$B$7<>1),"",$C$7) | AM7: =IF(OR(2=29,$B$7<>1),"",$C$7) | AN7: =IF(OR(2=30,$B$7<>1),"",$C$7) | AO7: =IF(OR(2=31,$B$7<>1),"",$C$7) | AP7: =IF(OR(2=32,$B$7<>1),"",$C$7) | AQ7: =IF(OR(2=33,$B$7<>1),"",$C$7) | AR7: =IF(OR(2=34,$B$7<>1),"",$C$7) | AS7: =IF(OR(2=35,$B$7<>1),"",$C$7) | AT7: =IF(OR(2=36,$B$7<>1),"",$C$7) | AU7: =IF(OR(2=37,$B$7<>1),"",$C$7) | AV7: =IF(OR(2=38,$B$7<>1),"",$C$7) | AW7: =IF(OR(2=39,$B$7<>1),"",$C$7) | AX7: =IF(OR(2=40,$B$7<>1),"",$C$7) | AY7: =IF(OR(2=41,$B$7<>1),"",$C$7) | AZ7: =IF(OR(2=42,$B$7<>1),"",$C$7) | BA7: =IF(OR(2=43,$B$7<>1),"",$C$7) | BB7: =IF(OR(2=44,$B$7<>1),"",$C$7) | BC7: =IF(OR(2=45,$B$7<>1),"",$C$7) | BD7: =IF(OR(2=46,$B$7<>1),"",$C$7) | BE7: =IF(OR(2=47,$B$7<>1),"",$C$7) | BF7: =IF(OR(2=48,$B$7<>1),"",$C$7) | BG7: =IF(OR(2=49,$B$7<>1),"",$C$7)
A8: =IF(Clients!A8="","",Clients!A8) | B8: =IF(A8="",0,IF(AND(Clients!K8=1,ISNUMBER(Clients!D8),ISNUMBER(INDEX(Clients!E8:J8,1,MATCH(Setup!$B$7,Clients!$E$4:$J$4,0)))),1,0)) | C8: =IF(B8=1,INDEX(Clients!E8:J8,1,MATCH(Setup!$B$7,Clients!$E$4:$J$4,0)),"") | D8: =IF(B8<>1,"",IF(COUNT(M5:M54)=0,"",MEDIAN(M5:M54))) | E8: =IF(B8=1,Clients!D8,"") | G8: =IF(AND(B8=1,ISNUMBER(F8)),F8-E8,"") | J8: =IF(OR(3=0,$B$8<>1),"",$C$8) | K8: =IF(OR(3=1,$B$8<>1),"",$C$8) | L8: =IF(OR(3=2,$B$8<>1),"",$C$8) | M8: =IF(OR(3=3,$B$8<>1),"",$C$8) | N8: =IF(OR(3=4,$B$8<>1),"",$C$8) | O8: =IF(OR(3=5,$B$8<>1),"",$C$8) | P8: =IF(OR(3=6,$B$8<>1),"",$C$8) | Q8: =IF(OR(3=7,$B$8<>1),"",$C$8) | R8: =IF(OR(3=8,$B$8<>1),"",$C$8) | S8: =IF(OR(3=9,$B$8<>1),"",$C$8) | T8: =IF(OR(3=10,$B$8<>1),"",$C$8) | U8: =IF(OR(3=11,$B$8<>1),"",$C$8) | V8: =IF(OR(3=12,$B$8<>1),"",$C$8) | W8: =IF(OR(3=13,$B$8<>1),"",$C$8) | X8: =IF(OR(3=14,$B$8<>1),"",$C$8) | Y8: =IF(OR(3=15,$B$8<>1),"",$C$8) | Z8: =IF(OR(3=16,$B$8<>1),"",$C$8) | AA8: =IF(OR(3=17,$B$8<>1),"",$C$8) | AB8: =IF(OR(3=18,$B$8<>1),"",$C$8) | AC8: =IF(OR(3=19,$B$8<>1),"",$C$8) | AD8: =IF(OR(3=20,$B$8<>1),"",$C$8) | AE8: =IF(OR(3=21,$B$8<>1),"",$C$8) | AF8: =IF(OR(3=22,$B$8<>1),"",$C$8) | AG8: =IF(OR(3=23,$B$8<>1),"",$C$8) | AH8: =IF(OR(3=24,$B$8<>1),"",$C$8) | AI8: =IF(OR(3=25,$B$8<>1),"",$C$8) | AJ8: =IF(OR(3=26,$B$8<>1),"",$C$8) | AK8: =IF(OR(3=27,$B$8<>1),"",$C$8) | AL8: =IF(OR(3=28,$B$8<>1),"",$C$8) | AM8: =IF(OR(3=29,$B$8<>1),"",$C$8) | AN8: =IF(OR(3=30,$B$8<>1),"",$C$8) | AO8: =IF(OR(3=31,$B$8<>1),"",$C$8) | AP8: =IF(OR(3=32,$B$8<>1),"",$C$8) | AQ8: =IF(OR(3=33,$B$8<>1),"",$C$8) | AR8: =IF(OR(3=34,$B$8<>1),"",$C$8) | AS8: =IF(OR(3=35,$B$8<>1),"",$C$8) | AT8: =IF(OR(3=36,$B$8<>1),"",$C$8) | AU8: =IF(OR(3=37,$B$8<>1),"",$C$8) | AV8: =IF(OR(3=38,$B$8<>1),"",$C$8) | AW8: =IF(OR(3=39,$B$8<>1),"",$C$8) | AX8: =IF(OR(3=40,$B$8<>1),"",$C$8) | AY8: =IF(OR(3=41,$B$8<>1),"",$C$8) | AZ8: =IF(OR(3=42,$B$8<>1),"",$C$8) | BA8: =IF(OR(3=43,$B$8<>1),"",$C$8) | BB8: =IF(OR(3=44,$B$8<>1),"",$C$8) | BC8: =IF(OR(3=45,$B$8<>1),"",$C$8) | BD8: =IF(OR(3=46,$B$8<>1),"",$C$8) | BE8: =IF(OR(3=47,$B$8<>1),"",$C$8) | BF8: =IF(OR(3=48,$B$8<>1),"",$C$8) | BG8: =IF(OR(3=49,$B$8<>1),"",$C$8)
A9: =IF(Clients!A9="","",Clients!A9) | B9: =IF(A9="",0,IF(AND(Clients!K9=1,ISNUMBER(Clients!D9),ISNUMBER(INDEX(Clients!E9:J9,1,MATCH(Setup!$B$7,Clients!$E$4:$J$4,0)))),1,0)) | C9: =IF(B9=1,INDEX(Clients!E9:J9,1,MATCH(Setup!$B$7,Clients!$E$4:$J$4,0)),"") | D9: =IF(B9<>1,"",IF(COUNT(N5:N54)=0,"",MEDIAN(N5:N54))) | E9: =IF(B9=1,Clients!D9,"") | G9: =IF(AND(B9=1,ISNUMBER(F9)),F9-E9,"") | J9: =IF(OR(4=0,$B$9<>1),"",$C$9) | K9: =IF(OR(4=1,$B$9<>1),"",$C$9) | L9: =IF(OR(4=2,$B$9<>1),"",$C$9) | M9: =IF(OR(4=3,$B$9<>1),"",$C$9) | N9: =IF(OR(4=4,$B$9<>1),"",$C$9) | O9: =IF(OR(4=5,$B$9<>1),"",$C$9) | P9: =IF(OR(4=6,$B$9<>1),"",$C$9) | Q9: =IF(OR(4=7,$B$9<>1),"",$C$9) | R9: =IF(OR(4=8,$B$9<>1),"",$C$9) | S9: =IF(OR(4=9,$B$9<>1),"",$C$9) | T9: =IF(OR(4=10,$B$9<>1),"",$C$9) | U9: =IF(OR(4=11,$B$9<>1),"",$C$9) | V9: =IF(OR(4=12,$B$9<>1),"",$C$9) | W9: =IF(OR(4=13,$B$9<>1),"",$C$9) | X9: =IF(OR(4=14,$B$9<>1),"",$C$9) | Y9: =IF(OR(4=15,$B$9<>1),"",$C$9) | Z9: =IF(OR(4=16,$B$9<>1),"",$C$9) | AA9: =IF(OR(4=17,$B$9<>1),"",$C$9) | AB9: =IF(OR(4=18,$B$9<>1),"",$C$9) | AC9: =IF(OR(4=19,$B$9<>1),"",$C$9) | AD9: =IF(OR(4=20,$B$9<>1),"",$C$9) | AE9: =IF(OR(4=21,$B$9<>1),"",$C$9) | AF9: =IF(OR(4=22,$B$9<>1),"",$C$9) | AG9: =IF(OR(4=23,$B$9<>1),"",$C$9) | AH9: =IF(OR(4=24,$B$9<>1),"",$C$9) | AI9: =IF(OR(4=25,$B$9<>1),"",$C$9) | AJ9: =IF(OR(4=26,$B$9<>1),"",$C$9) | AK9: =IF(OR(4=27,$B$9<>1),"",$C$9) | AL9: =IF(OR(4=28,$B$9<>1),"",$C$9) | AM9: =IF(OR(4=29,$B$9<>1),"",$C$9) | AN9: =IF(OR(4=30,$B$9<>1),"",$C$9) | AO9: =IF(OR(4=31,$B$9<>1),"",$C$9) | AP9: =IF(OR(4=32,$B$9<>1),"",$C$9) | AQ9: =IF(OR(4=33,$B$9<>1),"",$C$9) | AR9: =IF(OR(4=34,$B$9<>1),"",$C$9) | AS9: =IF(OR(4=35,$B$9<>1),"",$C$9) | AT9: =IF(OR(4=36,$B$9<>1),"",$C$9) | AU9: =IF(OR(4=37,$B$9<>1),"",$C$9) | AV9: =IF(OR(4=38,$B$9<>1),"",$C$9) | AW9: =IF(OR(4=39,$B$9<>1),"",$C$9) | AX9: =IF(OR(4=40,$B$9<>1),"",$C$9) | AY9: =IF(OR(4=41,$B$9<>1),"",$C$9) | AZ9: =IF(OR(4=42,$B$9<>1),"",$C$9) | BA9: =IF(OR(4=43,$B$9<>1),"",$C$9) | BB9: =IF(OR(4=44,$B$9<>1),"",$C$9) | BC9: =IF(OR(4=45,$B$9<>1),"",$C$9) | BD9: =IF(OR(4=46,$B$9<>1),"",$C$9) | BE9: =IF(OR(4=47,$B$9<>1),"",$C$9) | BF9: =IF(OR(4=48,$B$9<>1),"",$C$9) | BG9: =IF(OR(4=49,$B$9<>1),"",$C$9)
A10: =IF(Clients!A10="","",Clients!A10) | B10: =IF(A10="",0,IF(AND(Clients!K10=1,ISNUMBER(Clients!D10),ISNUMBER(INDEX(Clients!E10:J10,1,MATCH(Setup!$B$7,Clients!$E$4:$J$4,0)))),1,0)) | C10: =IF(B10=1,INDEX(Clients!E10:J10,1,MATCH(Setup!$B$7,Clients!$E$4:$J$4,0)),"") | D10: =IF(B10<>1,"",IF(COUNT(O5:O54)=0,"",MEDIAN(O5:O54))) | E10: =IF(B10=1,Clients!D10,"") | G10: =IF(AND(B10=1,ISNUMBER(F10)),F10-E10,"") | J10: =IF(OR(5=0,$B$10<>1),"",$C$10) | K10: =IF(OR(5=1,$B$10<>1),"",$C$10) | L10: =IF(OR(5=2,$B$10<>1),"",$C$10) | M10: =IF(OR(5=3,$B$10<>1),"",$C$10) | N10: =IF(OR(5=4,$B$10<>1),"",$C$10) | O10: =IF(OR(5=5,$B$10<>1),"",$C$10) | P10: =IF(OR(5=6,$B$10<>1),"",$C$10) | Q10: =IF(OR(5=7,$B$10<>1),"",$C$10) | R10: =IF(OR(5=8,$B$10<>1),"",$C$10) | S10: =IF(OR(5=9,$B$10<>1),"",$C$10) | T10: =IF(OR(5=10,$B$10<>1),"",$C$10) | U10: =IF(OR(5=11,$B$10<>1),"",$C$10) | V10: =IF(OR(5=12,$B$10<>1),"",$C$10) | W10: =IF(OR(5=13,$B$10<>1),"",$C$10) | X10: =IF(OR(5=14,$B$10<>1),"",$C$10) | Y10: =IF(OR(5=15,$B$10<>1),"",$C$10) | Z10: =IF(OR(5=16,$B$10<>1),"",$C$10) | AA10: =IF(OR(5=17,$B$10<>1),"",$C$10) | AB10: =IF(OR(5=18,$B$10<>1),"",$C$10) | AC10: =IF(OR(5=19,$B$10<>1),"",$C$10) | AD10: =IF(OR(5=20,$B$10<>1),"",$C$10) | AE10: =IF(OR(5=21,$B$10<>1),"",$C$10) | AF10: =IF(OR(5=22,$B$10<>1),"",$C$10) | AG10: =IF(OR(5=23,$B$10<>1),"",$C$10) | AH10: =IF(OR(5=24,$B$10<>1),"",$C$10) | AI10: =IF(OR(5=25,$B$10<>1),"",$C$10) | AJ10: =IF(OR(5=26,$B$10<>1),"",$C$10) | AK10: =IF(OR(5=27,$B$10<>1),"",$C$10) | AL10: =IF(OR(5=28,$B$10<>1),"",$C$10) | AM10: =IF(OR(5=29,$B$10<>1),"",$C$10) | AN10: =IF(OR(5=30,$B$10<>1),"",$C$10) | AO10: =IF(OR(5=31,$B$10<>1),"",$C$10) | AP10: =IF(OR(5=32,$B$10<>1),"",$C$10) | AQ10: =IF(OR(5=33,$B$10<>1),"",$C$10) | AR10: =IF(OR(5=34,$B$10<>1),"",$C$10) | AS10: =IF(OR(5=35,$B$10<>1),"",$C$10) | AT10: =IF(OR(5=36,$B$10<>1),"",$C$10) | AU10: =IF(OR(5=37,$B$10<>1),"",$C$10) | AV10: =IF(OR(5=38,$B$10<>1),"",$C$10) | AW10: =IF(OR(5=39,$B$10<>1),"",$C$10) | AX10: =IF(OR(5=40,$B$10<>1),"",$C$10) | AY10: =IF(OR(5=41,$B$10<>1),"",$C$10) | AZ10: =IF(OR(5=42,$B$10<>1),"",$C$10) | BA10: =IF(OR(5=43,$B$10<>1),"",$C$10) | BB10: =IF(OR(5=44,$B$10<>1),"",$C$10) | BC10: =IF(OR(5=45,$B$10<>1),"",$C$10) | BD10: =IF(OR(5=46,$B$10<>1),"",$C$10) | BE10: =IF(OR(5=47,$B$10<>1),"",$C$10) | BF10: =IF(OR(5=48,$B$10<>1),"",$C$10) | BG10: =IF(OR(5=49,$B$10<>1),"",$C$10)
A11: =IF(Clients!A11="","",Clients!A11) | B11: =IF(A11="",0,IF(AND(Clients!K11=1,ISNUMBER(Clients!D11),ISNUMBER(INDEX(Clients!E11:J11,1,MATCH(Setup!$B$7,Clients!$E$4:$J$4,0)))),1,0)) | C11: =IF(B11=1,INDEX(Clients!E11:J11,1,MATCH(Setup!$B$7,Clients!$E$4:$J$4,0)),"") | D11: =IF(B11<>1,"",IF(COUNT(P5:P54)=0,"",MEDIAN(P5:P54))) | E11: =IF(B11=1,Clients!D11,"") | G11: =IF(AND(B11=1,ISNUMBER(F11)),F11-E11,"") | J11: =IF(OR(6=0,$B$11<>1),"",$C$11) | K11: =IF(OR(6=1,$B$11<>1),"",$C$11) | L11: =IF(OR(6=2,$B$11<>1),"",$C$11) | M11: =IF(OR(6=3,$B$11<>1),"",$C$11) | N11: =IF(OR(6=4,$B$11<>1),"",$C$11) | O11: =IF(OR(6=5,$B$11<>1),"",$C$11) | P11: =IF(OR(6=6,$B$11<>1),"",$C$11) | Q11: =IF(OR(6=7,$B$11<>1),"",$C$11) | R11: =IF(OR(6=8,$B$11<>1),"",$C$11) | S11: =IF(OR(6=9,$B$11<>1),"",$C$11) | T11: =IF(OR(6=10,$B$11<>1),"",$C$11) | U11: =IF(OR(6=11,$B$11<>1),"",$C$11) | V11: =IF(OR(6=12,$B$11<>1),"",$C$11) | W11: =IF(OR(6=13,$B$11<>1),"",$C$11) | X11: =IF(OR(6=14,$B$11<>1),"",$C$11) | Y11: =IF(OR(6=15,$B$11<>1),"",$C$11) | Z11: =IF(OR(6=16,$B$11<>1),"",$C$11) | AA11: =IF(OR(6=17,$B$11<>1),"",$C$11) | AB11: =IF(OR(6=18,$B$11<>1),"",$C$11) | AC11: =IF(OR(6=19,$B$11<>1),"",$C$11) | AD11: =IF(OR(6=20,$B$11<>1),"",$C$11) | AE11: =IF(OR(6=21,$B$11<>1),"",$C$11) | AF11: =IF(OR(6=22,$B$11<>1),"",$C$11) | AG11: =IF(OR(6=23,$B$11<>1),"",$C$11) | AH11: =IF(OR(6=24,$B$11<>1),"",$C$11) | AI11: =IF(OR(6=25,$B$11<>1),"",$C$11) | AJ11: =IF(OR(6=26,$B$11<>1),"",$C$11) | AK11: =IF(OR(6=27,$B$11<>1),"",$C$11) | AL11: =IF(OR(6=28,$B$11<>1),"",$C$11) | AM11: =IF(OR(6=29,$B$11<>1),"",$C$11) | AN11: =IF(OR(6=30,$B$11<>1),"",$C$11) | AO11: =IF(OR(6=31,$B$11<>1),"",$C$11) | AP11: =IF(OR(6=32,$B$11<>1),"",$C$11) | AQ11: =IF(OR(6=33,$B$11<>1),"",$C$11) | AR11: =IF(OR(6=34,$B$11<>1),"",$C$11) | AS11: =IF(OR(6=35,$B$11<>1),"",$C$11) | AT11: =IF(OR(6=36,$B$11<>1),"",$C$11) | AU11: =IF(OR(6=37,$B$11<>1),"",$C$11) | AV11: =IF(OR(6=38,$B$11<>1),"",$C$11) | AW11: =IF(OR(6=39,$B$11<>1),"",$C$11) | AX11: =IF(OR(6=40,$B$11<>1),"",$C$11) | AY11: =IF(OR(6=41,$B$11<>1),"",$C$11) | AZ11: =IF(OR(6=42,$B$11<>1),"",$C$11) | BA11: =IF(OR(6=43,$B$11<>1),"",$C$11) | BB11: =IF(OR(6=44,$B$11<>1),"",$C$11) | BC11: =IF(OR(6=45,$B$11<>1),"",$C$11) | BD11: =IF(OR(6=46,$B$11<>1),"",$C$11) | BE11: =IF(OR(6=47,$B$11<>1),"",$C$11) | BF11: =IF(OR(6=48,$B$11<>1),"",$C$11) | BG11: =IF(OR(6=49,$B$11<>1),"",$C$11)
A12: =IF(Clients!A12="","",Clients!A12) | B12: =IF(A12="",0,IF(AND(Clients!K12=1,ISNUMBER(Clients!D12),ISNUMBER(INDEX(Clients!E12:J12,1,MATCH(Setup!$B$7,Clients!$E$4:$J$4,0)))),1,0)) | C12: =IF(B12=1,INDEX(Clients!E12:J12,1,MATCH(Setup!$B$7,Clients!$E$4:$J$4,0)),"") | D12: =IF(B12<>1,"",IF(COUNT(Q5:Q54)=0,"",MEDIAN(Q5:Q54))) | E12: =IF(B12=1,Clients!D12,"") | G12: =IF(AND(B12=1,ISNUMBER(F12)),F12-E12,"") | J12: =IF(OR(7=0,$B$12<>1),"",$C$12) | K12: =IF(OR(7=1,$B$12<>1),"",$C$12) | L12: =IF(OR(7=2,$B$12<>1),"",$C$12) | M12: =IF(OR(7=3,$B$12<>1),"",$C$12) | N12: =IF(OR(7=4,$B$12<>1),"",$C$12) | O12: =IF(OR(7=5,$B$12<>1),"",$C$12) | P12: =IF(OR(7=6,$B$12<>1),"",$C$12) | Q12: =IF(OR(7=7,$B$12<>1),"",$C$12) | R12: =IF(OR(7=8,$B$12<>1),"",$C$12) | S12: =IF(OR(7=9,$B$12<>1),"",$C$12) | T12: =IF(OR(7=10,$B$12<>1),"",$C$12) | U12: =IF(OR(7=11,$B$12<>1),"",$C$12) | V12: =IF(OR(7=12,$B$12<>1),"",$C$12) | W12: =IF(OR(7=13,$B$12<>1),"",$C$12) | X12: =IF(OR(7=14,$B$12<>1),"",$C$12) | Y12: =IF(OR(7=15,$B$12<>1),"",$C$12) | Z12: =IF(OR(7=16,$B$12<>1),"",$C$12) | AA12: =IF(OR(7=17,$B$12<>1),"",$C$12) | AB12: =IF(OR(7=18,$B$12<>1),"",$C$12) | AC12: =IF(OR(7=19,$B$12<>1),"",$C$12) | AD12: =IF(OR(7=20,$B$12<>1),"",$C$12) | AE12: =IF(OR(7=21,$B$12<>1),"",$C$12) | AF12: =IF(OR(7=22,$B$12<>1),"",$C$12) | AG12: =IF(OR(7=23,$B$12<>1),"",$C$12) | AH12: =IF(OR(7=24,$B$12<>1),"",$C$12) | AI12: =IF(OR(7=25,$B$12<>1),"",$C$12) | AJ12: =IF(OR(7=26,$B$12<>1),"",$C$12) | AK12: =IF(OR(7=27,$B$12<>1),"",$C$12) | AL12: =IF(OR(7=28,$B$12<>1),"",$C$12) | AM12: =IF(OR(7=29,$B$12<>1),"",$C$12) | AN12: =IF(OR(7=30,$B$12<>1),"",$C$12) | AO12: =IF(OR(7=31,$B$12<>1),"",$C$12) | AP12: =IF(OR(7=32,$B$12<>1),"",$C$12) | AQ12: =IF(OR(7=33,$B$12<>1),"",$C$12) | AR12: =IF(OR(7=34,$B$12<>1),"",$C$12) | AS12: =IF(OR(7=35,$B$12<>1),"",$C$12) | AT12: =IF(OR(7=36,$B$12<>1),"",$C$12) | AU12: =IF(OR(7=37,$B$12<>1),"",$C$12) | AV12: =IF(OR(7=38,$B$12<>1),"",$C$12) | AW12: =IF(OR(7=39,$B$12<>1),"",$C$12) | AX12: =IF(OR(7=40,$B$12<>1),"",$C$12) | AY12: =IF(OR(7=41,$B$12<>1),"",$C$12) | AZ12: =IF(OR(7=42,$B$12<>1),"",$C$12) | BA12: =IF(OR(7=43,$B$12<>1),"",$C$12) | BB12: =IF(OR(7=44,$B$12<>1),"",$C$12) | BC12: =IF(OR(7=45,$B$12<>1),"",$C$12) | BD12: =IF(OR(7=46,$B$12<>1),"",$C$12) | BE12: =IF(OR(7=47,$B$12<>1),"",$C$12) | BF12: =IF(OR(7=48,$B$12<>1),"",$C$12) | BG12: =IF(OR(7=49,$B$12<>1),"",$C$12)
A13: =IF(Clients!A13="","",Clients!A13) | B13: =IF(A13="",0,IF(AND(Clients!K13=1,ISNUMBER(Clients!D13),ISNUMBER(INDEX(Clients!E13:J13,1,MATCH(Setup!$B$7,Clients!$E$4:$J$4,0)))),1,0)) | C13: =IF(B13=1,INDEX(Clients!E13:J13,1,MATCH(Setup!$B$7,Clients!$E$4:$J$4,0)),"") | D13: =IF(B13<>1,"",IF(COUNT(R5:R54)=0,"",MEDIAN(R5:R54))) | E13: =IF(B13=1,Clients!D13,"") | G13: =IF(AND(B13=1,ISNUMBER(F13)),F13-E13,"") | J13: =IF(OR(8=0,$B$13<>1),"",$C$13) | K13: =IF(OR(8=1,$B$13<>1),"",$C$13) | L13: =IF(OR(8=2,$B$13<>1),"",$C$13) | M13: =IF(OR(8=3,$B$13<>1),"",$C$13) | N13: =IF(OR(8=4,$B$13<>1),"",$C$13) | O13: =IF(OR(8=5,$B$13<>1),"",$C$13) | P13: =IF(OR(8=6,$B$13<>1),"",$C$13) | Q13: =IF(OR(8=7,$B$13<>1),"",$C$13) | R13: =IF(OR(8=8,$B$13<>1),"",$C$13) | S13: =IF(OR(8=9,$B$13<>1),"",$C$13) | T13: =IF(OR(8=10,$B$13<>1),"",$C$13) | U13: =IF(OR(8=11,$B$13<>1),"",$C$13) | V13: =IF(OR(8=12,$B$13<>1),"",$C$13) | W13: =IF(OR(8=13,$B$13<>1),"",$C$13) | X13: =IF(OR(8=14,$B$13<>1),"",$C$13) | Y13: =IF(OR(8=15,$B$13<>1),"",$C$13) | Z13: =IF(OR(8=16,$B$13<>1),"",$C$13) | AA13: =IF(OR(8=17,$B$13<>1),"",$C$13) | AB13: =IF(OR(8=18,$B$13<>1),"",$C$13) | AC13: =IF(OR(8=19,$B$13<>1),"",$C$13) | AD13: =IF(OR(8=20,$B$13<>1),"",$C$13) | AE13: =IF(OR(8=21,$B$13<>1),"",$C$13) | AF13: =IF(OR(8=22,$B$13<>1),"",$C$13) | AG13: =IF(OR(8=23,$B$13<>1),"",$C$13) | AH13: =IF(OR(8=24,$B$13<>1),"",$C$13) | AI13: =IF(OR(8=25,$B$13<>1),"",$C$13) | AJ13: =IF(OR(8=26,$B$13<>1),"",$C$13) | AK13: =IF(OR(8=27,$B$13<>1),"",$C$13) | AL13: =IF(OR(8=28,$B$13<>1),"",$C$13) | AM13: =IF(OR(8=29,$B$13<>1),"",$C$13) | AN13: =IF(OR(8=30,$B$13<>1),"",$C$13) | AO13: =IF(OR(8=31,$B$13<>1),"",$C$13) | AP13: =IF(OR(8=32,$B$13<>1),"",$C$13) | AQ13: =IF(OR(8=33,$B$13<>1),"",$C$13) | AR13: =IF(OR(8=34,$B$13<>1),"",$C$13) | AS13: =IF(OR(8=35,$B$13<>1),"",$C$13) | AT13: =IF(OR(8=36,$B$13<>1),"",$C$13) | AU13: =IF(OR(8=37,$B$13<>1),"",$C$13) | AV13: =IF(OR(8=38,$B$13<>1),"",$C$13) | AW13: =IF(OR(8=39,$B$13<>1),"",$C$13) | AX13: =IF(OR(8=40,$B$13<>1),"",$C$13) | AY13: =IF(OR(8=41,$B$13<>1),"",$C$13) | AZ13: =IF(OR(8=42,$B$13<>1),"",$C$13) | BA13: =IF(OR(8=43,$B$13<>1),"",$C$13) | BB13: =IF(OR(8=44,$B$13<>1),"",$C$13) | BC13: =IF(OR(8=45,$B$13<>1),"",$C$13) | BD13: =IF(OR(8=46,$B$13<>1),"",$C$13) | BE13: =IF(OR(8=47,$B$13<>1),"",$C$13) | BF13: =IF(OR(8=48,$B$13<>1),"",$C$13) | BG13: =IF(OR(8=49,$B$13<>1),"",$C$13)
A14: =IF(Clients!A14="","",Clients!A14) | B14: =IF(A14="",0,IF(AND(Clients!K14=1,ISNUMBER(Clients!D14),ISNUMBER(INDEX(Clients!E14:J14,1,MATCH(Setup!$B$7,Clients!$E$4:$J$4,0)))),1,0)) | C14: =IF(B14=1,INDEX(Clients!E14:J14,1,MATCH(Setup!$B$7,Clients!$E$4:$J$4,0)),"") | D14: =IF(B14<>1,"",IF(COUNT(S5:S54)=0,"",MEDIAN(S5:S54))) | E14: =IF(B14=1,Clients!D14,"") | G14: =IF(AND(B14=1,ISNUMBER(F14)),F14-E14,"") | J14: =IF(OR(9=0,$B$14<>1),"",$C$14) | K14: =IF(OR(9=1,$B$14<>1),"",$C$14) | L14: =IF(OR(9=2,$B$14<>1),"",$C$14) | M14: =IF(OR(9=3,$B$14<>1),"",$C$14) | N14: =IF(OR(9=4,$B$14<>1),"",$C$14) | O14: =IF(OR(9=5,$B$14<>1),"",$C$14) | P14: =IF(OR(9=6,$B$14<>1),"",$C$14) | Q14: =IF(OR(9=7,$B$14<>1),"",$C$14) | R14: =IF(OR(9=8,$B$14<>1),"",$C$14) | S14: =IF(OR(9=9,$B$14<>1),"",$C$14) | T14: =IF(OR(9=10,$B$14<>1),"",$C$14) | U14: =IF(OR(9=11,$B$14<>1),"",$C$14) | V14: =IF(OR(9=12,$B$14<>1),"",$C$14) | W14: =IF(OR(9=13,$B$14<>1),"",$C$14) | X14: =IF(OR(9=14,$B$14<>1),"",$C$14) | Y14: =IF(OR(9=15,$B$14<>1),"",$C$14) | Z14: =IF(OR(9=16,$B$14<>1),"",$C$14) | AA14: =IF(OR(9=17,$B$14<>1),"",$C$14) | AB14: =IF(OR(9=18,$B$14<>1),"",$C$14) | AC14: =IF(OR(9=19,$B$14<>1),"",$C$14) | AD14: =IF(OR(9=20,$B$14<>1),"",$C$14) | AE14: =IF(OR(9=21,$B$14<>1),"",$C$14) | AF14: =IF(OR(9=22,$B$14<>1),"",$C$14) | AG14: =IF(OR(9=23,$B$14<>1),"",$C$14) | AH14: =IF(OR(9=24,$B$14<>1),"",$C$14) | AI14: =IF(OR(9=25,$B$14<>1),"",$C$14) | AJ14: =IF(OR(9=26,$B$14<>1),"",$C$14) | AK14: =IF(OR(9=27,$B$14<>1),"",$C$14) | AL14: =IF(OR(9=28,$B$14<>1),"",$C$14) | AM14: =IF(OR(9=29,$B$14<>1),"",$C$14) | AN14: =IF(OR(9=30,$B$14<>1),"",$C$14) | AO14: =IF(OR(9=31,$B$14<>1),"",$C$14) | AP14: =IF(OR(9=32,$B$14<>1),"",$C$14) | AQ14: =IF(OR(9=33,$B$14<>1),"",$C$14) | AR14: =IF(OR(9=34,$B$14<>1),"",$C$14) | AS14: =IF(OR(9=35,$B$14<>1),"",$C$14) | AT14: =IF(OR(9=36,$B$14<>1),"",$C$14) | AU14: =IF(OR(9=37,$B$14<>1),"",$C$14) | AV14: =IF(OR(9=38,$B$14<>1),"",$C$14) | AW14: =IF(OR(9=39,$B$14<>1),"",$C$14) | AX14: =IF(OR(9=40,$B$14<>1),"",$C$14) | AY14: =IF(OR(9=41,$B$14<>1),"",$C$14) | AZ14: =IF(OR(9=42,$B$14<>1),"",$C$14) | BA14: =IF(OR(9=43,$B$14<>1),"",$C$14) | BB14: =IF(OR(9=44,$B$14<>1),"",$C$14) | BC14: =IF(OR(9=45,$B$14<>1),"",$C$14) | BD14: =IF(OR(9=46,$B$14<>1),"",$C$14) | BE14: =IF(OR(9=47,$B$14<>1),"",$C$14) | BF14: =IF(OR(9=48,$B$14<>1),"",$C$14) | BG14: =IF(OR(9=49,$B$14<>1),"",$C$14)
A15: =IF(Clients!A15="","",Clients!A15) | B15: =IF(A15="",0,IF(AND(Clients!K15=1,ISNUMBER(Clients!D15),ISNUMBER(INDEX(Clients!E15:J15,1,MATCH(Setup!$B$7,Clients!$E$4:$J$4,0)))),1,0)) | C15: =IF(B15=1,INDEX(Clients!E15:J15,1,MATCH(Setup!$B$7,Clients!$E$4:$J$4,0)),"") | D15: =IF(B15<>1,"",IF(COUNT(T5:T54)=0,"",MEDIAN(T5:T54))) | E15: =IF(B15=1,Clients!D15,"") | G15: =IF(AND(B15=1,ISNUMBER(F15)),F15-E15,"") | J15: =IF(OR(10=0,$B$15<>1),"",$C$15) | K15: =IF(OR(10=1,$B$15<>1),"",$C$15) | L15: =IF(OR(10=2,$B$15<>1),"",$C$15) | M15: =IF(OR(10=3,$B$15<>1),"",$C$15) | N15: =IF(OR(10=4,$B$15<>1),"",$C$15) | O15: =IF(OR(10=5,$B$15<>1),"",$C$15) | P15: =IF(OR(10=6,$B$15<>1),"",$C$15) | Q15: =IF(OR(10=7,$B$15<>1),"",$C$15) | R15: =IF(OR(10=8,$B$15<>1),"",$C$15) | S15: =IF(OR(10=9,$B$15<>1),"",$C$15) | T15: =IF(OR(10=10,$B$15<>1),"",$C$15) | U15: =IF(OR(10=11,$B$15<>1),"",$C$15) | V15: =IF(OR(10=12,$B$15<>1),"",$C$15) | W15: =IF(OR(10=13,$B$15<>1),"",$C$15) | X15: =IF(OR(10=14,$B$15<>1),"",$C$15) | Y15: =IF(OR(10=15,$B$15<>1),"",$C$15) | Z15: =IF(OR(10=16,$B$15<>1),"",$C$15) | AA15: =IF(OR(10=17,$B$15<>1),"",$C$15) | AB15: =IF(OR(10=18,$B$15<>1),"",$C$15) | AC15: =IF(OR(10=19,$B$15<>1),"",$C$15) | AD15: =IF(OR(10=20,$B$15<>1),"",$C$15) | AE15: =IF(OR(10=21,$B$15<>1),"",$C$15) | AF15: =IF(OR(10=22,$B$15<>1),"",$C$15) | AG15: =IF(OR(10=23,$B$15<>1),"",$C$15) | AH15: =IF(OR(10=24,$B$15<>1),"",$C$15) | AI15: =IF(OR(10=25,$B$15<>1),"",$C$15) | AJ15: =IF(OR(10=26,$B$15<>1),"",$C$15) | AK15: =IF(OR(10=27,$B$15<>1),"",$C$15) | AL15: =IF(OR(10=28,$B$15<>1),"",$C$15) | AM15: =IF(OR(10=29,$B$15<>1),"",$C$15) | AN15: =IF(OR(10=30,$B$15<>1),"",$C$15) | AO15: =IF(OR(10=31,$B$15<>1),"",$C$15) | AP15: =IF(OR(10=32,$B$15<>1),"",$C$15) | AQ15: =IF(OR(10=33,$B$15<>1),"",$C$15) | AR15: =IF(OR(10=34,$B$15<>1),"",$C$15) | AS15: =IF(OR(10=35,$B$15<>1),"",$C$15) | AT15: =IF(OR(10=36,$B$15<>1),"",$C$15) | AU15: =IF(OR(10=37,$B$15<>1),"",$C$15) | AV15: =IF(OR(10=38,$B$15<>1),"",$C$15) | AW15: =IF(OR(10=39,$B$15<>1),"",$C$15) | AX15: =IF(OR(10=40,$B$15<>1),"",$C$15) | AY15: =IF(OR(10=41,$B$15<>1),"",$C$15) | AZ15: =IF(OR(10=42,$B$15<>1),"",$C$15) | BA15: =IF(OR(10=43,$B$15<>1),"",$C$15) | BB15: =IF(OR(10=44,$B$15<>1),"",$C$15) | BC15: =IF(OR(10=45,$B$15<>1),"",$C$15) | BD15: =IF(OR(10=46,$B$15<>1),"",$C$15) | BE15: =IF(OR(10=47,$B$15<>1),"",$C$15) | BF15: =IF(OR(10=48,$B$15<>1),"",$C$15) | BG15: =IF(OR(10=49,$B$15<>1),"",$C$15)
A16: =IF(Clients!A16="","",Clients!A16) | B16: =IF(A16="",0,IF(AND(Clients!K16=1,ISNUMBER(Clients!D16),ISNUMBER(INDEX(Clients!E16:J16,1,MATCH(Setup!$B$7,Clients!$E$4:$J$4,0)))),1,0)) | C16: =IF(B16=1,INDEX(Clients!E16:J16,1,MATCH(Setup!$B$7,Clients!$E$4:$J$4,0)),"") | D16: =IF(B16<>1,"",IF(COUNT(U5:U54)=0,"",MEDIAN(U5:U54))) | E16: =IF(B16=1,Clients!D16,"") | G16: =IF(AND(B16=1,ISNUMBER(F16)),F16-E16,"") | J16: =IF(OR(11=0,$B$16<>1),"",$C$16) | K16: =IF(OR(11=1,$B$16<>1),"",$C$16) | L16: =IF(OR(11=2,$B$16<>1),"",$C$16) | M16: =IF(OR(11=3,$B$16<>1),"",$C$16) | N16: =IF(OR(11=4,$B$16<>1),"",$C$16) | O16: =IF(OR(11=5,$B$16<>1),"",$C$16) | P16: =IF(OR(11=6,$B$16<>1),"",$C$16) | Q16: =IF(OR(11=7,$B$16<>1),"",$C$16) | R16: =IF(OR(11=8,$B$16<>1),"",$C$16) | S16: =IF(OR(11=9,$B$16<>1),"",$C$16) | T16: =IF(OR(11=10,$B$16<>1),"",$C$16) | U16: =IF(OR(11=11,$B$16<>1),"",$C$16) | V16: =IF(OR(11=12,$B$16<>1),"",$C$16) | W16: =IF(OR(11=13,$B$16<>1),"",$C$16) | X16: =IF(OR(11=14,$B$16<>1),"",$C$16) | Y16: =IF(OR(11=15,$B$16<>1),"",$C$16) | Z16: =IF(OR(11=16,$B$16<>1),"",$C$16) | AA16: =IF(OR(11=17,$B$16<>1),"",$C$16) | AB16: =IF(OR(11=18,$B$16<>1),"",$C$16) | AC16: =IF(OR(11=19,$B$16<>1),"",$C$16) | AD16: =IF(OR(11=20,$B$16<>1),"",$C$16) | AE16: =IF(OR(11=21,$B$16<>1),"",$C$16) | AF16: =IF(OR(11=22,$B$16<>1),"",$C$16) | AG16: =IF(OR(11=23,$B$16<>1),"",$C$16) | AH16: =IF(OR(11=24,$B$16<>1),"",$C$16) | AI16: =IF(OR(11=25,$B$16<>1),"",$C$16) | AJ16: =IF(OR(11=26,$B$16<>1),"",$C$16) | AK16: =IF(OR(11=27,$B$16<>1),"",$C$16) | AL16: =IF(OR(11=28,$B$16<>1),"",$C$16) | AM16: =IF(OR(11=29,$B$16<>1),"",$C$16) | AN16: =IF(OR(11=30,$B$16<>1),"",$C$16) | AO16: =IF(OR(11=31,$B$16<>1),"",$C$16) | AP16: =IF(OR(11=32,$B$16<>1),"",$C$16) | AQ16: =IF(OR(11=33,$B$16<>1),"",$C$16) | AR16: =IF(OR(11=34,$B$16<>1),"",$C$16) | AS16: =IF(OR(11=35,$B$16<>1),"",$C$16) | AT16: =IF(OR(11=36,$B$16<>1),"",$C$16) | AU16: =IF(OR(11=37,$B$16<>1),"",$C$16) | AV16: =IF(OR(11=38,$B$16<>1),"",$C$16) | AW16: =IF(OR(11=39,$B$16<>1),"",$C$16) | AX16: =IF(OR(11=40,$B$16<>1),"",$C$16) | AY16: =IF(OR(11=41,$B$16<>1),"",$C$16) | AZ16: =IF(OR(11=42,$B$16<>1),"",$C$16) | BA16: =IF(OR(11=43,$B$16<>1),"",$C$16) | BB16: =IF(OR(11=44,$B$16<>1),"",$C$16) | BC16: =IF(OR(11=45,$B$16<>1),"",$C$16) | BD16: =IF(OR(11=46,$B$16<>1),"",$C$16) | BE16: =IF(OR(11=47,$B$16<>1),"",$C$16) | BF16: =IF(OR(11=48,$B$16<>1),"",$C$16) | BG16: =IF(OR(11=49,$B$16<>1),"",$C$16)
A17: =IF(Clients!A17="","",Clients!A17) | B17: =IF(A17="",0,IF(AND(Clients!K17=1,ISNUMBER(Clients!D17),ISNUMBER(INDEX(Clients!E17:J17,1,MATCH(Setup!$B$7,Clients!$E$4:$J$4,0)))),1,0)) | C17: =IF(B17=1,INDEX(Clients!E17:J17,1,MATCH(Setup!$B$7,Clients!$E$4:$J$4,0)),"") | D17: =IF(B17<>1,"",IF(COUNT(V5:V54)=0,"",MEDIAN(V5:V54))) | E17: =IF(B17=1,Clients!D17,"") | G17: =IF(AND(B17=1,ISNUMBER(F17)),F17-E17,"") | J17: =IF(OR(12=0,$B$17<>1),"",$C$17) | K17: =IF(OR(12=1,$B$17<>1),"",$C$17) | L17: =IF(OR(12=2,$B$17<>1),"",$C$17) | M17: =IF(OR(12=3,$B$17<>1),"",$C$17) | N17: =IF(OR(12=4,$B$17<>1),"",$C$17) | O17: =IF(OR(12=5,$B$17<>1),"",$C$17) | P17: =IF(OR(12=6,$B$17<>1),"",$C$17) | Q17: =IF(OR(12=7,$B$17<>1),"",$C$17) | R17: =IF(OR(12=8,$B$17<>1),"",$C$17) | S17: =IF(OR(12=9,$B$17<>1),"",$C$17) | T17: =IF(OR(12=10,$B$17<>1),"",$C$17) | U17: =IF(OR(12=11,$B$17<>1),"",$C$17) | V17: =IF(OR(12=12,$B$17<>1),"",$C$17) | W17: =IF(OR(12=13,$B$17<>1),"",$C$17) | X17: =IF(OR(12=14,$B$17<>1),"",$C$17) | Y17: =IF(OR(12=15,$B$17<>1),"",$C$17) | Z17: =IF(OR(12=16,$B$17<>1),"",$C$17) | AA17: =IF(OR(12=17,$B$17<>1),"",$C$17) | AB17: =IF(OR(12=18,$B$17<>1),"",$C$17) | AC17: =IF(OR(12=19,$B$17<>1),"",$C$17) | AD17: =IF(OR(12=20,$B$17<>1),"",$C$17) | AE17: =IF(OR(12=21,$B$17<>1),"",$C$17) | AF17: =IF(OR(12=22,$B$17<>1),"",$C$17) | AG17: =IF(OR(12=23,$B$17<>1),"",$C$17) | AH17: =IF(OR(12=24,$B$17<>1),"",$C$17) | AI17: =IF(OR(12=25,$B$17<>1),"",$C$17) | AJ17: =IF(OR(12=26,$B$17<>1),"",$C$17) | AK17: =IF(OR(12=27,$B$17<>1),"",$C$17) | AL17: =IF(OR(12=28,$B$17<>1),"",$C$17) | AM17: =IF(OR(12=29,$B$17<>1),"",$C$17) | AN17: =IF(OR(12=30,$B$17<>1),"",$C$17) | AO17: =IF(OR(12=31,$B$17<>1),"",$C$17) | AP17: =IF(OR(12=32,$B$17<>1),"",$C$17) | AQ17: =IF(OR(12=33,$B$17<>1),"",$C$17) | AR17: =IF(OR(12=34,$B$17<>1),"",$C$17) | AS17: =IF(OR(12=35,$B$17<>1),"",$C$17) | AT17: =IF(OR(12=36,$B$17<>1),"",$C$17) | AU17: =IF(OR(12=37,$B$17<>1),"",$C$17) | AV17: =IF(OR(12=38,$B$17<>1),"",$C$17) | AW17: =IF(OR(12=39,$B$17<>1),"",$C$17) | AX17: =IF(OR(12=40,$B$17<>1),"",$C$17) | AY17: =IF(OR(12=41,$B$17<>1),"",$C$17) | AZ17: =IF(OR(12=42,$B$17<>1),"",$C$17) | BA17: =IF(OR(12=43,$B$17<>1),"",$C$17) | BB17: =IF(OR(12=44,$B$17<>1),"",$C$17) | BC17: =IF(OR(12=45,$B$17<>1),"",$C$17) | BD17: =IF(OR(12=46,$B$17<>1),"",$C$17) | BE17: =IF(OR(12=47,$B$17<>1),"",$C$17) | BF17: =IF(OR(12=48,$B$17<>1),"",$C$17) | BG17: =IF(OR(12=49,$B$17<>1),"",$C$17)
A18: =IF(Clients!A18="","",Clients!A18) | B18: =IF(A18="",0,IF(AND(Clients!K18=1,ISNUMBER(Clients!D18),ISNUMBER(INDEX(Clients!E18:J18,1,MATCH(Setup!$B$7,Clients!$E$4:$J$4,0)))),1,0)) | C18: =IF(B18=1,INDEX(Clients!E18:J18,1,MATCH(Setup!$B$7,Clients!$E$4:$J$4,0)),"") | D18: =IF(B18<>1,"",IF(COUNT(W5:W54)=0,"",MEDIAN(W5:W54))) | E18: =IF(B18=1,Clients!D18,"") | G18: =IF(AND(B18=1,ISNUMBER(F18)),F18-E18,"") | J18: =IF(OR(13=0,$B$18<>1),"",$C$18) | K18: =IF(OR(13=1,$B$18<>1),"",$C$18) | L18: =IF(OR(13=2,$B$18<>1),"",$C$18) | M18: =IF(OR(13=3,$B$18<>1),"",$C$18) | N18: =IF(OR(13=4,$B$18<>1),"",$C$18) | O18: =IF(OR(13=5,$B$18<>1),"",$C$18) | P18: =IF(OR(13=6,$B$18<>1),"",$C$18) | Q18: =IF(OR(13=7,$B$18<>1),"",$C$18) | R18: =IF(OR(13=8,$B$18<>1),"",$C$18) | S18: =IF(OR(13=9,$B$18<>1),"",$C$18) | T18: =IF(OR(13=10,$B$18<>1),"",$C$18) | U18: =IF(OR(13=11,$B$18<>1),"",$C$18) | V18: =IF(OR(13=12,$B$18<>1),"",$C$18) | W18: =IF(OR(13=13,$B$18<>1),"",$C$18) | X18: =IF(OR(13=14,$B$18<>1),"",$C$18) | Y18: =IF(OR(13=15,$B$18<>1),"",$C$18) | Z18: =IF(OR(13=16,$B$18<>1),"",$C$18) | AA18: =IF(OR(13=17,$B$18<>1),"",$C$18) | AB18: =IF(OR(13=18,$B$18<>1),"",$C$18) | AC18: =IF(OR(13=19,$B$18<>1),"",$C$18) | AD18: =IF(OR(13=20,$B$18<>1),"",$C$18) | AE18: =IF(OR(13=21,$B$18<>1),"",$C$18) | AF18: =IF(OR(13=22,$B$18<>1),"",$C$18) | AG18: =IF(OR(13=23,$B$18<>1),"",$C$18) | AH18: =IF(OR(13=24,$B$18<>1),"",$C$18) | AI18: =IF(OR(13=25,$B$18<>1),"",$C$18) | AJ18: =IF(OR(13=26,$B$18<>1),"",$C$18) | AK18: =IF(OR(13=27,$B$18<>1),"",$C$18) | AL18: =IF(OR(13=28,$B$18<>1),"",$C$18) | AM18: =IF(OR(13=29,$B$18<>1),"",$C$18) | AN18: =IF(OR(13=30,$B$18<>1),"",$C$18) | AO18: =IF(OR(13=31,$B$18<>1),"",$C$18) | AP18: =IF(OR(13=32,$B$18<>1),"",$C$18) | AQ18: =IF(OR(13=33,$B$18<>1),"",$C$18) | AR18: =IF(OR(13=34,$B$18<>1),"",$C$18) | AS18: =IF(OR(13=35,$B$18<>1),"",$C$18) | AT18: =IF(OR(13=36,$B$18<>1),"",$C$18) | AU18: =IF(OR(13=37,$B$18<>1),"",$C$18) | AV18: =IF(OR(13=38,$B$18<>1),"",$C$18) | AW18: =IF(OR(13=39,$B$18<>1),"",$C$18) | AX18: =IF(OR(13=40,$B$18<>1),"",$C$18) | AY18: =IF(OR(13=41,$B$18<>1),"",$C$18) | AZ18: =IF(OR(13=42,$B$18<>1),"",$C$18) | BA18: =IF(OR(13=43,$B$18<>1),"",$C$18) | BB18: =IF(OR(13=44,$B$18<>1),"",$C$18) | BC18: =IF(OR(13=45,$B$18<>1),"",$C$18) | BD18: =IF(OR(13=46,$B$18<>1),"",$C$18) | BE18: =IF(OR(13=47,$B$18<>1),"",$C$18) | BF18: =IF(OR(13=48,$B$18<>1),"",$C$18) | BG18: =IF(OR(13=49,$B$18<>1),"",$C$18)
A19: =IF(Clients!A19="","",Clients!A19) | B19: =IF(A19="",0,IF(AND(Clients!K19=1,ISNUMBER(Clients!D19),ISNUMBER(INDEX(Clients!E19:J19,1,MATCH(Setup!$B$7,Clients!$E$4:$J$4,0)))),1,0)) | C19: =IF(B19=1,INDEX(Clients!E19:J19,1,MATCH(Setup!$B$7,Clients!$E$4:$J$4,0)),"") | D19: =IF(B19<>1,"",IF(COUNT(X5:X54)=0,"",MEDIAN(X5:X54))) | E19: =IF(B19=1,Clients!D19,"") | G19: =IF(AND(B19=1,ISNUMBER(F19)),F19-E19,"") | J19: =IF(OR(14=0,$B$19<>1),"",$C$19) | K19: =IF(OR(14=1,$B$19<>1),"",$C$19) | L19: =IF(OR(14=2,$B$19<>1),"",$C$19) | M19: =IF(OR(14=3,$B$19<>1),"",$C$19) | N19: =IF(OR(14=4,$B$19<>1),"",$C$19) | O19: =IF(OR(14=5,$B$19<>1),"",$C$19) | P19: =IF(OR(14=6,$B$19<>1),"",$C$19) | Q19: =IF(OR(14=7,$B$19<>1),"",$C$19) | R19: =IF(OR(14=8,$B$19<>1),"",$C$19) | S19: =IF(OR(14=9,$B$19<>1),"",$C$19) | T19: =IF(OR(14=10,$B$19<>1),"",$C$19) | U19: =IF(OR(14=11,$B$19<>1),"",$C$19) | V19: =IF(OR(14=12,$B$19<>1),"",$C$19) | W19: =IF(OR(14=13,$B$19<>1),"",$C$19) | X19: =IF(OR(14=14,$B$19<>1),"",$C$19) | Y19: =IF(OR(14=15,$B$19<>1),"",$C$19) | Z19: =IF(OR(14=16,$B$19<>1),"",$C$19) | AA19: =IF(OR(14=17,$B$19<>1),"",$C$19) | AB19: =IF(OR(14=18,$B$19<>1),"",$C$19) | AC19: =IF(OR(14=19,$B$19<>1),"",$C$19) | AD19: =IF(OR(14=20,$B$19<>1),"",$C$19) | AE19: =IF(OR(14=21,$B$19<>1),"",$C$19) | AF19: =IF(OR(14=22,$B$19<>1),"",$C$19) | AG19: =IF(OR(14=23,$B$19<>1),"",$C$19) | AH19: =IF(OR(14=24,$B$19<>1),"",$C$19) | AI19: =IF(OR(14=25,$B$19<>1),"",$C$19) | AJ19: =IF(OR(14=26,$B$19<>1),"",$C$19) | AK19: =IF(OR(14=27,$B$19<>1),"",$C$19) | AL19: =IF(OR(14=28,$B$19<>1),"",$C$19) | AM19: =IF(OR(14=29,$B$19<>1),"",$C$19) | AN19: =IF(OR(14=30,$B$19<>1),"",$C$19) | AO19: =IF(OR(14=31,$B$19<>1),"",$C$19) | AP19: =IF(OR(14=32,$B$19<>1),"",$C$19) | AQ19: =IF(OR(14=33,$B$19<>1),"",$C$19) | AR19: =IF(OR(14=34,$B$19<>1),"",$C$19) | AS19: =IF(OR(14=35,$B$19<>1),"",$C$19) | AT19: =IF(OR(14=36,$B$19<>1),"",$C$19) | AU19: =IF(OR(14=37,$B$19<>1),"",$C$19) | AV19: =IF(OR(14=38,$B$19<>1),"",$C$19) | AW19: =IF(OR(14=39,$B$19<>1),"",$C$19) | AX19: =IF(OR(14=40,$B$19<>1),"",$C$19) | AY19: =IF(OR(14=41,$B$19<>1),"",$C$19) | AZ19: =IF(OR(14=42,$B$19<>1),"",$C$19) | BA19: =IF(OR(14=43,$B$19<>1),"",$C$19) | BB19: =IF(OR(14=44,$B$19<>1),"",$C$19) | BC19: =IF(OR(14=45,$B$19<>1),"",$C$19) | BD19: =IF(OR(14=46,$B$19<>1),"",$C$19) | BE19: =IF(OR(14=47,$B$19<>1),"",$C$19) | BF19: =IF(OR(14=48,$B$19<>1),"",$C$19) | BG19: =IF(OR(14=49,$B$19<>1),"",$C$19)
A20: =IF(Clients!A20="","",Clients!A20) | B20: =IF(A20="",0,IF(AND(Clients!K20=1,ISNUMBER(Clients!D20),ISNUMBER(INDEX(Clients!E20:J20,1,MATCH(Setup!$B$7,Clients!$E$4:$J$4,0)))),1,0)) | C20: =IF(B20=1,INDEX(Clients!E20:J20,1,MATCH(Setup!$B$7,Clients!$E$4:$J$4,0)),"") | D20: =IF(B20<>1,"",IF(COUNT(Y5:Y54)=0,"",MEDIAN(Y5:Y54))) | E20: =IF(B20=1,Clients!D20,"") | G20: =IF(AND(B20=1,ISNUMBER(F20)),F20-E20,"") | J20: =IF(OR(15=0,$B$20<>1),"",$C$20) | K20: =IF(OR(15=1,$B$20<>1),"",$C$20) | L20: =IF(OR(15=2,$B$20<>1),"",$C$20) | M20: =IF(OR(15=3,$B$20<>1),"",$C$20) | N20: =IF(OR(15=4,$B$20<>1),"",$C$20) | O20: =IF(OR(15=5,$B$20<>1),"",$C$20) | P20: =IF(OR(15=6,$B$20<>1),"",$C$20) | Q20: =IF(OR(15=7,$B$20<>1),"",$C$20) | R20: =IF(OR(15=8,$B$20<>1),"",$C$20) | S20: =IF(OR(15=9,$B$20<>1),"",$C$20) | T20: =IF(OR(15=10,$B$20<>1),"",$C$20) | U20: =IF(OR(15=11,$B$20<>1),"",$C$20) | V20: =IF(OR(15=12,$B$20<>1),"",$C$20) | W20: =IF(OR(15=13,$B$20<>1),"",$C$20) | X20: =IF(OR(15=14,$B$20<>1),"",$C$20) | Y20: =IF(OR(15=15,$B$20<>1),"",$C$20) | Z20: =IF(OR(15=16,$B$20<>1),"",$C$20) | AA20: =IF(OR(15=17,$B$20<>1),"",$C$20) | AB20: =IF(OR(15=18,$B$20<>1),"",$C$20) | AC20: =IF(OR(15=19,$B$20<>1),"",$C$20) | AD20: =IF(OR(15=20,$B$20<>1),"",$C$20) | AE20: =IF(OR(15=21,$B$20<>1),"",$C$20) | AF20: =IF(OR(15=22,$B$20<>1),"",$C$20) | AG20: =IF(OR(15=23,$B$20<>1),"",$C$20) | AH20: =IF(OR(15=24,$B$20<>1),"",$C$20) | AI20: =IF(OR(15=25,$B$20<>1),"",$C$20) | AJ20: =IF(OR(15=26,$B$20<>1),"",$C$20) | AK20: =IF(OR(15=27,$B$20<>1),"",$C$20) | AL20: =IF(OR(15=28,$B$20<>1),"",$C$20) | AM20: =IF(OR(15=29,$B$20<>1),"",$C$20) | AN20: =IF(OR(15=30,$B$20<>1),"",$C$20) | AO20: =IF(OR(15=31,$B$20<>1),"",$C$20) | AP20: =IF(OR(15=32,$B$20<>1),"",$C$20) | AQ20: =IF(OR(15=33,$B$20<>1),"",$C$20) | AR20: =IF(OR(15=34,$B$20<>1),"",$C$20) | AS20: =IF(OR(15=35,$B$20<>1),"",$C$20) | AT20: =IF(OR(15=36,$B$20<>1),"",$C$20) | AU20: =IF(OR(15=37,$B$20<>1),"",$C$20) | AV20: =IF(OR(15=38,$B$20<>1),"",$C$20) | AW20: =IF(OR(15=39,$B$20<>1),"",$C$20) | AX20: =IF(OR(15=40,$B$20<>1),"",$C$20) | AY20: =IF(OR(15=41,$B$20<>1),"",$C$20) | AZ20: =IF(OR(15=42,$B$20<>1),"",$C$20) | BA20: =IF(OR(15=43,$B$20<>1),"",$C$20) | BB20: =IF(OR(15=44,$B$20<>1),"",$C$20) | BC20: =IF(OR(15=45,$B$20<>1),"",$C$20) | BD20: =IF(OR(15=46,$B$20<>1),"",$C$20) | BE20: =IF(OR(15=47,$B$20<>1),"",$C$20) | BF20: =IF(OR(15=48,$B$20<>1),"",$C$20) | BG20: =IF(OR(15=49,$B$20<>1),"",$C$20)
A21: =IF(Clients!A21="","",Clients!A21) | B21: =IF(A21="",0,IF(AND(Clients!K21=1,ISNUMBER(Clients!D21),ISNUMBER(INDEX(Clients!E21:J21,1,MATCH(Setup!$B$7,Clients!$E$4:$J$4,0)))),1,0)) | C21: =IF(B21=1,INDEX(Clients!E21:J21,1,MATCH(Setup!$B$7,Clients!$E$4:$J$4,0)),"") | D21: =IF(B21<>1,"",IF(COUNT(Z5:Z54)=0,"",MEDIAN(Z5:Z54))) | E21: =IF(B21=1,Clients!D21,"") | G21: =IF(AND(B21=1,ISNUMBER(F21)),F21-E21,"") | J21: =IF(OR(16=0,$B$21<>1),"",$C$21) | K21: =IF(OR(16=1,$B$21<>1),"",$C$21) | L21: =IF(OR(16=2,$B$21<>1),"",$C$21) | M21: =IF(OR(16=3,$B$21<>1),"",$C$21) | N21: =IF(OR(16=4,$B$21<>1),"",$C$21) | O21: =IF(OR(16=5,$B$21<>1),"",$C$21) | P21: =IF(OR(16=6,$B$21<>1),"",$C$21) | Q21: =IF(OR(16=7,$B$21<>1),"",$C$21) | R21: =IF(OR(16=8,$B$21<>1),"",$C$21) | S21: =IF(OR(16=9,$B$21<>1),"",$C$21) | T21: =IF(OR(16=10,$B$21<>1),"",$C$21) | U21: =IF(OR(16=11,$B$21<>1),"",$C$21) | V21: =IF(OR(16=12,$B$21<>1),"",$C$21) | W21: =IF(OR(16=13,$B$21<>1),"",$C$21) | X21: =IF(OR(16=14,$B$21<>1),"",$C$21) | Y21: =IF(OR(16=15,$B$21<>1),"",$C$21) | Z21: =IF(OR(16=16,$B$21<>1),"",$C$21) | AA21: =IF(OR(16=17,$B$21<>1),"",$C$21) | AB21: =IF(OR(16=18,$B$21<>1),"",$C$21) | AC21: =IF(OR(16=19,$B$21<>1),"",$C$21) | AD21: =IF(OR(16=20,$B$21<>1),"",$C$21) | AE21: =IF(OR(16=21,$B$21<>1),"",$C$21) | AF21: =IF(OR(16=22,$B$21<>1),"",$C$21) | AG21: =IF(OR(16=23,$B$21<>1),"",$C$21) | AH21: =IF(OR(16=24,$B$21<>1),"",$C$21) | AI21: =IF(OR(16=25,$B$21<>1),"",$C$21) | AJ21: =IF(OR(16=26,$B$21<>1),"",$C$21) | AK21: =IF(OR(16=27,$B$21<>1),"",$C$21) | AL21: =IF(OR(16=28,$B$21<>1),"",$C$21) | AM21: =IF(OR(16=29,$B$21<>1),"",$C$21) | AN21: =IF(OR(16=30,$B$21<>1),"",$C$21) | AO21: =IF(OR(16=31,$B$21<>1),"",$C$21) | AP21: =IF(OR(16=32,$B$21<>1),"",$C$21) | AQ21: =IF(OR(16=33,$B$21<>1),"",$C$21) | AR21: =IF(OR(16=34,$B$21<>1),"",$C$21) | AS21: =IF(OR(16=35,$B$21<>1),"",$C$21) | AT21: =IF(OR(16=36,$B$21<>1),"",$C$21) | AU21: =IF(OR(16=37,$B$21<>1),"",$C$21) | AV21: =IF(OR(16=38,$B$21<>1),"",$C$21) | AW21: =IF(OR(16=39,$B$21<>1),"",$C$21) | AX21: =IF(OR(16=40,$B$21<>1),"",$C$21) | AY21: =IF(OR(16=41,$B$21<>1),"",$C$21) | AZ21: =IF(OR(16=42,$B$21<>1),"",$C$21) | BA21: =IF(OR(16=43,$B$21<>1),"",$C$21) | BB21: =IF(OR(16=44,$B$21<>1),"",$C$21) | BC21: =IF(OR(16=45,$B$21<>1),"",$C$21) | BD21: =IF(OR(16=46,$B$21<>1),"",$C$21) | BE21: =IF(OR(16=47,$B$21<>1),"",$C$21) | BF21: =IF(OR(16=48,$B$21<>1),"",$C$21) | BG21: =IF(OR(16=49,$B$21<>1),"",$C$21)
A22: =IF(Clients!A22="","",Clients!A22) | B22: =IF(A22="",0,IF(AND(Clients!K22=1,ISNUMBER(Clients!D22),ISNUMBER(INDEX(Clients!E22:J22,1,MATCH(Setup!$B$7,Clients!$E$4:$J$4,0)))),1,0)) | C22: =IF(B22=1,INDEX(Clients!E22:J22,1,MATCH(Setup!$B$7,Clients!$E$4:$J$4,0)),"") | D22: =IF(B22<>1,"",IF(COUNT(AA5:AA54)=0,"",MEDIAN(AA5:AA54))) | E22: =IF(B22=1,Clients!D22,"") | G22: =IF(AND(B22=1,ISNUMBER(F22)),F22-E22,"") | J22: =IF(OR(17=0,$B$22<>1),"",$C$22) | K22: =IF(OR(17=1,$B$22<>1),"",$C$22) | L22: =IF(OR(17=2,$B$22<>1),"",$C$22) | M22: =IF(OR(17=3,$B$22<>1),"",$C$22) | N22: =IF(OR(17=4,$B$22<>1),"",$C$22) | O22: =IF(OR(17=5,$B$22<>1),"",$C$22) | P22: =IF(OR(17=6,$B$22<>1),"",$C$22) | Q22: =IF(OR(17=7,$B$22<>1),"",$C$22) | R22: =IF(OR(17=8,$B$22<>1),"",$C$22) | S22: =IF(OR(17=9,$B$22<>1),"",$C$22) | T22: =IF(OR(17=10,$B$22<>1),"",$C$22) | U22: =IF(OR(17=11,$B$22<>1),"",$C$22) | V22: =IF(OR(17=12,$B$22<>1),"",$C$22) | W22: =IF(OR(17=13,$B$22<>1),"",$C$22) | X22: =IF(OR(17=14,$B$22<>1),"",$C$22) | Y22: =IF(OR(17=15,$B$22<>1),"",$C$22) | Z22: =IF(OR(17=16,$B$22<>1),"",$C$22) | AA22: =IF(OR(17=17,$B$22<>1),"",$C$22) | AB22: =IF(OR(17=18,$B$22<>1),"",$C$22) | AC22: =IF(OR(17=19,$B$22<>1),"",$C$22) | AD22: =IF(OR(17=20,$B$22<>1),"",$C$22) | AE22: =IF(OR(17=21,$B$22<>1),"",$C$22) | AF22: =IF(OR(17=22,$B$22<>1),"",$C$22) | AG22: =IF(OR(17=23,$B$22<>1),"",$C$22) | AH22: =IF(OR(17=24,$B$22<>1),"",$C$22) | AI22: =IF(OR(17=25,$B$22<>1),"",$C$22) | AJ22: =IF(OR(17=26,$B$22<>1),"",$C$22) | AK22: =IF(OR(17=27,$B$22<>1),"",$C$22) | AL22: =IF(OR(17=28,$B$22<>1),"",$C$22) | AM22: =IF(OR(17=29,$B$22<>1),"",$C$22) | AN22: =IF(OR(17=30,$B$22<>1),"",$C$22) | AO22: =IF(OR(17=31,$B$22<>1),"",$C$22) | AP22: =IF(OR(17=32,$B$22<>1),"",$C$22) | AQ22: =IF(OR(17=33,$B$22<>1),"",$C$22) | AR22: =IF(OR(17=34,$B$22<>1),"",$C$22) | AS22: =IF(OR(17=35,$B$22<>1),"",$C$22) | AT22: =IF(OR(17=36,$B$22<>1),"",$C$22) | AU22: =IF(OR(17=37,$B$22<>1),"",$C$22) | AV22: =IF(OR(17=38,$B$22<>1),"",$C$22) | AW22: =IF(OR(17=39,$B$22<>1),"",$C$22) | AX22: =IF(OR(17=40,$B$22<>1),"",$C$22) | AY22: =IF(OR(17=41,$B$22<>1),"",$C$22) | AZ22: =IF(OR(17=42,$B$22<>1),"",$C$22) | BA22: =IF(OR(17=43,$B$22<>1),"",$C$22) | BB22: =IF(OR(17=44,$B$22<>1),"",$C$22) | BC22: =IF(OR(17=45,$B$22<>1),"",$C$22) | BD22: =IF(OR(17=46,$B$22<>1),"",$C$22) | BE22: =IF(OR(17=47,$B$22<>1),"",$C$22) | BF22: =IF(OR(17=48,$B$22<>1),"",$C$22) | BG22: =IF(OR(17=49,$B$22<>1),"",$C$22)
A23: =IF(Clients!A23="","",Clients!A23) | B23: =IF(A23="",0,IF(AND(Clients!K23=1,ISNUMBER(Clients!D23),ISNUMBER(INDEX(Clients!E23:J23,1,MATCH(Setup!$B$7,Clients!$E$4:$J$4,0)))),1,0)) | C23: =IF(B23=1,INDEX(Clients!E23:J23,1,MATCH(Setup!$B$7,Clients!$E$4:$J$4,0)),"") | D23: =IF(B23<>1,"",IF(COUNT(AB5:AB54)=0,"",MEDIAN(AB5:AB54))) | E23: =IF(B23=1,Clients!D23,"") | G23: =IF(AND(B23=1,ISNUMBER(F23)),F23-E23,"") | J23: =IF(OR(18=0,$B$23<>1),"",$C$23) | K23: =IF(OR(18=1,$B$23<>1),"",$C$23) | L23: =IF(OR(18=2,$B$23<>1),"",$C$23) | M23: =IF(OR(18=3,$B$23<>1),"",$C$23) | N23: =IF(OR(18=4,$B$23<>1),"",$C$23) | O23: =IF(OR(18=5,$B$23<>1),"",$C$23) | P23: =IF(OR(18=6,$B$23<>1),"",$C$23) | Q23: =IF(OR(18=7,$B$23<>1),"",$C$23) | R23: =IF(OR(18=8,$B$23<>1),"",$C$23) | S23: =IF(OR(18=9,$B$23<>1),"",$C$23) | T23: =IF(OR(18=10,$B$23<>1),"",$C$23) | U23: =IF(OR(18=11,$B$23<>1),"",$C$23) | V23: =IF(OR(18=12,$B$23<>1),"",$C$23) | W23: =IF(OR(18=13,$B$23<>1),"",$C$23) | X23: =IF(OR(18=14,$B$23<>1),"",$C$23) | Y23: =IF(OR(18=15,$B$23<>1),"",$C$23) | Z23: =IF(OR(18=16,$B$23<>1),"",$C$23) | AA23: =IF(OR(18=17,$B$23<>1),"",$C$23) | AB23: =IF(OR(18=18,$B$23<>1),"",$C$23) | AC23: =IF(OR(18=19,$B$23<>1),"",$C$23) | AD23: =IF(OR(18=20,$B$23<>1),"",$C$23) | AE23: =IF(OR(18=21,$B$23<>1),"",$C$23) | AF23: =IF(OR(18=22,$B$23<>1),"",$C$23) | AG23: =IF(OR(18=23,$B$23<>1),"",$C$23) | AH23: =IF(OR(18=24,$B$23<>1),"",$C$23) | AI23: =IF(OR(18=25,$B$23<>1),"",$C$23) | AJ23: =IF(OR(18=26,$B$23<>1),"",$C$23) | AK23: =IF(OR(18=27,$B$23<>1),"",$C$23) | AL23: =IF(OR(18=28,$B$23<>1),"",$C$23) | AM23: =IF(OR(18=29,$B$23<>1),"",$C$23) | AN23: =IF(OR(18=30,$B$23<>1),"",$C$23) | AO23: =IF(OR(18=31,$B$23<>1),"",$C$23) | AP23: =IF(OR(18=32,$B$23<>1),"",$C$23) | AQ23: =IF(OR(18=33,$B$23<>1),"",$C$23) | AR23: =IF(OR(18=34,$B$23<>1),"",$C$23) | AS23: =IF(OR(18=35,$B$23<>1),"",$C$23) | AT23: =IF(OR(18=36,$B$23<>1),"",$C$23) | AU23: =IF(OR(18=37,$B$23<>1),"",$C$23) | AV23: =IF(OR(18=38,$B$23<>1),"",$C$23) | AW23: =IF(OR(18=39,$B$23<>1),"",$C$23) | AX23: =IF(OR(18=40,$B$23<>1),"",$C$23) | AY23: =IF(OR(18=41,$B$23<>1),"",$C$23) | AZ23: =IF(OR(18=42,$B$23<>1),"",$C$23) | BA23: =IF(OR(18=43,$B$23<>1),"",$C$23) | BB23: =IF(OR(18=44,$B$23<>1),"",$C$23) | BC23: =IF(OR(18=45,$B$23<>1),"",$C$23) | BD23: =IF(OR(18=46,$B$23<>1),"",$C$23) | BE23: =IF(OR(18=47,$B$23<>1),"",$C$23) | BF23: =IF(OR(18=48,$B$23<>1),"",$C$23) | BG23: =IF(OR(18=49,$B$23<>1),"",$C$23)
A24: =IF(Clients!A24="","",Clients!A24) | B24: =IF(A24="",0,IF(AND(Clients!K24=1,ISNUMBER(Clients!D24),ISNUMBER(INDEX(Clients!E24:J24,1,MATCH(Setup!$B$7,Clients!$E$4:$J$4,0)))),1,0)) | C24: =IF(B24=1,INDEX(Clients!E24:J24,1,MATCH(Setup!$B$7,Clients!$E$4:$J$4,0)),"") | D24: =IF(B24<>1,"",IF(COUNT(AC5:AC54)=0,"",MEDIAN(AC5:AC54))) | E24: =IF(B24=1,Clients!D24,"") | G24: =IF(AND(B24=1,ISNUMBER(F24)),F24-E24,"") | J24: =IF(OR(19=0,$B$24<>1),"",$C$24) | K24: =IF(OR(19=1,$B$24<>1),"",$C$24) | L24: =IF(OR(19=2,$B$24<>1),"",$C$24) | M24: =IF(OR(19=3,$B$24<>1),"",$C$24) | N24: =IF(OR(19=4,$B$24<>1),"",$C$24) | O24: =IF(OR(19=5,$B$24<>1),"",$C$24) | P24: =IF(OR(19=6,$B$24<>1),"",$C$24) | Q24: =IF(OR(19=7,$B$24<>1),"",$C$24) | R24: =IF(OR(19=8,$B$24<>1),"",$C$24) | S24: =IF(OR(19=9,$B$24<>1),"",$C$24) | T24: =IF(OR(19=10,$B$24<>1),"",$C$24) | U24: =IF(OR(19=11,$B$24<>1),"",$C$24) | V24: =IF(OR(19=12,$B$24<>1),"",$C$24) | W24: =IF(OR(19=13,$B$24<>1),"",$C$24) | X24: =IF(OR(19=14,$B$24<>1),"",$C$24) | Y24: =IF(OR(19=15,$B$24<>1),"",$C$24) | Z24: =IF(OR(19=16,$B$24<>1),"",$C$24) | AA24: =IF(OR(19=17,$B$24<>1),"",$C$24) | AB24: =IF(OR(19=18,$B$24<>1),"",$C$24) | AC24: =IF(OR(19=19,$B$24<>1),"",$C$24) | AD24: =IF(OR(19=20,$B$24<>1),"",$C$24) | AE24: =IF(OR(19=21,$B$24<>1),"",$C$24) | AF24: =IF(OR(19=22,$B$24<>1),"",$C$24) | AG24: =IF(OR(19=23,$B$24<>1),"",$C$24) | AH24: =IF(OR(19=24,$B$24<>1),"",$C$24) | AI24: =IF(OR(19=25,$B$24<>1),"",$C$24) | AJ24: =IF(OR(19=26,$B$24<>1),"",$C$24) | AK24: =IF(OR(19=27,$B$24<>1),"",$C$24) | AL24: =IF(OR(19=28,$B$24<>1),"",$C$24) | AM24: =IF(OR(19=29,$B$24<>1),"",$C$24) | AN24: =IF(OR(19=30,$B$24<>1),"",$C$24) | AO24: =IF(OR(19=31,$B$24<>1),"",$C$24) | AP24: =IF(OR(19=32,$B$24<>1),"",$C$24) | AQ24: =IF(OR(19=33,$B$24<>1),"",$C$24) | AR24: =IF(OR(19=34,$B$24<>1),"",$C$24) | AS24: =IF(OR(19=35,$B$24<>1),"",$C$24) | AT24: =IF(OR(19=36,$B$24<>1),"",$C$24) | AU24: =IF(OR(19=37,$B$24<>1),"",$C$24) | AV24: =IF(OR(19=38,$B$24<>1),"",$C$24) | AW24: =IF(OR(19=39,$B$24<>1),"",$C$24) | AX24: =IF(OR(19=40,$B$24<>1),"",$C$24) | AY24: =IF(OR(19=41,$B$24<>1),"",$C$24) | AZ24: =IF(OR(19=42,$B$24<>1),"",$C$24) | BA24: =IF(OR(19=43,$B$24<>1),"",$C$24) | BB24: =IF(OR(19=44,$B$24<>1),"",$C$24) | BC24: =IF(OR(19=45,$B$24<>1),"",$C$24) | BD24: =IF(OR(19=46,$B$24<>1),"",$C$24) | BE24: =IF(OR(19=47,$B$24<>1),"",$C$24) | BF24: =IF(OR(19=48,$B$24<>1),"",$C$24) | BG24: =IF(OR(19=49,$B$24<>1),"",$C$24)
A25: =IF(Clients!A25="","",Clients!A25) | B25: =IF(A25="",0,IF(AND(Clients!K25=1,ISNUMBER(Clients!D25),ISNUMBER(INDEX(Clients!E25:J25,1,MATCH(Setup!$B$7,Clients!$E$4:$J$4,0)))),1,0)) | C25: =IF(B25=1,INDEX(Clients!E25:J25,1,MATCH(Setup!$B$7,Clients!$E$4:$J$4,0)),"") | D25: =IF(B25<>1,"",IF(COUNT(AD5:AD54)=0,"",MEDIAN(AD5:AD54))) | E25: =IF(B25=1,Clients!D25,"") | G25: =IF(AND(B25=1,ISNUMBER(F25)),F25-E25,"") | J25: =IF(OR(20=0,$B$25<>1),"",$C$25) | K25: =IF(OR(20=1,$B$25<>1),"",$C$25) | L25: =IF(OR(20=2,$B$25<>1),"",$C$25) | M25: =IF(OR(20=3,$B$25<>1),"",$C$25) | N25: =IF(OR(20=4,$B$25<>1),"",$C$25) | O25: =IF(OR(20=5,$B$25<>1),"",$C$25) | P25: =IF(OR(20=6,$B$25<>1),"",$C$25) | Q25: =IF(OR(20=7,$B$25<>1),"",$C$25) | R25: =IF(OR(20=8,$B$25<>1),"",$C$25) | S25: =IF(OR(20=9,$B$25<>1),"",$C$25) | T25: =IF(OR(20=10,$B$25<>1),"",$C$25) | U25: =IF(OR(20=11,$B$25<>1),"",$C$25) | V25: =IF(OR(20=12,$B$25<>1),"",$C$25) | W25: =IF(OR(20=13,$B$25<>1),"",$C$25) | X25: =IF(OR(20=14,$B$25<>1),"",$C$25) | Y25: =IF(OR(20=15,$B$25<>1),"",$C$25) | Z25: =IF(OR(20=16,$B$25<>1),"",$C$25) | AA25: =IF(OR(20=17,$B$25<>1),"",$C$25) | AB25: =IF(OR(20=18,$B$25<>1),"",$C$25) | AC25: =IF(OR(20=19,$B$25<>1),"",$C$25) | AD25: =IF(OR(20=20,$B$25<>1),"",$C$25) | AE25: =IF(OR(20=21,$B$25<>1),"",$C$25) | AF25: =IF(OR(20=22,$B$25<>1),"",$C$25) | AG25: =IF(OR(20=23,$B$25<>1),"",$C$25) | AH25: =IF(OR(20=24,$B$25<>1),"",$C$25) | AI25: =IF(OR(20=25,$B$25<>1),"",$C$25) | AJ25: =IF(OR(20=26,$B$25<>1),"",$C$25) | AK25: =IF(OR(20=27,$B$25<>1),"",$C$25) | AL25: =IF(OR(20=28,$B$25<>1),"",$C$25) | AM25: =IF(OR(20=29,$B$25<>1),"",$C$25) | AN25: =IF(OR(20=30,$B$25<>1),"",$C$25) | AO25: =IF(OR(20=31,$B$25<>1),"",$C$25) | AP25: =IF(OR(20=32,$B$25<>1),"",$C$25) | AQ25: =IF(OR(20=33,$B$25<>1),"",$C$25) | AR25: =IF(OR(20=34,$B$25<>1),"",$C$25) | AS25: =IF(OR(20=35,$B$25<>1),"",$C$25) | AT25: =IF(OR(20=36,$B$25<>1),"",$C$25) | AU25: =IF(OR(20=37,$B$25<>1),"",$C$25) | AV25: =IF(OR(20=38,$B$25<>1),"",$C$25) | AW25: =IF(OR(20=39,$B$25<>1),"",$C$25) | AX25: =IF(OR(20=40,$B$25<>1),"",$C$25) | AY25: =IF(OR(20=41,$B$25<>1),"",$C$25) | AZ25: =IF(OR(20=42,$B$25<>1),"",$C$25) | BA25: =IF(OR(20=43,$B$25<>1),"",$C$25) | BB25: =IF(OR(20=44,$B$25<>1),"",$C$25) | BC25: =IF(OR(20=45,$B$25<>1),"",$C$25) | BD25: =IF(OR(20=46,$B$25<>1),"",$C$25) | BE25: =IF(OR(20=47,$B$25<>1),"",$C$25) | BF25: =IF(OR(20=48,$B$25<>1),"",$C$25) | BG25: =IF(OR(20=49,$B$25<>1),"",$C$25)
