Workbook
Name intake_ready: 'Readiness'!$J$1

Sheet README
A1: K10 · Intake Readiness, Next Questions & Onboarding Renderer (no-code kernel)
A3: Replaces openfpa: pyfpa.memory.intake (question bank, record_intake_fact, intake_ready, next_intake_questions) and onboarding (render_business_profile, ArchitectureProposal, render_architecture_proposal, write_onboarding_outputs); CLI intake-next, intake-record, onboarding-render.
A4: Facts
A5: Paste memory/intake.csv rows into 'Facts' (key, topic, question, answer, status confirmed/inferred/conflict, confidence 0..1, source_type user/local_file/external/inference, sources ; -separated, alternatives ; -separated).
A6: A key is KNOWN when its fact is not a conflict and is confirmed, or has confidence >= 0.70. intake_ready = all 11 core keys known.
A7: Next questions (intake-next)
A8: Walk the bank in order; pending = missing, conflict (re-ask with the alternatives) or inferred below 0.70 (ask to confirm). Take the topic of the FIRST pending question and return at most 3 pending questions of that topic.
A9: Recording a fact (intake-record) - progressive authority
A10: A user answer is confirmed at confidence 1.0 (keeps earlier sources). New non-user evidence that DISAGREES (case-insensitive) with an existing answer -> status conflict, confidence = min, alternative appended. AGREEING evidence -> confidence = max, sources merged. A new key from non-user evidence -> inferred at the supplied confidence (default 0.8). Use 'RecordFact' to compute the new row deterministically.
A11: Onboarding outputs
A12: When ready, 'Profile' renders memory/business-profile.md and 'Proposal' renders memory/decisions/initial-model-architecture.md (status Proposed - HUMAN APPROVAL REQUIRED before scaffolding).
A13: Tamil Nadu extension questions (tn_statutory topic) are asked after the core bank; they do not block readiness but every TN company should answer them before W03.

Sheet Checks
A1: Checks - OVERALL must be PASS
B3: OVERALL | C3: =IF(COUNTIF(C5:C8,"PASS")=COUNT(A5:A8),"PASS","FAIL") | D3: =COUNTIF(C5:C8,"PASS")&" pass / "&COUNTIF(C5:C8,"FAIL")&" fail / "&(COUNT(A5:A8)-COUNTIF(C5:C8,"PASS")-COUNTIF(C5:C8,"FAIL"))&" error"
A4: # | B4: check | C4: result | D4: detail
A5: 1 | B5: every fact status is confirmed/inferred/conflict | C5: =IF(SUMPRODUCT((Facts!A5:A64<>"")*((LOWER(Facts!E5:E64)="confirmed")+(LOWER(Facts!E5:E64)="inferred")+(LOWER(Facts!E5:E64)="conflict")=0))=0,"PASS","FAIL")
A6: 2 | B6: every confidence within 0..1 | C6: =IF(SUMPRODUCT((Facts!A5:A64<>"")*((Facts!F5:F64<0)+(Facts!F5:F64>1)>0))=0,"PASS","FAIL")
A7: 3 | B7: fact keys unique | C7: =IF(SUMPRODUCT((Facts!A5:A64<>"")*(COUNTIF(Facts!A5:A64,Facts!A5:A64)>1))=0,"PASS","FAIL")
A8: 4 | B8: no empty answers | C8: =IF(SUMPRODUCT((Facts!A5:A64<>"")*(TRIM(Facts!D5:D64)=""))=0,"PASS","FAIL")

Sheet QuestionBank
A1: Question bank (order matters)
A4: # | B4: key | C4: topic | D4: prompt | E4: required for readiness?
A5: 1 | B5: business_model | C5: business | D5: What does the company sell, and who are the primary customers? | E5: yes
A6: 2 | B6: revenue_model | C6: business | D6: How is revenue earned and billed, including pricing and payment terms? | E6: yes
A7: 3 | B7: customer_channels | C7: business | D7: Which channels, products, or segments should the model distinguish? | E7: yes
A8: 4 | B8: collections | C8: cash_cycle | D8: When do customers usually pay, and what causes collections to vary? | E8: yes
A9: 5 | B9: supplier_payments | C9: cash_cycle | D9: When are suppliers, payroll, inventory, and other major obligations paid? | E9: yes
A10: 6 | B10: seasonality | C10: cash_cycle | D10: What is seasonal or lumpy across revenue, costs, inventory, and cash? | E10: yes
A11: 7 | B11: entities | C11: finance_structure | D11: Which legal entities, currencies, and intercompany relationships matter? | E11: yes
A12: 8 | B12: financing | C12: finance_structure | D12: What debt, credit lines, covenants, or other financing is in place? | E12: yes
A13: 9 | B13: data_sources | C13: finance_structure | D13: Which systems and files contain the financial and operating actuals? | E13: yes
A14: 10 | B14: planning_cadence | C14: planning | D14: How often do you close, reforecast, report, and make planning decisions? | E14: yes
A15: 11 | B15: cfo_priorities | C15: planning | D15: Which decisions, risks, or questions matter most to the CFO right now? | E15: yes
A16: 12 | B16: gst_profile | C16: tn_statutory | D16: What is the GSTIN set-up (state code 33 and others), filing frequency (monthly / QRMP), e-invoicing status and main GST rates? | E16: no
... A20: 16 | B20: seasonal_calendar_tn | C20: tn_statutory | D20: Which Tamil Nadu festivals, crop seasons, monsoon months or export seasons move sales, collections or production (Pongal, Tamil New Year, Aadi, Deepavali, wedding muhurtham months, NE monsoon)? | E20: no

Sheet Facts
A1: Facts (paste memory/intake.csv)
A3: business_name | B3: Company
A4: key | B4: topic | C4: question | D4: answer | E4: status | F4: confidence | G4: source_type | H4: sources (; separated) | I4: alternatives (; separated) | L4: ord business | M4: ord cash_cycle | N4: ord finance_structure | O4: ord planning | P4: ord tn_statutory
L5: =IF(B5="business",COUNTIF($B$5:B5,"business"),"") | M5: =IF(B5="cash_cycle",COUNTIF($B$5:B5,"cash_cycle"),"") | N5: =IF(B5="finance_structure",COUNTIF($B$5:B5,"finance_structure"),"") | O5: =IF(B5="planning",COUNTIF($B$5:B5,"planning"),"") | P5: =IF(B5="tn_statutory",COUNTIF($B$5:B5,"tn_statutory"),"")
L6: =IF(B6="business",COUNTIF($B$5:B6,"business"),"") | M6: =IF(B6="cash_cycle",COUNTIF($B$5:B6,"cash_cycle"),"") | N6: =IF(B6="finance_structure",COUNTIF($B$5:B6,"finance_structure"),"") | O6: =IF(B6="planning",COUNTIF($B$5:B6,"planning"),"") | P6: =IF(B6="tn_statutory",COUNTIF($B$5:B6,"tn_statutory"),"")
L7: =IF(B7="business",COUNTIF($B$5:B7,"business"),"") | M7: =IF(B7="cash_cycle",COUNTIF($B$5:B7,"cash_cycle"),"") | N7: =IF(B7="finance_structure",COUNTIF($B$5:B7,"finance_structure"),"") | O7: =IF(B7="planning",COUNTIF($B$5:B7,"planning"),"") | P7: =IF(B7="tn_statutory",COUNTIF($B$5:B7,"tn_statutory"),"")
L8: =IF(B8="business",COUNTIF($B$5:B8,"business"),"") | M8: =IF(B8="cash_cycle",COUNTIF($B$5:B8,"cash_cycle"),"") | N8: =IF(B8="finance_structure",COUNTIF($B$5:B8,"finance_structure"),"") | O8: =IF(B8="planning",COUNTIF($B$5:B8,"planning"),"") | P8: =IF(B8="tn_statutory",COUNTIF($B$5:B8,"tn_statutory"),"")
L9: =IF(B9="business",COUNTIF($B$5:B9,"business"),"") | M9: =IF(B9="cash_cycle",COUNTIF($B$5:B9,"cash_cycle"),"") | N9: =IF(B9="finance_structure",COUNTIF($B$5:B9,"finance_structure"),"") | O9: =IF(B9="planning",COUNTIF($B$5:B9,"planning"),"") | P9: =IF(B9="tn_statutory",COUNTIF($B$5:B9,"tn_statutory"),"")
L10: =IF(B10="business",COUNTIF($B$5:B10,"business"),"") | M10: =IF(B10="cash_cycle",COUNTIF($B$5:B10,"cash_cycle"),"") | N10: =IF(B10="finance_structure",COUNTIF($B$5:B10,"finance_structure"),"") | O10: =IF(B10="planning",COUNTIF($B$5:B10,"planning"),"") | P10: =IF(B10="tn_statutory",COUNTIF($B$5:B10,"tn_statutory"),"")
L11: =IF(B11="business",COUNTIF($B$5:B11,"business"),"") | M11: =IF(B11="cash_cycle",COUNTIF($B$5:B11,"cash_cycle"),"") | N11: =IF(B11="finance_structure",COUNTIF($B$5:B11,"finance_structure"),"") | O11: =IF(B11="planning",COUNTIF($B$5:B11,"planning"),"") | P11: =IF(B11="tn_statutory",COUNTIF($B$5:B11,"tn_statutory"),"")
L12: =IF(B12="business",COUNTIF($B$5:B12,"business"),"") | M12: =IF(B12="cash_cycle",COUNTIF($B$5:B12,"cash_cycle"),"") | N12: =IF(B12="finance_structure",COUNTIF($B$5:B12,"finance_structure"),"") | O12: =IF(B12="planning",COUNTIF($B$5:B12,"planning"),"") | P12: =IF(B12="tn_statutory",COUNTIF($B$5:B12,"tn_statutory"),"")
L13: =IF(B13="business",COUNTIF($B$5:B13,"business"),"") | M13: =IF(B13="cash_cycle",COUNTIF($B$5:B13,"cash_cycle"),"") | N13: =IF(B13="finance_structure",COUNTIF($B$5:B13,"finance_structure"),"") | O13: =IF(B13="planning",COUNTIF($B$5:B13,"planning"),"") | P13: =IF(B13="tn_statutory",COUNTIF($B$5:B13,"tn_statutory"),"")
L14: =IF(B14="business",COUNTIF($B$5:B14,"business"),"") | M14: =IF(B14="cash_cycle",COUNTIF($B$5:B14,"cash_cycle"),"") | N14: =IF(B14="finance_structure",COUNTIF($B$5:B14,"finance_structure"),"") | O14: =IF(B14="planning",COUNTIF($B$5:B14,"planning"),"") | P14: =IF(B14="tn_statutory",COUNTIF($B$5:B14,"tn_statutory"),"")
L15: =IF(B15="business",COUNTIF($B$5:B15,"business"),"") | M15: =IF(B15="cash_cycle",COUNTIF($B$5:B15,"cash_cycle"),"") | N15: =IF(B15="finance_structure",COUNTIF($B$5:B15,"finance_structure"),"") | O15: =IF(B15="planning",COUNTIF($B$5:B15,"planning"),"") | P15: =IF(B15="tn_statutory",COUNTIF($B$5:B15,"tn_statutory"),"")
L16: =IF(B16="business",COUNTIF($B$5:B16,"business"),"") | M16: =IF(B16="cash_cycle",COUNTIF($B$5:B16,"cash_cycle"),"") | N16: =IF(B16="finance_structure",COUNTIF($B$5:B16,"finance_structure"),"") | O16: =IF(B16="planning",COUNTIF($B$5:B16,"planning"),"") | P16: =IF(B16="tn_statutory",COUNTIF($B$5:B16,"tn_statutory"),"")
... L64: =IF(B64="business",COUNTIF($B$5:B64,"business"),"") | M64: =IF(B64="cash_cycle",COUNTIF($B$5:B64,"cash_cycle"),"") | N64: =IF(B64="finance_structure",COUNTIF($B$5:B64,"finance_structure"),"") | O64: =IF(B64="planning",COUNTIF($B$5:B64,"planning"),"") | P64: =IF(B64="tn_statutory",COUNTIF($B$5:B64,"tn_statutory"),"")

Sheet Readiness
A1: Readiness and next questions | F1: INTAKE READY (core 11 keys known) | J1: =COUNTIF(G5:G15,TRUE)=11
A2: next-round topic | B2: =IFERROR(INDEX(C5:C20,MATCH(1,I5:I20,0)),"(none - all answered)") | C2: question limit | D2: 3
A4: # | B4: key | C4: topic | D4: fact row | E4: status | F4: confidence | G4: known? | H4: pending reason | I4: pending order | J4: in next round? | K4: question to ask
A5: 1 | B5: =QuestionBank!B5 | C5: =QuestionBank!C5 | D5: =IFERROR(MATCH(B5,Facts!$A$5:$A$64,0),"") | E5: =IF(D5="","",LOWER(INDEX(Facts!$E$5:$E$64,D5))) | F5: =IF(D5="","",INDEX(Facts!$F$5:$F$64,D5)) | G5: =IF(D5="",FALSE,AND(E5<>"conflict",OR(E5="confirmed",F5>=0.7))) | H5: =IF(D5="","missing",IF(E5="conflict","conflict",IF(AND(E5="inferred",F5<0.7),"confirm",""))) | I5: =IF(H5="","",SUMPRODUCT(($H$5:H5<>"")*1)) | J5: =IF(H5="",FALSE,AND(C5=$B$2,SUMPRODUCT(($C$5:C5=$B$2)*($H$5:H5<>""))<=$D$2)) | K5: =IF(H5="missing",QuestionBank!D5,IF(H5="conflict","I found conflicting answers for this: '"&INDEX(Facts!$D$5:$D$64,D5)&"' and '"&SUBSTITUTE(INDEX(Facts!$I$5:$I$64,D5),"; ","', '")&"'. Which is correct?",IF(H5="confirm","I inferred '"&INDEX(Facts!$D$5:$D$64,D5)&"'. Is that accurate?",""))) | L5: =IF(J5,ROW()-4,"")
A6: 2 | B6: =QuestionBank!B6 | C6: =QuestionBank!C6 | D6: =IFERROR(MATCH(B6,Facts!$A$5:$A$64,0),"") | E6: =IF(D6="","",LOWER(INDEX(Facts!$E$5:$E$64,D6))) | F6: =IF(D6="","",INDEX(Facts!$F$5:$F$64,D6)) | G6: =IF(D6="",FALSE,AND(E6<>"conflict",OR(E6="confirmed",F6>=0.7))) | H6: =IF(D6="","missing",IF(E6="conflict","conflict",IF(AND(E6="inferred",F6<0.7),"confirm",""))) | I6: =IF(H6="","",SUMPRODUCT(($H$5:H6<>"")*1)) | J6: =IF(H6="",FALSE,AND(C6=$B$2,SUMPRODUCT(($C$5:C6=$B$2)*($H$5:H6<>""))<=$D$2)) | K6: =IF(H6="missing",QuestionBank!D6,IF(H6="conflict","I found conflicting answers for this: '"&INDEX(Facts!$D$5:$D$64,D6)&"' and '"&SUBSTITUTE(INDEX(Facts!$I$5:$I$64,D6),"; ","', '")&"'. Which is correct?",IF(H6="confirm","I inferred '"&INDEX(Facts!$D$5:$D$64,D6)&"'. Is that accurate?",""))) | L6: =IF(J6,ROW()-4,"")
A7: 3 | B7: =QuestionBank!B7 | C7: =QuestionBank!C7 | D7: =IFERROR(MATCH(B7,Facts!$A$5:$A$64,0),"") | E7: =IF(D7="","",LOWER(INDEX(Facts!$E$5:$E$64,D7))) | F7: =IF(D7="","",INDEX(Facts!$F$5:$F$64,D7)) | G7: =IF(D7="",FALSE,AND(E7<>"conflict",OR(E7="confirmed",F7>=0.7))) | H7: =IF(D7="","missing",IF(E7="conflict","conflict",IF(AND(E7="inferred",F7<0.7),"confirm",""))) | I7: =IF(H7="","",SUMPRODUCT(($H$5:H7<>"")*1)) | J7: =IF(H7="",FALSE,AND(C7=$B$2,SUMPRODUCT(($C$5:C7=$B$2)*($H$5:H7<>""))<=$D$2)) | K7: =IF(H7="missing",QuestionBank!D7,IF(H7="conflict","I found conflicting answers for this: '"&INDEX(Facts!$D$5:$D$64,D7)&"' and '"&SUBSTITUTE(INDEX(Facts!$I$5:$I$64,D7),"; ","', '")&"'. Which is correct?",IF(H7="confirm","I inferred '"&INDEX(Facts!$D$5:$D$64,D7)&"'. Is that accurate?",""))) | L7: =IF(J7,ROW()-4,"")
A8: 4 | B8: =QuestionBank!B8 | C8: =QuestionBank!C8 | D8: =IFERROR(MATCH(B8,Facts!$A$5:$A$64,0),"") | E8: =IF(D8="","",LOWER(INDEX(Facts!$E$5:$E$64,D8))) | F8: =IF(D8="","",INDEX(Facts!$F$5:$F$64,D8)) | G8: =IF(D8="",FALSE,AND(E8<>"conflict",OR(E8="confirmed",F8>=0.7))) | H8: =IF(D8="","missing",IF(E8="conflict","conflict",IF(AND(E8="inferred",F8<0.7),"confirm",""))) | I8: =IF(H8="","",SUMPRODUCT(($H$5:H8<>"")*1)) | J8: =IF(H8="",FALSE,AND(C8=$B$2,SUMPRODUCT(($C$5:C8=$B$2)*($H$5:H8<>""))<=$D$2)) | K8: =IF(H8="missing",QuestionBank!D8,IF(H8="conflict","I found conflicting answers for this: '"&INDEX(Facts!$D$5:$D$64,D8)&"' and '"&SUBSTITUTE(INDEX(Facts!$I$5:$I$64,D8),"; ","', '")&"'. Which is correct?",IF(H8="confirm","I inferred '"&INDEX(Facts!$D$5:$D$64,D8)&"'. Is that accurate?",""))) | L8: =IF(J8,ROW()-4,"")
A9: 5 | B9: =QuestionBank!B9 | C9: =QuestionBank!C9 | D9: =IFERROR(MATCH(B9,Facts!$A$5:$A$64,0),"") | E9: =IF(D9="","",LOWER(INDEX(Facts!$E$5:$E$64,D9))) | F9: =IF(D9="","",INDEX(Facts!$F$5:$F$64,D9)) | G9: =IF(D9="",FALSE,AND(E9<>"conflict",OR(E9="confirmed",F9>=0.7))) | H9: =IF(D9="","missing",IF(E9="conflict","conflict",IF(AND(E9="inferred",F9<0.7),"confirm",""))) | I9: =IF(H9="","",SUMPRODUCT(($H$5:H9<>"")*1)) | J9: =IF(H9="",FALSE,AND(C9=$B$2,SUMPRODUCT(($C$5:C9=$B$2)*($H$5:H9<>""))<=$D$2)) | K9: =IF(H9="missing",QuestionBank!D9,IF(H9="conflict","I found conflicting answers for this: '"&INDEX(Facts!$D$5:$D$64,D9)&"' and '"&SUBSTITUTE(INDEX(Facts!$I$5:$I$64,D9),"; ","', '")&"'. Which is correct?",IF(H9="confirm","I inferred '"&INDEX(Facts!$D$5:$D$64,D9)&"'. Is that accurate?",""))) | L9: =IF(J9,ROW()-4,"")
A10: 6 | B10: =QuestionBank!B10 | C10: =QuestionBank!C10 | D10: =IFERROR(MATCH(B10,Facts!$A$5:$A$64,0),"") | E10: =IF(D10="","",LOWER(INDEX(Facts!$E$5:$E$64,D10))) | F10: =IF(D10="","",INDEX(Facts!$F$5:$F$64,D10)) | G10: =IF(D10="",FALSE,AND(E10<>"conflict",OR(E10="confirmed",F10>=0.7))) | H10: =IF(D10="","missing",IF(E10="conflict","conflict",IF(AND(E10="inferred",F10<0.7),"confirm",""))) | I10: =IF(H10="","",SUMPRODUCT(($H$5:H10<>"")*1)) | J10: =IF(H10="",FALSE,AND(C10=$B$2,SUMPRODUCT(($C$5:C10=$B$2)*($H$5:H10<>""))<=$D$2)) | K10: =IF(H10="missing",QuestionBank!D10,IF(H10="conflict","I found conflicting answers for this: '"&INDEX(Facts!$D$5:$D$64,D10)&"' and '"&SUBSTITUTE(INDEX(Facts!$I$5:$I$64,D10),"; ","', '")&"'. Which is correct?",IF(H10="confirm","I inferred '"&INDEX(Facts!$D$5:$D$64,D10)&"'. Is that accurate?",""))) | L10: =IF(J10,ROW()-4,"")
A11: 7 | B11: =QuestionBank!B11 | C11: =QuestionBank!C11 | D11: =IFERROR(MATCH(B11,Facts!$A$5:$A$64,0),"") | E11: =IF(D11="","",LOWER(INDEX(Facts!$E$5:$E$64,D11))) | F11: =IF(D11="","",INDEX(Facts!$F$5:$F$64,D11)) | G11: =IF(D11="",FALSE,AND(E11<>"conflict",OR(E11="confirmed",F11>=0.7))) | H11: =IF(D11="","missing",IF(E11="conflict","conflict",IF(AND(E11="inferred",F11<0.7),"confirm",""))) | I11: =IF(H11="","",SUMPRODUCT(($H$5:H11<>"")*1)) | J11: =IF(H11="",FALSE,AND(C11=$B$2,SUMPRODUCT(($C$5:C11=$B$2)*($H$5:H11<>""))<=$D$2)) | K11: =IF(H11="missing",QuestionBank!D11,IF(H11="conflict","I found conflicting answers for this: '"&INDEX(Facts!$D$5:$D$64,D11)&"' and '"&SUBSTITUTE(INDEX(Facts!$I$5:$I$64,D11),"; ","', '")&"'. Which is correct?",IF(H11="confirm","I inferred '"&INDEX(Facts!$D$5:$D$64,D11)&"'. Is that accurate?",""))) | L11: =IF(J11,ROW()-4,"")
A12: 8 | B12: =QuestionBank!B12 | C12: =QuestionBank!C12 | D12: =IFERROR(MATCH(B12,Facts!$A$5:$A$64,0),"") | E12: =IF(D12="","",LOWER(INDEX(Facts!$E$5:$E$64,D12))) | F12: =IF(D12="","",INDEX(Facts!$F$5:$F$64,D12)) | G12: =IF(D12="",FALSE,AND(E12<>"conflict",OR(E12="confirmed",F12>=0.7))) | H12: =IF(D12="","missing",IF(E12="conflict","conflict",IF(AND(E12="inferred",F12<0.7),"confirm",""))) | I12: =IF(H12="","",SUMPRODUCT(($H$5:H12<>"")*1)) | J12: =IF(H12="",FALSE,AND(C12=$B$2,SUMPRODUCT(($C$5:C12=$B$2)*($H$5:H12<>""))<=$D$2)) | K12: =IF(H12="missing",QuestionBank!D12,IF(H12="conflict","I found conflicting answers for this: '"&INDEX(Facts!$D$5:$D$64,D12)&"' and '"&SUBSTITUTE(INDEX(Facts!$I$5:$I$64,D12),"; ","', '")&"'. Which is correct?",IF(H12="confirm","I inferred '"&INDEX(Facts!$D$5:$D$64,D12)&"'. Is that accurate?",""))) | L12: =IF(J12,ROW()-4,"")
A13: 9 | B13: =QuestionBank!B13 | C13: =QuestionBank!C13 | D13: =IFERROR(MATCH(B13,Facts!$A$5:$A$64,0),"") | E13: =IF(D13="","",LOWER(INDEX(Facts!$E$5:$E$64,D13))) | F13: =IF(D13="","",INDEX(Facts!$F$5:$F$64,D13)) | G13: =IF(D13="",FALSE,AND(E13<>"conflict",OR(E13="confirmed",F13>=0.7))) | H13: =IF(D13="","missing",IF(E13="conflict","conflict",IF(AND(E13="inferred",F13<0.7),"confirm",""))) | I13: =IF(H13="","",SUMPRODUCT(($H$5:H13<>"")*1)) | J13: =IF(H13="",FALSE,AND(C13=$B$2,SUMPRODUCT(($C$5:C13=$B$2)*($H$5:H13<>""))<=$D$2)) | K13: =IF(H13="missing",QuestionBank!D13,IF(H13="conflict","I found conflicting answers for this: '"&INDEX(Facts!$D$5:$D$64,D13)&"' and '"&SUBSTITUTE(INDEX(Facts!$I$5:$I$64,D13),"; ","', '")&"'. Which is correct?",IF(H13="confirm","I inferred '"&INDEX(Facts!$D$5:$D$64,D13)&"'. Is that accurate?",""))) | L13: =IF(J13,ROW()-4,"")
A14: 10 | B14: =QuestionBank!B14 | C14: =QuestionBank!C14 | D14: =IFERROR(MATCH(B14,Facts!$A$5:$A$64,0),"") | E14: =IF(D14="","",LOWER(INDEX(Facts!$E$5:$E$64,D14))) | F14: =IF(D14="","",INDEX(Facts!$F$5:$F$64,D14)) | G14: =IF(D14="",FALSE,AND(E14<>"conflict",OR(E14="confirmed",F14>=0.7))) | H14: =IF(D14="","missing",IF(E14="conflict","conflict",IF(AND(E14="inferred",F14<0.7),"confirm",""))) | I14: =IF(H14="","",SUMPRODUCT(($H$5:H14<>"")*1)) | J14: =IF(H14="",FALSE,AND(C14=$B$2,SUMPRODUCT(($C$5:C14=$B$2)*($H$5:H14<>""))<=$D$2)) | K14: =IF(H14="missing",QuestionBank!D14,IF(H14="conflict","I found conflicting answers for this: '"&INDEX(Facts!$D$5:$D$64,D14)&"' and '"&SUBSTITUTE(INDEX(Facts!$I$5:$I$64,D14),"; ","', '")&"'. Which is correct?",IF(H14="confirm","I inferred '"&INDEX(Facts!$D$5:$D$64,D14)&"'. Is that accurate?",""))) | L14: =IF(J14,ROW()-4,"")
A15: 11 | B15: =QuestionBank!B15 | C15: =QuestionBank!C15 | D15: =IFERROR(MATCH(B15,Facts!$A$5:$A$64,0),"") | E15: =IF(D15="","",LOWER(INDEX(Facts!$E$5:$E$64,D15))) | F15: =IF(D15="","",INDEX(Facts!$F$5:$F$64,D15)) | G15: =IF(D15="",FALSE,AND(E15<>"conflict",OR(E15="confirmed",F15>=0.7))) | H15: =IF(D15="","missing",IF(E15="conflict","conflict",IF(AND(E15="inferred",F15<0.7),"confirm",""))) | I15: =IF(H15="","",SUMPRODUCT(($H$5:H15<>"")*1)) | J15: =IF(H15="",FALSE,AND(C15=$B$2,SUMPRODUCT(($C$5:C15=$B$2)*($H$5:H15<>""))<=$D$2)) | K15: =IF(H15="missing",QuestionBank!D15,IF(H15="conflict","I found conflicting answers for this: '"&INDEX(Facts!$D$5:$D$64,D15)&"' and '"&SUBSTITUTE(INDEX(Facts!$I$5:$I$64,D15),"; ","', '")&"'. Which is correct?",IF(H15="confirm","I inferred '"&INDEX(Facts!$D$5:$D$64,D15)&"'. Is that accurate?",""))) | L15: =IF(J15,ROW()-4,"")
A16: 12 | B16: =QuestionBank!B16 | C16: =QuestionBank!C16 | D16: =IFERROR(MATCH(B16,Facts!$A$5:$A$64,0),"") | E16: =IF(D16="","",LOWER(INDEX(Facts!$E$5:$E$64,D16))) | F16: =IF(D16="","",INDEX(Facts!$F$5:$F$64,D16)) | G16: =IF(D16="",FALSE,AND(E16<>"conflict",OR(E16="confirmed",F16>=0.7))) | H16: =IF(D16="","missing",IF(E16="conflict","conflict",IF(AND(E16="inferred",F16<0.7),"confirm",""))) | I16: =IF(H16="","",SUMPRODUCT(($H$5:H16<>"")*1)) | J16: =IF(H16="",FALSE,AND(C16=$B$2,SUMPRODUCT(($C$5:C16=$B$2)*($H$5:H16<>""))<=$D$2)) | K16: =IF(H16="missing",QuestionBank!D16,IF(H16="conflict","I found conflicting answers for this: '"&INDEX(Facts!$D$5:$D$64,D16)&"' and '"&SUBSTITUTE(INDEX(Facts!$I$5:$I$64,D16),"; ","', '")&"'. Which is correct?",IF(H16="confirm","I inferred '"&INDEX(Facts!$D$5:$D$64,D16)&"'. Is that accurate?",""))) | L16: =IF(J16,ROW()-4,"")
... A20: 16 | B20: =QuestionBank!B20 | C20: =QuestionBank!C20 | D20: =IFERROR(MATCH(B20,Facts!$A$5:$A$64,0),"") | E20: =IF(D20="","",LOWER(INDEX(Facts!$E$5:$E$64,D20))) | F20: =IF(D20="","",INDEX(Facts!$F$5:$F$64,D20)) | G20: =IF(D20="",FALSE,AND(E20<>"conflict",OR(E20="confirmed",F20>=0.7))) | H20: =IF(D20="","missing",IF(E20="conflict","conflict",IF(AND(E20="inferred",F20<0.7),"confirm",""))) | I20: =IF(H20="","",SUMPRODUCT(($H$5:H20<>"")*1)) | J20: =IF(H20="",FALSE,AND(C20=$B$2,SUMPRODUCT(($C$5:C20=$B$2)*($H$5:H20<>""))<=$D$2)) | K20: =IF(H20="missing",QuestionBank!D20,IF(H20="conflict","I found conflicting answers for this: '"&INDEX(Facts!$D$5:$D$64,D20)&"' and '"&SUBSTITUTE(INDEX(Facts!$I$5:$I$64,D20),"; ","', '")&"'. Which is correct?",IF(H20="confirm","I inferred '"&INDEX(Facts!$D$5:$D$64,D20)&"'. Is that accurate?",""))) | L20: =IF(J20,ROW()-4,"")
A23: Next round (ask these, max 3, one topic)
A24: =IFERROR(INDEX($K$5:$K$20,SMALL($L$5:$L$20,1)),"")
A25: =IFERROR(INDEX($K$5:$K$20,SMALL($L$5:$L$20,2)),"")
A26: =IFERROR(INDEX($K$5:$K$20,SMALL($L$5:$L$20,3)),"")

Sheet RecordFact
A1: RecordFact - progressive-authority rule for one new piece of evidence (intake-record)
A4: key
A5: new answer
A6: new source_type (user/local_file/external/inference)
A7: new sources (; separated)
A8: new confidence (blank = default)
A10: existing fact row (lookup) | B10: =IFERROR(MATCH(B4,Facts!$A$5:$A$64,0),"")
A11: existing answer | B11: =IF(B10="","",INDEX(Facts!$D$5:$D$64,$B$10))
A12: existing status / confidence | B12: =IF(B10="","",INDEX(Facts!$E$5:$E$64,$B$10)) | C12: =IF(B10="","",INDEX(Facts!$F$5:$F$64,$B$10))
A13: resolved new confidence | B13: =IF(B5="","",IF(LOWER(B6)="user",1,IF(B8="",0.8,B8)))
A15: resulting field | B15: value to write in memory/intake.csv
A16: key | B16: =B4
A17: topic | B17: =IF(B10<>"",INDEX(Facts!$B$5:$B$64,$B$10),IFERROR(INDEX(QuestionBank!$C$5:$C$30,MATCH(B4,QuestionBank!$B$5:$B$30,0)),"other"))
A18: question | B18: =IF(B10<>"",INDEX(Facts!$C$5:$C$64,$B$10),IFERROR(INDEX(QuestionBank!$D$5:$D$30,MATCH(B4,QuestionBank!$B$5:$B$30,0)),B4))
A19: answer | B19: =IF(LOWER(B6)="user",TRIM(B5),IF(B10="",TRIM(B5),B11))
A20: status | B20: =IF(LOWER(B6)="user","confirmed",IF(B10="","inferred",IF(LOWER(TRIM(B11))<>LOWER(TRIM(B5)),"conflict",B12)))
A21: confidence | B21: =IF(LOWER(B6)="user",1,IF(B10="",B13,IF(LOWER(TRIM(B11))<>LOWER(TRIM(B5)),MIN(C12,B13),MAX(C12,B13))))
A22: source_type | B22: =IF(LOWER(B6)="user","user",IF(B10="",LOWER(B6),INDEX(Facts!$G$5:$G$64,$B$10)))
A23: sources | B23: =IF(B10="",B7,IF(INDEX(Facts!$H$5:$H$64,$B$10)="",B7,IF(B7="",INDEX(Facts!$H$5:$H$64,$B$10),INDEX(Facts!$H$5:$H$64,$B$10)&"; "&B7)))
A24: alternatives | B24: =IF(LOWER(B6)="user","",IF(B10="","",IF(LOWER(TRIM(B11))<>LOWER(TRIM(B5)),IF(INDEX(Facts!$I$5:$I$64,$B$10)="",TRIM(B5),INDEX(Facts!$I$5:$I$64,$B$10)&"; "&TRIM(B5)),INDEX(Facts!$I$5:$I$64,$B$10))))
A26: Note: de-duplicate repeated sources when writing; an empty answer is rejected (do not record).

Sheet Profile
A1: business-profile.md renderer (copy column A from row 4)
A4: ="# "&Facts!B3&" Business Profile"
A6: > Generated from `memory/intake.csv`. Update the intake when facts change.
A8: ## Business Model And Revenue
A10: =IF(COUNTIF(Facts!$B$5:$B$64,"business")=0,"- Not yet known.","")
A11: =IFERROR("- **"&INDEX(Facts!$C$5:$C$64,MATCH(1,Facts!$L$5:$L$64,0))&"** "&INDEX(Facts!$D$5:$D$64,MATCH(1,Facts!$L$5:$L$64,0))&" _(status: "&INDEX(Facts!$E$5:$E$64,MATCH(1,Facts!$L$5:$L$64,0))&"; confidence: "&TEXT(INDEX(Facts!$F$5:$F$64,MATCH(1,Facts!$L$5:$L$64,0)),"0%")&"; source: "&IF(INDEX(Facts!$H$5:$H$64,MATCH(1,Facts!$L$5:$L$64,0))="",INDEX(Facts!$G$5:$G$64,MATCH(1,Facts!$L$5:$L$64,0)),SUBSTITUTE(INDEX(Facts!$H$5:$H$64,MATCH(1,Facts!$L$5:$L$64,0)),"; ",", "))&")_","")
A12: =IFERROR("- **"&INDEX(Facts!$C$5:$C$64,MATCH(2,Facts!$L$5:$L$64,0))&"** "&INDEX(Facts!$D$5:$D$64,MATCH(2,Facts!$L$5:$L$64,0))&" _(status: "&INDEX(Facts!$E$5:$E$64,MATCH(2,Facts!$L$5:$L$64,0))&"; confidence: "&TEXT(INDEX(Facts!$F$5:$F$64,MATCH(2,Facts!$L$5:$L$64,0)),"0%")&"; source: "&IF(INDEX(Facts!$H$5:$H$64,MATCH(2,Facts!$L$5:$L$64,0))="",INDEX(Facts!$G$5:$G$64,MATCH(2,Facts!$L$5:$L$64,0)),SUBSTITUTE(INDEX(Facts!$H$5:$H$64,MATCH(2,Facts!$L$5:$L$64,0)),"; ",", "))&")_","")
A13: =IFERROR("- **"&INDEX(Facts!$C$5:$C$64,MATCH(3,Facts!$L$5:$L$64,0))&"** "&INDEX(Facts!$D$5:$D$64,MATCH(3,Facts!$L$5:$L$64,0))&" _(status: "&INDEX(Facts!$E$5:$E$64,MATCH(3,Facts!$L$5:$L$64,0))&"; confidence: "&TEXT(INDEX(Facts!$F$5:$F$64,MATCH(3,Facts!$L$5:$L$64,0)),"0%")&"; source: "&IF(INDEX(Facts!$H$5:$H$64,MATCH(3,Facts!$L$5:$L$64,0))="",INDEX(Facts!$G$5:$G$64,MATCH(3,Facts!$L$5:$L$64,0)),SUBSTITUTE(INDEX(Facts!$H$5:$H$64,MATCH(3,Facts!$L$5:$L$64,0)),"; ",", "))&")_","")
A14: =IFERROR("- **"&INDEX(Facts!$C$5:$C$64,MATCH(4,Facts!$L$5:$L$64,0))&"** "&INDEX(Facts!$D$5:$D$64,MATCH(4,Facts!$L$5:$L$64,0))&" _(status: "&INDEX(Facts!$E$5:$E$64,MATCH(4,Facts!$L$5:$L$64,0))&"; confidence: "&TEXT(INDEX(Facts!$F$5:$F$64,MATCH(4,Facts!$L$5:$L$64,0)),"0%")&"; source: "&IF(INDEX(Facts!$H$5:$H$64,MATCH(4,Facts!$L$5:$L$64,0))="",INDEX(Facts!$G$5:$G$64,MATCH(4,Facts!$L$5:$L$64,0)),SUBSTITUTE(INDEX(Facts!$H$5:$H$64,MATCH(4,Facts!$L$5:$L$64,0)),"; ",", "))&")_","")
A15: =IFERROR("- **"&INDEX(Facts!$C$5:$C$64,MATCH(5,Facts!$L$5:$L$64,0))&"** "&INDEX(Facts!$D$5:$D$64,MATCH(5,Facts!$L$5:$L$64,0))&" _(status: "&INDEX(Facts!$E$5:$E$64,MATCH(5,Facts!$L$5:$L$64,0))&"; confidence: "&TEXT(INDEX(Facts!$F$5:$F$64,MATCH(5,Facts!$L$5:$L$64,0)),"0%")&"; source: "&IF(INDEX(Facts!$H$5:$H$64,MATCH(5,Facts!$L$5:$L$64,0))="",INDEX(Facts!$G$5:$G$64,MATCH(5,Facts!$L$5:$L$64,0)),SUBSTITUTE(INDEX(Facts!$H$5:$H$64,MATCH(5,Facts!$L$5:$L$64,0)),"; ",", "))&")_","")
A16: =IFERROR("- **"&INDEX(Facts!$C$5:$C$64,MATCH(6,Facts!$L$5:$L$64,0))&"** "&INDEX(Facts!$D$5:$D$64,MATCH(6,Facts!$L$5:$L$64,0))&" _(status: "&INDEX(Facts!$E$5:$E$64,MATCH(6,Facts!$L$5:$L$64,0))&"; confidence: "&TEXT(INDEX(Facts!$F$5:$F$64,MATCH(6,Facts!$L$5:$L$64,0)),"0%")&"; source: "&IF(INDEX(Facts!$H$5:$H$64,MATCH(6,Facts!$L$5:$L$64,0))="",INDEX(Facts!$G$5:$G$64,MATCH(6,Facts!$L$5:$L$64,0)),SUBSTITUTE(INDEX(Facts!$H$5:$H$64,MATCH(6,Facts!$L$5:$L$64,0)),"; ",", "))&")_","")
A17: =IFERROR("- **"&INDEX(Facts!$C$5:$C$64,MATCH(7,Facts!$L$5:$L$64,0))&"** "&INDEX(Facts!$D$5:$D$64,MATCH(7,Facts!$L$5:$L$64,0))&" _(status: "&INDEX(Facts!$E$5:$E$64,MATCH(7,Facts!$L$5:$L$64,0))&"; confidence: "&TEXT(INDEX(Facts!$F$5:$F$64,MATCH(7,Facts!$L$5:$L$64,0)),"0%")&"; source: "&IF(INDEX(Facts!$H$5:$H$64,MATCH(7,Facts!$L$5:$L$64,0))="",INDEX(Facts!$G$5:$G$64,MATCH(7,Facts!$L$5:$L$64,0)),SUBSTITUTE(INDEX(Facts!$H$5:$H$64,MATCH(7,Facts!$L$5:$L$64,0)),"; ",", "))&")_","")
A18: =IFERROR("- **"&INDEX(Facts!$C$5:$C$64,MATCH(8,Facts!$L$5:$L$64,0))&"** "&INDEX(Facts!$D$5:$D$64,MATCH(8,Facts!$L$5:$L$64,0))&" _(status: "&INDEX(Facts!$E$5:$E$64,MATCH(8,Facts!$L$5:$L$64,0))&"; confidence: "&TEXT(INDEX(Facts!$F$5:$F$64,MATCH(8,Facts!$L$5:$L$64,0)),"0%")&"; source: "&IF(INDEX(Facts!$H$5:$H$64,MATCH(8,Facts!$L$5:$L$64,0))="",INDEX(Facts!$G$5:$G$64,MATCH(8,Facts!$L$5:$L$64,0)),SUBSTITUTE(INDEX(Facts!$H$5:$H$64,MATCH(8,Facts!$L$5:$L$64,0)),"; ",", "))&")_","")
A19: =IFERROR("- **"&INDEX(Facts!$C$5:$C$64,MATCH(9,Facts!$L$5:$L$64,0))&"** "&INDEX(Facts!$D$5:$D$64,MATCH(9,Facts!$L$5:$L$64,0))&" _(status: "&INDEX(Facts!$E$5:$E$64,MATCH(9,Facts!$L$5:$L$64,0))&"; confidence: "&TEXT(INDEX(Facts!$F$5:$F$64,MATCH(9,Facts!$L$5:$L$64,0)),"0%")&"; source: "&IF(INDEX(Facts!$H$5:$H$64,MATCH(9,Facts!$L$5:$L$64,0))="",INDEX(Facts!$G$5:$G$64,MATCH(9,Facts!$L$5:$L$64,0)),SUBSTITUTE(INDEX(Facts!$H$5:$H$64,MATCH(9,Facts!$L$5:$L$64,0)),"; ",", "))&")_","")
A20: =IFERROR("- **"&INDEX(Facts!$C$5:$C$64,MATCH(10,Facts!$L$5:$L$64,0))&"** "&INDEX(Facts!$D$5:$D$64,MATCH(10,Facts!$L$5:$L$64,0))&" _(status: "&INDEX(Facts!$E$5:$E$64,MATCH(10,Facts!$L$5:$L$64,0))&"; confidence: "&TEXT(INDEX(Facts!$F$5:$F$64,MATCH(10,Facts!$L$5:$L$64,0)),"0%")&"; source: "&IF(INDEX(Facts!$H$5:$H$64,MATCH(10,Facts!$L$5:$L$64,0))="",INDEX(Facts!$G$5:$G$64,MATCH(10,Facts!$L$5:$L$64,0)),SUBSTITUTE(INDEX(Facts!$H$5:$H$64,MATCH(10,Facts!$L$5:$L$64,0)),"; ",", "))&")_","")
A21: =IFERROR("- **"&INDEX(Facts!$C$5:$C$64,MATCH(11,Facts!$L$5:$L$64,0))&"** "&INDEX(Facts!$D$5:$D$64,MATCH(11,Facts!$L$5:$L$64,0))&" _(status: "&INDEX(Facts!$E$5:$E$64,MATCH(11,Facts!$L$5:$L$64,0))&"; confidence: "&TEXT(INDEX(Facts!$F$5:$F$64,MATCH(11,Facts!$L$5:$L$64,0)),"0%")&"; source: "&IF(INDEX(Facts!$H$5:$H$64,MATCH(11,Facts!$L$5:$L$64,0))="",INDEX(Facts!$G$5:$G$64,MATCH(11,Facts!$L$5:$L$64,0)),SUBSTITUTE(INDEX(Facts!$H$5:$H$64,MATCH(11,Facts!$L$5:$L$64,0)),"; ",", "))&")_","")
A22: =IFERROR("- **"&INDEX(Facts!$C$5:$C$64,MATCH(12,Facts!$L$5:$L$64,0))&"** "&INDEX(Facts!$D$5:$D$64,MATCH(12,Facts!$L$5:$L$64,0))&" _(status: "&INDEX(Facts!$E$5:$E$64,MATCH(12,Facts!$L$5:$L$64,0))&"; confidence: "&TEXT(INDEX(Facts!$F$5:$F$64,MATCH(12,Facts!$L$5:$L$64,0)),"0%")&"; source: "&IF(INDEX(Facts!$H$5:$H$64,MATCH(12,Facts!$L$5:$L$64,0))="",INDEX(Facts!$G$5:$G$64,MATCH(12,Facts!$L$5:$L$64,0)),SUBSTITUTE(INDEX(Facts!$H$5:$H$64,MATCH(12,Facts!$L$5:$L$64,0)),"; ",", "))&")_","")
A23: =IFERROR("- **"&INDEX(Facts!$C$5:$C$64,MATCH(13,Facts!$L$5:$L$64,0))&"** "&INDEX(Facts!$D$5:$D$64,MATCH(13,Facts!$L$5:$L$64,0))&" _(status: "&INDEX(Facts!$E$5:$E$64,MATCH(13,Facts!$L$5:$L$64,0))&"; confidence: "&TEXT(INDEX(Facts!$F$5:$F$64,MATCH(13,Facts!$L$5:$L$64,0)),"0%")&"; source: "&IF(INDEX(Facts!$H$5:$H$64,MATCH(13,Facts!$L$5:$L$64,0))="",INDEX(Facts!$G$5:$G$64,MATCH(13,Facts!$L$5:$L$64,0)),SUBSTITUTE(INDEX(Facts!$H$5:$H$64,MATCH(13,Facts!$L$5:$L$64,0)),"; ",", "))&")_","")
A24: =IFERROR("- **"&INDEX(Facts!$C$5:$C$64,MATCH(14,Facts!$L$5:$L$64,0))&"** "&INDEX(Facts!$D$5:$D$64,MATCH(14,Facts!$L$5:$L$64,0))&" _(status: "&INDEX(Facts!$E$5:$E$64,MATCH(14,Facts!$L$5:$L$64,0))&"; confidence: "&TEXT(INDEX(Facts!$F$5:$F$64,MATCH(14,Facts!$L$5:$L$64,0)),"0%")&"; source: "&IF(INDEX(Facts!$H$5:$H$64,MATCH(14,Facts!$L$5:$L$64,0))="",INDEX(Facts!$G$5:$G$64,MATCH(14,Facts!$L$5:$L$64,0)),SUBSTITUTE(INDEX(Facts!$H$5:$H$64,MATCH(14,Facts!$L$5:$L$64,0)),"; ",", "))&")_","")
A25: =IFERROR("- **"&INDEX(Facts!$C$5:$C$64,MATCH(15,Facts!$L$5:$L$64,0))&"** "&INDEX(Facts!$D$5:$D$64,MATCH(15,Facts!$L$5:$L$64,0))&" _(status: "&INDEX(Facts!$E$5:$E$64,MATCH(15,Facts!$L$5:$L$64,0))&"; confidence: "&TEXT(INDEX(Facts!$F$5:$F$64,MATCH(15,Facts!$L$5:$L$64,0)),"0%")&"; source: "&IF(INDEX(Facts!$H$5:$H$64,MATCH(15,Facts!$L$5:$L$64,0))="",INDEX(Facts!$G$5:$G$64,MATCH(15,Facts!$L$5:$L$64,0)),SUBSTITUTE(INDEX(Facts!$H$5:$H$64,MATCH(15,Facts!$L$5:$L$64,0)),"; ",", "))&")_","")
A27: ## Cash Cycle And Seasonality
A29: =IF(COUNTIF(Facts!$B$5:$B$64,"cash_cycle")=0,"- Not yet known.","")
A30: =IFERROR("- **"&INDEX(Facts!$C$5:$C$64,MATCH(1,Facts!$M$5:$M$64,0))&"** "&INDEX(Facts!$D$5:$D$64,MATCH(1,Facts!$M$5:$M$64,0))&" _(status: "&INDEX(Facts!$E$5:$E$64,MATCH(1,Facts!$M$5:$M$64,0))&"; confidence: "&TEXT(INDEX(Facts!$F$5:$F$64,MATCH(1,Facts!$M$5:$M$64,0)),"0%")&"; source: "&IF(INDEX(Facts!$H$5:$H$64,MATCH(1,Facts!$M$5:$M$64,0))="",INDEX(Facts!$G$5:$G$64,MATCH(1,Facts!$M$5:$M$64,0)),SUBSTITUTE(INDEX(Facts!$H$5:$H$64,MATCH(1,Facts!$M$5:$M$64,0)),"; ",", "))&")_","")
A31: =IFERROR("- **"&INDEX(Facts!$C$5:$C$64,MATCH(2,Facts!$M$5:$M$64,0))&"** "&INDEX(Facts!$D$5:$D$64,MATCH(2,Facts!$M$5:$M$64,0))&" _(status: "&INDEX(Facts!$E$5:$E$64,MATCH(2,Facts!$M$5:$M$64,0))&"; confidence: "&TEXT(INDEX(Facts!$F$5:$F$64,MATCH(2,Facts!$M$5:$M$64,0)),"0%")&"; source: "&IF(INDEX(Facts!$H$5:$H$64,MATCH(2,Facts!$M$5:$M$64,0))="",INDEX(Facts!$G$5:$G$64,MATCH(2,Facts!$M$5:$M$64,0)),SUBSTITUTE(INDEX(Facts!$H$5:$H$64,MATCH(2,Facts!$M$5:$M$64,0)),"; ",", "))&")_","")
A32: =IFERROR("- **"&INDEX(Facts!$C$5:$C$64,MATCH(3,Facts!$M$5:$M$64,0))&"** "&INDEX(Facts!$D$5:$D$64,MATCH(3,Facts!$M$5:$M$64,0))&" _(status: "&INDEX(Facts!$E$5:$E$64,MATCH(3,Facts!$M$5:$M$64,0))&"; confidence: "&TEXT(INDEX(Facts!$F$5:$F$64,MATCH(3,Facts!$M$5:$M$64,0)),"0%")&"; source: "&IF(INDEX(Facts!$H$5:$H$64,MATCH(3,Facts!$M$5:$M$64,0))="",INDEX(Facts!$G$5:$G$64,MATCH(3,Facts!$M$5:$M$64,0)),SUBSTITUTE(INDEX(Facts!$H$5:$H$64,MATCH(3,Facts!$M$5:$M$64,0)),"; ",", "))&")_","")
A33: =IFERROR("- **"&INDEX(Facts!$C$5:$C$64,MATCH(4,Facts!$M$5:$M$64,0))&"** "&INDEX(Facts!$D$5:$D$64,MATCH(4,Facts!$M$5:$M$64,0))&" _(status: "&INDEX(Facts!$E$5:$E$64,MATCH(4,Facts!$M$5:$M$64,0))&"; confidence: "&TEXT(INDEX(Facts!$F$5:$F$64,MATCH(4,Facts!$M$5:$M$64,0)),"0%")&"; source: "&IF(INDEX(Facts!$H$5:$H$64,MATCH(4,Facts!$M$5:$M$64,0))="",INDEX(Facts!$G$5:$G$64,MATCH(4,Facts!$M$5:$M$64,0)),SUBSTITUTE(INDEX(Facts!$H$5:$H$64,MATCH(4,Facts!$M$5:$M$64,0)),"; ",", "))&")_","")
A34: =IFERROR("- **"&INDEX(Facts!$C$5:$C$64,MATCH(5,Facts!$M$5:$M$64,0))&"** "&INDEX(Facts!$D$5:$D$64,MATCH(5,Facts!$M$5:$M$64,0))&" _(status: "&INDEX(Facts!$E$5:$E$64,MATCH(5,Facts!$M$5:$M$64,0))&"; confidence: "&TEXT(INDEX(Facts!$F$5:$F$64,MATCH(5,Facts!$M$5:$M$64,0)),"0%")&"; source: "&IF(INDEX(Facts!$H$5:$H$64,MATCH(5,Facts!$M$5:$M$64,0))="",INDEX(Facts!$G$5:$G$64,MATCH(5,Facts!$M$5:$M$64,0)),SUBSTITUTE(INDEX(Facts!$H$5:$H$64,MATCH(5,Facts!$M$5:$M$64,0)),"; ",", "))&")_","")
A35: =IFERROR("- **"&INDEX(Facts!$C$5:$C$64,MATCH(6,Facts!$M$5:$M$64,0))&"** "&INDEX(Facts!$D$5:$D$64,MATCH(6,Facts!$M$5:$M$64,0))&" _(status: "&INDEX(Facts!$E$5:$E$64,MATCH(6,Facts!$M$5:$M$64,0))&"; confidence: "&TEXT(INDEX(Facts!$F$5:$F$64,MATCH(6,Facts!$M$5:$M$64,0)),"0%")&"; source: "&IF(INDEX(Facts!$H$5:$H$64,MATCH(6,Facts!$M$5:$M$64,0))="",INDEX(Facts!$G$5:$G$64,MATCH(6,Facts!$M$5:$M$64,0)),SUBSTITUTE(INDEX(Facts!$H$5:$H$64,MATCH(6,Facts!$M$5:$M$64,0)),"; ",", "))&")_","")
A36: =IFERROR("- **"&INDEX(Facts!$C$5:$C$64,MATCH(7,Facts!$M$5:$M$64,0))&"** "&INDEX(Facts!$D$5:$D$64,MATCH(7,Facts!$M$5:$M$64,0))&" _(status: "&INDEX(Facts!$E$5:$E$64,MATCH(7,Facts!$M$5:$M$64,0))&"; confidence: "&TEXT(INDEX(Facts!$F$5:$F$64,MATCH(7,Facts!$M$5:$M$64,0)),"0%")&"; source: "&IF(INDEX(Facts!$H$5:$H$64,MATCH(7,Facts!$M$5:$M$64,0))="",INDEX(Facts!$G$5:$G$64,MATCH(7,Facts!$M$5:$M$64,0)),SUBSTITUTE(INDEX(Facts!$H$5:$H$64,MATCH(7,Facts!$M$5:$M$64,0)),"; ",", "))&")_","")
A37: =IFERROR("- **"&INDEX(Facts!$C$5:$C$64,MATCH(8,Facts!$M$5:$M$64,0))&"** "&INDEX(Facts!$D$5:$D$64,MATCH(8,Facts!$M$5:$M$64,0))&" _(status: "&INDEX(Facts!$E$5:$E$64,MATCH(8,Facts!$M$5:$M$64,0))&"; confidence: "&TEXT(INDEX(Facts!$F$5:$F$64,MATCH(8,Facts!$M$5:$M$64,0)),"0%")&"; source: "&IF(INDEX(Facts!$H$5:$H$64,MATCH(8,Facts!$M$5:$M$64,0))="",INDEX(Facts!$G$5:$G$64,MATCH(8,Facts!$M$5:$M$64,0)),SUBSTITUTE(INDEX(Facts!$H$5:$H$64,MATCH(8,Facts!$M$5:$M$64,0)),"; ",", "))&")_","")
A38: =IFERROR("- **"&INDEX(Facts!$C$5:$C$64,MATCH(9,Facts!$M$5:$M$64,0))&"** "&INDEX(Facts!$D$5:$D$64,MATCH(9,Facts!$M$5:$M$64,0))&" _(status: "&INDEX(Facts!$E$5:$E$64,MATCH(9,Facts!$M$5:$M$64,0))&"; confidence: "&TEXT(INDEX(Facts!$F$5:$F$64,MATCH(9,Facts!$M$5:$M$64,0)),"0%")&"; source: "&IF(INDEX(Facts!$H$5:$H$64,MATCH(9,Facts!$M$5:$M$64,0))="",INDEX(Facts!$G$5:$G$64,MATCH(9,Facts!$M$5:$M$64,0)),SUBSTITUTE(INDEX(Facts!$H$5:$H$64,MATCH(9,Facts!$M$5:$M$64,0)),"; ",", "))&")_","")
A39: =IFERROR("- **"&INDEX(Facts!$C$5:$C$64,MATCH(10,Facts!$M$5:$M$64,0))&"** "&INDEX(Facts!$D$5:$D$64,MATCH(10,Facts!$M$5:$M$64,0))&" _(status: "&INDEX(Facts!$E$5:$E$64,MATCH(10,Facts!$M$5:$M$64,0))&"; confidence: "&TEXT(INDEX(Facts!$F$5:$F$64,MATCH(10,Facts!$M$5:$M$64,0)),"0%")&"; source: "&IF(INDEX(Facts!$H$5:$H$64,MATCH(10,Facts!$M$5:$M$64,0))="",INDEX(Facts!$G$5:$G$64,MATCH(10,Facts!$M$5:$M$64,0)),SUBSTITUTE(INDEX(Facts!$H$5:$H$64,MATCH(10,Facts!$M$5:$M$64,0)),"; ",", "))&")_","")
A40: =IFERROR("- **"&INDEX(Facts!$C$5:$C$64,MATCH(11,Facts!$M$5:$M$64,0))&"** "&INDEX(Facts!$D$5:$D$64,MATCH(11,Facts!$M$5:$M$64,0))&" _(status: "&INDEX(Facts!$E$5:$E$64,MATCH(11,Facts!$M$5:$M$64,0))&"; confidence: "&TEXT(INDEX(Facts!$F$5:$F$64,MATCH(11,Facts!$M$5:$M$64,0)),"0%")&"; source: "&IF(INDEX(Facts!$H$5:$H$64,MATCH(11,Facts!$M$5:$M$64,0))="",INDEX(Facts!$G$5:$G$64,MATCH(11,Facts!$M$5:$M$64,0)),SUBSTITUTE(INDEX(Facts!$H$5:$H$64,MATCH(11,Facts!$M$5:$M$64,0)),"; ",", "))&")_","")
A41: =IFERROR("- **"&INDEX(Facts!$C$5:$C$64,MATCH(12,Facts!$M$5:$M$64,0))&"** "&INDEX(Facts!$D$5:$D$64,MATCH(12,Facts!$M$5:$M$64,0))&" _(status: "&INDEX(Facts!$E$5:$E$64,MATCH(12,Facts!$M$5:$M$64,0))&"; confidence: "&TEXT(INDEX(Facts!$F$5:$F$64,MATCH(12,Facts!$M$5:$M$64,0)),"0%")&"; source: "&IF(INDEX(Facts!$H$5:$H$64,MATCH(12,Facts!$M$5:$M$64,0))="",INDEX(Facts!$G$5:$G$64,MATCH(12,Facts!$M$5:$M$64,0)),SUBSTITUTE(INDEX(Facts!$H$5:$H$64,MATCH(12,Facts!$M$5:$M$64,0)),"; ",", "))&")_","")
A42: =IFERROR("- **"&INDEX(Facts!$C$5:$C$64,MATCH(13,Facts!$M$5:$M$64,0))&"** "&INDEX(Facts!$D$5:$D$64,MATCH(13,Facts!$M$5:$M$64,0))&" _(status: "&INDEX(Facts!$E$5:$E$64,MATCH(13,Facts!$M$5:$M$64,0))&"; confidence: "&TEXT(INDEX(Facts!$F$5:$F$64,MATCH(13,Facts!$M$5:$M$64,0)),"0%")&"; source: "&IF(INDEX(Facts!$H$5:$H$64,MATCH(13,Facts!$M$5:$M$64,0))="",INDEX(Facts!$G$5:$G$64,MATCH(13,Facts!$M$5:$M$64,0)),SUBSTITUTE(INDEX(Facts!$H$5:$H$64,MATCH(13,Facts!$M$5:$M$64,0)),"; ",", "))&")_","")
A43: =IFERROR("- **"&INDEX(Facts!$C$5:$C$64,MATCH(14,Facts!$M$5:$M$64,0))&"** "&INDEX(Facts!$D$5:$D$64,MATCH(14,Facts!$M$5:$M$64,0))&" _(status: "&INDEX(Facts!$E$5:$E$64,MATCH(14,Facts!$M$5:$M$64,0))&"; confidence: "&TEXT(INDEX(Facts!$F$5:$F$64,MATCH(14,Facts!$M$5:$M$64,0)),"0%")&"; source: "&IF(INDEX(Facts!$H$5:$H$64,MATCH(14,Facts!$M$5:$M$64,0))="",INDEX(Facts!$G$5:$G$64,MATCH(14,Facts!$M$5:$M$64,0)),SUBSTITUTE(INDEX(Facts!$H$5:$H$64,MATCH(14,Facts!$M$5:$M$64,0)),"; ",", "))&")_","")
A44: =IFERROR("- **"&INDEX(Facts!$C$5:$C$64,MATCH(15,Facts!$M$5:$M$64,0))&"** "&INDEX(Facts!$D$5:$D$64,MATCH(15,Facts!$M$5:$M$64,0))&" _(status: "&INDEX(Facts!$E$5:$E$64,MATCH(15,Facts!$M$5:$M$64,0))&"; confidence: "&TEXT(INDEX(Facts!$F$5:$F$64,MATCH(15,Facts!$M$5:$M$64,0)),"0%")&"; source: "&IF(INDEX(Facts!$H$5:$H$64,MATCH(15,Facts!$M$5:$M$64,0))="",INDEX(Facts!$G$5:$G$64,MATCH(15,Facts!$M$5:$M$64,0)),SUBSTITUTE(INDEX(Facts!$H$5:$H$64,MATCH(15,Facts!$M$5:$M$64,0)),"; ",", "))&")_","")
A46: ## Entity, Financing, And Data Structure
A48: =IF(COUNTIF(Facts!$B$5:$B$64,"finance_structure")=0,"- Not yet known.","")
A49: =IFERROR("- **"&INDEX(Facts!$C$5:$C$64,MATCH(1,Facts!$N$5:$N$64,0))&"** "&INDEX(Facts!$D$5:$D$64,MATCH(1,Facts!$N$5:$N$64,0))&" _(status: "&INDEX(Facts!$E$5:$E$64,MATCH(1,Facts!$N$5:$N$64,0))&"; confidence: "&TEXT(INDEX(Facts!$F$5:$F$64,MATCH(1,Facts!$N$5:$N$64,0)),"0%")&"; source: "&IF(INDEX(Facts!$H$5:$H$64,MATCH(1,Facts!$N$5:$N$64,0))="",INDEX(Facts!$G$5:$G$64,MATCH(1,Facts!$N$5:$N$64,0)),SUBSTITUTE(INDEX(Facts!$H$5:$H$64,MATCH(1,Facts!$N$5:$N$64,0)),"; ",", "))&")_","")
...

Sheet Proposal
A1: initial-model-architecture.md renderer - fill the proposal inputs, copy column D from row 4
D2: Renderer is only valid when intake is ready: | F2: =IF(Readiness!$J$1,"READY - write the files","NOT READY - keep asking (Readiness sheet)")
A4: summary | D4: ="# Initial Model Architecture Proposal"
D5: =""
A6: connectors | D6: ="**Status:** Proposed. Human approval required before scaffolding."
D7: =""
D8: ="## Objective"
D9: =""
D10: =TRIM(B4)
D11: =""
D12: ="## Known Facts"
D13: =""
D14: =IF(Facts!A5="","",IF(AND(LOWER(Facts!E5)<>"conflict",OR(LOWER(Facts!E5)="confirmed",Facts!F5>=0.7)),"- "&Facts!C5&": "&Facts!D5,""))
A15: model_components | D15: =IF(Facts!A6="","",IF(AND(LOWER(Facts!E6)<>"conflict",OR(LOWER(Facts!E6)="confirmed",Facts!F6>=0.7)),"- "&Facts!C6&": "&Facts!D6,""))
D16: =IF(Facts!A7="","",IF(AND(LOWER(Facts!E7)<>"conflict",OR(LOWER(Facts!E7)="confirmed",Facts!F7>=0.7)),"- "&Facts!C7&": "&Facts!D7,""))
D17: =IF(Facts!A8="","",IF(AND(LOWER(Facts!E8)<>"conflict",OR(LOWER(Facts!E8)="confirmed",Facts!F8>=0.7)),"- "&Facts!C8&": "&Facts!D8,""))
D18: =IF(Facts!A9="","",IF(AND(LOWER(Facts!E9)<>"conflict",OR(LOWER(Facts!E9)="confirmed",Facts!F9>=0.7)),"- "&Facts!C9&": "&Facts!D9,""))
D19: =IF(Facts!A10="","",IF(AND(LOWER(Facts!E10)<>"conflict",OR(LOWER(Facts!E10)="confirmed",Facts!F10>=0.7)),"- "&Facts!C10&": "&Facts!D10,""))
D20: =IF(Facts!A11="","",IF(AND(LOWER(Facts!E11)<>"conflict",OR(LOWER(Facts!E11)="confirmed",Facts!F11>=0.7)),"- "&Facts!C11&": "&Facts!D11,""))
D21: =IF(Facts!A12="","",IF(AND(LOWER(Facts!E12)<>"conflict",OR(LOWER(Facts!E12)="confirmed",Facts!F12>=0.7)),"- "&Facts!C12&": "&Facts!D12,""))
D22: =IF(Facts!A13="","",IF(AND(LOWER(Facts!E13)<>"conflict",OR(LOWER(Facts!E13)="confirmed",Facts!F13>=0.7)),"- "&Facts!C13&": "&Facts!D13,""))
D23: =IF(Facts!A14="","",IF(AND(LOWER(Facts!E14)<>"conflict",OR(LOWER(Facts!E14)="confirmed",Facts!F14>=0.7)),"- "&Facts!C14&": "&Facts!D14,""))
A24: generated_skills | D24: =IF(Facts!A15="","",IF(AND(LOWER(Facts!E15)<>"conflict",OR(LOWER(Facts!E15)="confirmed",Facts!F15>=0.7)),"- "&Facts!C15&": "&Facts!D15,""))
D25: =IF(Facts!A16="","",IF(AND(LOWER(Facts!E16)<>"conflict",OR(LOWER(Facts!E16)="confirmed",Facts!F16>=0.7)),"- "&Facts!C16&": "&Facts!D16,""))
D26: =IF(Facts!A17="","",IF(AND(LOWER(Facts!E17)<>"conflict",OR(LOWER(Facts!E17)="confirmed",Facts!F17>=0.7)),"- "&Facts!C17&": "&Facts!D17,""))
D27: =IF(Facts!A18="","",IF(AND(LOWER(Facts!E18)<>"conflict",OR(LOWER(Facts!E18)="confirmed",Facts!F18>=0.7)),"- "&Facts!C18&": "&Facts!D18,""))
D28: =IF(Facts!A19="","",IF(AND(LOWER(Facts!E19)<>"conflict",OR(LOWER(Facts!E19)="confirmed",Facts!F19>=0.7)),"- "&Facts!C19&": "&Facts!D19,""))
D29: =IF(Facts!A20="","",IF(AND(LOWER(Facts!E20)<>"conflict",OR(LOWER(Facts!E20)="confirmed",Facts!F20>=0.7)),"- "&Facts!C20&": "&Facts!D20,""))
D30: =IF(Facts!A21="","",IF(AND(LOWER(Facts!E21)<>"conflict",OR(LOWER(Facts!E21)="confirmed",Facts!F21>=0.7)),"- "&Facts!C21&": "&Facts!D21,""))
D31: =IF(Facts!A22="","",IF(AND(LOWER(Facts!E22)<>"conflict",OR(LOWER(Facts!E22)="confirmed",Facts!F22>=0.7)),"- "&Facts!C22&": "&Facts!D22,""))
D32: =IF(Facts!A23="","",IF(AND(LOWER(Facts!E23)<>"conflict",OR(LOWER(Facts!E23)="confirmed",Facts!F23>=0.7)),"- "&Facts!C23&": "&Facts!D23,""))
A33: risks | D33: =IF(Facts!A24="","",IF(AND(LOWER(Facts!E24)<>"conflict",OR(LOWER(Facts!E24)="confirmed",Facts!F24>=0.7)),"- "&Facts!C24&": "&Facts!D24,""))
D34: =IF(Facts!A25="","",IF(AND(LOWER(Facts!E25)<>"conflict",OR(LOWER(Facts!E25)="confirmed",Facts!F25>=0.7)),"- "&Facts!C25&": "&Facts!D25,""))
D35: =IF(Facts!A26="","",IF(AND(LOWER(Facts!E26)<>"conflict",OR(LOWER(Facts!E26)="confirmed",Facts!F26>=0.7)),"- "&Facts!C26&": "&Facts!D26,""))
D36: =IF(Facts!A27="","",IF(AND(LOWER(Facts!E27)<>"conflict",OR(LOWER(Facts!E27)="confirmed",Facts!F27>=0.7)),"- "&Facts!C27&": "&Facts!D27,""))
D37: =IF(Facts!A28="","",IF(AND(LOWER(Facts!E28)<>"conflict",OR(LOWER(Facts!E28)="confirmed",Facts!F28>=0.7)),"- "&Facts!C28&": "&Facts!D28,""))
D38: =IF(Facts!A29="","",IF(AND(LOWER(Facts!E29)<>"conflict",OR(LOWER(Facts!E29)="confirmed",Facts!F29>=0.7)),"- "&Facts!C29&": "&Facts!D29,""))
D39: =IF(Facts!A30="","",IF(AND(LOWER(Facts!E30)<>"conflict",OR(LOWER(Facts!E30)="confirmed",Facts!F30>=0.7)),"- "&Facts!C30&": "&Facts!D30,""))
D40: =IF(Facts!A31="","",IF(AND(LOWER(Facts!E31)<>"conflict",OR(LOWER(Facts!E31)="confirmed",Facts!F31>=0.7)),"- "&Facts!C31&": "&Facts!D31,""))
D41: =IF(Facts!A32="","",IF(AND(LOWER(Facts!E32)<>"conflict",OR(LOWER(Facts!E32)="confirmed",Facts!F32>=0.7)),"- "&Facts!C32&": "&Facts!D32,""))
...
