Workbook

Sheet README
A1: K11 · Memory Index & Task Context Pack (no-code kernel)
A3: Replaces openfpa: pyfpa.memory.retrieval (build_memory_index, search_memory, build_context_pack) and CLI context-pack.
A4: Index = memory/index.csv: one row per canonical memory file (path relative to memory/, category = first folder or file stem, title = first '# ' heading or the stem in Title Case, keywords = the unique lowercase words [a-z0-9_-, 2+ chars] of the path, title, headings and frontmatter values). index.csv and context-pack.md are never indexed. The index is derived - rebuild it, never treat it as truth.
A5: Task tokens: split the task sentence into the same kind of lowercase words (one per cell, up to 12, duplicates removed).
A6: Score = (task tokens found in the entry) / (task tokens) + 0.5 x (task tokens found in the title) + 0.25 x (task tokens found in the path). Entries with zero overlap are dropped. Ties break by path ascending. Default limit 8; optional category filter.
A7: 'Pack' renders memory/context-pack.md (a TEMPORARY retrieval output; canonical memory stays in the linked files).

Sheet Checks
A1: Checks - OVERALL must be PASS
B3: OVERALL | C3: =IF(COUNTIF(C5:C7,"PASS")=COUNT(A5:A7),"PASS","FAIL") | D3: =COUNTIF(C5:C7,"PASS")&" pass / "&COUNTIF(C5:C7,"FAIL")&" fail / "&(COUNT(A5:A7)-COUNTIF(C5:C7,"PASS")-COUNTIF(C5:C7,"FAIL"))&" error"
A4: # | B4: check | C4: result | D4: detail
A5: 1 | B5: at least one task token | C5: =IF(Task!B21>0,"PASS","FAIL") | D5: =Task!B21
A6: 2 | B6: index paths unique | C6: =IF(SUMPRODUCT((Index!A5:A404<>"")*(COUNTIF(Index!A5:A404,Index!A5:A404)>1))=0,"PASS","FAIL")
A7: 3 | B7: limit >= 1 | C7: =IF(Task!B4>=1,"PASS","FAIL")

Sheet Task
A1: Task
A3: task (sentence)
A4: limit | B4: 8
A5: category filter (blank = all; up to 4)
A7: task token (lowercase word)
A21: token count | B21: =SUMPRODUCT((A8:A19<>"")*1)

Sheet Index
A1: Index (paste memory/index.csv)
A4: path | B4: category | C4: title | D4: keywords (space separated) | E4: allowed? | F4: overlap | G4: title hits | H4: path hits | I4: score | J4: rank key | K4: rank
E5: =IF(A5="",0,IF(COUNTA(Task!$B$5:$E$5)=0,1,IF(COUNTIF(Task!$B$5:$E$5,B5)>0,1,0))) | F5: =IF(E5=0,0,IF(Task!$A$8="",0,IF(ISNUMBER(SEARCH(" "&Task!$A$8&" "," "&LOWER(D5&" "&C5&" "&LOWER(SUBSTITUTE(SUBSTITUTE(SUBSTITUTE(SUBSTITUTE(A5,"/"," "),"."," "),"\"," "),"_"," ")))&" ")),1,0))+IF(Task!$A$9="",0,IF(ISNUMBER(SEARCH(" "&Task!$A$9&" "," "&LOWER(D5&" "&C5&" "&LOWER(SUBSTITUTE(SUBSTITUTE(SUBSTITUTE(SUBSTITUTE(A5,"/"," "),"."," "),"\"," "),"_"," ")))&" ")),1,0))+IF(Task!$A$10="",0,IF(ISNUMBER(SEARCH(" "&Task!$A$10&" "," "&LOWER(D5&" "&C5&" "&LOWER(SUBSTITUTE(SUBSTITUTE(SUBSTITUTE(SUBSTITUTE(A5,"/"," "),"."," "),"\"," "),"_"," ")))&" ")),1,0))+IF(Task!$A$11="",0,IF(ISNUMBER(SEARCH(" "&Task!$A$11&" "," "&LOWER(D5&" "&C5&" "&LOWER(SUBSTITUTE(SUBSTITUTE(SUBSTITUTE(SUBSTITUTE(A5,"/"," "),"."," "),"\"," "),"_"," ")))&" ")),1,0))+IF(Task!$A$12="",0,IF(ISNUMBER(SEARCH(" "&Task!$A$12&" "," "&LOWER(D5&" "&C5&" "&LOWER(SUBSTITUTE(SUBSTITUTE(SUBSTITUTE(SUBSTITUTE(A5,"/"," "),"."," "),"\"," "),"_"," ")))&" ")),1,0))+IF(Task!$A$13="",0,IF(ISNUMBER(SEARCH(" "&Task!$A$13&" "," "&LOWER(D5&" "&C5&" "&LOWER(SUBSTITUTE(SUBSTITUTE(SUBSTITUTE(SUBSTITUTE(A5,"/"," "),"."," "),"\"," "),"_"," ")))&" ")),1,0))+IF(Task!$A$14="",0,IF(ISNUMBER(SEARCH(" "&Task!$A$14&" "," "&LOWER(D5&" "&C5&" "&LOWER(SUBSTITUTE(SUBSTITUTE(SUBSTITUTE(SUBSTITUTE(A5,"/"," "),"."," "),"\"," "),"_"," ")))&" ")),1,0))+IF(Task!$A$15="",0,IF(ISNUMBER(SEARCH(" "&Task!$A$15&" "," "&LOWER(D5&" "&C5&" "&LOWER(SUBSTITUTE(SUBSTITUTE(SUBSTITUTE(SUBSTITUTE(A5,"/"," "),"."," "),"\"," "),"_"," ")))&" ")),1,0))+IF(Task!$A$16="",0,IF(ISNUMBER(SEARCH(" "&Task!$A$16&" "," "&LOWER(D5&" "&C5&" "&LOWER(SUBSTITUTE(SUBSTITUTE(SUBSTITUTE(SUBSTITUTE(A5,"/"," "),"."," "),"\"," "),"_"," ")))&" ")),1,0))+IF(Task!$A$17="",0,IF(ISNUMBER(SEARCH(" "&Task!$A$17&" "," "&LOWER(D5&" "&C5&" "&LOWER(SUBSTITUTE(SUBSTITUTE(SUBSTITUTE(SUBSTITUTE(A5,"/"," "),"."," "),"\"," "),"_"," ")))&" ")),1,0))+IF(Task!$A$18="",0,IF(ISNUMBER(SEARCH(" "&Task!$A$18&" "," "&LOWER(D5&" "&C5&" "&LOWER(SUBSTITUTE(SUBSTITUTE(SUBSTITUTE(SUBSTITUTE(A5,"/"," "),"."," "),"\"," "),"_"," ")))&" ")),1,0))+IF(Task!$A$19="",0,IF(ISNUMBER(SEARCH(" "&Task!$A$19&" "," "&LOWER(D5&" "&C5&" "&LOWER(SUBSTITUTE(SUBSTITUTE(SUBSTITUTE(SUBSTITUTE(A5,"/"," "),"."," "),"\"," "),"_"," ")))&" ")),1,0))) | G5: =IF(E5=0,0,IF(Task!$A$8="",0,IF(ISNUMBER(SEARCH(" "&Task!$A$8&" "," "&LOWER(C5)&" ")),1,0))+IF(Task!$A$9="",0,IF(ISNUMBER(SEARCH(" "&Task!$A$9&" "," "&LOWER(C5)&" ")),1,0))+IF(Task!$A$10="",0,IF(ISNUMBER(SEARCH(" "&Task!$A$10&" "," "&LOWER(C5)&" ")),1,0))+IF(Task!$A$11="",0,IF(ISNUMBER(SEARCH(" "&Task!$A$11&" "," "&LOWER(C5)&" ")),1,0))+IF(Task!$A$12="",0,IF(ISNUMBER(SEARCH(" "&Task!$A$12&" "," "&LOWER(C5)&" ")),1,0))+IF(Task!$A$13="",0,IF(ISNUMBER(SEARCH(" "&Task!$A$13&" "," "&LOWER(C5)&" ")),1,0))+IF(Task!$A$14="",0,IF(ISNUMBER(SEARCH(" "&Task!$A$14&" "," "&LOWER(C5)&" ")),1,0))+IF(Task!$A$15="",0,IF(ISNUMBER(SEARCH(" "&Task!$A$15&" "," "&LOWER(C5)&" ")),1,0))+IF(Task!$A$16="",0,IF(ISNUMBER(SEARCH(" "&Task!$A$16&" "," "&LOWER(C5)&" ")),1,0))+IF(Task!$A$17="",0,IF(ISNUMBER(SEARCH(" "&Task!$A$17&" "," "&LOWER(C5)&" ")),1,0))+IF(Task!$A$18="",0,IF(ISNUMBER(SEARCH(" "&Task!$A$18&" "," "&LOWER(C5)&" ")),1,0))+IF(Task!$A$19="",0,IF(ISNUMBER(SEARCH(" "&Task!$A$19&" "," "&LOWER(C5)&" ")),1,0))) | H5: =IF(E5=0,0,IF(Task!$A$8="",0,IF(ISNUMBER(SEARCH(" "&Task!$A$8&" "," "&LOWER(SUBSTITUTE(SUBSTITUTE(SUBSTITUTE(SUBSTITUTE(A5,"/"," "),"."," "),"\"," "),"_"," "))&" ")),1,0))+IF(Task!$A$9="",0,IF(ISNUMBER(SEARCH(" "&Task!$A$9&" "," "&LOWER(SUBSTITUTE(SUBSTITUTE(SUBSTITUTE(SUBSTITUTE(A5,"/"," "),"."," "),"\"," "),"_"," "))&" ")),1,0))+IF(Task!$A$10="",0,IF(ISNUMBER(SEARCH(" "&Task!$A$10&" "," "&LOWER(SUBSTITUTE(SUBSTITUTE(SUBSTITUTE(SUBSTITUTE(A5,"/"," "),"."," "),"\"," "),"_"," "))&" ")),1,0))+IF(Task!$A$11="",0,IF(ISNUMBER(SEARCH(" "&Task!$A$11&" "," "&LOWER(SUBSTITUTE(SUBSTITUTE(SUBSTITUTE(SUBSTITUTE(A5,"/"," "),"."," "),"\"," "),"_"," "))&" ")),1,0))+IF(Task!$A$12="",0,IF(ISNUMBER(SEARCH(" "&Task!$A$12&" "," "&LOWER(SUBSTITUTE(SUBSTITUTE(SUBSTITUTE(SUBSTITUTE(A5,"/"," "),"."," "),"\"," "),"_"," "))&" ")),1,0))+IF(Task!$A$13="",0,IF(ISNUMBER(SEARCH(" "&Task!$A$13&" "," "&LOWER(SUBSTITUTE(SUBSTITUTE(SUBSTITUTE(SUBSTITUTE(A5,"/"," "),"."," "),"\"," "),"_"," "))&" ")),1,0))+IF(Task!$A$14="",0,IF(ISNUMBER(SEARCH(" "&Task!$A$14&" "," "&LOWER(SUBSTITUTE(SUBSTITUTE(SUBSTITUTE(SUBSTITUTE(A5,"/"," "),"."," "),"\"," "),"_"," "))&" ")),1,0))+IF(Task!$A$15="",0,IF(ISNUMBER(SEARCH(" "&Task!$A$15&" "," "&LOWER(SUBSTITUTE(SUBSTITUTE(SUBSTITUTE(SUBSTITUTE(A5,"/"," "),"."," "),"\"," "),"_"," "))&" ")),1,0))+IF(Task!$A$16="",0,IF(ISNUMBER(SEARCH(" "&Task!$A$16&" "," "&LOWER(SUBSTITUTE(SUBSTITUTE(SUBSTITUTE(SUBSTITUTE(A5,"/"," "),"."," "),"\"," "),"_"," "))&" ")),1,0))+IF(Task!$A$17="",0,IF(ISNUMBER(SEARCH(" "&Task!$A$17&" "," "&LOWER(SUBSTITUTE(SUBSTITUTE(SUBSTITUTE(SUBSTITUTE(A5,"/"," "),"."," "),"\"," "),"_"," "))&" ")),1,0))+IF(Task!$A$18="",0,IF(ISNUMBER(SEARCH(" "&Task!$A$18&" "," "&LOWER(SUBSTITUTE(SUBSTITUTE(SUBSTITUTE(SUBSTITUTE(A5,"/"," "),"."," "),"\"," "),"_"," "))&" ")),1,0))+IF(Task!$A$19="",0,IF(ISNUMBER(SEARCH(" "&Task!$A$19&" "," "&LOWER(SUBSTITUTE(SUBSTITUTE(SUBSTITUTE(SUBSTITUTE(A5,"/"," "),"."," "),"\"," "),"_"," "))&" ")),1,0))) | I5: =IF(OR(E5=0,F5=0,Task!$B$21=0),"",F5/Task!$B$21+0.5*G5+0.25*H5) | J5: =IF(I5="","",I5-ROW()/1000000) | K5: =IF(J5="","",COUNTIF($J$5:$J$404,">"&J5)+1)
E6: =IF(A6="",0,IF(COUNTA(Task!$B$5:$E$5)=0,1,IF(COUNTIF(Task!$B$5:$E$5,B6)>0,1,0))) | F6: =IF(E6=0,0,IF(Task!$A$8="",0,IF(ISNUMBER(SEARCH(" "&Task!$A$8&" "," "&LOWER(D6&" "&C6&" "&LOWER(SUBSTITUTE(SUBSTITUTE(SUBSTITUTE(SUBSTITUTE(A6,"/"," "),"."," "),"\"," "),"_"," ")))&" ")),1,0))+IF(Task!$A$9="",0,IF(ISNUMBER(SEARCH(" "&Task!$A$9&" "," "&LOWER(D6&" "&C6&" "&LOWER(SUBSTITUTE(SUBSTITUTE(SUBSTITUTE(SUBSTITUTE(A6,"/"," "),"."," "),"\"," "),"_"," ")))&" ")),1,0))+IF(Task!$A$10="",0,IF(ISNUMBER(SEARCH(" "&Task!$A$10&" "," "&LOWER(D6&" "&C6&" "&LOWER(SUBSTITUTE(SUBSTITUTE(SUBSTITUTE(SUBSTITUTE(A6,"/"," "),"."," "),"\"," "),"_"," ")))&" ")),1,0))+IF(Task!$A$11="",0,IF(ISNUMBER(SEARCH(" "&Task!$A$11&" "," "&LOWER(D6&" "&C6&" "&LOWER(SUBSTITUTE(SUBSTITUTE(SUBSTITUTE(SUBSTITUTE(A6,"/"," "),"."," "),"\"," "),"_"," ")))&" ")),1,0))+IF(Task!$A$12="",0,IF(ISNUMBER(SEARCH(" "&Task!$A$12&" "," "&LOWER(D6&" "&C6&" "&LOWER(SUBSTITUTE(SUBSTITUTE(SUBSTITUTE(SUBSTITUTE(A6,"/"," "),"."," "),"\"," "),"_"," ")))&" ")),1,0))+IF(Task!$A$13="",0,IF(ISNUMBER(SEARCH(" "&Task!$A$13&" "," "&LOWER(D6&" "&C6&" "&LOWER(SUBSTITUTE(SUBSTITUTE(SUBSTITUTE(SUBSTITUTE(A6,"/"," "),"."," "),"\"," "),"_"," ")))&" ")),1,0))+IF(Task!$A$14="",0,IF(ISNUMBER(SEARCH(" "&Task!$A$14&" "," "&LOWER(D6&" "&C6&" "&LOWER(SUBSTITUTE(SUBSTITUTE(SUBSTITUTE(SUBSTITUTE(A6,"/"," "),"."," "),"\"," "),"_"," ")))&" ")),1,0))+IF(Task!$A$15="",0,IF(ISNUMBER(SEARCH(" "&Task!$A$15&" "," "&LOWER(D6&" "&C6&" "&LOWER(SUBSTITUTE(SUBSTITUTE(SUBSTITUTE(SUBSTITUTE(A6,"/"," "),"."," "),"\"," "),"_"," ")))&" ")),1,0))+IF(Task!$A$16="",0,IF(ISNUMBER(SEARCH(" "&Task!$A$16&" "," "&LOWER(D6&" "&C6&" "&LOWER(SUBSTITUTE(SUBSTITUTE(SUBSTITUTE(SUBSTITUTE(A6,"/"," "),"."," "),"\"," "),"_"," ")))&" ")),1,0))+IF(Task!$A$17="",0,IF(ISNUMBER(SEARCH(" "&Task!$A$17&" "," "&LOWER(D6&" "&C6&" "&LOWER(SUBSTITUTE(SUBSTITUTE(SUBSTITUTE(SUBSTITUTE(A6,"/"," "),"."," "),"\"," "),"_"," ")))&" ")),1,0))+IF(Task!$A$18="",0,IF(ISNUMBER(SEARCH(" "&Task!$A$18&" "," "&LOWER(D6&" "&C6&" "&LOWER(SUBSTITUTE(SUBSTITUTE(SUBSTITUTE(SUBSTITUTE(A6,"/"," "),"."," "),"\"," "),"_"," ")))&" ")),1,0))+IF(Task!$A$19="",0,IF(ISNUMBER(SEARCH(" "&Task!$A$19&" "," "&LOWER(D6&" "&C6&" "&LOWER(SUBSTITUTE(SUBSTITUTE(SUBSTITUTE(SUBSTITUTE(A6,"/"," "),"."," "),"\"," "),"_"," ")))&" ")),1,0))) | G6: =IF(E6=0,0,IF(Task!$A$8="",0,IF(ISNUMBER(SEARCH(" "&Task!$A$8&" "," "&LOWER(C6)&" ")),1,0))+IF(Task!$A$9="",0,IF(ISNUMBER(SEARCH(" "&Task!$A$9&" "," "&LOWER(C6)&" ")),1,0))+IF(Task!$A$10="",0,IF(ISNUMBER(SEARCH(" "&Task!$A$10&" "," "&LOWER(C6)&" ")),1,0))+IF(Task!$A$11="",0,IF(ISNUMBER(SEARCH(" "&Task!$A$11&" "," "&LOWER(C6)&" ")),1,0))+IF(Task!$A$12="",0,IF(ISNUMBER(SEARCH(" "&Task!$A$12&" "," "&LOWER(C6)&" ")),1,0))+IF(Task!$A$13="",0,IF(ISNUMBER(SEARCH(" "&Task!$A$13&" "," "&LOWER(C6)&" ")),1,0))+IF(Task!$A$14="",0,IF(ISNUMBER(SEARCH(" "&Task!$A$14&" "," "&LOWER(C6)&" ")),1,0))+IF(Task!$A$15="",0,IF(ISNUMBER(SEARCH(" "&Task!$A$15&" "," "&LOWER(C6)&" ")),1,0))+IF(Task!$A$16="",0,IF(ISNUMBER(SEARCH(" "&Task!$A$16&" "," "&LOWER(C6)&" ")),1,0))+IF(Task!$A$17="",0,IF(ISNUMBER(SEARCH(" "&Task!$A$17&" "," "&LOWER(C6)&" ")),1,0))+IF(Task!$A$18="",0,IF(ISNUMBER(SEARCH(" "&Task!$A$18&" "," "&LOWER(C6)&" ")),1,0))+IF(Task!$A$19="",0,IF(ISNUMBER(SEARCH(" "&Task!$A$19&" "," "&LOWER(C6)&" ")),1,0))) | H6: =IF(E6=0,0,IF(Task!$A$8="",0,IF(ISNUMBER(SEARCH(" "&Task!$A$8&" "," "&LOWER(SUBSTITUTE(SUBSTITUTE(SUBSTITUTE(SUBSTITUTE(A6,"/"," "),"."," "),"\"," "),"_"," "))&" ")),1,0))+IF(Task!$A$9="",0,IF(ISNUMBER(SEARCH(" "&Task!$A$9&" "," "&LOWER(SUBSTITUTE(SUBSTITUTE(SUBSTITUTE(SUBSTITUTE(A6,"/"," "),"."," "),"\"," "),"_"," "))&" ")),1,0))+IF(Task!$A$10="",0,IF(ISNUMBER(SEARCH(" "&Task!$A$10&" "," "&LOWER(SUBSTITUTE(SUBSTITUTE(SUBSTITUTE(SUBSTITUTE(A6,"/"," "),"."," "),"\"," "),"_"," "))&" ")),1,0))+IF(Task!$A$11="",0,IF(ISNUMBER(SEARCH(" "&Task!$A$11&" "," "&LOWER(SUBSTITUTE(SUBSTITUTE(SUBSTITUTE(SUBSTITUTE(A6,"/"," "),"."," "),"\"," "),"_"," "))&" ")),1,0))+IF(Task!$A$12="",0,IF(ISNUMBER(SEARCH(" "&Task!$A$12&" "," "&LOWER(SUBSTITUTE(SUBSTITUTE(SUBSTITUTE(SUBSTITUTE(A6,"/"," "),"."," "),"\"," "),"_"," "))&" ")),1,0))+IF(Task!$A$13="",0,IF(ISNUMBER(SEARCH(" "&Task!$A$13&" "," "&LOWER(SUBSTITUTE(SUBSTITUTE(SUBSTITUTE(SUBSTITUTE(A6,"/"," "),"."," "),"\"," "),"_"," "))&" ")),1,0))+IF(Task!$A$14="",0,IF(ISNUMBER(SEARCH(" "&Task!$A$14&" "," "&LOWER(SUBSTITUTE(SUBSTITUTE(SUBSTITUTE(SUBSTITUTE(A6,"/"," "),"."," "),"\"," "),"_"," "))&" ")),1,0))+IF(Task!$A$15="",0,IF(ISNUMBER(SEARCH(" "&Task!$A$15&" "," "&LOWER(SUBSTITUTE(SUBSTITUTE(SUBSTITUTE(SUBSTITUTE(A6,"/"," "),"."," "),"\"," "),"_"," "))&" ")),1,0))+IF(Task!$A$16="",0,IF(ISNUMBER(SEARCH(" "&Task!$A$16&" "," "&LOWER(SUBSTITUTE(SUBSTITUTE(SUBSTITUTE(SUBSTITUTE(A6,"/"," "),"."," "),"\"," "),"_"," "))&" ")),1,0))+IF(Task!$A$17="",0,IF(ISNUMBER(SEARCH(" "&Task!$A$17&" "," "&LOWER(SUBSTITUTE(SUBSTITUTE(SUBSTITUTE(SUBSTITUTE(A6,"/"," "),"."," "),"\"," "),"_"," "))&" ")),1,0))+IF(Task!$A$18="",0,IF(ISNUMBER(SEARCH(" "&Task!$A$18&" "," "&LOWER(SUBSTITUTE(SUBSTITUTE(SUBSTITUTE(SUBSTITUTE(A6,"/"," "),"."," "),"\"," "),"_"," "))&" ")),1,0))+IF(Task!$A$19="",0,IF(ISNUMBER(SEARCH(" "&Task!$A$19&" "," "&LOWER(SUBSTITUTE(SUBSTITUTE(SUBSTITUTE(SUBSTITUTE(A6,"/"," "),"."," "),"\"," "),"_"," "))&" ")),1,0))) | I6: =IF(OR(E6=0,F6=0,Task!$B$21=0),"",F6/Task!$B$21+0.5*G6+0.25*H6) | J6: =IF(I6="","",I6-ROW()/1000000) | K6: =IF(J6="","",COUNTIF($J$5:$J$404,">"&J6)+1)
E7: =IF(A7="",0,IF(COUNTA(Task!$B$5:$E$5)=0,1,IF(COUNTIF(Task!$B$5:$E$5,B7)>0,1,0))) | F7: =IF(E7=0,0,IF(Task!$A$8="",0,IF(ISNUMBER(SEARCH(" "&Task!$A$8&" "," "&LOWER(D7&" "&C7&" "&LOWER(SUBSTITUTE(SUBSTITUTE(SUBSTITUTE(SUBSTITUTE(A7,"/"," "),"."," "),"\"," "),"_"," ")))&" ")),1,0))+IF(Task!$A$9="",0,IF(ISNUMBER(SEARCH(" "&Task!$A$9&" "," "&LOWER(D7&" "&C7&" "&LOWER(SUBSTITUTE(SUBSTITUTE(SUBSTITUTE(SUBSTITUTE(A7,"/"," "),"."," "),"\"," "),"_"," ")))&" ")),1,0))+IF(Task!$A$10="",0,IF(ISNUMBER(SEARCH(" "&Task!$A$10&" "," "&LOWER(D7&" "&C7&" "&LOWER(SUBSTITUTE(SUBSTITUTE(SUBSTITUTE(SUBSTITUTE(A7,"/"," "),"."," "),"\"," "),"_"," ")))&" ")),1,0))+IF(Task!$A$11="",0,IF(ISNUMBER(SEARCH(" "&Task!$A$11&" "," "&LOWER(D7&" "&C7&" "&LOWER(SUBSTITUTE(SUBSTITUTE(SUBSTITUTE(SUBSTITUTE(A7,"/"," "),"."," "),"\"," "),"_"," ")))&" ")),1,0))+IF(Task!$A$12="",0,IF(ISNUMBER(SEARCH(" "&Task!$A$12&" "," "&LOWER(D7&" "&C7&" "&LOWER(SUBSTITUTE(SUBSTITUTE(SUBSTITUTE(SUBSTITUTE(A7,"/"," "),"."," "),"\"," "),"_"," ")))&" ")),1,0))+IF(Task!$A$13="",0,IF(ISNUMBER(SEARCH(" "&Task!$A$13&" "," "&LOWER(D7&" "&C7&" "&LOWER(SUBSTITUTE(SUBSTITUTE(SUBSTITUTE(SUBSTITUTE(A7,"/"," "),"."," "),"\"," "),"_"," ")))&" ")),1,0))+IF(Task!$A$14="",0,IF(ISNUMBER(SEARCH(" "&Task!$A$14&" "," "&LOWER(D7&" "&C7&" "&LOWER(SUBSTITUTE(SUBSTITUTE(SUBSTITUTE(SUBSTITUTE(A7,"/"," "),"."," "),"\"," "),"_"," ")))&" ")),1,0))+IF(Task!$A$15="",0,IF(ISNUMBER(SEARCH(" "&Task!$A$15&" "," "&LOWER(D7&" "&C7&" "&LOWER(SUBSTITUTE(SUBSTITUTE(SUBSTITUTE(SUBSTITUTE(A7,"/"," "),"."," "),"\"," "),"_"," ")))&" ")),1,0))+IF(Task!$A$16="",0,IF(ISNUMBER(SEARCH(" "&Task!$A$16&" "," "&LOWER(D7&" "&C7&" "&LOWER(SUBSTITUTE(SUBSTITUTE(SUBSTITUTE(SUBSTITUTE(A7,"/"," "),"."," "),"\"," "),"_"," ")))&" ")),1,0))+IF(Task!$A$17="",0,IF(ISNUMBER(SEARCH(" "&Task!$A$17&" "," "&LOWER(D7&" "&C7&" "&LOWER(SUBSTITUTE(SUBSTITUTE(SUBSTITUTE(SUBSTITUTE(A7,"/"," "),"."," "),"\"," "),"_"," ")))&" ")),1,0))+IF(Task!$A$18="",0,IF(ISNUMBER(SEARCH(" "&Task!$A$18&" "," "&LOWER(D7&" "&C7&" "&LOWER(SUBSTITUTE(SUBSTITUTE(SUBSTITUTE(SUBSTITUTE(A7,"/"," "),"."," "),"\"," "),"_"," ")))&" ")),1,0))+IF(Task!$A$19="",0,IF(ISNUMBER(SEARCH(" "&Task!$A$19&" "," "&LOWER(D7&" "&C7&" "&LOWER(SUBSTITUTE(SUBSTITUTE(SUBSTITUTE(SUBSTITUTE(A7,"/"," "),"."," "),"\"," "),"_"," ")))&" ")),1,0))) | G7: =IF(E7=0,0,IF(Task!$A$8="",0,IF(ISNUMBER(SEARCH(" "&Task!$A$8&" "," "&LOWER(C7)&" ")),1,0))+IF(Task!$A$9="",0,IF(ISNUMBER(SEARCH(" "&Task!$A$9&" "," "&LOWER(C7)&" ")),1,0))+IF(Task!$A$10="",0,IF(ISNUMBER(SEARCH(" "&Task!$A$10&" "," "&LOWER(C7)&" ")),1,0))+IF(Task!$A$11="",0,IF(ISNUMBER(SEARCH(" "&Task!$A$11&" "," "&LOWER(C7)&" ")),1,0))+IF(Task!$A$12="",0,IF(ISNUMBER(SEARCH(" "&Task!$A$12&" "," "&LOWER(C7)&" ")),1,0))+IF(Task!$A$13="",0,IF(ISNUMBER(SEARCH(" "&Task!$A$13&" "," "&LOWER(C7)&" ")),1,0))+IF(Task!$A$14="",0,IF(ISNUMBER(SEARCH(" "&Task!$A$14&" "," "&LOWER(C7)&" ")),1,0))+IF(Task!$A$15="",0,IF(ISNUMBER(SEARCH(" "&Task!$A$15&" "," "&LOWER(C7)&" ")),1,0))+IF(Task!$A$16="",0,IF(ISNUMBER(SEARCH(" "&Task!$A$16&" "," "&LOWER(C7)&" ")),1,0))+IF(Task!$A$17="",0,IF(ISNUMBER(SEARCH(" "&Task!$A$17&" "," "&LOWER(C7)&" ")),1,0))+IF(Task!$A$18="",0,IF(ISNUMBER(SEARCH(" "&Task!$A$18&" "," "&LOWER(C7)&" ")),1,0))+IF(Task!$A$19="",0,IF(ISNUMBER(SEARCH(" "&Task!$A$19&" "," "&LOWER(C7)&" ")),1,0))) | H7: =IF(E7=0,0,IF(Task!$A$8="",0,IF(ISNUMBER(SEARCH(" "&Task!$A$8&" "," "&LOWER(SUBSTITUTE(SUBSTITUTE(SUBSTITUTE(SUBSTITUTE(A7,"/"," "),"."," "),"\"," "),"_"," "))&" ")),1,0))+IF(Task!$A$9="",0,IF(ISNUMBER(SEARCH(" "&Task!$A$9&" "," "&LOWER(SUBSTITUTE(SUBSTITUTE(SUBSTITUTE(SUBSTITUTE(A7,"/"," "),"."," "),"\"," "),"_"," "))&" ")),1,0))+IF(Task!$A$10="",0,IF(ISNUMBER(SEARCH(" "&Task!$A$10&" "," "&LOWER(SUBSTITUTE(SUBSTITUTE(SUBSTITUTE(SUBSTITUTE(A7,"/"," "),"."," "),"\"," "),"_"," "))&" ")),1,0))+IF(Task!$A$11="",0,IF(ISNUMBER(SEARCH(" "&Task!$A$11&" "," "&LOWER(SUBSTITUTE(SUBSTITUTE(SUBSTITUTE(SUBSTITUTE(A7,"/"," "),"."," "),"\"," "),"_"," "))&" ")),1,0))+IF(Task!$A$12="",0,IF(ISNUMBER(SEARCH(" "&Task!$A$12&" "," "&LOWER(SUBSTITUTE(SUBSTITUTE(SUBSTITUTE(SUBSTITUTE(A7,"/"," "),"."," "),"\"," "),"_"," "))&" ")),1,0))+IF(Task!$A$13="",0,IF(ISNUMBER(SEARCH(" "&Task!$A$13&" "," "&LOWER(SUBSTITUTE(SUBSTITUTE(SUBSTITUTE(SUBSTITUTE(A7,"/"," "),"."," "),"\"," "),"_"," "))&" ")),1,0))+IF(Task!$A$14="",0,IF(ISNUMBER(SEARCH(" "&Task!$A$14&" "," "&LOWER(SUBSTITUTE(SUBSTITUTE(SUBSTITUTE(SUBSTITUTE(A7,"/"," "),"."," "),"\"," "),"_"," "))&" ")),1,0))+IF(Task!$A$15="",0,IF(ISNUMBER(SEARCH(" "&Task!$A$15&" "," "&LOWER(SUBSTITUTE(SUBSTITUTE(SUBSTITUTE(SUBSTITUTE(A7,"/"," "),"."," "),"\"," "),"_"," "))&" ")),1,0))+IF(Task!$A$16="",0,IF(ISNUMBER(SEARCH(" "&Task!$A$16&" "," "&LOWER(SUBSTITUTE(SUBSTITUTE(SUBSTITUTE(SUBSTITUTE(A7,"/"," "),"."," "),"\"," "),"_"," "))&" ")),1,0))+IF(Task!$A$17="",0,IF(ISNUMBER(SEARCH(" "&Task!$A$17&" "," "&LOWER(SUBSTITUTE(SUBSTITUTE(SUBSTITUTE(SUBSTITUTE(A7,"/"," "),"."," "),"\"," "),"_"," "))&" ")),1,0))+IF(Task!$A$18="",0,IF(ISNUMBER(SEARCH(" "&Task!$A$18&" "," "&LOWER(SUBSTITUTE(SUBSTITUTE(SUBSTITUTE(SUBSTITUTE(A7,"/"," "),"."," "),"\"," "),"_"," "))&" ")),1,0))+IF(Task!$A$19="",0,IF(ISNUMBER(SEARCH(" "&Task!$A$19&" "," "&LOWER(SUBSTITUTE(SUBSTITUTE(SUBSTITUTE(SUBSTITUTE(A7,"/"," "),"."," "),"\"," "),"_"," "))&" ")),1,0))) | I7: =IF(OR(E7=0,F7=0,Task!$B$21=0),"",F7/Task!$B$21+0.5*G7+0.25*H7) | J7: =IF(I7="","",I7-ROW()/1000000) | K7: =IF(J7="","",COUNTIF($J$5:$J$404,">"&J7)+1)
E8: =IF(A8="",0,IF(COUNTA(Task!$B$5:$E$5)=0,1,IF(COUNTIF(Task!$B$5:$E$5,B8)>0,1,0))) | F8: =IF(E8=0,0,IF(Task!$A$8="",0,IF(ISNUMBER(SEARCH(" "&Task!$A$8&" "," "&LOWER(D8&" "&C8&" "&LOWER(SUBSTITUTE(SUBSTITUTE(SUBSTITUTE(SUBSTITUTE(A8,"/"," "),"."," "),"\"," "),"_"," ")))&" ")),1,0))+IF(Task!$A$9="",0,IF(ISNUMBER(SEARCH(" "&Task!$A$9&" "," "&LOWER(D8&" "&C8&" "&LOWER(SUBSTITUTE(SUBSTITUTE(SUBSTITUTE(SUBSTITUTE(A8,"/"," "),"."," "),"\"," "),"_"," ")))&" ")),1,0))+IF(Task!$A$10="",0,IF(ISNUMBER(SEARCH(" "&Task!$A$10&" "," "&LOWER(D8&" "&C8&" "&LOWER(SUBSTITUTE(SUBSTITUTE(SUBSTITUTE(SUBSTITUTE(A8,"/"," "),"."," "),"\"," "),"_"," ")))&" ")),1,0))+IF(Task!$A$11="",0,IF(ISNUMBER(SEARCH(" "&Task!$A$11&" "," "&LOWER(D8&" "&C8&" "&LOWER(SUBSTITUTE(SUBSTITUTE(SUBSTITUTE(SUBSTITUTE(A8,"/"," "),"."," "),"\"," "),"_"," ")))&" ")),1,0))+IF(Task!$A$12="",0,IF(ISNUMBER(SEARCH(" "&Task!$A$12&" "," "&LOWER(D8&" "&C8&" "&LOWER(SUBSTITUTE(SUBSTITUTE(SUBSTITUTE(SUBSTITUTE(A8,"/"," "),"."," "),"\"," "),"_"," ")))&" ")),1,0))+IF(Task!$A$13="",0,IF(ISNUMBER(SEARCH(" "&Task!$A$13&" "," "&LOWER(D8&" "&C8&" "&LOWER(SUBSTITUTE(SUBSTITUTE(SUBSTITUTE(SUBSTITUTE(A8,"/"," "),"."," "),"\"," "),"_"," ")))&" ")),1,0))+IF(Task!$A$14="",0,IF(ISNUMBER(SEARCH(" "&Task!$A$14&" "," "&LOWER(D8&" "&C8&" "&LOWER(SUBSTITUTE(SUBSTITUTE(SUBSTITUTE(SUBSTITUTE(A8,"/"," "),"."," "),"\"," "),"_"," ")))&" ")),1,0))+IF(Task!$A$15="",0,IF(ISNUMBER(SEARCH(" "&Task!$A$15&" "," "&LOWER(D8&" "&C8&" "&LOWER(SUBSTITUTE(SUBSTITUTE(SUBSTITUTE(SUBSTITUTE(A8,"/"," "),"."," "),"\"," "),"_"," ")))&" ")),1,0))+IF(Task!$A$16="",0,IF(ISNUMBER(SEARCH(" "&Task!$A$16&" "," "&LOWER(D8&" "&C8&" "&LOWER(SUBSTITUTE(SUBSTITUTE(SUBSTITUTE(SUBSTITUTE(A8,"/"," "),"."," "),"\"," "),"_"," ")))&" ")),1,0))+IF(Task!$A$17="",0,IF(ISNUMBER(SEARCH(" "&Task!$A$17&" "," "&LOWER(D8&" "&C8&" "&LOWER(SUBSTITUTE(SUBSTITUTE(SUBSTITUTE(SUBSTITUTE(A8,"/"," "),"."," "),"\"," "),"_"," ")))&" ")),1,0))+IF(Task!$A$18="",0,IF(ISNUMBER(SEARCH(" "&Task!$A$18&" "," "&LOWER(D8&" "&C8&" "&LOWER(SUBSTITUTE(SUBSTITUTE(SUBSTITUTE(SUBSTITUTE(A8,"/"," "),"."," "),"\"," "),"_"," ")))&" ")),1,0))+IF(Task!$A$19="",0,IF(ISNUMBER(SEARCH(" "&Task!$A$19&" "," "&LOWER(D8&" "&C8&" "&LOWER(SUBSTITUTE(SUBSTITUTE(SUBSTITUTE(SUBSTITUTE(A8,"/"," "),"."," "),"\"," "),"_"," ")))&" ")),1,0))) | G8: =IF(E8=0,0,IF(Task!$A$8="",0,IF(ISNUMBER(SEARCH(" "&Task!$A$8&" "," "&LOWER(C8)&" ")),1,0))+IF(Task!$A$9="",0,IF(ISNUMBER(SEARCH(" "&Task!$A$9&" "," "&LOWER(C8)&" ")),1,0))+IF(Task!$A$10="",0,IF(ISNUMBER(SEARCH(" "&Task!$A$10&" "," "&LOWER(C8)&" ")),1,0))+IF(Task!$A$11="",0,IF(ISNUMBER(SEARCH(" "&Task!$A$11&" "," "&LOWER(C8)&" ")),1,0))+IF(Task!$A$12="",0,IF(ISNUMBER(SEARCH(" "&Task!$A$12&" "," "&LOWER(C8)&" ")),1,0))+IF(Task!$A$13="",0,IF(ISNUMBER(SEARCH(" "&Task!$A$13&" "," "&LOWER(C8)&" ")),1,0))+IF(Task!$A$14="",0,IF(ISNUMBER(SEARCH(" "&Task!$A$14&" "," "&LOWER(C8)&" ")),1,0))+IF(Task!$A$15="",0,IF(ISNUMBER(SEARCH(" "&Task!$A$15&" "," "&LOWER(C8)&" ")),1,0))+IF(Task!$A$16="",0,IF(ISNUMBER(SEARCH(" "&Task!$A$16&" "," "&LOWER(C8)&" ")),1,0))+IF(Task!$A$17="",0,IF(ISNUMBER(SEARCH(" "&Task!$A$17&" "," "&LOWER(C8)&" ")),1,0))+IF(Task!$A$18="",0,IF(ISNUMBER(SEARCH(" "&Task!$A$18&" "," "&LOWER(C8)&" ")),1,0))+IF(Task!$A$19="",0,IF(ISNUMBER(SEARCH(" "&Task!$A$19&" "," "&LOWER(C8)&" ")),1,0))) | H8: =IF(E8=0,0,IF(Task!$A$8="",0,IF(ISNUMBER(SEARCH(" "&Task!$A$8&" "," "&LOWER(SUBSTITUTE(SUBSTITUTE(SUBSTITUTE(SUBSTITUTE(A8,"/"," "),"."," "),"\"," "),"_"," "))&" ")),1,0))+IF(Task!$A$9="",0,IF(ISNUMBER(SEARCH(" "&Task!$A$9&" "," "&LOWER(SUBSTITUTE(SUBSTITUTE(SUBSTITUTE(SUBSTITUTE(A8,"/"," "),"."," "),"\"," "),"_"," "))&" ")),1,0))+IF(Task!$A$10="",0,IF(ISNUMBER(SEARCH(" "&Task!$A$10&" "," "&LOWER(SUBSTITUTE(SUBSTITUTE(SUBSTITUTE(SUBSTITUTE(A8,"/"," "),"."," "),"\"," "),"_"," "))&" ")),1,0))+IF(Task!$A$11="",0,IF(ISNUMBER(SEARCH(" "&Task!$A$11&" "," "&LOWER(SUBSTITUTE(SUBSTITUTE(SUBSTITUTE(SUBSTITUTE(A8,"/"," "),"."," "),"\"," "),"_"," "))&" ")),1,0))+IF(Task!$A$12="",0,IF(ISNUMBER(SEARCH(" "&Task!$A$12&" "," "&LOWER(SUBSTITUTE(SUBSTITUTE(SUBSTITUTE(SUBSTITUTE(A8,"/"," "),"."," "),"\"," "),"_"," "))&" ")),1,0))+IF(Task!$A$13="",0,IF(ISNUMBER(SEARCH(" "&Task!$A$13&" "," "&LOWER(SUBSTITUTE(SUBSTITUTE(SUBSTITUTE(SUBSTITUTE(A8,"/"," "),"."," "),"\"," "),"_"," "))&" ")),1,0))+IF(Task!$A$14="",0,IF(ISNUMBER(SEARCH(" "&Task!$A$14&" "," "&LOWER(SUBSTITUTE(SUBSTITUTE(SUBSTITUTE(SUBSTITUTE(A8,"/"," "),"."," "),"\"," "),"_"," "))&" ")),1,0))+IF(Task!$A$15="",0,IF(ISNUMBER(SEARCH(" "&Task!$A$15&" "," "&LOWER(SUBSTITUTE(SUBSTITUTE(SUBSTITUTE(SUBSTITUTE(A8,"/"," "),"."," "),"\"," "),"_"," "))&" ")),1,0))+IF(Task!$A$16="",0,IF(ISNUMBER(SEARCH(" "&Task!$A$16&" "," "&LOWER(SUBSTITUTE(SUBSTITUTE(SUBSTITUTE(SUBSTITUTE(A8,"/"," "),"."," "),"\"," "),"_"," "))&" ")),1,0))+IF(Task!$A$17="",0,IF(ISNUMBER(SEARCH(" "&Task!$A$17&" "," "&LOWER(SUBSTITUTE(SUBSTITUTE(SUBSTITUTE(SUBSTITUTE(A8,"/"," "),"."," "),"\"," "),"_"," "))&" ")),1,0))+IF(Task!$A$18="",0,IF(ISNUMBER(SEARCH(" "&Task!$A$18&" "," "&LOWER(SUBSTITUTE(SUBSTITUTE(SUBSTITUTE(SUBSTITUTE(A8,"/"," "),"."," "),"\"," "),"_"," "))&" ")),1,0))+IF(Task!$A$19="",0,IF(ISNUMBER(SEARCH(" "&Task!$A$19&" "," "&LOWER(SUBSTITUTE(SUBSTITUTE(SUBSTITUTE(SUBSTITUTE(A8,"/"," "),"."," "),"\"," "),"_"," "))&" ")),1,0))) | I8: =IF(OR(E8=0,F8=0,Task!$B$21=0),"",F8/Task!$B$21+0.5*G8+0.25*H8) | J8: =IF(I8="","",I8-ROW()/1000000) | K8: =IF(J8="","",COUNTIF($J$5:$J$404,">"&J8)+1)
E9: =IF(A9="",0,IF(COUNTA(Task!$B$5:$E$5)=0,1,IF(COUNTIF(Task!$B$5:$E$5,B9)>0,1,0))) | F9: =IF(E9=0,0,IF(Task!$A$8="",0,IF(ISNUMBER(SEARCH(" "&Task!$A$8&" "," "&LOWER(D9&" "&C9&" "&LOWER(SUBSTITUTE(SUBSTITUTE(SUBSTITUTE(SUBSTITUTE(A9,"/"," "),"."," "),"\"," "),"_"," ")))&" ")),1,0))+IF(Task!$A$9="",0,IF(ISNUMBER(SEARCH(" "&Task!$A$9&" "," "&LOWER(D9&" "&C9&" "&LOWER(SUBSTITUTE(SUBSTITUTE(SUBSTITUTE(SUBSTITUTE(A9,"/"," "),"."," "),"\"," "),"_"," ")))&" ")),1,0))+IF(Task!$A$10="",0,IF(ISNUMBER(SEARCH(" "&Task!$A$10&" "," "&LOWER(D9&" "&C9&" "&LOWER(SUBSTITUTE(SUBSTITUTE(SUBSTITUTE(SUBSTITUTE(A9,"/"," "),"."," "),"\"," "),"_"," ")))&" ")),1,0))+IF(Task!$A$11="",0,IF(ISNUMBER(SEARCH(" "&Task!$A$11&" "," "&LOWER(D9&" "&C9&" "&LOWER(SUBSTITUTE(SUBSTITUTE(SUBSTITUTE(SUBSTITUTE(A9,"/"," "),"."," "),"\"," "),"_"," ")))&" ")),1,0))+IF(Task!$A$12="",0,IF(ISNUMBER(SEARCH(" "&Task!$A$12&" "," "&LOWER(D9&" "&C9&" "&LOWER(SUBSTITUTE(SUBSTITUTE(SUBSTITUTE(SUBSTITUTE(A9,"/"," "),"."," "),"\"," "),"_"," ")))&" ")),1,0))+IF(Task!$A$13="",0,IF(ISNUMBER(SEARCH(" "&Task!$A$13&" "," "&LOWER(D9&" "&C9&" "&LOWER(SUBSTITUTE(SUBSTITUTE(SUBSTITUTE(SUBSTITUTE(A9,"/"," "),"."," "),"\"," "),"_"," ")))&" ")),1,0))+IF(Task!$A$14="",0,IF(ISNUMBER(SEARCH(" "&Task!$A$14&" "," "&LOWER(D9&" "&C9&" "&LOWER(SUBSTITUTE(SUBSTITUTE(SUBSTITUTE(SUBSTITUTE(A9,"/"," "),"."," "),"\"," "),"_"," ")))&" ")),1,0))+IF(Task!$A$15="",0,IF(ISNUMBER(SEARCH(" "&Task!$A$15&" "," "&LOWER(D9&" "&C9&" "&LOWER(SUBSTITUTE(SUBSTITUTE(SUBSTITUTE(SUBSTITUTE(A9,"/"," "),"."," "),"\"," "),"_"," ")))&" ")),1,0))+IF(Task!$A$16="",0,IF(ISNUMBER(SEARCH(" "&Task!$A$16&" "," "&LOWER(D9&" "&C9&" "&LOWER(SUBSTITUTE(SUBSTITUTE(SUBSTITUTE(SUBSTITUTE(A9,"/"," "),"."," "),"\"," "),"_"," ")))&" ")),1,0))+IF(Task!$A$17="",0,IF(ISNUMBER(SEARCH(" "&Task!$A$17&" "," "&LOWER(D9&" "&C9&" "&LOWER(SUBSTITUTE(SUBSTITUTE(SUBSTITUTE(SUBSTITUTE(A9,"/"," "),"."," "),"\"," "),"_"," ")))&" ")),1,0))+IF(Task!$A$18="",0,IF(ISNUMBER(SEARCH(" "&Task!$A$18&" "," "&LOWER(D9&" "&C9&" "&LOWER(SUBSTITUTE(SUBSTITUTE(SUBSTITUTE(SUBSTITUTE(A9,"/"," "),"."," "),"\"," "),"_"," ")))&" ")),1,0))+IF(Task!$A$19="",0,IF(ISNUMBER(SEARCH(" "&Task!$A$19&" "," "&LOWER(D9&" "&C9&" "&LOWER(SUBSTITUTE(SUBSTITUTE(SUBSTITUTE(SUBSTITUTE(A9,"/"," "),"."," "),"\"," "),"_"," ")))&" ")),1,0))) | G9: =IF(E9=0,0,IF(Task!$A$8="",0,IF(ISNUMBER(SEARCH(" "&Task!$A$8&" "," "&LOWER(C9)&" ")),1,0))+IF(Task!$A$9="",0,IF(ISNUMBER(SEARCH(" "&Task!$A$9&" "," "&LOWER(C9)&" ")),1,0))+IF(Task!$A$10="",0,IF(ISNUMBER(SEARCH(" "&Task!$A$10&" "," "&LOWER(C9)&" ")),1,0))+IF(Task!$A$11="",0,IF(ISNUMBER(SEARCH(" "&Task!$A$11&" "," "&LOWER(C9)&" ")),1,0))+IF(Task!$A$12="",0,IF(ISNUMBER(SEARCH(" "&Task!$A$12&" "," "&LOWER(C9)&" ")),1,0))+IF(Task!$A$13="",0,IF(ISNUMBER(SEARCH(" "&Task!$A$13&" "," "&LOWER(C9)&" ")),1,0))+IF(Task!$A$14="",0,IF(ISNUMBER(SEARCH(" "&Task!$A$14&" "," "&LOWER(C9)&" ")),1,0))+IF(Task!$A$15="",0,IF(ISNUMBER(SEARCH(" "&Task!$A$15&" "," "&LOWER(C9)&" ")),1,0))+IF(Task!$A$16="",0,IF(ISNUMBER(SEARCH(" "&Task!$A$16&" "," "&LOWER(C9)&" ")),1,0))+IF(Task!$A$17="",0,IF(ISNUMBER(SEARCH(" "&Task!$A$17&" "," "&LOWER(C9)&" ")),1,0))+IF(Task!$A$18="",0,IF(ISNUMBER(SEARCH(" "&Task!$A$18&" "," "&LOWER(C9)&" ")),1,0))+IF(Task!$A$19="",0,IF(ISNUMBER(SEARCH(" "&Task!$A$19&" "," "&LOWER(C9)&" ")),1,0))) | H9: =IF(E9=0,0,IF(Task!$A$8="",0,IF(ISNUMBER(SEARCH(" "&Task!$A$8&" "," "&LOWER(SUBSTITUTE(SUBSTITUTE(SUBSTITUTE(SUBSTITUTE(A9,"/"," "),"."," "),"\"," "),"_"," "))&" ")),1,0))+IF(Task!$A$9="",0,IF(ISNUMBER(SEARCH(" "&Task!$A$9&" "," "&LOWER(SUBSTITUTE(SUBSTITUTE(SUBSTITUTE(SUBSTITUTE(A9,"/"," "),"."," "),"\"," "),"_"," "))&" ")),1,0))+IF(Task!$A$10="",0,IF(ISNUMBER(SEARCH(" "&Task!$A$10&" "," "&LOWER(SUBSTITUTE(SUBSTITUTE(SUBSTITUTE(SUBSTITUTE(A9,"/"," "),"."," "),"\"," "),"_"," "))&" ")),1,0))+IF(Task!$A$11="",0,IF(ISNUMBER(SEARCH(" "&Task!$A$11&" "," "&LOWER(SUBSTITUTE(SUBSTITUTE(SUBSTITUTE(SUBSTITUTE(A9,"/"," "),"."," "),"\"," "),"_"," "))&" ")),1,0))+IF(Task!$A$12="",0,IF(ISNUMBER(SEARCH(" "&Task!$A$12&" "," "&LOWER(SUBSTITUTE(SUBSTITUTE(SUBSTITUTE(SUBSTITUTE(A9,"/"," "),"."," "),"\"," "),"_"," "))&" ")),1,0))+IF(Task!$A$13="",0,IF(ISNUMBER(SEARCH(" "&Task!$A$13&" "," "&LOWER(SUBSTITUTE(SUBSTITUTE(SUBSTITUTE(SUBSTITUTE(A9,"/"," "),"."," "),"\"," "),"_"," "))&" ")),1,0))+IF(Task!$A$14="",0,IF(ISNUMBER(SEARCH(" "&Task!$A$14&" "," "&LOWER(SUBSTITUTE(SUBSTITUTE(SUBSTITUTE(SUBSTITUTE(A9,"/"," "),"."," "),"\"," "),"_"," "))&" ")),1,0))+IF(Task!$A$15="",0,IF(ISNUMBER(SEARCH(" "&Task!$A$15&" "," "&LOWER(SUBSTITUTE(SUBSTITUTE(SUBSTITUTE(SUBSTITUTE(A9,"/"," "),"."," "),"\"," "),"_"," "))&" ")),1,0))+IF(Task!$A$16="",0,IF(ISNUMBER(SEARCH(" "&Task!$A$16&" "," "&LOWER(SUBSTITUTE(SUBSTITUTE(SUBSTITUTE(SUBSTITUTE(A9,"/"," "),"."," "),"\"," "),"_"," "))&" ")),1,0))+IF(Task!$A$17="",0,IF(ISNUMBER(SEARCH(" "&Task!$A$17&" "," "&LOWER(SUBSTITUTE(SUBSTITUTE(SUBSTITUTE(SUBSTITUTE(A9,"/"," "),"."," "),"\"," "),"_"," "))&" ")),1,0))+IF(Task!$A$18="",0,IF(ISNUMBER(SEARCH(" "&Task!$A$18&" "," "&LOWER(SUBSTITUTE(SUBSTITUTE(SUBSTITUTE(SUBSTITUTE(A9,"/"," "),"."," "),"\"," "),"_"," "))&" ")),1,0))+IF(Task!$A$19="",0,IF(ISNUMBER(SEARCH(" "&Task!$A$19&" "," "&LOWER(SUBSTITUTE(SUBSTITUTE(SUBSTITUTE(SUBSTITUTE(A9,"/"," "),"."," "),"\"," "),"_"," "))&" ")),1,0))) | I9: =IF(OR(E9=0,F9=0,Task!$B$21=0),"",F9/Task!$B$21+0.5*G9+0.25*H9) | J9: =IF(I9="","",I9-ROW()/1000000) | K9: =IF(J9="","",COUNTIF($J$5:$J$404,">"&J9)+1)
E10: =IF(A10="",0,IF(COUNTA(Task!$B$5:$E$5)=0,1,IF(COUNTIF(Task!$B$5:$E$5,B10)>0,1,0))) | F10: =IF(E10=0,0,IF(Task!$A$8="",0,IF(ISNUMBER(SEARCH(" "&Task!$A$8&" "," "&LOWER(D10&" "&C10&" "&LOWER(SUBSTITUTE(SUBSTITUTE(SUBSTITUTE(SUBSTITUTE(A10,"/"," "),"."," "),"\"," "),"_"," ")))&" ")),1,0))+IF(Task!$A$9="",0,IF(ISNUMBER(SEARCH(" "&Task!$A$9&" "," "&LOWER(D10&" "&C10&" "&LOWER(SUBSTITUTE(SUBSTITUTE(SUBSTITUTE(SUBSTITUTE(A10,"/"," "),"."," "),"\"," "),"_"," ")))&" ")),1,0))+IF(Task!$A$10="",0,IF(ISNUMBER(SEARCH(" "&Task!$A$10&" "," "&LOWER(D10&" "&C10&" "&LOWER(SUBSTITUTE(SUBSTITUTE(SUBSTITUTE(SUBSTITUTE(A10,"/"," "),"."," "),"\"," "),"_"," ")))&" ")),1,0))+IF(Task!$A$11="",0,IF(ISNUMBER(SEARCH(" "&Task!$A$11&" "," "&LOWER(D10&" "&C10&" "&LOWER(SUBSTITUTE(SUBSTITUTE(SUBSTITUTE(SUBSTITUTE(A10,"/"," "),"."," "),"\"," "),"_"," ")))&" ")),1,0))+IF(Task!$A$12="",0,IF(ISNUMBER(SEARCH(" "&Task!$A$12&" "," "&LOWER(D10&" "&C10&" "&LOWER(SUBSTITUTE(SUBSTITUTE(SUBSTITUTE(SUBSTITUTE(A10,"/"," "),"."," "),"\"," "),"_"," ")))&" ")),1,0))+IF(Task!$A$13="",0,IF(ISNUMBER(SEARCH(" "&Task!$A$13&" "," "&LOWER(D10&" "&C10&" "&LOWER(SUBSTITUTE(SUBSTITUTE(SUBSTITUTE(SUBSTITUTE(A10,"/"," "),"."," "),"\"," "),"_"," ")))&" ")),1,0))+IF(Task!$A$14="",0,IF(ISNUMBER(SEARCH(" "&Task!$A$14&" "," "&LOWER(D10&" "&C10&" "&LOWER(SUBSTITUTE(SUBSTITUTE(SUBSTITUTE(SUBSTITUTE(A10,"/"," "),"."," "),"\"," "),"_"," ")))&" ")),1,0))+IF(Task!$A$15="",0,IF(ISNUMBER(SEARCH(" "&Task!$A$15&" "," "&LOWER(D10&" "&C10&" "&LOWER(SUBSTITUTE(SUBSTITUTE(SUBSTITUTE(SUBSTITUTE(A10,"/"," "),"."," "),"\"," "),"_"," ")))&" ")),1,0))+IF(Task!$A$16="",0,IF(ISNUMBER(SEARCH(" "&Task!$A$16&" "," "&LOWER(D10&" "&C10&" "&LOWER(SUBSTITUTE(SUBSTITUTE(SUBSTITUTE(SUBSTITUTE(A10,"/"," "),"."," "),"\"," "),"_"," ")))&" ")),1,0))+IF(Task!$A$17="",0,IF(ISNUMBER(SEARCH(" "&Task!$A$17&" "," "&LOWER(D10&" "&C10&" "&LOWER(SUBSTITUTE(SUBSTITUTE(SUBSTITUTE(SUBSTITUTE(A10,"/"," "),"."," "),"\"," "),"_"," ")))&" ")),1,0))+IF(Task!$A$18="",0,IF(ISNUMBER(SEARCH(" "&Task!$A$18&" "," "&LOWER(D10&" "&C10&" "&LOWER(SUBSTITUTE(SUBSTITUTE(SUBSTITUTE(SUBSTITUTE(A10,"/"," "),"."," "),"\"," "),"_"," ")))&" ")),1,0))+IF(Task!$A$19="",0,IF(ISNUMBER(SEARCH(" "&Task!$A$19&" "," "&LOWER(D10&" "&C10&" "&LOWER(SUBSTITUTE(SUBSTITUTE(SUBSTITUTE(SUBSTITUTE(A10,"/"," "),"."," "),"\"," "),"_"," ")))&" ")),1,0))) | G10: =IF(E10=0,0,IF(Task!$A$8="",0,IF(ISNUMBER(SEARCH(" "&Task!$A$8&" "," "&LOWER(C10)&" ")),1,0))+IF(Task!$A$9="",0,IF(ISNUMBER(SEARCH(" "&Task!$A$9&" "," "&LOWER(C10)&" ")),1,0))+IF(Task!$A$10="",0,IF(ISNUMBER(SEARCH(" "&Task!$A$10&" "," "&LOWER(C10)&" ")),1,0))+IF(Task!$A$11="",0,IF(ISNUMBER(SEARCH(" "&Task!$A$11&" "," "&LOWER(C10)&" ")),1,0))+IF(Task!$A$12="",0,IF(ISNUMBER(SEARCH(" "&Task!$A$12&" "," "&LOWER(C10)&" ")),1,0))+IF(Task!$A$13="",0,IF(ISNUMBER(SEARCH(" "&Task!$A$13&" "," "&LOWER(C10)&" ")),1,0))+IF(Task!$A$14="",0,IF(ISNUMBER(SEARCH(" "&Task!$A$14&" "," "&LOWER(C10)&" ")),1,0))+IF(Task!$A$15="",0,IF(ISNUMBER(SEARCH(" "&Task!$A$15&" "," "&LOWER(C10)&" ")),1,0))+IF(Task!$A$16="",0,IF(ISNUMBER(SEARCH(" "&Task!$A$16&" "," "&LOWER(C10)&" ")),1,0))+IF(Task!$A$17="",0,IF(ISNUMBER(SEARCH(" "&Task!$A$17&" "," "&LOWER(C10)&" ")),1,0))+IF(Task!$A$18="",0,IF(ISNUMBER(SEARCH(" "&Task!$A$18&" "," "&LOWER(C10)&" ")),1,0))+IF(Task!$A$19="",0,IF(ISNUMBER(SEARCH(" "&Task!$A$19&" "," "&LOWER(C10)&" ")),1,0))) | H10: =IF(E10=0,0,IF(Task!$A$8="",0,IF(ISNUMBER(SEARCH(" "&Task!$A$8&" "," "&LOWER(SUBSTITUTE(SUBSTITUTE(SUBSTITUTE(SUBSTITUTE(A10,"/"," "),"."," "),"\"," "),"_"," "))&" ")),1,0))+IF(Task!$A$9="",0,IF(ISNUMBER(SEARCH(" "&Task!$A$9&" "," "&LOWER(SUBSTITUTE(SUBSTITUTE(SUBSTITUTE(SUBSTITUTE(A10,"/"," "),"."," "),"\"," "),"_"," "))&" ")),1,0))+IF(Task!$A$10="",0,IF(ISNUMBER(SEARCH(" "&Task!$A$10&" "," "&LOWER(SUBSTITUTE(SUBSTITUTE(SUBSTITUTE(SUBSTITUTE(A10,"/"," "),"."," "),"\"," "),"_"," "))&" ")),1,0))+IF(Task!$A$11="",0,IF(ISNUMBER(SEARCH(" "&Task!$A$11&" "," "&LOWER(SUBSTITUTE(SUBSTITUTE(SUBSTITUTE(SUBSTITUTE(A10,"/"," "),"."," "),"\"," "),"_"," "))&" ")),1,0))+IF(Task!$A$12="",0,IF(ISNUMBER(SEARCH(" "&Task!$A$12&" "," "&LOWER(SUBSTITUTE(SUBSTITUTE(SUBSTITUTE(SUBSTITUTE(A10,"/"," "),"."," "),"\"," "),"_"," "))&" ")),1,0))+IF(Task!$A$13="",0,IF(ISNUMBER(SEARCH(" "&Task!$A$13&" "," "&LOWER(SUBSTITUTE(SUBSTITUTE(SUBSTITUTE(SUBSTITUTE(A10,"/"," "),"."," "),"\"," "),"_"," "))&" ")),1,0))+IF(Task!$A$14="",0,IF(ISNUMBER(SEARCH(" "&Task!$A$14&" "," "&LOWER(SUBSTITUTE(SUBSTITUTE(SUBSTITUTE(SUBSTITUTE(A10,"/"," "),"."," "),"\"," "),"_"," "))&" ")),1,0))+IF(Task!$A$15="",0,IF(ISNUMBER(SEARCH(" "&Task!$A$15&" "," "&LOWER(SUBSTITUTE(SUBSTITUTE(SUBSTITUTE(SUBSTITUTE(A10,"/"," "),"."," "),"\"," "),"_"," "))&" ")),1,0))+IF(Task!$A$16="",0,IF(ISNUMBER(SEARCH(" "&Task!$A$16&" "," "&LOWER(SUBSTITUTE(SUBSTITUTE(SUBSTITUTE(SUBSTITUTE(A10,"/"," "),"."," "),"\"," "),"_"," "))&" ")),1,0))+IF(Task!$A$17="",0,IF(ISNUMBER(SEARCH(" "&Task!$A$17&" "," "&LOWER(SUBSTITUTE(SUBSTITUTE(SUBSTITUTE(SUBSTITUTE(A10,"/"," "),"."," "),"\"," "),"_"," "))&" ")),1,0))+IF(Task!$A$18="",0,IF(ISNUMBER(SEARCH(" "&Task!$A$18&" "," "&LOWER(SUBSTITUTE(SUBSTITUTE(SUBSTITUTE(SUBSTITUTE(A10,"/"," "),"."," "),"\"," "),"_"," "))&" ")),1,0))+IF(Task!$A$19="",0,IF(ISNUMBER(SEARCH(" "&Task!$A$19&" "," "&LOWER(SUBSTITUTE(SUBSTITUTE(SUBSTITUTE(SUBSTITUTE(A10,"/"," "),"."," "),"\"," "),"_"," "))&" ")),1,0))) | I10: =IF(OR(E10=0,F10=0,Task!$B$21=0),"",F10/Task!$B$21+0.5*G10+0.25*H10) | J10: =IF(I10="","",I10-ROW()/1000000) | K10: =IF(J10="","",COUNTIF($J$5:$J$404,">"&J10)+1)
E11: =IF(A11="",0,IF(COUNTA(Task!$B$5:$E$5)=0,1,IF(COUNTIF(Task!$B$5:$E$5,B11)>0,1,0))) | F11: =IF(E11=0,0,IF(Task!$A$8="",0,IF(ISNUMBER(SEARCH(" "&Task!$A$8&" "," "&LOWER(D11&" "&C11&" "&LOWER(SUBSTITUTE(SUBSTITUTE(SUBSTITUTE(SUBSTITUTE(A11,"/"," "),"."," "),"\"," "),"_"," ")))&" ")),1,0))+IF(Task!$A$9="",0,IF(ISNUMBER(SEARCH(" "&Task!$A$9&" "," "&LOWER(D11&" "&C11&" "&LOWER(SUBSTITUTE(SUBSTITUTE(SUBSTITUTE(SUBSTITUTE(A11,"/"," "),"."," "),"\"," "),"_"," ")))&" ")),1,0))+IF(Task!$A$10="",0,IF(ISNUMBER(SEARCH(" "&Task!$A$10&" "," "&LOWER(D11&" "&C11&" "&LOWER(SUBSTITUTE(SUBSTITUTE(SUBSTITUTE(SUBSTITUTE(A11,"/"," "),"."," "),"\"," "),"_"," ")))&" ")),1,0))+IF(Task!$A$11="",0,IF(ISNUMBER(SEARCH(" "&Task!$A$11&" "," "&LOWER(D11&" "&C11&" "&LOWER(SUBSTITUTE(SUBSTITUTE(SUBSTITUTE(SUBSTITUTE(A11,"/"," "),"."," "),"\"," "),"_"," ")))&" ")),1,0))+IF(Task!$A$12="",0,IF(ISNUMBER(SEARCH(" "&Task!$A$12&" "," "&LOWER(D11&" "&C11&" "&LOWER(SUBSTITUTE(SUBSTITUTE(SUBSTITUTE(SUBSTITUTE(A11,"/"," "),"."," "),"\"," "),"_"," ")))&" ")),1,0))+IF(Task!$A$13="",0,IF(ISNUMBER(SEARCH(" "&Task!$A$13&" "," "&LOWER(D11&" "&C11&" "&LOWER(SUBSTITUTE(SUBSTITUTE(SUBSTITUTE(SUBSTITUTE(A11,"/"," "),"."," "),"\"," "),"_"," ")))&" ")),1,0))+IF(Task!$A$14="",0,IF(ISNUMBER(SEARCH(" "&Task!$A$14&" "," "&LOWER(D11&" "&C11&" "&LOWER(SUBSTITUTE(SUBSTITUTE(SUBSTITUTE(SUBSTITUTE(A11,"/"," "),"."," "),"\"," "),"_"," ")))&" ")),1,0))+IF(Task!$A$15="",0,IF(ISNUMBER(SEARCH(" "&Task!$A$15&" "," "&LOWER(D11&" "&C11&" "&LOWER(SUBSTITUTE(SUBSTITUTE(SUBSTITUTE(SUBSTITUTE(A11,"/"," "),"."," "),"\"," "),"_"," ")))&" ")),1,0))+IF(Task!$A$16="",0,IF(ISNUMBER(SEARCH(" "&Task!$A$16&" "," "&LOWER(D11&" "&C11&" "&LOWER(SUBSTITUTE(SUBSTITUTE(SUBSTITUTE(SUBSTITUTE(A11,"/"," "),"."," "),"\"," "),"_"," ")))&" ")),1,0))+IF(Task!$A$17="",0,IF(ISNUMBER(SEARCH(" "&Task!$A$17&" "," "&LOWER(D11&" "&C11&" "&LOWER(SUBSTITUTE(SUBSTITUTE(SUBSTITUTE(SUBSTITUTE(A11,"/"," "),"."," "),"\"," "),"_"," ")))&" ")),1,0))+IF(Task!$A$18="",0,IF(ISNUMBER(SEARCH(" "&Task!$A$18&" "," "&LOWER(D11&" "&C11&" "&LOWER(SUBSTITUTE(SUBSTITUTE(SUBSTITUTE(SUBSTITUTE(A11,"/"," "),"."," "),"\"," "),"_"," ")))&" ")),1,0))+IF(Task!$A$19="",0,IF(ISNUMBER(SEARCH(" "&Task!$A$19&" "," "&LOWER(D11&" "&C11&" "&LOWER(SUBSTITUTE(SUBSTITUTE(SUBSTITUTE(SUBSTITUTE(A11,"/"," "),"."," "),"\"," "),"_"," ")))&" ")),1,0))) | G11: =IF(E11=0,0,IF(Task!$A$8="",0,IF(ISNUMBER(SEARCH(" "&Task!$A$8&" "," "&LOWER(C11)&" ")),1,0))+IF(Task!$A$9="",0,IF(ISNUMBER(SEARCH(" "&Task!$A$9&" "," "&LOWER(C11)&" ")),1,0))+IF(Task!$A$10="",0,IF(ISNUMBER(SEARCH(" "&Task!$A$10&" "," "&LOWER(C11)&" ")),1,0))+IF(Task!$A$11="",0,IF(ISNUMBER(SEARCH(" "&Task!$A$11&" "," "&LOWER(C11)&" ")),1,0))+IF(Task!$A$12="",0,IF(ISNUMBER(SEARCH(" "&Task!$A$12&" "," "&LOWER(C11)&" ")),1,0))+IF(Task!$A$13="",0,IF(ISNUMBER(SEARCH(" "&Task!$A$13&" "," "&LOWER(C11)&" ")),1,0))+IF(Task!$A$14="",0,IF(ISNUMBER(SEARCH(" "&Task!$A$14&" "," "&LOWER(C11)&" ")),1,0))+IF(Task!$A$15="",0,IF(ISNUMBER(SEARCH(" "&Task!$A$15&" "," "&LOWER(C11)&" ")),1,0))+IF(Task!$A$16="",0,IF(ISNUMBER(SEARCH(" "&Task!$A$16&" "," "&LOWER(C11)&" ")),1,0))+IF(Task!$A$17="",0,IF(ISNUMBER(SEARCH(" "&Task!$A$17&" "," "&LOWER(C11)&" ")),1,0))+IF(Task!$A$18="",0,IF(ISNUMBER(SEARCH(" "&Task!$A$18&" "," "&LOWER(C11)&" ")),1,0))+IF(Task!$A$19="",0,IF(ISNUMBER(SEARCH(" "&Task!$A$19&" "," "&LOWER(C11)&" ")),1,0))) | H11: =IF(E11=0,0,IF(Task!$A$8="",0,IF(ISNUMBER(SEARCH(" "&Task!$A$8&" "," "&LOWER(SUBSTITUTE(SUBSTITUTE(SUBSTITUTE(SUBSTITUTE(A11,"/"," "),"."," "),"\"," "),"_"," "))&" ")),1,0))+IF(Task!$A$9="",0,IF(ISNUMBER(SEARCH(" "&Task!$A$9&" "," "&LOWER(SUBSTITUTE(SUBSTITUTE(SUBSTITUTE(SUBSTITUTE(A11,"/"," "),"."," "),"\"," "),"_"," "))&" ")),1,0))+IF(Task!$A$10="",0,IF(ISNUMBER(SEARCH(" "&Task!$A$10&" "," "&LOWER(SUBSTITUTE(SUBSTITUTE(SUBSTITUTE(SUBSTITUTE(A11,"/"," "),"."," "),"\"," "),"_"," "))&" ")),1,0))+IF(Task!$A$11="",0,IF(ISNUMBER(SEARCH(" "&Task!$A$11&" "," "&LOWER(SUBSTITUTE(SUBSTITUTE(SUBSTITUTE(SUBSTITUTE(A11,"/"," "),"."," "),"\"," "),"_"," "))&" ")),1,0))+IF(Task!$A$12="",0,IF(ISNUMBER(SEARCH(" "&Task!$A$12&" "," "&LOWER(SUBSTITUTE(SUBSTITUTE(SUBSTITUTE(SUBSTITUTE(A11,"/"," "),"."," "),"\"," "),"_"," "))&" ")),1,0))+IF(Task!$A$13="",0,IF(ISNUMBER(SEARCH(" "&Task!$A$13&" "," "&LOWER(SUBSTITUTE(SUBSTITUTE(SUBSTITUTE(SUBSTITUTE(A11,"/"," "),"."," "),"\"," "),"_"," "))&" ")),1,0))+IF(Task!$A$14="",0,IF(ISNUMBER(SEARCH(" "&Task!$A$14&" "," "&LOWER(SUBSTITUTE(SUBSTITUTE(SUBSTITUTE(SUBSTITUTE(A11,"/"," "),"."," "),"\"," "),"_"," "))&" ")),1,0))+IF(Task!$A$15="",0,IF(ISNUMBER(SEARCH(" "&Task!$A$15&" "," "&LOWER(SUBSTITUTE(SUBSTITUTE(SUBSTITUTE(SUBSTITUTE(A11,"/"," "),"."," "),"\"," "),"_"," "))&" ")),1,0))+IF(Task!$A$16="",0,IF(ISNUMBER(SEARCH(" "&Task!$A$16&" "," "&LOWER(SUBSTITUTE(SUBSTITUTE(SUBSTITUTE(SUBSTITUTE(A11,"/"," "),"."," "),"\"," "),"_"," "))&" ")),1,0))+IF(Task!$A$17="",0,IF(ISNUMBER(SEARCH(" "&Task!$A$17&" "," "&LOWER(SUBSTITUTE(SUBSTITUTE(SUBSTITUTE(SUBSTITUTE(A11,"/"," "),"."," "),"\"," "),"_"," "))&" ")),1,0))+IF(Task!$A$18="",0,IF(ISNUMBER(SEARCH(" "&Task!$A$18&" "," "&LOWER(SUBSTITUTE(SUBSTITUTE(SUBSTITUTE(SUBSTITUTE(A11,"/"," "),"."," "),"\"," "),"_"," "))&" ")),1,0))+IF(Task!$A$19="",0,IF(ISNUMBER(SEARCH(" "&Task!$A$19&" "," "&LOWER(SUBSTITUTE(SUBSTITUTE(SUBSTITUTE(SUBSTITUTE(A11,"/"," "),"."," "),"\"," "),"_"," "))&" ")),1,0))) | I11: =IF(OR(E11=0,F11=0,Task!$B$21=0),"",F11/Task!$B$21+0.5*G11+0.25*H11) | J11: =IF(I11="","",I11-ROW()/1000000) | K11: =IF(J11="","",COUNTIF($J$5:$J$404,">"&J11)+1)
E12: =IF(A12="",0,IF(COUNTA(Task!$B$5:$E$5)=0,1,IF(COUNTIF(Task!$B$5:$E$5,B12)>0,1,0))) | F12: =IF(E12=0,0,IF(Task!$A$8="",0,IF(ISNUMBER(SEARCH(" "&Task!$A$8&" "," "&LOWER(D12&" "&C12&" "&LOWER(SUBSTITUTE(SUBSTITUTE(SUBSTITUTE(SUBSTITUTE(A12,"/"," "),"."," "),"\"," "),"_"," ")))&" ")),1,0))+IF(Task!$A$9="",0,IF(ISNUMBER(SEARCH(" "&Task!$A$9&" "," "&LOWER(D12&" "&C12&" "&LOWER(SUBSTITUTE(SUBSTITUTE(SUBSTITUTE(SUBSTITUTE(A12,"/"," "),"."," "),"\"," "),"_"," ")))&" ")),1,0))+IF(Task!$A$10="",0,IF(ISNUMBER(SEARCH(" "&Task!$A$10&" "," "&LOWER(D12&" "&C12&" "&LOWER(SUBSTITUTE(SUBSTITUTE(SUBSTITUTE(SUBSTITUTE(A12,"/"," "),"."," "),"\"," "),"_"," ")))&" ")),1,0))+IF(Task!$A$11="",0,IF(ISNUMBER(SEARCH(" "&Task!$A$11&" "," "&LOWER(D12&" "&C12&" "&LOWER(SUBSTITUTE(SUBSTITUTE(SUBSTITUTE(SUBSTITUTE(A12,"/"," "),"."," "),"\"," "),"_"," ")))&" ")),1,0))+IF(Task!$A$12="",0,IF(ISNUMBER(SEARCH(" "&Task!$A$12&" "," "&LOWER(D12&" "&C12&" "&LOWER(SUBSTITUTE(SUBSTITUTE(SUBSTITUTE(SUBSTITUTE(A12,"/"," "),"."," "),"\"," "),"_"," ")))&" ")),1,0))+IF(Task!$A$13="",0,IF(ISNUMBER(SEARCH(" "&Task!$A$13&" "," "&LOWER(D12&" "&C12&" "&LOWER(SUBSTITUTE(SUBSTITUTE(SUBSTITUTE(SUBSTITUTE(A12,"/"," "),"."," "),"\"," "),"_"," ")))&" ")),1,0))+IF(Task!$A$14="",0,IF(ISNUMBER(SEARCH(" "&Task!$A$14&" "," "&LOWER(D12&" "&C12&" "&LOWER(SUBSTITUTE(SUBSTITUTE(SUBSTITUTE(SUBSTITUTE(A12,"/"," "),"."," "),"\"," "),"_"," ")))&" ")),1,0))+IF(Task!$A$15="",0,IF(ISNUMBER(SEARCH(" "&Task!$A$15&" "," "&LOWER(D12&" "&C12&" "&LOWER(SUBSTITUTE(SUBSTITUTE(SUBSTITUTE(SUBSTITUTE(A12,"/"," "),"."," "),"\"," "),"_"," ")))&" ")),1,0))+IF(Task!$A$16="",0,IF(ISNUMBER(SEARCH(" "&Task!$A$16&" "," "&LOWER(D12&" "&C12&" "&LOWER(SUBSTITUTE(SUBSTITUTE(SUBSTITUTE(SUBSTITUTE(A12,"/"," "),"."," "),"\"," "),"_"," ")))&" ")),1,0))+IF(Task!$A$17="",0,IF(ISNUMBER(SEARCH(" "&Task!$A$17&" "," "&LOWER(D12&" "&C12&" "&LOWER(SUBSTITUTE(SUBSTITUTE(SUBSTITUTE(SUBSTITUTE(A12,"/"," "),"."," "),"\"," "),"_"," ")))&" ")),1,0))+IF(Task!$A$18="",0,IF(ISNUMBER(SEARCH(" "&Task!$A$18&" "," "&LOWER(D12&" "&C12&" "&LOWER(SUBSTITUTE(SUBSTITUTE(SUBSTITUTE(SUBSTITUTE(A12,"/"," "),"."," "),"\"," "),"_"," ")))&" ")),1,0))+IF(Task!$A$19="",0,IF(ISNUMBER(SEARCH(" "&Task!$A$19&" "," "&LOWER(D12&" "&C12&" "&LOWER(SUBSTITUTE(SUBSTITUTE(SUBSTITUTE(SUBSTITUTE(A12,"/"," "),"."," "),"\"," "),"_"," ")))&" ")),1,0))) | G12: =IF(E12=0,0,IF(Task!$A$8="",0,IF(ISNUMBER(SEARCH(" "&Task!$A$8&" "," "&LOWER(C12)&" ")),1,0))+IF(Task!$A$9="",0,IF(ISNUMBER(SEARCH(" "&Task!$A$9&" "," "&LOWER(C12)&" ")),1,0))+IF(Task!$A$10="",0,IF(ISNUMBER(SEARCH(" "&Task!$A$10&" "," "&LOWER(C12)&" ")),1,0))+IF(Task!$A$11="",0,IF(ISNUMBER(SEARCH(" "&Task!$A$11&" "," "&LOWER(C12)&" ")),1,0))+IF(Task!$A$12="",0,IF(ISNUMBER(SEARCH(" "&Task!$A$12&" "," "&LOWER(C12)&" ")),1,0))+IF(Task!$A$13="",0,IF(ISNUMBER(SEARCH(" "&Task!$A$13&" "," "&LOWER(C12)&" ")),1,0))+IF(Task!$A$14="",0,IF(ISNUMBER(SEARCH(" "&Task!$A$14&" "," "&LOWER(C12)&" ")),1,0))+IF(Task!$A$15="",0,IF(ISNUMBER(SEARCH(" "&Task!$A$15&" "," "&LOWER(C12)&" ")),1,0))+IF(Task!$A$16="",0,IF(ISNUMBER(SEARCH(" "&Task!$A$16&" "," "&LOWER(C12)&" ")),1,0))+IF(Task!$A$17="",0,IF(ISNUMBER(SEARCH(" "&Task!$A$17&" "," "&LOWER(C12)&" ")),1,0))+IF(Task!$A$18="",0,IF(ISNUMBER(SEARCH(" "&Task!$A$18&" "," "&LOWER(C12)&" ")),1,0))+IF(Task!$A$19="",0,IF(ISNUMBER(SEARCH(" "&Task!$A$19&" "," "&LOWER(C12)&" ")),1,0))) | H12: =IF(E12=0,0,IF(Task!$A$8="",0,IF(ISNUMBER(SEARCH(" "&Task!$A$8&" "," "&LOWER(SUBSTITUTE(SUBSTITUTE(SUBSTITUTE(SUBSTITUTE(A12,"/"," "),"."," "),"\"," "),"_"," "))&" ")),1,0))+IF(Task!$A$9="",0,IF(ISNUMBER(SEARCH(" "&Task!$A$9&" "," "&LOWER(SUBSTITUTE(SUBSTITUTE(SUBSTITUTE(SUBSTITUTE(A12,"/"," "),"."," "),"\"," "),"_"," "))&" ")),1,0))+IF(Task!$A$10="",0,IF(ISNUMBER(SEARCH(" "&Task!$A$10&" "," "&LOWER(SUBSTITUTE(SUBSTITUTE(SUBSTITUTE(SUBSTITUTE(A12,"/"," "),"."," "),"\"," "),"_"," "))&" ")),1,0))+IF(Task!$A$11="",0,IF(ISNUMBER(SEARCH(" "&Task!$A$11&" "," "&LOWER(SUBSTITUTE(SUBSTITUTE(SUBSTITUTE(SUBSTITUTE(A12,"/"," "),"."," "),"\"," "),"_"," "))&" ")),1,0))+IF(Task!$A$12="",0,IF(ISNUMBER(SEARCH(" "&Task!$A$12&" "," "&LOWER(SUBSTITUTE(SUBSTITUTE(SUBSTITUTE(SUBSTITUTE(A12,"/"," "),"."," "),"\"," "),"_"," "))&" ")),1,0))+IF(Task!$A$13="",0,IF(ISNUMBER(SEARCH(" "&Task!$A$13&" "," "&LOWER(SUBSTITUTE(SUBSTITUTE(SUBSTITUTE(SUBSTITUTE(A12,"/"," "),"."," "),"\"," "),"_"," "))&" ")),1,0))+IF(Task!$A$14="",0,IF(ISNUMBER(SEARCH(" "&Task!$A$14&" "," "&LOWER(SUBSTITUTE(SUBSTITUTE(SUBSTITUTE(SUBSTITUTE(A12,"/"," "),"."," "),"\"," "),"_"," "))&" ")),1,0))+IF(Task!$A$15="",0,IF(ISNUMBER(SEARCH(" "&Task!$A$15&" "," "&LOWER(SUBSTITUTE(SUBSTITUTE(SUBSTITUTE(SUBSTITUTE(A12,"/"," "),"."," "),"\"," "),"_"," "))&" ")),1,0))+IF(Task!$A$16="",0,IF(ISNUMBER(SEARCH(" "&Task!$A$16&" "," "&LOWER(SUBSTITUTE(SUBSTITUTE(SUBSTITUTE(SUBSTITUTE(A12,"/"," "),"."," "),"\"," "),"_"," "))&" ")),1,0))+IF(Task!$A$17="",0,IF(ISNUMBER(SEARCH(" "&Task!$A$17&" "," "&LOWER(SUBSTITUTE(SUBSTITUTE(SUBSTITUTE(SUBSTITUTE(A12,"/"," "),"."," "),"\"," "),"_"," "))&" ")),1,0))+IF(Task!$A$18="",0,IF(ISNUMBER(SEARCH(" "&Task!$A$18&" "," "&LOWER(SUBSTITUTE(SUBSTITUTE(SUBSTITUTE(SUBSTITUTE(A12,"/"," "),"."," "),"\"," "),"_"," "))&" ")),1,0))+IF(Task!$A$19="",0,IF(ISNUMBER(SEARCH(" "&Task!$A$19&" "," "&LOWER(SUBSTITUTE(SUBSTITUTE(SUBSTITUTE(SUBSTITUTE(A12,"/"," "),"."," "),"\"," "),"_"," "))&" ")),1,0))) | I12: =IF(OR(E12=0,F12=0,Task!$B$21=0),"",F12/Task!$B$21+0.5*G12+0.25*H12) | J12: =IF(I12="","",I12-ROW()/1000000) | K12: =IF(J12="","",COUNTIF($J$5:$J$404,">"&J12)+1)
E13: =IF(A13="",0,IF(COUNTA(Task!$B$5:$E$5)=0,1,IF(COUNTIF(Task!$B$5:$E$5,B13)>0,1,0))) | F13: =IF(E13=0,0,IF(Task!$A$8="",0,IF(ISNUMBER(SEARCH(" "&Task!$A$8&" "," "&LOWER(D13&" "&C13&" "&LOWER(SUBSTITUTE(SUBSTITUTE(SUBSTITUTE(SUBSTITUTE(A13,"/"," "),"."," "),"\"," "),"_"," ")))&" ")),1,0))+IF(Task!$A$9="",0,IF(ISNUMBER(SEARCH(" "&Task!$A$9&" "," "&LOWER(D13&" "&C13&" "&LOWER(SUBSTITUTE(SUBSTITUTE(SUBSTITUTE(SUBSTITUTE(A13,"/"," "),"."," "),"\"," "),"_"," ")))&" ")),1,0))+IF(Task!$A$10="",0,IF(ISNUMBER(SEARCH(" "&Task!$A$10&" "," "&LOWER(D13&" "&C13&" "&LOWER(SUBSTITUTE(SUBSTITUTE(SUBSTITUTE(SUBSTITUTE(A13,"/"," "),"."," "),"\"," "),"_"," ")))&" ")),1,0))+IF(Task!$A$11="",0,IF(ISNUMBER(SEARCH(" "&Task!$A$11&" "," "&LOWER(D13&" "&C13&" "&LOWER(SUBSTITUTE(SUBSTITUTE(SUBSTITUTE(SUBSTITUTE(A13,"/"," "),"."," "),"\"," "),"_"," ")))&" ")),1,0))+IF(Task!$A$12="",0,IF(ISNUMBER(SEARCH(" "&Task!$A$12&" "," "&LOWER(D13&" "&C13&" "&LOWER(SUBSTITUTE(SUBSTITUTE(SUBSTITUTE(SUBSTITUTE(A13,"/"," "),"."," "),"\"," "),"_"," ")))&" ")),1,0))+IF(Task!$A$13="",0,IF(ISNUMBER(SEARCH(" "&Task!$A$13&" "," "&LOWER(D13&" "&C13&" "&LOWER(SUBSTITUTE(SUBSTITUTE(SUBSTITUTE(SUBSTITUTE(A13,"/"," "),"."," "),"\"," "),"_"," ")))&" ")),1,0))+IF(Task!$A$14="",0,IF(ISNUMBER(SEARCH(" "&Task!$A$14&" "," "&LOWER(D13&" "&C13&" "&LOWER(SUBSTITUTE(SUBSTITUTE(SUBSTITUTE(SUBSTITUTE(A13,"/"," "),"."," "),"\"," "),"_"," ")))&" ")),1,0))+IF(Task!$A$15="",0,IF(ISNUMBER(SEARCH(" "&Task!$A$15&" "," "&LOWER(D13&" "&C13&" "&LOWER(SUBSTITUTE(SUBSTITUTE(SUBSTITUTE(SUBSTITUTE(A13,"/"," "),"."," "),"\"," "),"_"," ")))&" ")),1,0))+IF(Task!$A$16="",0,IF(ISNUMBER(SEARCH(" "&Task!$A$16&" "," "&LOWER(D13&" "&C13&" "&LOWER(SUBSTITUTE(SUBSTITUTE(SUBSTITUTE(SUBSTITUTE(A13,"/"," "),"."," "),"\"," "),"_"," ")))&" ")),1,0))+IF(Task!$A$17="",0,IF(ISNUMBER(SEARCH(" "&Task!$A$17&" "," "&LOWER(D13&" "&C13&" "&LOWER(SUBSTITUTE(SUBSTITUTE(SUBSTITUTE(SUBSTITUTE(A13,"/"," "),"."," "),"\"," "),"_"," ")))&" ")),1,0))+IF(Task!$A$18="",0,IF(ISNUMBER(SEARCH(" "&Task!$A$18&" "," "&LOWER(D13&" "&C13&" "&LOWER(SUBSTITUTE(SUBSTITUTE(SUBSTITUTE(SUBSTITUTE(A13,"/"," "),"."," "),"\"," "),"_"," ")))&" ")),1,0))+IF(Task!$A$19="",0,IF(ISNUMBER(SEARCH(" "&Task!$A$19&" "," "&LOWER(D13&" "&C13&" "&LOWER(SUBSTITUTE(SUBSTITUTE(SUBSTITUTE(SUBSTITUTE(A13,"/"," "),"."," "),"\"," "),"_"," ")))&" ")),1,0))) | G13: =IF(E13=0,0,IF(Task!$A$8="",0,IF(ISNUMBER(SEARCH(" "&Task!$A$8&" "," "&LOWER(C13)&" ")),1,0))+IF(Task!$A$9="",0,IF(ISNUMBER(SEARCH(" "&Task!$A$9&" "," "&LOWER(C13)&" ")),1,0))+IF(Task!$A$10="",0,IF(ISNUMBER(SEARCH(" "&Task!$A$10&" "," "&LOWER(C13)&" ")),1,0))+IF(Task!$A$11="",0,IF(ISNUMBER(SEARCH(" "&Task!$A$11&" "," "&LOWER(C13)&" ")),1,0))+IF(Task!$A$12="",0,IF(ISNUMBER(SEARCH(" "&Task!$A$12&" "," "&LOWER(C13)&" ")),1,0))+IF(Task!$A$13="",0,IF(ISNUMBER(SEARCH(" "&Task!$A$13&" "," "&LOWER(C13)&" ")),1,0))+IF(Task!$A$14="",0,IF(ISNUMBER(SEARCH(" "&Task!$A$14&" "," "&LOWER(C13)&" ")),1,0))+IF(Task!$A$15="",0,IF(ISNUMBER(SEARCH(" "&Task!$A$15&" "," "&LOWER(C13)&" ")),1,0))+IF(Task!$A$16="",0,IF(ISNUMBER(SEARCH(" "&Task!$A$16&" "," "&LOWER(C13)&" ")),1,0))+IF(Task!$A$17="",0,IF(ISNUMBER(SEARCH(" "&Task!$A$17&" "," "&LOWER(C13)&" ")),1,0))+IF(Task!$A$18="",0,IF(ISNUMBER(SEARCH(" "&Task!$A$18&" "," "&LOWER(C13)&" ")),1,0))+IF(Task!$A$19="",0,IF(ISNUMBER(SEARCH(" "&Task!$A$19&" "," "&LOWER(C13)&" ")),1,0))) | H13: =IF(E13=0,0,IF(Task!$A$8="",0,IF(ISNUMBER(SEARCH(" "&Task!$A$8&" "," "&LOWER(SUBSTITUTE(SUBSTITUTE(SUBSTITUTE(SUBSTITUTE(A13,"/"," "),"."," "),"\"," "),"_"," "))&" ")),1,0))+IF(Task!$A$9="",0,IF(ISNUMBER(SEARCH(" "&Task!$A$9&" "," "&LOWER(SUBSTITUTE(SUBSTITUTE(SUBSTITUTE(SUBSTITUTE(A13,"/"," "),"."," "),"\"," "),"_"," "))&" ")),1,0))+IF(Task!$A$10="",0,IF(ISNUMBER(SEARCH(" "&Task!$A$10&" "," "&LOWER(SUBSTITUTE(SUBSTITUTE(SUBSTITUTE(SUBSTITUTE(A13,"/"," "),"."," "),"\"," "),"_"," "))&" ")),1,0))+IF(Task!$A$11="",0,IF(ISNUMBER(SEARCH(" "&Task!$A$11&" "," "&LOWER(SUBSTITUTE(SUBSTITUTE(SUBSTITUTE(SUBSTITUTE(A13,"/"," "),"."," "),"\"," "),"_"," "))&" ")),1,0))+IF(Task!$A$12="",0,IF(ISNUMBER(SEARCH(" "&Task!$A$12&" "," "&LOWER(SUBSTITUTE(SUBSTITUTE(SUBSTITUTE(SUBSTITUTE(A13,"/"," "),"."," "),"\"," "),"_"," "))&" ")),1,0))+IF(Task!$A$13="",0,IF(ISNUMBER(SEARCH(" "&Task!$A$13&" "," "&LOWER(SUBSTITUTE(SUBSTITUTE(SUBSTITUTE(SUBSTITUTE(A13,"/"," "),"."," "),"\"," "),"_"," "))&" ")),1,0))+IF(Task!$A$14="",0,IF(ISNUMBER(SEARCH(" "&Task!$A$14&" "," "&LOWER(SUBSTITUTE(SUBSTITUTE(SUBSTITUTE(SUBSTITUTE(A13,"/"," "),"."," "),"\"," "),"_"," "))&" ")),1,0))+IF(Task!$A$15="",0,IF(ISNUMBER(SEARCH(" "&Task!$A$15&" "," "&LOWER(SUBSTITUTE(SUBSTITUTE(SUBSTITUTE(SUBSTITUTE(A13,"/"," "),"."," "),"\"," "),"_"," "))&" ")),1,0))+IF(Task!$A$16="",0,IF(ISNUMBER(SEARCH(" "&Task!$A$16&" "," "&LOWER(SUBSTITUTE(SUBSTITUTE(SUBSTITUTE(SUBSTITUTE(A13,"/"," "),"."," "),"\"," "),"_"," "))&" ")),1,0))+IF(Task!$A$17="",0,IF(ISNUMBER(SEARCH(" "&Task!$A$17&" "," "&LOWER(SUBSTITUTE(SUBSTITUTE(SUBSTITUTE(SUBSTITUTE(A13,"/"," "),"."," "),"\"," "),"_"," "))&" ")),1,0))+IF(Task!$A$18="",0,IF(ISNUMBER(SEARCH(" "&Task!$A$18&" "," "&LOWER(SUBSTITUTE(SUBSTITUTE(SUBSTITUTE(SUBSTITUTE(A13,"/"," "),"."," "),"\"," "),"_"," "))&" ")),1,0))+IF(Task!$A$19="",0,IF(ISNUMBER(SEARCH(" "&Task!$A$19&" "," "&LOWER(SUBSTITUTE(SUBSTITUTE(SUBSTITUTE(SUBSTITUTE(A13,"/"," "),"."," "),"\"," "),"_"," "))&" ")),1,0))) | I13: =IF(OR(E13=0,F13=0,Task!$B$21=0),"",F13/Task!$B$21+0.5*G13+0.25*H13) | J13: =IF(I13="","",I13-ROW()/1000000) | K13: =IF(J13="","",COUNTIF($J$5:$J$404,">"&J13)+1)
E14: =IF(A14="",0,IF(COUNTA(Task!$B$5:$E$5)=0,1,IF(COUNTIF(Task!$B$5:$E$5,B14)>0,1,0))) | F14: =IF(E14=0,0,IF(Task!$A$8="",0,IF(ISNUMBER(SEARCH(" "&Task!$A$8&" "," "&LOWER(D14&" "&C14&" "&LOWER(SUBSTITUTE(SUBSTITUTE(SUBSTITUTE(SUBSTITUTE(A14,"/"," "),"."," "),"\"," "),"_"," ")))&" ")),1,0))+IF(Task!$A$9="",0,IF(ISNUMBER(SEARCH(" "&Task!$A$9&" "," "&LOWER(D14&" "&C14&" "&LOWER(SUBSTITUTE(SUBSTITUTE(SUBSTITUTE(SUBSTITUTE(A14,"/"," "),"."," "),"\"," "),"_"," ")))&" ")),1,0))+IF(Task!$A$10="",0,IF(ISNUMBER(SEARCH(" "&Task!$A$10&" "," "&LOWER(D14&" "&C14&" "&LOWER(SUBSTITUTE(SUBSTITUTE(SUBSTITUTE(SUBSTITUTE(A14,"/"," "),"."," "),"\"," "),"_"," ")))&" ")),1,0))+IF(Task!$A$11="",0,IF(ISNUMBER(SEARCH(" "&Task!$A$11&" "," "&LOWER(D14&" "&C14&" "&LOWER(SUBSTITUTE(SUBSTITUTE(SUBSTITUTE(SUBSTITUTE(A14,"/"," "),"."," "),"\"," "),"_"," ")))&" ")),1,0))+IF(Task!$A$12="",0,IF(ISNUMBER(SEARCH(" "&Task!$A$12&" "," "&LOWER(D14&" "&C14&" "&LOWER(SUBSTITUTE(SUBSTITUTE(SUBSTITUTE(SUBSTITUTE(A14,"/"," "),"."," "),"\"," "),"_"," ")))&" ")),1,0))+IF(Task!$A$13="",0,IF(ISNUMBER(SEARCH(" "&Task!$A$13&" "," "&LOWER(D14&" "&C14&" "&LOWER(SUBSTITUTE(SUBSTITUTE(SUBSTITUTE(SUBSTITUTE(A14,"/"," "),"."," "),"\"," "),"_"," ")))&" ")),1,0))+IF(Task!$A$14="",0,IF(ISNUMBER(SEARCH(" "&Task!$A$14&" "," "&LOWER(D14&" "&C14&" "&LOWER(SUBSTITUTE(SUBSTITUTE(SUBSTITUTE(SUBSTITUTE(A14,"/"," "),"."," "),"\"," "),"_"," ")))&" ")),1,0))+IF(Task!$A$15="",0,IF(ISNUMBER(SEARCH(" "&Task!$A$15&" "," "&LOWER(D14&" "&C14&" "&LOWER(SUBSTITUTE(SUBSTITUTE(SUBSTITUTE(SUBSTITUTE(A14,"/"," "),"."," "),"\"," "),"_"," ")))&" ")),1,0))+IF(Task!$A$16="",0,IF(ISNUMBER(SEARCH(" "&Task!$A$16&" "," "&LOWER(D14&" "&C14&" "&LOWER(SUBSTITUTE(SUBSTITUTE(SUBSTITUTE(SUBSTITUTE(A14,"/"," "),"."," "),"\"," "),"_"," ")))&" ")),1,0))+IF(Task!$A$17="",0,IF(ISNUMBER(SEARCH(" "&Task!$A$17&" "," "&LOWER(D14&" "&C14&" "&LOWER(SUBSTITUTE(SUBSTITUTE(SUBSTITUTE(SUBSTITUTE(A14,"/"," "),"."," "),"\"," "),"_"," ")))&" ")),1,0))+IF(Task!$A$18="",0,IF(ISNUMBER(SEARCH(" "&Task!$A$18&" "," "&LOWER(D14&" "&C14&" "&LOWER(SUBSTITUTE(SUBSTITUTE(SUBSTITUTE(SUBSTITUTE(A14,"/"," "),"."," "),"\"," "),"_"," ")))&" ")),1,0))+IF(Task!$A$19="",0,IF(ISNUMBER(SEARCH(" "&Task!$A$19&" "," "&LOWER(D14&" "&C14&" "&LOWER(SUBSTITUTE(SUBSTITUTE(SUBSTITUTE(SUBSTITUTE(A14,"/"," "),"."," "),"\"," "),"_"," ")))&" ")),1,0))) | G14: =IF(E14=0,0,IF(Task!$A$8="",0,IF(ISNUMBER(SEARCH(" "&Task!$A$8&" "," "&LOWER(C14)&" ")),1,0))+IF(Task!$A$9="",0,IF(ISNUMBER(SEARCH(" "&Task!$A$9&" "," "&LOWER(C14)&" ")),1,0))+IF(Task!$A$10="",0,IF(ISNUMBER(SEARCH(" "&Task!$A$10&" "," "&LOWER(C14)&" ")),1,0))+IF(Task!$A$11="",0,IF(ISNUMBER(SEARCH(" "&Task!$A$11&" "," "&LOWER(C14)&" ")),1,0))+IF(Task!$A$12="",0,IF(ISNUMBER(SEARCH(" "&Task!$A$12&" "," "&LOWER(C14)&" ")),1,0))+IF(Task!$A$13="",0,IF(ISNUMBER(SEARCH(" "&Task!$A$13&" "," "&LOWER(C14)&" ")),1,0))+IF(Task!$A$14="",0,IF(ISNUMBER(SEARCH(" "&Task!$A$14&" "," "&LOWER(C14)&" ")),1,0))+IF(Task!$A$15="",0,IF(ISNUMBER(SEARCH(" "&Task!$A$15&" "," "&LOWER(C14)&" ")),1,0))+IF(Task!$A$16="",0,IF(ISNUMBER(SEARCH(" "&Task!$A$16&" "," "&LOWER(C14)&" ")),1,0))+IF(Task!$A$17="",0,IF(ISNUMBER(SEARCH(" "&Task!$A$17&" "," "&LOWER(C14)&" ")),1,0))+IF(Task!$A$18="",0,IF(ISNUMBER(SEARCH(" "&Task!$A$18&" "," "&LOWER(C14)&" ")),1,0))+IF(Task!$A$19="",0,IF(ISNUMBER(SEARCH(" "&Task!$A$19&" "," "&LOWER(C14)&" ")),1,0))) | H14: =IF(E14=0,0,IF(Task!$A$8="",0,IF(ISNUMBER(SEARCH(" "&Task!$A$8&" "," "&LOWER(SUBSTITUTE(SUBSTITUTE(SUBSTITUTE(SUBSTITUTE(A14,"/"," "),"."," "),"\"," "),"_"," "))&" ")),1,0))+IF(Task!$A$9="",0,IF(ISNUMBER(SEARCH(" "&Task!$A$9&" "," "&LOWER(SUBSTITUTE(SUBSTITUTE(SUBSTITUTE(SUBSTITUTE(A14,"/"," "),"."," "),"\"," "),"_"," "))&" ")),1,0))+IF(Task!$A$10="",0,IF(ISNUMBER(SEARCH(" "&Task!$A$10&" "," "&LOWER(SUBSTITUTE(SUBSTITUTE(SUBSTITUTE(SUBSTITUTE(A14,"/"," "),"."," "),"\"," "),"_"," "))&" ")),1,0))+IF(Task!$A$11="",0,IF(ISNUMBER(SEARCH(" "&Task!$A$11&" "," "&LOWER(SUBSTITUTE(SUBSTITUTE(SUBSTITUTE(SUBSTITUTE(A14,"/"," "),"."," "),"\"," "),"_"," "))&" ")),1,0))+IF(Task!$A$12="",0,IF(ISNUMBER(SEARCH(" "&Task!$A$12&" "," "&LOWER(SUBSTITUTE(SUBSTITUTE(SUBSTITUTE(SUBSTITUTE(A14,"/"," "),"."," "),"\"," "),"_"," "))&" ")),1,0))+IF(Task!$A$13="",0,IF(ISNUMBER(SEARCH(" "&Task!$A$13&" "," "&LOWER(SUBSTITUTE(SUBSTITUTE(SUBSTITUTE(SUBSTITUTE(A14,"/"," "),"."," "),"\"," "),"_"," "))&" ")),1,0))+IF(Task!$A$14="",0,IF(ISNUMBER(SEARCH(" "&Task!$A$14&" "," "&LOWER(SUBSTITUTE(SUBSTITUTE(SUBSTITUTE(SUBSTITUTE(A14,"/"," "),"."," "),"\"," "),"_"," "))&" ")),1,0))+IF(Task!$A$15="",0,IF(ISNUMBER(SEARCH(" "&Task!$A$15&" "," "&LOWER(SUBSTITUTE(SUBSTITUTE(SUBSTITUTE(SUBSTITUTE(A14,"/"," "),"."," "),"\"," "),"_"," "))&" ")),1,0))+IF(Task!$A$16="",0,IF(ISNUMBER(SEARCH(" "&Task!$A$16&" "," "&LOWER(SUBSTITUTE(SUBSTITUTE(SUBSTITUTE(SUBSTITUTE(A14,"/"," "),"."," "),"\"," "),"_"," "))&" ")),1,0))+IF(Task!$A$17="",0,IF(ISNUMBER(SEARCH(" "&Task!$A$17&" "," "&LOWER(SUBSTITUTE(SUBSTITUTE(SUBSTITUTE(SUBSTITUTE(A14,"/"," "),"."," "),"\"," "),"_"," "))&" ")),1,0))+IF(Task!$A$18="",0,IF(ISNUMBER(SEARCH(" "&Task!$A$18&" "," "&LOWER(SUBSTITUTE(SUBSTITUTE(SUBSTITUTE(SUBSTITUTE(A14,"/"," "),"."," "),"\"," "),"_"," "))&" ")),1,0))+IF(Task!$A$19="",0,IF(ISNUMBER(SEARCH(" "&Task!$A$19&" "," "&LOWER(SUBSTITUTE(SUBSTITUTE(SUBSTITUTE(SUBSTITUTE(A14,"/"," "),"."," "),"\"," "),"_"," "))&" ")),1,0))) | I14: =IF(OR(E14=0,F14=0,Task!$B$21=0),"",F14/Task!$B$21+0.5*G14+0.25*H14) | J14: =IF(I14="","",I14-ROW()/1000000) | K14: =IF(J14="","",COUNTIF($J$5:$J$404,">"&J14)+1)
